{DataVersion:3465,size:[48,20,40],palette:[{Name:"minecraft:blackstone"},{Name:"minecraft:bone_block"},{Name:"minecraft:chest"},{Name:"minecraft:polished_blackstone_bricks"},{Name:"minecraft:soul_lantern"},{Name:"minecraft:structure_block"}],entities:[],blocks:[
{pos:[0,0,0],state:0},
{pos:[1,0,0],state:0},
{pos:[2,0,0],state:0},
{pos:[3,0,0],state:0},
{pos:[4,0,0],state:0},
{pos:[5,0,0],state:0},
{pos:[6,0,0],state:0},
{pos:[7,0,0],state:0},
{pos:[8,0,0],state:0},
{pos:[9,0,0],state:0},
{pos:[10,0,0],state:0},
{pos:[11,0,0],state:0},
{pos:[12,0,0],state:0},
{pos:[13,0,0],state:0},
{pos:[14,0,0],state:0},
{pos:[15,0,0],state:0},
{pos:[16,0,0],state:0},
{pos:[17,0,0],state:0},
{pos:[18,0,0],state:0},
{pos:[19,0,0],state:0},
{pos:[20,0,0],state:0},
{pos:[21,0,0],state:0},
{pos:[22,0,0],state:0},
{pos:[23,0,0],state:0},
{pos:[24,0,0],state:0},
{pos:[25,0,0],state:0},
{pos:[26,0,0],state:0},
{pos:[27,0,0],state:0},
{pos:[28,0,0],state:0},
{pos:[29,0,0],state:0},
{pos:[30,0,0],state:0},
{pos:[31,0,0],state:0},
{pos:[32,0,0],state:0},
{pos:[33,0,0],state:0},
{pos:[34,0,0],state:0},
{pos:[35,0,0],state:0},
{pos:[36,0,0],state:0},
{pos:[37,0,0],state:0},
{pos:[38,0,0],state:0},
{pos:[39,0,0],state:0},
{pos:[40,0,0],state:0},
{pos:[41,0,0],state:0},
{pos:[42,0,0],state:0},
{pos:[43,0,0],state:0},
{pos:[44,0,0],state:0},
{pos:[45,0,0],state:0},
{pos:[46,0,0],state:0},
{pos:[47,0,0],state:0},
{pos:[0,0,1],state:0},
{pos:[1,0,1],state:0},
{pos:[2,0,1],state:0},
{pos:[3,0,1],state:0},
{pos:[4,0,1],state:0},
{pos:[5,0,1],state:0},
{pos:[6,0,1],state:0},
{pos:[7,0,1],state:0},
{pos:[8,0,1],state:0},
{pos:[9,0,1],state:0},
{pos:[10,0,1],state:0},
{pos:[11,0,1],state:0},
{pos:[12,0,1],state:0},
{pos:[13,0,1],state:0},
{pos:[14,0,1],state:0},
{pos:[15,0,1],state:0},
{pos:[16,0,1],state:0},
{pos:[17,0,1],state:0},
{pos:[18,0,1],state:0},
{pos:[19,0,1],state:0},
{pos:[20,0,1],state:0},
{pos:[21,0,1],state:0},
{pos:[22,0,1],state:0},
{pos:[23,0,1],state:0},
{pos:[24,0,1],state:0},
{pos:[25,0,1],state:0},
{pos:[26,0,1],state:0},
{pos:[27,0,1],state:0},
{pos:[28,0,1],state:0},
{pos:[29,0,1],state:0},
{pos:[30,0,1],state:0},
{pos:[31,0,1],state:0},
{pos:[32,0,1],state:0},
{pos:[33,0,1],state:0},
{pos:[34,0,1],state:0},
{pos:[35,0,1],state:0},
{pos:[36,0,1],state:0},
{pos:[37,0,1],state:0},
{pos:[38,0,1],state:0},
{pos:[39,0,1],state:0},
{pos:[40,0,1],state:0},
{pos:[41,0,1],state:0},
{pos:[42,0,1],state:0},
{pos:[43,0,1],state:0},
{pos:[44,0,1],state:0},
{pos:[45,0,1],state:0},
{pos:[46,0,1],state:0},
{pos:[47,0,1],state:0},
{pos:[0,0,2],state:0},
{pos:[1,0,2],state:0},
{pos:[2,0,2],state:0},
{pos:[3,0,2],state:0},
{pos:[4,0,2],state:0},
{pos:[5,0,2],state:0},
{pos:[6,0,2],state:0},
{pos:[7,0,2],state:0},
{pos:[8,0,2],state:0},
{pos:[9,0,2],state:0},
{pos:[10,0,2],state:0},
{pos:[11,0,2],state:0},
{pos:[12,0,2],state:0},
{pos:[13,0,2],state:0},
{pos:[14,0,2],state:0},
{pos:[15,0,2],state:0},
{pos:[16,0,2],state:0},
{pos:[17,0,2],state:0},
{pos:[18,0,2],state:0},
{pos:[19,0,2],state:0},
{pos:[20,0,2],state:0},
{pos:[21,0,2],state:0},
{pos:[22,0,2],state:0},
{pos:[23,0,2],state:0},
{pos:[24,0,2],state:0},
{pos:[25,0,2],state:0},
{pos:[26,0,2],state:0},
{pos:[27,0,2],state:0},
{pos:[28,0,2],state:0},
{pos:[29,0,2],state:0},
{pos:[30,0,2],state:0},
{pos:[31,0,2],state:0},
{pos:[32,0,2],state:0},
{pos:[33,0,2],state:0},
{pos:[34,0,2],state:0},
{pos:[35,0,2],state:0},
{pos:[36,0,2],state:0},
{pos:[37,0,2],state:0},
{pos:[38,0,2],state:0},
{pos:[39,0,2],state:0},
{pos:[40,0,2],state:0},
{pos:[41,0,2],state:0},
{pos:[42,0,2],state:0},
{pos:[43,0,2],state:0},
{pos:[44,0,2],state:0},
{pos:[45,0,2],state:0},
{pos:[46,0,2],state:0},
{pos:[47,0,2],state:0},
{pos:[0,0,3],state:0},
{pos:[1,0,3],state:0},
{pos:[2,0,3],state:0},
{pos:[3,0,3],state:0},
{pos:[4,0,3],state:0},
{pos:[5,0,3],state:0},
{pos:[6,0,3],state:0},
{pos:[7,0,3],state:0},
{pos:[8,0,3],state:0},
{pos:[9,0,3],state:0},
{pos:[10,0,3],state:0},
{pos:[11,0,3],state:0},
{pos:[12,0,3],state:0},
{pos:[13,0,3],state:0},
{pos:[14,0,3],state:0},
{pos:[15,0,3],state:0},
{pos:[16,0,3],state:0},
{pos:[17,0,3],state:0},
{pos:[18,0,3],state:0},
{pos:[19,0,3],state:0},
{pos:[20,0,3],state:0},
{pos:[21,0,3],state:0},
{pos:[22,0,3],state:0},
{pos:[23,0,3],state:0},
{pos:[24,0,3],state:0},
{pos:[25,0,3],state:0},
{pos:[26,0,3],state:0},
{pos:[27,0,3],state:0},
{pos:[28,0,3],state:0},
{pos:[29,0,3],state:0},
{pos:[30,0,3],state:0},
{pos:[31,0,3],state:0},
{pos:[32,0,3],state:0},
{pos:[33,0,3],state:0},
{pos:[34,0,3],state:0},
{pos:[35,0,3],state:0},
{pos:[36,0,3],state:0},
{pos:[37,0,3],state:0},
{pos:[38,0,3],state:0},
{pos:[39,0,3],state:0},
{pos:[40,0,3],state:0},
{pos:[41,0,3],state:0},
{pos:[42,0,3],state:0},
{pos:[43,0,3],state:0},
{pos:[44,0,3],state:0},
{pos:[45,0,3],state:0},
{pos:[46,0,3],state:0},
{pos:[47,0,3],state:0},
{pos:[0,0,4],state:0},
{pos:[1,0,4],state:0},
{pos:[2,0,4],state:0},
{pos:[3,0,4],state:0},
{pos:[4,0,4],state:0},
{pos:[5,0,4],state:0},
{pos:[6,0,4],state:0},
{pos:[7,0,4],state:0},
{pos:[8,0,4],state:0},
{pos:[9,0,4],state:0},
{pos:[10,0,4],state:0},
{pos:[11,0,4],state:0},
{pos:[12,0,4],state:0},
{pos:[13,0,4],state:0},
{pos:[14,0,4],state:0},
{pos:[15,0,4],state:0},
{pos:[16,0,4],state:0},
{pos:[17,0,4],state:0},
{pos:[18,0,4],state:0},
{pos:[19,0,4],state:0},
{pos:[20,0,4],state:0},
{pos:[21,0,4],state:0},
{pos:[22,0,4],state:0},
{pos:[23,0,4],state:0},
{pos:[24,0,4],state:0},
{pos:[25,0,4],state:0},
{pos:[26,0,4],state:0},
{pos:[27,0,4],state:0},
{pos:[28,0,4],state:0},
{pos:[29,0,4],state:0},
{pos:[30,0,4],state:0},
{pos:[31,0,4],state:0},
{pos:[32,0,4],state:0},
{pos:[33,0,4],state:0},
{pos:[34,0,4],state:0},
{pos:[35,0,4],state:0},
{pos:[36,0,4],state:0},
{pos:[37,0,4],state:0},
{pos:[38,0,4],state:0},
{pos:[39,0,4],state:0},
{pos:[40,0,4],state:0},
{pos:[41,0,4],state:0},
{pos:[42,0,4],state:0},
{pos:[43,0,4],state:0},
{pos:[44,0,4],state:0},
{pos:[45,0,4],state:0},
{pos:[46,0,4],state:0},
{pos:[47,0,4],state:0},
{pos:[0,0,5],state:0},
{pos:[1,0,5],state:0},
{pos:[2,0,5],state:0},
{pos:[3,0,5],state:0},
{pos:[4,0,5],state:0},
{pos:[5,0,5],state:0},
{pos:[6,0,5],state:0},
{pos:[7,0,5],state:0},
{pos:[8,0,5],state:0},
{pos:[9,0,5],state:0},
{pos:[10,0,5],state:0},
{pos:[11,0,5],state:0},
{pos:[12,0,5],state:0},
{pos:[13,0,5],state:0},
{pos:[14,0,5],state:0},
{pos:[15,0,5],state:0},
{pos:[16,0,5],state:0},
{pos:[17,0,5],state:0},
{pos:[18,0,5],state:0},
{pos:[19,0,5],state:0},
{pos:[20,0,5],state:0},
{pos:[21,0,5],state:0},
{pos:[22,0,5],state:0},
{pos:[23,0,5],state:0},
{pos:[24,0,5],state:0},
{pos:[25,0,5],state:0},
{pos:[26,0,5],state:0},
{pos:[27,0,5],state:0},
{pos:[28,0,5],state:0},
{pos:[29,0,5],state:0},
{pos:[30,0,5],state:0},
{pos:[31,0,5],state:0},
{pos:[32,0,5],state:0},
{pos:[33,0,5],state:0},
{pos:[34,0,5],state:0},
{pos:[35,0,5],state:0},
{pos:[36,0,5],state:0},
{pos:[37,0,5],state:0},
{pos:[38,0,5],state:0},
{pos:[39,0,5],state:0},
{pos:[40,0,5],state:0},
{pos:[41,0,5],state:0},
{pos:[42,0,5],state:0},
{pos:[43,0,5],state:0},
{pos:[44,0,5],state:0},
{pos:[45,0,5],state:0},
{pos:[46,0,5],state:0},
{pos:[47,0,5],state:0},
{pos:[0,0,6],state:0},
{pos:[1,0,6],state:0},
{pos:[2,0,6],state:0},
{pos:[3,0,6],state:0},
{pos:[4,0,6],state:0},
{pos:[5,0,6],state:0},
{pos:[6,0,6],state:0},
{pos:[7,0,6],state:0},
{pos:[8,0,6],state:0},
{pos:[9,0,6],state:0},
{pos:[10,0,6],state:0},
{pos:[11,0,6],state:0},
{pos:[12,0,6],state:0},
{pos:[13,0,6],state:0},
{pos:[14,0,6],state:0},
{pos:[15,0,6],state:0},
{pos:[16,0,6],state:0},
{pos:[17,0,6],state:0},
{pos:[18,0,6],state:0},
{pos:[19,0,6],state:0},
{pos:[20,0,6],state:0},
{pos:[21,0,6],state:0},
{pos:[22,0,6],state:0},
{pos:[23,0,6],state:0},
{pos:[24,0,6],state:0},
{pos:[25,0,6],state:0},
{pos:[26,0,6],state:0},
{pos:[27,0,6],state:0},
{pos:[28,0,6],state:0},
{pos:[29,0,6],state:0},
{pos:[30,0,6],state:0},
{pos:[31,0,6],state:0},
{pos:[32,0,6],state:0},
{pos:[33,0,6],state:0},
{pos:[34,0,6],state:0},
{pos:[35,0,6],state:0},
{pos:[36,0,6],state:0},
{pos:[37,0,6],state:0},
{pos:[38,0,6],state:0},
{pos:[39,0,6],state:0},
{pos:[40,0,6],state:0},
{pos:[41,0,6],state:0},
{pos:[42,0,6],state:0},
{pos:[43,0,6],state:0},
{pos:[44,0,6],state:0},
{pos:[45,0,6],state:0},
{pos:[46,0,6],state:0},
{pos:[47,0,6],state:0},
{pos:[0,0,7],state:0},
{pos:[1,0,7],state:0},
{pos:[2,0,7],state:0},
{pos:[3,0,7],state:0},
{pos:[4,0,7],state:0},
{pos:[5,0,7],state:0},
{pos:[6,0,7],state:0},
{pos:[7,0,7],state:0},
{pos:[8,0,7],state:0},
{pos:[9,0,7],state:0},
{pos:[10,0,7],state:0},
{pos:[11,0,7],state:0},
{pos:[12,0,7],state:0},
{pos:[13,0,7],state:0},
{pos:[14,0,7],state:0},
{pos:[15,0,7],state:0},
{pos:[16,0,7],state:0},
{pos:[17,0,7],state:0},
{pos:[18,0,7],state:0},
{pos:[19,0,7],state:0},
{pos:[20,0,7],state:0},
{pos:[21,0,7],state:0},
{pos:[22,0,7],state:0},
{pos:[23,0,7],state:0},
{pos:[24,0,7],state:0},
{pos:[25,0,7],state:0},
{pos:[26,0,7],state:0},
{pos:[27,0,7],state:0},
{pos:[28,0,7],state:0},
{pos:[29,0,7],state:0},
{pos:[30,0,7],state:0},
{pos:[31,0,7],state:0},
{pos:[32,0,7],state:0},
{pos:[33,0,7],state:0},
{pos:[34,0,7],state:0},
{pos:[35,0,7],state:0},
{pos:[36,0,7],state:0},
{pos:[37,0,7],state:0},
{pos:[38,0,7],state:0},
{pos:[39,0,7],state:0},
{pos:[40,0,7],state:0},
{pos:[41,0,7],state:0},
{pos:[42,0,7],state:0},
{pos:[43,0,7],state:0},
{pos:[44,0,7],state:0},
{pos:[45,0,7],state:0},
{pos:[46,0,7],state:0},
{pos:[47,0,7],state:0},
{pos:[0,0,8],state:0},
{pos:[1,0,8],state:0},
{pos:[2,0,8],state:0},
{pos:[3,0,8],state:0},
{pos:[4,0,8],state:0},
{pos:[5,0,8],state:0},
{pos:[6,0,8],state:0},
{pos:[7,0,8],state:0},
{pos:[8,0,8],state:0},
{pos:[9,0,8],state:0},
{pos:[10,0,8],state:0},
{pos:[11,0,8],state:0},
{pos:[12,0,8],state:0},
{pos:[13,0,8],state:0},
{pos:[14,0,8],state:0},
{pos:[15,0,8],state:0},
{pos:[16,0,8],state:0},
{pos:[17,0,8],state:0},
{pos:[18,0,8],state:0},
{pos:[19,0,8],state:0},
{pos:[20,0,8],state:0},
{pos:[21,0,8],state:0},
{pos:[22,0,8],state:0},
{pos:[23,0,8],state:0},
{pos:[24,0,8],state:0},
{pos:[25,0,8],state:0},
{pos:[26,0,8],state:0},
{pos:[27,0,8],state:0},
{pos:[28,0,8],state:0},
{pos:[29,0,8],state:0},
{pos:[30,0,8],state:0},
{pos:[31,0,8],state:0},
{pos:[32,0,8],state:0},
{pos:[33,0,8],state:0},
{pos:[34,0,8],state:0},
{pos:[35,0,8],state:0},
{pos:[36,0,8],state:0},
{pos:[37,0,8],state:0},
{pos:[38,0,8],state:0},
{pos:[39,0,8],state:0},
{pos:[40,0,8],state:0},
{pos:[41,0,8],state:0},
{pos:[42,0,8],state:0},
{pos:[43,0,8],state:0},
{pos:[44,0,8],state:0},
{pos:[45,0,8],state:0},
{pos:[46,0,8],state:0},
{pos:[47,0,8],state:0},
{pos:[0,0,9],state:0},
{pos:[1,0,9],state:0},
{pos:[2,0,9],state:0},
{pos:[3,0,9],state:0},
{pos:[4,0,9],state:0},
{pos:[5,0,9],state:0},
{pos:[6,0,9],state:0},
{pos:[7,0,9],state:0},
{pos:[8,0,9],state:0},
{pos:[9,0,9],state:0},
{pos:[10,0,9],state:0},
{pos:[11,0,9],state:0},
{pos:[12,0,9],state:0},
{pos:[13,0,9],state:0},
{pos:[14,0,9],state:0},
{pos:[15,0,9],state:0},
{pos:[16,0,9],state:0},
{pos:[17,0,9],state:0},
{pos:[18,0,9],state:0},
{pos:[19,0,9],state:0},
{pos:[20,0,9],state:0},
{pos:[21,0,9],state:0},
{pos:[22,0,9],state:0},
{pos:[23,0,9],state:0},
{pos:[24,0,9],state:0},
{pos:[25,0,9],state:0},
{pos:[26,0,9],state:0},
{pos:[27,0,9],state:0},
{pos:[28,0,9],state:0},
{pos:[29,0,9],state:0},
{pos:[30,0,9],state:0},
{pos:[31,0,9],state:0},
{pos:[32,0,9],state:0},
{pos:[33,0,9],state:0},
{pos:[34,0,9],state:0},
{pos:[35,0,9],state:0},
{pos:[36,0,9],state:0},
{pos:[37,0,9],state:0},
{pos:[38,0,9],state:0},
{pos:[39,0,9],state:0},
{pos:[40,0,9],state:0},
{pos:[41,0,9],state:0},
{pos:[42,0,9],state:0},
{pos:[43,0,9],state:0},
{pos:[44,0,9],state:0},
{pos:[45,0,9],state:0},
{pos:[46,0,9],state:0},
{pos:[47,0,9],state:0},
{pos:[0,0,10],state:0},
{pos:[1,0,10],state:0},
{pos:[2,0,10],state:0},
{pos:[3,0,10],state:0},
{pos:[4,0,10],state:0},
{pos:[5,0,10],state:0},
{pos:[6,0,10],state:0},
{pos:[7,0,10],state:0},
{pos:[8,0,10],state:0},
{pos:[9,0,10],state:0},
{pos:[10,0,10],state:0},
{pos:[11,0,10],state:0},
{pos:[12,0,10],state:0},
{pos:[13,0,10],state:0},
{pos:[14,0,10],state:0},
{pos:[15,0,10],state:0},
{pos:[16,0,10],state:0},
{pos:[17,0,10],state:0},
{pos:[18,0,10],state:0},
{pos:[19,0,10],state:0},
{pos:[20,0,10],state:0},
{pos:[21,0,10],state:0},
{pos:[22,0,10],state:0},
{pos:[23,0,10],state:0},
{pos:[24,0,10],state:0},
{pos:[25,0,10],state:0},
{pos:[26,0,10],state:0},
{pos:[27,0,10],state:0},
{pos:[28,0,10],state:0},
{pos:[29,0,10],state:0},
{pos:[30,0,10],state:0},
{pos:[31,0,10],state:0},
{pos:[32,0,10],state:0},
{pos:[33,0,10],state:0},
{pos:[34,0,10],state:0},
{pos:[35,0,10],state:0},
{pos:[36,0,10],state:0},
{pos:[37,0,10],state:0},
{pos:[38,0,10],state:0},
{pos:[39,0,10],state:0},
{pos:[40,0,10],state:0},
{pos:[41,0,10],state:0},
{pos:[42,0,10],state:0},
{pos:[43,0,10],state:0},
{pos:[44,0,10],state:0},
{pos:[45,0,10],state:0},
{pos:[46,0,10],state:0},
{pos:[47,0,10],state:0},
{pos:[0,0,11],state:0},
{pos:[1,0,11],state:0},
{pos:[2,0,11],state:0},
{pos:[3,0,11],state:0},
{pos:[4,0,11],state:0},
{pos:[5,0,11],state:0},
{pos:[6,0,11],state:0},
{pos:[7,0,11],state:0},
{pos:[8,0,11],state:0},
{pos:[9,0,11],state:0},
{pos:[10,0,11],state:0},
{pos:[11,0,11],state:0},
{pos:[12,0,11],state:0},
{pos:[13,0,11],state:0},
{pos:[14,0,11],state:0},
{pos:[15,0,11],state:0},
{pos:[16,0,11],state:0},
{pos:[17,0,11],state:0},
{pos:[18,0,11],state:0},
{pos:[19,0,11],state:0},
{pos:[20,0,11],state:0},
{pos:[21,0,11],state:0},
{pos:[22,0,11],state:0},
{pos:[23,0,11],state:0},
{pos:[24,0,11],state:0},
{pos:[25,0,11],state:0},
{pos:[26,0,11],state:0},
{pos:[27,0,11],state:0},
{pos:[28,0,11],state:0},
{pos:[29,0,11],state:0},
{pos:[30,0,11],state:0},
{pos:[31,0,11],state:0},
{pos:[32,0,11],state:0},
{pos:[33,0,11],state:0},
{pos:[34,0,11],state:0},
{pos:[35,0,11],state:0},
{pos:[36,0,11],state:0},
{pos:[37,0,11],state:0},
{pos:[38,0,11],state:0},
{pos:[39,0,11],state:0},
{pos:[40,0,11],state:0},
{pos:[41,0,11],state:0},
{pos:[42,0,11],state:0},
{pos:[43,0,11],state:0},
{pos:[44,0,11],state:0},
{pos:[45,0,11],state:0},
{pos:[46,0,11],state:0},
{pos:[47,0,11],state:0},
{pos:[0,0,12],state:0},
{pos:[1,0,12],state:0},
{pos:[2,0,12],state:0},
{pos:[3,0,12],state:0},
{pos:[4,0,12],state:0},
{pos:[5,0,12],state:0},
{pos:[6,0,12],state:0},
{pos:[7,0,12],state:0},
{pos:[8,0,12],state:0},
{pos:[9,0,12],state:0},
{pos:[10,0,12],state:0},
{pos:[11,0,12],state:0},
{pos:[12,0,12],state:0},
{pos:[13,0,12],state:0},
{pos:[14,0,12],state:0},
{pos:[15,0,12],state:0},
{pos:[16,0,12],state:0},
{pos:[17,0,12],state:0},
{pos:[18,0,12],state:0},
{pos:[19,0,12],state:0},
{pos:[20,0,12],state:0},
{pos:[21,0,12],state:0},
{pos:[22,0,12],state:0},
{pos:[23,0,12],state:0},
{pos:[24,0,12],state:0},
{pos:[25,0,12],state:0},
{pos:[26,0,12],state:0},
{pos:[27,0,12],state:0},
{pos:[28,0,12],state:0},
{pos:[29,0,12],state:0},
{pos:[30,0,12],state:0},
{pos:[31,0,12],state:0},
{pos:[32,0,12],state:0},
{pos:[33,0,12],state:0},
{pos:[34,0,12],state:0},
{pos:[35,0,12],state:0},
{pos:[36,0,12],state:0},
{pos:[37,0,12],state:0},
{pos:[38,0,12],state:0},
{pos:[39,0,12],state:0},
{pos:[40,0,12],state:0},
{pos:[41,0,12],state:0},
{pos:[42,0,12],state:0},
{pos:[43,0,12],state:0},
{pos:[44,0,12],state:0},
{pos:[45,0,12],state:0},
{pos:[46,0,12],state:0},
{pos:[47,0,12],state:0},
{pos:[0,0,13],state:0},
{pos:[1,0,13],state:0},
{pos:[2,0,13],state:0},
{pos:[3,0,13],state:0},
{pos:[4,0,13],state:0},
{pos:[5,0,13],state:0},
{pos:[6,0,13],state:0},
{pos:[7,0,13],state:0},
{pos:[8,0,13],state:0},
{pos:[9,0,13],state:0},
{pos:[10,0,13],state:0},
{pos:[11,0,13],state:0},
{pos:[12,0,13],state:0},
{pos:[13,0,13],state:0},
{pos:[14,0,13],state:0},
{pos:[15,0,13],state:0},
{pos:[16,0,13],state:0},
{pos:[17,0,13],state:0},
{pos:[18,0,13],state:0},
{pos:[19,0,13],state:0},
{pos:[20,0,13],state:0},
{pos:[21,0,13],state:0},
{pos:[22,0,13],state:0},
{pos:[23,0,13],state:0},
{pos:[24,0,13],state:0},
{pos:[25,0,13],state:0},
{pos:[26,0,13],state:0},
{pos:[27,0,13],state:0},
{pos:[28,0,13],state:0},
{pos:[29,0,13],state:0},
{pos:[30,0,13],state:0},
{pos:[31,0,13],state:0},
{pos:[32,0,13],state:0},
{pos:[33,0,13],state:0},
{pos:[34,0,13],state:0},
{pos:[35,0,13],state:0},
{pos:[36,0,13],state:0},
{pos:[37,0,13],state:0},
{pos:[38,0,13],state:0},
{pos:[39,0,13],state:0},
{pos:[40,0,13],state:0},
{pos:[41,0,13],state:0},
{pos:[42,0,13],state:0},
{pos:[43,0,13],state:0},
{pos:[44,0,13],state:0},
{pos:[45,0,13],state:0},
{pos:[46,0,13],state:0},
{pos:[47,0,13],state:0},
{pos:[0,0,14],state:0},
{pos:[1,0,14],state:0},
{pos:[2,0,14],state:0},
{pos:[3,0,14],state:0},
{pos:[4,0,14],state:0},
{pos:[5,0,14],state:0},
{pos:[6,0,14],state:0},
{pos:[7,0,14],state:0},
{pos:[8,0,14],state:0},
{pos:[9,0,14],state:0},
{pos:[10,0,14],state:0},
{pos:[11,0,14],state:0},
{pos:[12,0,14],state:0},
{pos:[13,0,14],state:0},
{pos:[14,0,14],state:0},
{pos:[15,0,14],state:0},
{pos:[16,0,14],state:0},
{pos:[17,0,14],state:0},
{pos:[18,0,14],state:0},
{pos:[19,0,14],state:0},
{pos:[20,0,14],state:0},
{pos:[21,0,14],state:0},
{pos:[22,0,14],state:0},
{pos:[23,0,14],state:0},
{pos:[24,0,14],state:0},
{pos:[25,0,14],state:0},
{pos:[26,0,14],state:0},
{pos:[27,0,14],state:0},
{pos:[28,0,14],state:0},
{pos:[29,0,14],state:0},
{pos:[30,0,14],state:0},
{pos:[31,0,14],state:0},
{pos:[32,0,14],state:0},
{pos:[33,0,14],state:0},
{pos:[34,0,14],state:0},
{pos:[35,0,14],state:0},
{pos:[36,0,14],state:0},
{pos:[37,0,14],state:0},
{pos:[38,0,14],state:0},
{pos:[39,0,14],state:0},
{pos:[40,0,14],state:0},
{pos:[41,0,14],state:0},
{pos:[42,0,14],state:0},
{pos:[43,0,14],state:0},
{pos:[44,0,14],state:0},
{pos:[45,0,14],state:0},
{pos:[46,0,14],state:0},
{pos:[47,0,14],state:0},
{pos:[0,0,15],state:0},
{pos:[1,0,15],state:0},
{pos:[2,0,15],state:0},
{pos:[3,0,15],state:0},
{pos:[4,0,15],state:0},
{pos:[5,0,15],state:0},
{pos:[6,0,15],state:0},
{pos:[7,0,15],state:0},
{pos:[8,0,15],state:0},
{pos:[9,0,15],state:0},
{pos:[10,0,15],state:0},
{pos:[11,0,15],state:0},
{pos:[12,0,15],state:0},
{pos:[13,0,15],state:0},
{pos:[14,0,15],state:0},
{pos:[15,0,15],state:0},
{pos:[16,0,15],state:0},
{pos:[17,0,15],state:0},
{pos:[18,0,15],state:0},
{pos:[19,0,15],state:0},
{pos:[20,0,15],state:0},
{pos:[21,0,15],state:0},
{pos:[22,0,15],state:0},
{pos:[23,0,15],state:0},
{pos:[24,0,15],state:0},
{pos:[25,0,15],state:0},
{pos:[26,0,15],state:0},
{pos:[27,0,15],state:0},
{pos:[28,0,15],state:0},
{pos:[29,0,15],state:0},
{pos:[30,0,15],state:0},
{pos:[31,0,15],state:0},
{pos:[32,0,15],state:0},
{pos:[33,0,15],state:0},
{pos:[34,0,15],state:0},
{pos:[35,0,15],state:0},
{pos:[36,0,15],state:0},
{pos:[37,0,15],state:0},
{pos:[38,0,15],state:0},
{pos:[39,0,15],state:0},
{pos:[40,0,15],state:0},
{pos:[41,0,15],state:0},
{pos:[42,0,15],state:0},
{pos:[43,0,15],state:0},
{pos:[44,0,15],state:0},
{pos:[45,0,15],state:0},
{pos:[46,0,15],state:0},
{pos:[47,0,15],state:0},
{pos:[0,0,16],state:0},
{pos:[1,0,16],state:0},
{pos:[2,0,16],state:0},
{pos:[3,0,16],state:0},
{pos:[4,0,16],state:0},
{pos:[5,0,16],state:0},
{pos:[6,0,16],state:0},
{pos:[7,0,16],state:0},
{pos:[8,0,16],state:0},
{pos:[9,0,16],state:0},
{pos:[10,0,16],state:0},
{pos:[11,0,16],state:0},
{pos:[12,0,16],state:0},
{pos:[13,0,16],state:0},
{pos:[14,0,16],state:0},
{pos:[15,0,16],state:0},
{pos:[16,0,16],state:0},
{pos:[17,0,16],state:0},
{pos:[18,0,16],state:0},
{pos:[19,0,16],state:0},
{pos:[20,0,16],state:0},
{pos:[21,0,16],state:0},
{pos:[22,0,16],state:0},
{pos:[23,0,16],state:0},
{pos:[24,0,16],state:0},
{pos:[25,0,16],state:0},
{pos:[26,0,16],state:0},
{pos:[27,0,16],state:0},
{pos:[28,0,16],state:0},
{pos:[29,0,16],state:0},
{pos:[30,0,16],state:0},
{pos:[31,0,16],state:0},
{pos:[32,0,16],state:0},
{pos:[33,0,16],state:0},
{pos:[34,0,16],state:0},
{pos:[35,0,16],state:0},
{pos:[36,0,16],state:0},
{pos:[37,0,16],state:0},
{pos:[38,0,16],state:0},
{pos:[39,0,16],state:0},
{pos:[40,0,16],state:0},
{pos:[41,0,16],state:0},
{pos:[42,0,16],state:0},
{pos:[43,0,16],state:0},
{pos:[44,0,16],state:0},
{pos:[45,0,16],state:0},
{pos:[46,0,16],state:0},
{pos:[47,0,16],state:0},
{pos:[0,0,17],state:0},
{pos:[1,0,17],state:0},
{pos:[2,0,17],state:0},
{pos:[3,0,17],state:0},
{pos:[4,0,17],state:0},
{pos:[5,0,17],state:0},
{pos:[6,0,17],state:0},
{pos:[7,0,17],state:0},
{pos:[8,0,17],state:0},
{pos:[9,0,17],state:0},
{pos:[10,0,17],state:0},
{pos:[11,0,17],state:0},
{pos:[12,0,17],state:0},
{pos:[13,0,17],state:0},
{pos:[14,0,17],state:0},
{pos:[15,0,17],state:0},
{pos:[16,0,17],state:0},
{pos:[17,0,17],state:0},
{pos:[18,0,17],state:0},
{pos:[19,0,17],state:0},
{pos:[20,0,17],state:0},
{pos:[21,0,17],state:0},
{pos:[22,0,17],state:0},
{pos:[23,0,17],state:0},
{pos:[24,0,17],state:0},
{pos:[25,0,17],state:0},
{pos:[26,0,17],state:0},
{pos:[27,0,17],state:0},
{pos:[28,0,17],state:0},
{pos:[29,0,17],state:0},
{pos:[30,0,17],state:0},
{pos:[31,0,17],state:0},
{pos:[32,0,17],state:0},
{pos:[33,0,17],state:0},
{pos:[34,0,17],state:0},
{pos:[35,0,17],state:0},
{pos:[36,0,17],state:0},
{pos:[37,0,17],state:0},
{pos:[38,0,17],state:0},
{pos:[39,0,17],state:0},
{pos:[40,0,17],state:0},
{pos:[41,0,17],state:0},
{pos:[42,0,17],state:0},
{pos:[43,0,17],state:0},
{pos:[44,0,17],state:0},
{pos:[45,0,17],state:0},
{pos:[46,0,17],state:0},
{pos:[47,0,17],state:0},
{pos:[0,0,18],state:0},
{pos:[1,0,18],state:0},
{pos:[2,0,18],state:0},
{pos:[3,0,18],state:0},
{pos:[4,0,18],state:0},
{pos:[5,0,18],state:0},
{pos:[6,0,18],state:0},
{pos:[7,0,18],state:0},
{pos:[8,0,18],state:0},
{pos:[9,0,18],state:0},
{pos:[10,0,18],state:0},
{pos:[11,0,18],state:0},
{pos:[12,0,18],state:0},
{pos:[13,0,18],state:0},
{pos:[14,0,18],state:0},
{pos:[15,0,18],state:0},
{pos:[16,0,18],state:0},
{pos:[17,0,18],state:0},
{pos:[18,0,18],state:0},
{pos:[19,0,18],state:0},
{pos:[20,0,18],state:0},
{pos:[21,0,18],state:0},
{pos:[22,0,18],state:0},
{pos:[23,0,18],state:0},
{pos:[24,0,18],state:0},
{pos:[25,0,18],state:0},
{pos:[26,0,18],state:0},
{pos:[27,0,18],state:0},
{pos:[28,0,18],state:0},
{pos:[29,0,18],state:0},
{pos:[30,0,18],state:0},
{pos:[31,0,18],state:0},
{pos:[32,0,18],state:0},
{pos:[33,0,18],state:0},
{pos:[34,0,18],state:0},
{pos:[35,0,18],state:0},
{pos:[36,0,18],state:0},
{pos:[37,0,18],state:0},
{pos:[38,0,18],state:0},
{pos:[39,0,18],state:0},
{pos:[40,0,18],state:0},
{pos:[41,0,18],state:0},
{pos:[42,0,18],state:0},
{pos:[43,0,18],state:0},
{pos:[44,0,18],state:0},
{pos:[45,0,18],state:0},
{pos:[46,0,18],state:0},
{pos:[47,0,18],state:0},
{pos:[0,0,19],state:0},
{pos:[1,0,19],state:0},
{pos:[2,0,19],state:0},
{pos:[3,0,19],state:0},
{pos:[4,0,19],state:0},
{pos:[5,0,19],state:0},
{pos:[6,0,19],state:0},
{pos:[7,0,19],state:0},
{pos:[8,0,19],state:0},
{pos:[9,0,19],state:0},
{pos:[10,0,19],state:0},
{pos:[11,0,19],state:0},
{pos:[12,0,19],state:0},
{pos:[13,0,19],state:0},
{pos:[14,0,19],state:0},
{pos:[15,0,19],state:0},
{pos:[16,0,19],state:0},
{pos:[17,0,19],state:0},
{pos:[18,0,19],state:0},
{pos:[19,0,19],state:0},
{pos:[20,0,19],state:0},
{pos:[21,0,19],state:0},
{pos:[22,0,19],state:0},
{pos:[23,0,19],state:0},
{pos:[24,0,19],state:0},
{pos:[25,0,19],state:0},
{pos:[26,0,19],state:0},
{pos:[27,0,19],state:0},
{pos:[28,0,19],state:0},
{pos:[29,0,19],state:0},
{pos:[30,0,19],state:0},
{pos:[31,0,19],state:0},
{pos:[32,0,19],state:0},
{pos:[33,0,19],state:0},
{pos:[34,0,19],state:0},
{pos:[35,0,19],state:0},
{pos:[36,0,19],state:0},
{pos:[37,0,19],state:0},
{pos:[38,0,19],state:0},
{pos:[39,0,19],state:0},
{pos:[40,0,19],state:0},
{pos:[41,0,19],state:0},
{pos:[42,0,19],state:0},
{pos:[43,0,19],state:0},
{pos:[44,0,19],state:0},
{pos:[45,0,19],state:0},
{pos:[46,0,19],state:0},
{pos:[47,0,19],state:0},
{pos:[0,0,20],state:0},
{pos:[1,0,20],state:0},
{pos:[2,0,20],state:0},
{pos:[3,0,20],state:0},
{pos:[4,0,20],state:0},
{pos:[5,0,20],state:0},
{pos:[6,0,20],state:0},
{pos:[7,0,20],state:0},
{pos:[8,0,20],state:0},
{pos:[9,0,20],state:0},
{pos:[10,0,20],state:0},
{pos:[11,0,20],state:0},
{pos:[12,0,20],state:0},
{pos:[13,0,20],state:0},
{pos:[14,0,20],state:0},
{pos:[15,0,20],state:0},
{pos:[16,0,20],state:0},
{pos:[17,0,20],state:0},
{pos:[18,0,20],state:0},
{pos:[19,0,20],state:0},
{pos:[20,0,20],state:0},
{pos:[21,0,20],state:0},
{pos:[22,0,20],state:0},
{pos:[23,0,20],state:0},
{pos:[24,0,20],state:0},
{pos:[25,0,20],state:0},
{pos:[26,0,20],state:0},
{pos:[27,0,20],state:0},
{pos:[28,0,20],state:0},
{pos:[29,0,20],state:0},
{pos:[30,0,20],state:0},
{pos:[31,0,20],state:0},
{pos:[32,0,20],state:0},
{pos:[33,0,20],state:0},
{pos:[34,0,20],state:0},
{pos:[35,0,20],state:0},
{pos:[36,0,20],state:0},
{pos:[37,0,20],state:0},
{pos:[38,0,20],state:0},
{pos:[39,0,20],state:0},
{pos:[40,0,20],state:0},
{pos:[41,0,20],state:0},
{pos:[42,0,20],state:0},
{pos:[43,0,20],state:0},
{pos:[44,0,20],state:0},
{pos:[45,0,20],state:0},
{pos:[46,0,20],state:0},
{pos:[47,0,20],state:0},
{pos:[0,0,21],state:0},
{pos:[1,0,21],state:0},
{pos:[2,0,21],state:0},
{pos:[3,0,21],state:0},
{pos:[4,0,21],state:0},
{pos:[5,0,21],state:0},
{pos:[6,0,21],state:0},
{pos:[7,0,21],state:0},
{pos:[8,0,21],state:0},
{pos:[9,0,21],state:0},
{pos:[10,0,21],state:0},
{pos:[11,0,21],state:0},
{pos:[12,0,21],state:0},
{pos:[13,0,21],state:0},
{pos:[14,0,21],state:0},
{pos:[15,0,21],state:0},
{pos:[16,0,21],state:0},
{pos:[17,0,21],state:0},
{pos:[18,0,21],state:0},
{pos:[19,0,21],state:0},
{pos:[20,0,21],state:0},
{pos:[21,0,21],state:0},
{pos:[22,0,21],state:0},
{pos:[23,0,21],state:0},
{pos:[24,0,21],state:0},
{pos:[25,0,21],state:0},
{pos:[26,0,21],state:0},
{pos:[27,0,21],state:0},
{pos:[28,0,21],state:0},
{pos:[29,0,21],state:0},
{pos:[30,0,21],state:0},
{pos:[31,0,21],state:0},
{pos:[32,0,21],state:0},
{pos:[33,0,21],state:0},
{pos:[34,0,21],state:0},
{pos:[35,0,21],state:0},
{pos:[36,0,21],state:0},
{pos:[37,0,21],state:0},
{pos:[38,0,21],state:0},
{pos:[39,0,21],state:0},
{pos:[40,0,21],state:0},
{pos:[41,0,21],state:0},
{pos:[42,0,21],state:0},
{pos:[43,0,21],state:0},
{pos:[44,0,21],state:0},
{pos:[45,0,21],state:0},
{pos:[46,0,21],state:0},
{pos:[47,0,21],state:0},
{pos:[0,0,22],state:0},
{pos:[1,0,22],state:0},
{pos:[2,0,22],state:0},
{pos:[3,0,22],state:0},
{pos:[4,0,22],state:0},
{pos:[5,0,22],state:0},
{pos:[6,0,22],state:0},
{pos:[7,0,22],state:0},
{pos:[8,0,22],state:0},
{pos:[9,0,22],state:0},
{pos:[10,0,22],state:0},
{pos:[11,0,22],state:0},
{pos:[12,0,22],state:0},
{pos:[13,0,22],state:0},
{pos:[14,0,22],state:0},
{pos:[15,0,22],state:0},
{pos:[16,0,22],state:0},
{pos:[17,0,22],state:0},
{pos:[18,0,22],state:0},
{pos:[19,0,22],state:0},
{pos:[20,0,22],state:0},
{pos:[21,0,22],state:0},
{pos:[22,0,22],state:0},
{pos:[23,0,22],state:0},
{pos:[24,0,22],state:0},
{pos:[25,0,22],state:0},
{pos:[26,0,22],state:0},
{pos:[27,0,22],state:0},
{pos:[28,0,22],state:0},
{pos:[29,0,22],state:0},
{pos:[30,0,22],state:0},
{pos:[31,0,22],state:0},
{pos:[32,0,22],state:0},
{pos:[33,0,22],state:0},
{pos:[34,0,22],state:0},
{pos:[35,0,22],state:0},
{pos:[36,0,22],state:0},
{pos:[37,0,22],state:0},
{pos:[38,0,22],state:0},
{pos:[39,0,22],state:0},
{pos:[40,0,22],state:0},
{pos:[41,0,22],state:0},
{pos:[42,0,22],state:0},
{pos:[43,0,22],state:0},
{pos:[44,0,22],state:0},
{pos:[45,0,22],state:0},
{pos:[46,0,22],state:0},
{pos:[47,0,22],state:0},
{pos:[0,0,23],state:0},
{pos:[1,0,23],state:0},
{pos:[2,0,23],state:0},
{pos:[3,0,23],state:0},
{pos:[4,0,23],state:0},
{pos:[5,0,23],state:0},
{pos:[6,0,23],state:0},
{pos:[7,0,23],state:0},
{pos:[8,0,23],state:0},
{pos:[9,0,23],state:0},
{pos:[10,0,23],state:0},
{pos:[11,0,23],state:0},
{pos:[12,0,23],state:0},
{pos:[13,0,23],state:0},
{pos:[14,0,23],state:0},
{pos:[15,0,23],state:0},
{pos:[16,0,23],state:0},
{pos:[17,0,23],state:0},
{pos:[18,0,23],state:0},
{pos:[19,0,23],state:0},
{pos:[20,0,23],state:0},
{pos:[21,0,23],state:0},
{pos:[22,0,23],state:0},
{pos:[23,0,23],state:0},
{pos:[24,0,23],state:0},
{pos:[25,0,23],state:0},
{pos:[26,0,23],state:0},
{pos:[27,0,23],state:0},
{pos:[28,0,23],state:0},
{pos:[29,0,23],state:0},
{pos:[30,0,23],state:0},
{pos:[31,0,23],state:0},
{pos:[32,0,23],state:0},
{pos:[33,0,23],state:0},
{pos:[34,0,23],state:0},
{pos:[35,0,23],state:0},
{pos:[36,0,23],state:0},
{pos:[37,0,23],state:0},
{pos:[38,0,23],state:0},
{pos:[39,0,23],state:0},
{pos:[40,0,23],state:0},
{pos:[41,0,23],state:0},
{pos:[42,0,23],state:0},
{pos:[43,0,23],state:0},
{pos:[44,0,23],state:0},
{pos:[45,0,23],state:0},
{pos:[46,0,23],state:0},
{pos:[47,0,23],state:0},
{pos:[0,0,24],state:0},
{pos:[1,0,24],state:0},
{pos:[2,0,24],state:0},
{pos:[3,0,24],state:0},
{pos:[4,0,24],state:0},
{pos:[5,0,24],state:0},
{pos:[6,0,24],state:0},
{pos:[7,0,24],state:0},
{pos:[8,0,24],state:0},
{pos:[9,0,24],state:0},
{pos:[10,0,24],state:0},
{pos:[11,0,24],state:0},
{pos:[12,0,24],state:0},
{pos:[13,0,24],state:0},
{pos:[14,0,24],state:0},
{pos:[15,0,24],state:0},
{pos:[16,0,24],state:0},
{pos:[17,0,24],state:0},
{pos:[18,0,24],state:0},
{pos:[19,0,24],state:0},
{pos:[20,0,24],state:0},
{pos:[21,0,24],state:0},
{pos:[22,0,24],state:0},
{pos:[23,0,24],state:0},
{pos:[24,0,24],state:0},
{pos:[25,0,24],state:0},
{pos:[26,0,24],state:0},
{pos:[27,0,24],state:0},
{pos:[28,0,24],state:0},
{pos:[29,0,24],state:0},
{pos:[30,0,24],state:0},
{pos:[31,0,24],state:0},
{pos:[32,0,24],state:0},
{pos:[33,0,24],state:0},
{pos:[34,0,24],state:0},
{pos:[35,0,24],state:0},
{pos:[36,0,24],state:0},
{pos:[37,0,24],state:0},
{pos:[38,0,24],state:0},
{pos:[39,0,24],state:0},
{pos:[40,0,24],state:0},
{pos:[41,0,24],state:0},
{pos:[42,0,24],state:0},
{pos:[43,0,24],state:0},
{pos:[44,0,24],state:0},
{pos:[45,0,24],state:0},
{pos:[46,0,24],state:0},
{pos:[47,0,24],state:0},
{pos:[0,0,25],state:0},
{pos:[1,0,25],state:0},
{pos:[2,0,25],state:0},
{pos:[3,0,25],state:0},
{pos:[4,0,25],state:0},
{pos:[5,0,25],state:0},
{pos:[6,0,25],state:0},
{pos:[7,0,25],state:0},
{pos:[8,0,25],state:0},
{pos:[9,0,25],state:0},
{pos:[10,0,25],state:0},
{pos:[11,0,25],state:0},
{pos:[12,0,25],state:0},
{pos:[13,0,25],state:0},
{pos:[14,0,25],state:0},
{pos:[15,0,25],state:0},
{pos:[16,0,25],state:0},
{pos:[17,0,25],state:0},
{pos:[18,0,25],state:0},
{pos:[19,0,25],state:0},
{pos:[20,0,25],state:0},
{pos:[21,0,25],state:0},
{pos:[22,0,25],state:0},
{pos:[23,0,25],state:0},
{pos:[24,0,25],state:0},
{pos:[25,0,25],state:0},
{pos:[26,0,25],state:0},
{pos:[27,0,25],state:0},
{pos:[28,0,25],state:0},
{pos:[29,0,25],state:0},
{pos:[30,0,25],state:0},
{pos:[31,0,25],state:0},
{pos:[32,0,25],state:0},
{pos:[33,0,25],state:0},
{pos:[34,0,25],state:0},
{pos:[35,0,25],state:0},
{pos:[36,0,25],state:0},
{pos:[37,0,25],state:0},
{pos:[38,0,25],state:0},
{pos:[39,0,25],state:0},
{pos:[40,0,25],state:0},
{pos:[41,0,25],state:0},
{pos:[42,0,25],state:0},
{pos:[43,0,25],state:0},
{pos:[44,0,25],state:0},
{pos:[45,0,25],state:0},
{pos:[46,0,25],state:0},
{pos:[47,0,25],state:0},
{pos:[0,0,26],state:0},
{pos:[1,0,26],state:0},
{pos:[2,0,26],state:0},
{pos:[3,0,26],state:0},
{pos:[4,0,26],state:0},
{pos:[5,0,26],state:0},
{pos:[6,0,26],state:0},
{pos:[7,0,26],state:0},
{pos:[8,0,26],state:0},
{pos:[9,0,26],state:0},
{pos:[10,0,26],state:0},
{pos:[11,0,26],state:0},
{pos:[12,0,26],state:0},
{pos:[13,0,26],state:0},
{pos:[14,0,26],state:0},
{pos:[15,0,26],state:0},
{pos:[16,0,26],state:0},
{pos:[17,0,26],state:0},
{pos:[18,0,26],state:0},
{pos:[19,0,26],state:0},
{pos:[20,0,26],state:0},
{pos:[21,0,26],state:0},
{pos:[22,0,26],state:0},
{pos:[23,0,26],state:0},
{pos:[24,0,26],state:0},
{pos:[25,0,26],state:0},
{pos:[26,0,26],state:0},
{pos:[27,0,26],state:0},
{pos:[28,0,26],state:0},
{pos:[29,0,26],state:0},
{pos:[30,0,26],state:0},
{pos:[31,0,26],state:0},
{pos:[32,0,26],state:0},
{pos:[33,0,26],state:0},
{pos:[34,0,26],state:0},
{pos:[35,0,26],state:0},
{pos:[36,0,26],state:0},
{pos:[37,0,26],state:0},
{pos:[38,0,26],state:0},
{pos:[39,0,26],state:0},
{pos:[40,0,26],state:0},
{pos:[41,0,26],state:0},
{pos:[42,0,26],state:0},
{pos:[43,0,26],state:0},
{pos:[44,0,26],state:0},
{pos:[45,0,26],state:0},
{pos:[46,0,26],state:0},
{pos:[47,0,26],state:0},
{pos:[0,0,27],state:0},
{pos:[1,0,27],state:0},
{pos:[2,0,27],state:0},
{pos:[3,0,27],state:0},
{pos:[4,0,27],state:0},
{pos:[5,0,27],state:0},
{pos:[6,0,27],state:0},
{pos:[7,0,27],state:0},
{pos:[8,0,27],state:0},
{pos:[9,0,27],state:0},
{pos:[10,0,27],state:0},
{pos:[11,0,27],state:0},
{pos:[12,0,27],state:0},
{pos:[13,0,27],state:0},
{pos:[14,0,27],state:0},
{pos:[15,0,27],state:0},
{pos:[16,0,27],state:0},
{pos:[17,0,27],state:0},
{pos:[18,0,27],state:0},
{pos:[19,0,27],state:0},
{pos:[20,0,27],state:0},
{pos:[21,0,27],state:0},
{pos:[22,0,27],state:0},
{pos:[23,0,27],state:0},
{pos:[24,0,27],state:0},
{pos:[25,0,27],state:0},
{pos:[26,0,27],state:0},
{pos:[27,0,27],state:0},
{pos:[28,0,27],state:0},
{pos:[29,0,27],state:0},
{pos:[30,0,27],state:0},
{pos:[31,0,27],state:0},
{pos:[32,0,27],state:0},
{pos:[33,0,27],state:0},
{pos:[34,0,27],state:0},
{pos:[35,0,27],state:0},
{pos:[36,0,27],state:0},
{pos:[37,0,27],state:0},
{pos:[38,0,27],state:0},
{pos:[39,0,27],state:0},
{pos:[40,0,27],state:0},
{pos:[41,0,27],state:0},
{pos:[42,0,27],state:0},
{pos:[43,0,27],state:0},
{pos:[44,0,27],state:0},
{pos:[45,0,27],state:0},
{pos:[46,0,27],state:0},
{pos:[47,0,27],state:0},
{pos:[0,0,28],state:0},
{pos:[1,0,28],state:0},
{pos:[2,0,28],state:0},
{pos:[3,0,28],state:0},
{pos:[4,0,28],state:0},
{pos:[5,0,28],state:0},
{pos:[6,0,28],state:0},
{pos:[7,0,28],state:0},
{pos:[8,0,28],state:0},
{pos:[9,0,28],state:0},
{pos:[10,0,28],state:0},
{pos:[11,0,28],state:0},
{pos:[12,0,28],state:0},
{pos:[13,0,28],state:0},
{pos:[14,0,28],state:0},
{pos:[15,0,28],state:0},
{pos:[16,0,28],state:0},
{pos:[17,0,28],state:0},
{pos:[18,0,28],state:0},
{pos:[19,0,28],state:0},
{pos:[20,0,28],state:0},
{pos:[21,0,28],state:0},
{pos:[22,0,28],state:0},
{pos:[23,0,28],state:0},
{pos:[24,0,28],state:0},
{pos:[25,0,28],state:0},
{pos:[26,0,28],state:0},
{pos:[27,0,28],state:0},
{pos:[28,0,28],state:0},
{pos:[29,0,28],state:0},
{pos:[30,0,28],state:0},
{pos:[31,0,28],state:0},
{pos:[32,0,28],state:0},
{pos:[33,0,28],state:0},
{pos:[34,0,28],state:0},
{pos:[35,0,28],state:0},
{pos:[36,0,28],state:0},
{pos:[37,0,28],state:0},
{pos:[38,0,28],state:0},
{pos:[39,0,28],state:0},
{pos:[40,0,28],state:0},
{pos:[41,0,28],state:0},
{pos:[42,0,28],state:0},
{pos:[43,0,28],state:0},
{pos:[44,0,28],state:0},
{pos:[45,0,28],state:0},
{pos:[46,0,28],state:0},
{pos:[47,0,28],state:0},
{pos:[0,0,29],state:0},
{pos:[1,0,29],state:0},
{pos:[2,0,29],state:0},
{pos:[3,0,29],state:0},
{pos:[4,0,29],state:0},
{pos:[5,0,29],state:0},
{pos:[6,0,29],state:0},
{pos:[7,0,29],state:0},
{pos:[8,0,29],state:0},
{pos:[9,0,29],state:0},
{pos:[10,0,29],state:0},
{pos:[11,0,29],state:0},
{pos:[12,0,29],state:0},
{pos:[13,0,29],state:0},
{pos:[14,0,29],state:0},
{pos:[15,0,29],state:0},
{pos:[16,0,29],state:0},
{pos:[17,0,29],state:0},
{pos:[18,0,29],state:0},
{pos:[19,0,29],state:0},
{pos:[20,0,29],state:0},
{pos:[21,0,29],state:0},
{pos:[22,0,29],state:0},
{pos:[23,0,29],state:0},
{pos:[24,0,29],state:0},
{pos:[25,0,29],state:0},
{pos:[26,0,29],state:0},
{pos:[27,0,29],state:0},
{pos:[28,0,29],state:0},
{pos:[29,0,29],state:0},
{pos:[30,0,29],state:0},
{pos:[31,0,29],state:0},
{pos:[32,0,29],state:0},
{pos:[33,0,29],state:0},
{pos:[34,0,29],state:0},
{pos:[35,0,29],state:0},
{pos:[36,0,29],state:0},
{pos:[37,0,29],state:0},
{pos:[38,0,29],state:0},
{pos:[39,0,29],state:0},
{pos:[40,0,29],state:0},
{pos:[41,0,29],state:0},
{pos:[42,0,29],state:0},
{pos:[43,0,29],state:0},
{pos:[44,0,29],state:0},
{pos:[45,0,29],state:0},
{pos:[46,0,29],state:0},
{pos:[47,0,29],state:0},
{pos:[0,0,30],state:0},
{pos:[1,0,30],state:0},
{pos:[2,0,30],state:0},
{pos:[3,0,30],state:0},
{pos:[4,0,30],state:0},
{pos:[5,0,30],state:0},
{pos:[6,0,30],state:0},
{pos:[7,0,30],state:0},
{pos:[8,0,30],state:0},
{pos:[9,0,30],state:0},
{pos:[10,0,30],state:0},
{pos:[11,0,30],state:0},
{pos:[12,0,30],state:0},
{pos:[13,0,30],state:0},
{pos:[14,0,30],state:0},
{pos:[15,0,30],state:0},
{pos:[16,0,30],state:0},
{pos:[17,0,30],state:0},
{pos:[18,0,30],state:0},
{pos:[19,0,30],state:0},
{pos:[20,0,30],state:0},
{pos:[21,0,30],state:0},
{pos:[22,0,30],state:0},
{pos:[23,0,30],state:0},
{pos:[24,0,30],state:0},
{pos:[25,0,30],state:0},
{pos:[26,0,30],state:0},
{pos:[27,0,30],state:0},
{pos:[28,0,30],state:0},
{pos:[29,0,30],state:0},
{pos:[30,0,30],state:0},
{pos:[31,0,30],state:0},
{pos:[32,0,30],state:0},
{pos:[33,0,30],state:0},
{pos:[34,0,30],state:0},
{pos:[35,0,30],state:0},
{pos:[36,0,30],state:0},
{pos:[37,0,30],state:0},
{pos:[38,0,30],state:0},
{pos:[39,0,30],state:0},
{pos:[40,0,30],state:0},
{pos:[41,0,30],state:0},
{pos:[42,0,30],state:0},
{pos:[43,0,30],state:0},
{pos:[44,0,30],state:0},
{pos:[45,0,30],state:0},
{pos:[46,0,30],state:0},
{pos:[47,0,30],state:0},
{pos:[0,0,31],state:0},
{pos:[1,0,31],state:0},
{pos:[2,0,31],state:0},
{pos:[3,0,31],state:0},
{pos:[4,0,31],state:0},
{pos:[5,0,31],state:0},
{pos:[6,0,31],state:0},
{pos:[7,0,31],state:0},
{pos:[8,0,31],state:0},
{pos:[9,0,31],state:0},
{pos:[10,0,31],state:0},
{pos:[11,0,31],state:0},
{pos:[12,0,31],state:0},
{pos:[13,0,31],state:0},
{pos:[14,0,31],state:0},
{pos:[15,0,31],state:0},
{pos:[16,0,31],state:0},
{pos:[17,0,31],state:0},
{pos:[18,0,31],state:0},
{pos:[19,0,31],state:0},
{pos:[20,0,31],state:0},
{pos:[21,0,31],state:0},
{pos:[22,0,31],state:0},
{pos:[23,0,31],state:0},
{pos:[24,0,31],state:0},
{pos:[25,0,31],state:0},
{pos:[26,0,31],state:0},
{pos:[27,0,31],state:0},
{pos:[28,0,31],state:0},
{pos:[29,0,31],state:0},
{pos:[30,0,31],state:0},
{pos:[31,0,31],state:0},
{pos:[32,0,31],state:0},
{pos:[33,0,31],state:0},
{pos:[34,0,31],state:0},
{pos:[35,0,31],state:0},
{pos:[36,0,31],state:0},
{pos:[37,0,31],state:0},
{pos:[38,0,31],state:0},
{pos:[39,0,31],state:0},
{pos:[40,0,31],state:0},
{pos:[41,0,31],state:0},
{pos:[42,0,31],state:0},
{pos:[43,0,31],state:0},
{pos:[44,0,31],state:0},
{pos:[45,0,31],state:0},
{pos:[46,0,31],state:0},
{pos:[47,0,31],state:0},
{pos:[0,0,32],state:0},
{pos:[1,0,32],state:0},
{pos:[2,0,32],state:0},
{pos:[3,0,32],state:0},
{pos:[4,0,32],state:0},
{pos:[5,0,32],state:0},
{pos:[6,0,32],state:0},
{pos:[7,0,32],state:0},
{pos:[8,0,32],state:0},
{pos:[9,0,32],state:0},
{pos:[10,0,32],state:0},
{pos:[11,0,32],state:0},
{pos:[12,0,32],state:0},
{pos:[13,0,32],state:0},
{pos:[14,0,32],state:0},
{pos:[15,0,32],state:0},
{pos:[16,0,32],state:0},
{pos:[17,0,32],state:0},
{pos:[18,0,32],state:0},
{pos:[19,0,32],state:0},
{pos:[20,0,32],state:0},
{pos:[21,0,32],state:0},
{pos:[22,0,32],state:0},
{pos:[23,0,32],state:0},
{pos:[24,0,32],state:0},
{pos:[25,0,32],state:0},
{pos:[26,0,32],state:0},
{pos:[27,0,32],state:0},
{pos:[28,0,32],state:0},
{pos:[29,0,32],state:0},
{pos:[30,0,32],state:0},
{pos:[31,0,32],state:0},
{pos:[32,0,32],state:0},
{pos:[33,0,32],state:0},
{pos:[34,0,32],state:0},
{pos:[35,0,32],state:0},
{pos:[36,0,32],state:0},
{pos:[37,0,32],state:0},
{pos:[38,0,32],state:0},
{pos:[39,0,32],state:0},
{pos:[40,0,32],state:0},
{pos:[41,0,32],state:0},
{pos:[42,0,32],state:0},
{pos:[43,0,32],state:0},
{pos:[44,0,32],state:0},
{pos:[45,0,32],state:0},
{pos:[46,0,32],state:0},
{pos:[47,0,32],state:0},
{pos:[0,0,33],state:0},
{pos:[1,0,33],state:0},
{pos:[2,0,33],state:0},
{pos:[3,0,33],state:0},
{pos:[4,0,33],state:0},
{pos:[5,0,33],state:0},
{pos:[6,0,33],state:0},
{pos:[7,0,33],state:0},
{pos:[8,0,33],state:0},
{pos:[9,0,33],state:0},
{pos:[10,0,33],state:0},
{pos:[11,0,33],state:0},
{pos:[12,0,33],state:0},
{pos:[13,0,33],state:0},
{pos:[14,0,33],state:0},
{pos:[15,0,33],state:0},
{pos:[16,0,33],state:0},
{pos:[17,0,33],state:0},
{pos:[18,0,33],state:0},
{pos:[19,0,33],state:0},
{pos:[20,0,33],state:0},
{pos:[21,0,33],state:0},
{pos:[22,0,33],state:0},
{pos:[23,0,33],state:0},
{pos:[24,0,33],state:0},
{pos:[25,0,33],state:0},
{pos:[26,0,33],state:0},
{pos:[27,0,33],state:0},
{pos:[28,0,33],state:0},
{pos:[29,0,33],state:0},
{pos:[30,0,33],state:0},
{pos:[31,0,33],state:0},
{pos:[32,0,33],state:0},
{pos:[33,0,33],state:0},
{pos:[34,0,33],state:0},
{pos:[35,0,33],state:0},
{pos:[36,0,33],state:0},
{pos:[37,0,33],state:0},
{pos:[38,0,33],state:0},
{pos:[39,0,33],state:0},
{pos:[40,0,33],state:0},
{pos:[41,0,33],state:0},
{pos:[42,0,33],state:0},
{pos:[43,0,33],state:0},
{pos:[44,0,33],state:0},
{pos:[45,0,33],state:0},
{pos:[46,0,33],state:0},
{pos:[47,0,33],state:0},
{pos:[0,0,34],state:0},
{pos:[1,0,34],state:0},
{pos:[2,0,34],state:0},
{pos:[3,0,34],state:0},
{pos:[4,0,34],state:0},
{pos:[5,0,34],state:0},
{pos:[6,0,34],state:0},
{pos:[7,0,34],state:0},
{pos:[8,0,34],state:0},
{pos:[9,0,34],state:0},
{pos:[10,0,34],state:0},
{pos:[11,0,34],state:0},
{pos:[12,0,34],state:0},
{pos:[13,0,34],state:0},
{pos:[14,0,34],state:0},
{pos:[15,0,34],state:0},
{pos:[16,0,34],state:0},
{pos:[17,0,34],state:0},
{pos:[18,0,34],state:0},
{pos:[19,0,34],state:0},
{pos:[20,0,34],state:0},
{pos:[21,0,34],state:0},
{pos:[22,0,34],state:0},
{pos:[23,0,34],state:0},
{pos:[24,0,34],state:0},
{pos:[25,0,34],state:0},
{pos:[26,0,34],state:0},
{pos:[27,0,34],state:0},
{pos:[28,0,34],state:0},
{pos:[29,0,34],state:0},
{pos:[30,0,34],state:0},
{pos:[31,0,34],state:0},
{pos:[32,0,34],state:0},
{pos:[33,0,34],state:0},
{pos:[34,0,34],state:0},
{pos:[35,0,34],state:0},
{pos:[36,0,34],state:0},
{pos:[37,0,34],state:0},
{pos:[38,0,34],state:0},
{pos:[39,0,34],state:0},
{pos:[40,0,34],state:0},
{pos:[41,0,34],state:0},
{pos:[42,0,34],state:0},
{pos:[43,0,34],state:0},
{pos:[44,0,34],state:0},
{pos:[45,0,34],state:0},
{pos:[46,0,34],state:0},
{pos:[47,0,34],state:0},
{pos:[0,0,35],state:0},
{pos:[1,0,35],state:0},
{pos:[2,0,35],state:0},
{pos:[3,0,35],state:0},
{pos:[4,0,35],state:0},
{pos:[5,0,35],state:0},
{pos:[6,0,35],state:0},
{pos:[7,0,35],state:0},
{pos:[8,0,35],state:0},
{pos:[9,0,35],state:0},
{pos:[10,0,35],state:0},
{pos:[11,0,35],state:0},
{pos:[12,0,35],state:0},
{pos:[13,0,35],state:0},
{pos:[14,0,35],state:0},
{pos:[15,0,35],state:0},
{pos:[16,0,35],state:0},
{pos:[17,0,35],state:0},
{pos:[18,0,35],state:0},
{pos:[19,0,35],state:0},
{pos:[20,0,35],state:0},
{pos:[21,0,35],state:0},
{pos:[22,0,35],state:0},
{pos:[23,0,35],state:0},
{pos:[24,0,35],state:0},
{pos:[25,0,35],state:0},
{pos:[26,0,35],state:0},
{pos:[27,0,35],state:0},
{pos:[28,0,35],state:0},
{pos:[29,0,35],state:0},
{pos:[30,0,35],state:0},
{pos:[31,0,35],state:0},
{pos:[32,0,35],state:0},
{pos:[33,0,35],state:0},
{pos:[34,0,35],state:0},
{pos:[35,0,35],state:0},
{pos:[36,0,35],state:0},
{pos:[37,0,35],state:0},
{pos:[38,0,35],state:0},
{pos:[39,0,35],state:0},
{pos:[40,0,35],state:0},
{pos:[41,0,35],state:0},
{pos:[42,0,35],state:0},
{pos:[43,0,35],state:0},
{pos:[44,0,35],state:0},
{pos:[45,0,35],state:0},
{pos:[46,0,35],state:0},
{pos:[47,0,35],state:0},
{pos:[0,0,36],state:0},
{pos:[1,0,36],state:0},
{pos:[2,0,36],state:0},
{pos:[3,0,36],state:0},
{pos:[4,0,36],state:0},
{pos:[5,0,36],state:0},
{pos:[6,0,36],state:0},
{pos:[7,0,36],state:0},
{pos:[8,0,36],state:0},
{pos:[9,0,36],state:0},
{pos:[10,0,36],state:0},
{pos:[11,0,36],state:0},
{pos:[12,0,36],state:0},
{pos:[13,0,36],state:0},
{pos:[14,0,36],state:0},
{pos:[15,0,36],state:0},
{pos:[16,0,36],state:0},
{pos:[17,0,36],state:0},
{pos:[18,0,36],state:0},
{pos:[19,0,36],state:0},
{pos:[20,0,36],state:0},
{pos:[21,0,36],state:0},
{pos:[22,0,36],state:0},
{pos:[23,0,36],state:0},
{pos:[24,0,36],state:0},
{pos:[25,0,36],state:0},
{pos:[26,0,36],state:0},
{pos:[27,0,36],state:0},
{pos:[28,0,36],state:0},
{pos:[29,0,36],state:0},
{pos:[30,0,36],state:0},
{pos:[31,0,36],state:0},
{pos:[32,0,36],state:0},
{pos:[33,0,36],state:0},
{pos:[34,0,36],state:0},
{pos:[35,0,36],state:0},
{pos:[36,0,36],state:0},
{pos:[37,0,36],state:0},
{pos:[38,0,36],state:0},
{pos:[39,0,36],state:0},
{pos:[40,0,36],state:0},
{pos:[41,0,36],state:0},
{pos:[42,0,36],state:0},
{pos:[43,0,36],state:0},
{pos:[44,0,36],state:0},
{pos:[45,0,36],state:0},
{pos:[46,0,36],state:0},
{pos:[47,0,36],state:0},
{pos:[0,0,37],state:0},
{pos:[1,0,37],state:0},
{pos:[2,0,37],state:0},
{pos:[3,0,37],state:0},
{pos:[4,0,37],state:0},
{pos:[5,0,37],state:0},
{pos:[6,0,37],state:0},
{pos:[7,0,37],state:0},
{pos:[8,0,37],state:0},
{pos:[9,0,37],state:0},
{pos:[10,0,37],state:0},
{pos:[11,0,37],state:0},
{pos:[12,0,37],state:0},
{pos:[13,0,37],state:0},
{pos:[14,0,37],state:0},
{pos:[15,0,37],state:0},
{pos:[16,0,37],state:0},
{pos:[17,0,37],state:0},
{pos:[18,0,37],state:0},
{pos:[19,0,37],state:0},
{pos:[20,0,37],state:0},
{pos:[21,0,37],state:0},
{pos:[22,0,37],state:0},
{pos:[23,0,37],state:0},
{pos:[24,0,37],state:0},
{pos:[25,0,37],state:0},
{pos:[26,0,37],state:0},
{pos:[27,0,37],state:0},
{pos:[28,0,37],state:0},
{pos:[29,0,37],state:0},
{pos:[30,0,37],state:0},
{pos:[31,0,37],state:0},
{pos:[32,0,37],state:0},
{pos:[33,0,37],state:0},
{pos:[34,0,37],state:0},
{pos:[35,0,37],state:0},
{pos:[36,0,37],state:0},
{pos:[37,0,37],state:0},
{pos:[38,0,37],state:0},
{pos:[39,0,37],state:0},
{pos:[40,0,37],state:0},
{pos:[41,0,37],state:0},
{pos:[42,0,37],state:0},
{pos:[43,0,37],state:0},
{pos:[44,0,37],state:0},
{pos:[45,0,37],state:0},
{pos:[46,0,37],state:0},
{pos:[47,0,37],state:0},
{pos:[0,0,38],state:0},
{pos:[1,0,38],state:0},
{pos:[2,0,38],state:0},
{pos:[3,0,38],state:0},
{pos:[4,0,38],state:0},
{pos:[5,0,38],state:0},
{pos:[6,0,38],state:0},
{pos:[7,0,38],state:0},
{pos:[8,0,38],state:0},
{pos:[9,0,38],state:0},
{pos:[10,0,38],state:0},
{pos:[11,0,38],state:0},
{pos:[12,0,38],state:0},
{pos:[13,0,38],state:0},
{pos:[14,0,38],state:0},
{pos:[15,0,38],state:0},
{pos:[16,0,38],state:0},
{pos:[17,0,38],state:0},
{pos:[18,0,38],state:0},
{pos:[19,0,38],state:0},
{pos:[20,0,38],state:0},
{pos:[21,0,38],state:0},
{pos:[22,0,38],state:0},
{pos:[23,0,38],state:0},
{pos:[24,0,38],state:0},
{pos:[25,0,38],state:0},
{pos:[26,0,38],state:0},
{pos:[27,0,38],state:0},
{pos:[28,0,38],state:0},
{pos:[29,0,38],state:0},
{pos:[30,0,38],state:0},
{pos:[31,0,38],state:0},
{pos:[32,0,38],state:0},
{pos:[33,0,38],state:0},
{pos:[34,0,38],state:0},
{pos:[35,0,38],state:0},
{pos:[36,0,38],state:0},
{pos:[37,0,38],state:0},
{pos:[38,0,38],state:0},
{pos:[39,0,38],state:0},
{pos:[40,0,38],state:0},
{pos:[41,0,38],state:0},
{pos:[42,0,38],state:0},
{pos:[43,0,38],state:0},
{pos:[44,0,38],state:0},
{pos:[45,0,38],state:0},
{pos:[46,0,38],state:0},
{pos:[47,0,38],state:0},
{pos:[0,0,39],state:0},
{pos:[1,0,39],state:0},
{pos:[2,0,39],state:0},
{pos:[3,0,39],state:0},
{pos:[4,0,39],state:0},
{pos:[5,0,39],state:0},
{pos:[6,0,39],state:0},
{pos:[7,0,39],state:0},
{pos:[8,0,39],state:0},
{pos:[9,0,39],state:0},
{pos:[10,0,39],state:0},
{pos:[11,0,39],state:0},
{pos:[12,0,39],state:0},
{pos:[13,0,39],state:0},
{pos:[14,0,39],state:0},
{pos:[15,0,39],state:0},
{pos:[16,0,39],state:0},
{pos:[17,0,39],state:0},
{pos:[18,0,39],state:0},
{pos:[19,0,39],state:0},
{pos:[20,0,39],state:0},
{pos:[21,0,39],state:0},
{pos:[22,0,39],state:0},
{pos:[23,0,39],state:0},
{pos:[24,0,39],state:0},
{pos:[25,0,39],state:0},
{pos:[26,0,39],state:0},
{pos:[27,0,39],state:0},
{pos:[28,0,39],state:0},
{pos:[29,0,39],state:0},
{pos:[30,0,39],state:0},
{pos:[31,0,39],state:0},
{pos:[32,0,39],state:0},
{pos:[33,0,39],state:0},
{pos:[34,0,39],state:0},
{pos:[35,0,39],state:0},
{pos:[36,0,39],state:0},
{pos:[37,0,39],state:0},
{pos:[38,0,39],state:0},
{pos:[39,0,39],state:0},
{pos:[40,0,39],state:0},
{pos:[41,0,39],state:0},
{pos:[42,0,39],state:0},
{pos:[43,0,39],state:0},
{pos:[44,0,39],state:0},
{pos:[45,0,39],state:0},
{pos:[46,0,39],state:0},
{pos:[47,0,39],state:0},
{pos:[0,1,0],state:3},
{pos:[1,1,0],state:3},
{pos:[2,1,0],state:3},
{pos:[3,1,0],state:3},
{pos:[4,1,0],state:3},
{pos:[5,1,0],state:3},
{pos:[6,1,0],state:3},
{pos:[7,1,0],state:3},
{pos:[8,1,0],state:3},
{pos:[9,1,0],state:3},
{pos:[10,1,0],state:3},
{pos:[11,1,0],state:3},
{pos:[12,1,0],state:3},
{pos:[13,1,0],state:3},
{pos:[14,1,0],state:3},
{pos:[15,1,0],state:3},
{pos:[16,1,0],state:3},
{pos:[17,1,0],state:3},
{pos:[18,1,0],state:3},
{pos:[19,1,0],state:3},
{pos:[20,1,0],state:3},
{pos:[21,1,0],state:3},
{pos:[22,1,0],state:3},
{pos:[23,1,0],state:3},
{pos:[24,1,0],state:3},
{pos:[25,1,0],state:3},
{pos:[26,1,0],state:3},
{pos:[27,1,0],state:3},
{pos:[28,1,0],state:3},
{pos:[29,1,0],state:3},
{pos:[30,1,0],state:3},
{pos:[31,1,0],state:3},
{pos:[32,1,0],state:3},
{pos:[33,1,0],state:3},
{pos:[34,1,0],state:3},
{pos:[35,1,0],state:3},
{pos:[36,1,0],state:3},
{pos:[37,1,0],state:3},
{pos:[43,1,0],state:3},
{pos:[44,1,0],state:3},
{pos:[45,1,0],state:3},
{pos:[46,1,0],state:3},
{pos:[47,1,0],state:3},
{pos:[0,1,1],state:3},
{pos:[1,1,1],state:3},
{pos:[2,1,1],state:3},
{pos:[3,1,1],state:3},
{pos:[4,1,1],state:3},
{pos:[5,1,1],state:3},
{pos:[6,1,1],state:3},
{pos:[7,1,1],state:3},
{pos:[8,1,1],state:3},
{pos:[9,1,1],state:3},
{pos:[10,1,1],state:3},
{pos:[11,1,1],state:3},
{pos:[12,1,1],state:3},
{pos:[13,1,1],state:3},
{pos:[14,1,1],state:3},
{pos:[15,1,1],state:3},
{pos:[16,1,1],state:3},
{pos:[17,1,1],state:3},
{pos:[18,1,1],state:3},
{pos:[19,1,1],state:3},
{pos:[20,1,1],state:3},
{pos:[21,1,1],state:3},
{pos:[22,1,1],state:3},
{pos:[23,1,1],state:3},
{pos:[24,1,1],state:3},
{pos:[25,1,1],state:3},
{pos:[26,1,1],state:3},
{pos:[27,1,1],state:3},
{pos:[28,1,1],state:3},
{pos:[29,1,1],state:3},
{pos:[30,1,1],state:3},
{pos:[31,1,1],state:3},
{pos:[32,1,1],state:3},
{pos:[33,1,1],state:3},
{pos:[34,1,1],state:3},
{pos:[35,1,1],state:3},
{pos:[36,1,1],state:3},
{pos:[37,1,1],state:3},
{pos:[43,1,1],state:3},
{pos:[44,1,1],state:3},
{pos:[45,1,1],state:3},
{pos:[46,1,1],state:3},
{pos:[47,1,1],state:3},
{pos:[0,1,2],state:3},
{pos:[1,1,2],state:3},
{pos:[4,1,2],state:1},
{pos:[11,1,2],state:1},
{pos:[18,1,2],state:1},
{pos:[25,1,2],state:1},
{pos:[32,1,2],state:1},
{pos:[39,1,2],state:1},
{pos:[46,1,2],state:3},
{pos:[47,1,2],state:3},
{pos:[0,1,3],state:3},
{pos:[1,1,3],state:3},
{pos:[46,1,3],state:3},
{pos:[47,1,3],state:3},
{pos:[0,1,4],state:3},
{pos:[1,1,4],state:3},
{pos:[46,1,4],state:3},
{pos:[47,1,4],state:3},
{pos:[0,1,5],state:3},
{pos:[1,1,5],state:3},
{pos:[2,1,5],state:1},
{pos:[45,1,5],state:1},
{pos:[46,1,5],state:3},
{pos:[47,1,5],state:3},
{pos:[0,1,6],state:3},
{pos:[1,1,6],state:3},
{pos:[46,1,6],state:3},
{pos:[47,1,6],state:3},
{pos:[0,1,7],state:3},
{pos:[1,1,7],state:3},
{pos:[46,1,7],state:3},
{pos:[47,1,7],state:3},
{pos:[0,1,8],state:3},
{pos:[1,1,8],state:3},
{pos:[10,1,8],state:1},
{pos:[11,1,8],state:1},
{pos:[12,1,8],state:1},
{pos:[18,1,8],state:1},
{pos:[19,1,8],state:1},
{pos:[20,1,8],state:1},
{pos:[29,1,8],state:1},
{pos:[30,1,8],state:1},
{pos:[31,1,8],state:1},
{pos:[37,1,8],state:1},
{pos:[38,1,8],state:1},
{pos:[39,1,8],state:1},
{pos:[46,1,8],state:3},
{pos:[47,1,8],state:3},
{pos:[0,1,9],state:3},
{pos:[1,1,9],state:3},
{pos:[10,1,9],state:1},
{pos:[11,1,9],state:1},
{pos:[12,1,9],state:1},
{pos:[18,1,9],state:1},
{pos:[19,1,9],state:1},
{pos:[20,1,9],state:1},
{pos:[29,1,9],state:1},
{pos:[30,1,9],state:1},
{pos:[31,1,9],state:1},
{pos:[37,1,9],state:1},
{pos:[38,1,9],state:1},
{pos:[39,1,9],state:1},
{pos:[46,1,9],state:3},
{pos:[47,1,9],state:3},
{pos:[0,1,10],state:3},
{pos:[1,1,10],state:3},
{pos:[10,1,10],state:1},
{pos:[11,1,10],state:1},
{pos:[12,1,10],state:1},
{pos:[18,1,10],state:1},
{pos:[19,1,10],state:1},
{pos:[20,1,10],state:1},
{pos:[29,1,10],state:1},
{pos:[30,1,10],state:1},
{pos:[31,1,10],state:1},
{pos:[37,1,10],state:1},
{pos:[38,1,10],state:1},
{pos:[39,1,10],state:1},
{pos:[46,1,10],state:3},
{pos:[47,1,10],state:3},
{pos:[0,1,11],state:3},
{pos:[1,1,11],state:3},
{pos:[10,1,11],state:1},
{pos:[11,1,11],state:1},
{pos:[12,1,11],state:1},
{pos:[18,1,11],state:1},
{pos:[19,1,11],state:1},
{pos:[20,1,11],state:1},
{pos:[29,1,11],state:1},
{pos:[30,1,11],state:1},
{pos:[31,1,11],state:1},
{pos:[37,1,11],state:1},
{pos:[38,1,11],state:1},
{pos:[39,1,11],state:1},
{pos:[46,1,11],state:3},
{pos:[47,1,11],state:3},
{pos:[0,1,12],state:3},
{pos:[1,1,12],state:3},
{pos:[10,1,12],state:1},
{pos:[11,1,12],state:1},
{pos:[12,1,12],state:1},
{pos:[18,1,12],state:1},
{pos:[19,1,12],state:1},
{pos:[20,1,12],state:1},
{pos:[29,1,12],state:1},
{pos:[30,1,12],state:1},
{pos:[31,1,12],state:1},
{pos:[37,1,12],state:1},
{pos:[38,1,12],state:1},
{pos:[39,1,12],state:1},
{pos:[46,1,12],state:3},
{pos:[47,1,12],state:3},
{pos:[0,1,13],state:3},
{pos:[1,1,13],state:3},
{pos:[2,1,13],state:1},
{pos:[45,1,13],state:1},
{pos:[46,1,13],state:3},
{pos:[47,1,13],state:3},
{pos:[0,1,14],state:3},
{pos:[1,1,14],state:3},
{pos:[14,1,14],state:5,nbt:{mode:"DATA",metadata:"enemy:melee:0"}},
{pos:[46,1,14],state:3},
{pos:[47,1,14],state:3},
{pos:[0,1,15],state:3},
{pos:[1,1,15],state:3},
{pos:[46,1,15],state:3},
{pos:[47,1,15],state:3},
{pos:[0,1,16],state:3},
{pos:[1,1,16],state:3},
{pos:[46,1,16],state:3},
{pos:[47,1,16],state:3},
{pos:[0,1,17],state:3},
{pos:[1,1,17],state:3},
{pos:[0,1,18],state:3},
{pos:[1,1,18],state:3},
{pos:[0,1,19],state:3},
{pos:[1,1,19],state:3},
{pos:[0,1,20],state:3},
{pos:[1,1,20],state:3},
{pos:[24,1,20],state:5,nbt:{mode:"DATA",metadata:"objective:0"}},
{pos:[0,1,21],state:3},
{pos:[1,1,21],state:3},
{pos:[2,1,21],state:1},
{pos:[45,1,21],state:1},
{pos:[0,1,22],state:3},
{pos:[1,1,22],state:3},
{pos:[46,1,22],state:3},
{pos:[47,1,22],state:3},
{pos:[0,1,23],state:3},
{pos:[1,1,23],state:3},
{pos:[46,1,23],state:3},
{pos:[47,1,23],state:3},
{pos:[0,1,24],state:3},
{pos:[1,1,24],state:3},
{pos:[46,1,24],state:3},
{pos:[47,1,24],state:3},
{pos:[0,1,25],state:3},
{pos:[1,1,25],state:3},
{pos:[46,1,25],state:3},
{pos:[47,1,25],state:3},
{pos:[0,1,26],state:3},
{pos:[1,1,26],state:3},
{pos:[46,1,26],state:3},
{pos:[47,1,26],state:3},
{pos:[0,1,27],state:3},
{pos:[1,1,27],state:3},
{pos:[34,1,27],state:5,nbt:{mode:"DATA",metadata:"enemy:ranged:0"}},
{pos:[46,1,27],state:3},
{pos:[47,1,27],state:3},
{pos:[0,1,28],state:3},
{pos:[1,1,28],state:3},
{pos:[10,1,28],state:1},
{pos:[11,1,28],state:1},
{pos:[12,1,28],state:1},
{pos:[18,1,28],state:1},
{pos:[19,1,28],state:1},
{pos:[20,1,28],state:1},
{pos:[29,1,28],state:1},
{pos:[30,1,28],state:1},
{pos:[31,1,28],state:1},
{pos:[37,1,28],state:1},
{pos:[38,1,28],state:1},
{pos:[39,1,28],state:1},
{pos:[46,1,28],state:3},
{pos:[47,1,28],state:3},
{pos:[0,1,29],state:3},
{pos:[1,1,29],state:3},
{pos:[2,1,29],state:1},
{pos:[10,1,29],state:1},
{pos:[11,1,29],state:1},
{pos:[12,1,29],state:1},
{pos:[18,1,29],state:1},
{pos:[19,1,29],state:1},
{pos:[20,1,29],state:1},
{pos:[29,1,29],state:1},
{pos:[30,1,29],state:1},
{pos:[31,1,29],state:1},
{pos:[37,1,29],state:1},
{pos:[38,1,29],state:1},
{pos:[39,1,29],state:1},
{pos:[45,1,29],state:1},
{pos:[46,1,29],state:3},
{pos:[47,1,29],state:3},
{pos:[0,1,30],state:3},
{pos:[1,1,30],state:3},
{pos:[10,1,30],state:1},
{pos:[11,1,30],state:1},
{pos:[12,1,30],state:1},
{pos:[18,1,30],state:1},
{pos:[19,1,30],state:1},
{pos:[20,1,30],state:1},
{pos:[29,1,30],state:1},
{pos:[30,1,30],state:1},
{pos:[31,1,30],state:1},
{pos:[37,1,30],state:1},
{pos:[38,1,30],state:1},
{pos:[39,1,30],state:1},
{pos:[46,1,30],state:3},
{pos:[47,1,30],state:3},
{pos:[0,1,31],state:3},
{pos:[1,1,31],state:3},
{pos:[6,1,31],state:5,nbt:{mode:"DATA",metadata:"secret:west_crypt"}},
{pos:[7,1,31],state:2,nbt:{id:"minecraft:chest",LootTable:"minecraft:chests/simple_dungeon"}},
{pos:[10,1,31],state:1},
{pos:[11,1,31],state:1},
{pos:[12,1,31],state:1},
{pos:[18,1,31],state:1},
{pos:[19,1,31],state:1},
{pos:[20,1,31],state:1},
{pos:[29,1,31],state:1},
{pos:[30,1,31],state:1},
{pos:[31,1,31],state:1},
{pos:[37,1,31],state:1},
{pos:[38,1,31],state:1},
{pos:[39,1,31],state:1},
{pos:[46,1,31],state:3},
{pos:[47,1,31],state:3},
{pos:[0,1,32],state:3},
{pos:[1,1,32],state:3},
{pos:[10,1,32],state:1},
{pos:[11,1,32],state:1},
{pos:[12,1,32],state:1},
{pos:[18,1,32],state:1},
{pos:[19,1,32],state:1},
{pos:[20,1,32],state:1},
{pos:[29,1,32],state:1},
{pos:[30,1,32],state:1},
{pos:[31,1,32],state:1},
{pos:[37,1,32],state:1},
{pos:[38,1,32],state:1},
{pos:[39,1,32],state:1},
{pos:[46,1,32],state:3},
{pos:[47,1,32],state:3},
{pos:[0,1,33],state:3},
{pos:[1,1,33],state:3},
{pos:[46,1,33],state:3},
{pos:[47,1,33],state:3},
{pos:[0,1,34],state:3},
{pos:[1,1,34],state:3},
{pos:[46,1,34],state:3},
{pos:[47,1,34],state:3},
{pos:[0,1,35],state:3},
{pos:[1,1,35],state:3},
{pos:[46,1,35],state:3},
{pos:[47,1,35],state:3},
{pos:[0,1,36],state:3},
{pos:[1,1,36],state:3},
{pos:[46,1,36],state:3},
{pos:[47,1,36],state:3},
{pos:[0,1,37],state:3},
{pos:[1,1,37],state:3},
{pos:[4,1,37],state:1},
{pos:[11,1,37],state:1},
{pos:[18,1,37],state:1},
{pos:[25,1,37],state:1},
{pos:[32,1,37],state:1},
{pos:[39,1,37],state:1},
{pos:[46,1,37],state:3},
{pos:[47,1,37],state:3},
{pos:[0,1,38],state:3},
{pos:[1,1,38],state:3},
{pos:[2,1,38],state:3},
{pos:[3,1,38],state:3},
{pos:[4,1,38],state:3},
{pos:[5,1,38],state:3},
{pos:[6,1,38],state:3},
{pos:[7,1,38],state:3},
{pos:[8,1,38],state:3},
{pos:[9,1,38],state:3},
{pos:[10,1,38],state:3},
{pos:[11,1,38],state:3},
{pos:[12,1,38],state:3},
{pos:[13,1,38],state:3},
{pos:[14,1,38],state:3},
{pos:[15,1,38],state:3},
{pos:[16,1,38],state:3},
{pos:[17,1,38],state:3},
{pos:[18,1,38],state:3},
{pos:[19,1,38],state:3},
{pos:[20,1,38],state:3},
{pos:[21,1,38],state:3},
{pos:[22,1,38],state:3},
{pos:[23,1,38],state:3},
{pos:[24,1,38],state:3},
{pos:[25,1,38],state:3},
{pos:[26,1,38],state:3},
{pos:[27,1,38],state:3},
{pos:[28,1,38],state:3},
{pos:[29,1,38],state:3},
{pos:[30,1,38],state:3},
{pos:[31,1,38],state:3},
{pos:[32,1,38],state:3},
{pos:[33,1,38],state:3},
{pos:[34,1,38],state:3},
{pos:[35,1,38],state:3},
{pos:[36,1,38],state:3},
{pos:[37,1,38],state:3},
{pos:[38,1,38],state:3},
{pos:[39,1,38],state:3},
{pos:[40,1,38],state:3},
{pos:[41,1,38],state:3},
{pos:[42,1,38],state:3},
{pos:[43,1,38],state:3},
{pos:[44,1,38],state:3},
{pos:[45,1,38],state:3},
{pos:[46,1,38],state:3},
{pos:[47,1,38],state:3},
{pos:[0,1,39],state:3},
{pos:[1,1,39],state:3},
{pos:[2,1,39],state:3},
{pos:[3,1,39],state:3},
{pos:[4,1,39],state:3},
{pos:[5,1,39],state:3},
{pos:[6,1,39],state:3},
{pos:[7,1,39],state:3},
{pos:[8,1,39],state:3},
{pos:[9,1,39],state:3},
{pos:[10,1,39],state:3},
{pos:[11,1,39],state:3},
{pos:[12,1,39],state:3},
{pos:[13,1,39],state:3},
{pos:[14,1,39],state:3},
{pos:[15,1,39],state:3},
{pos:[16,1,39],state:3},
{pos:[17,1,39],state:3},
{pos:[18,1,39],state:3},
{pos:[19,1,39],state:3},
{pos:[20,1,39],state:3},
{pos:[21,1,39],state:3},
{pos:[22,1,39],state:3},
{pos:[23,1,39],state:3},
{pos:[24,1,39],state:3},
{pos:[25,1,39],state:3},
{pos:[26,1,39],state:3},
{pos:[27,1,39],state:3},
{pos:[28,1,39],state:3},
{pos:[29,1,39],state:3},
{pos:[30,1,39],state:3},
{pos:[31,1,39],state:3},
{pos:[32,1,39],state:3},
{pos:[33,1,39],state:3},
{pos:[34,1,39],state:3},
{pos:[35,1,39],state:3},
{pos:[36,1,39],state:3},
{pos:[37,1,39],state:3},
{pos:[38,1,39],state:3},
{pos:[39,1,39],state:3},
{pos:[40,1,39],state:3},
{pos:[41,1,39],state:3},
{pos:[42,1,39],state:3},
{pos:[43,1,39],state:3},
{pos:[44,1,39],state:3},
{pos:[45,1,39],state:3},
{pos:[46,1,39],state:3},
{pos:[47,1,39],state:3},
{pos:[0,2,0],state:3},
{pos:[1,2,0],state:3},
{pos:[2,2,0],state:3},
{pos:[3,2,0],state:3},
{pos:[4,2,0],state:3},
{pos:[5,2,0],state:3},
{pos:[6,2,0],state:3},
{pos:[7,2,0],state:3},
{pos:[8,2,0],state:3},
{pos:[9,2,0],state:3},
{pos:[10,2,0],state:3},
{pos:[11,2,0],state:3},
{pos:[12,2,0],state:3},
{pos:[13,2,0],state:3},
{pos:[14,2,0],state:3},
{pos:[15,2,0],state:3},
{pos:[16,2,0],state:3},
{pos:[17,2,0],state:3},
{pos:[18,2,0],state:3},
{pos:[19,2,0],state:3},
{pos:[20,2,0],state:3},
{pos:[21,2,0],state:3},
{pos:[22,2,0],state:3},
{pos:[23,2,0],state:3},
{pos:[24,2,0],state:3},
{pos:[25,2,0],state:3},
{pos:[26,2,0],state:3},
{pos:[27,2,0],state:3},
{pos:[28,2,0],state:3},
{pos:[29,2,0],state:3},
{pos:[30,2,0],state:3},
{pos:[31,2,0],state:3},
{pos:[32,2,0],state:3},
{pos:[33,2,0],state:3},
{pos:[34,2,0],state:3},
{pos:[35,2,0],state:3},
{pos:[36,2,0],state:3},
{pos:[37,2,0],state:3},
{pos:[43,2,0],state:3},
{pos:[44,2,0],state:3},
{pos:[45,2,0],state:3},
{pos:[46,2,0],state:3},
{pos:[47,2,0],state:3},
{pos:[0,2,1],state:3},
{pos:[1,2,1],state:3},
{pos:[2,2,1],state:3},
{pos:[3,2,1],state:3},
{pos:[4,2,1],state:3},
{pos:[5,2,1],state:3},
{pos:[6,2,1],state:3},
{pos:[7,2,1],state:3},
{pos:[8,2,1],state:3},
{pos:[9,2,1],state:3},
{pos:[10,2,1],state:3},
{pos:[11,2,1],state:3},
{pos:[12,2,1],state:3},
{pos:[13,2,1],state:3},
{pos:[14,2,1],state:3},
{pos:[15,2,1],state:3},
{pos:[16,2,1],state:3},
{pos:[17,2,1],state:3},
{pos:[18,2,1],state:3},
{pos:[19,2,1],state:3},
{pos:[20,2,1],state:3},
{pos:[21,2,1],state:3},
{pos:[22,2,1],state:3},
{pos:[23,2,1],state:3},
{pos:[24,2,1],state:3},
{pos:[25,2,1],state:3},
{pos:[26,2,1],state:3},
{pos:[27,2,1],state:3},
{pos:[28,2,1],state:3},
{pos:[29,2,1],state:3},
{pos:[30,2,1],state:3},
{pos:[31,2,1],state:3},
{pos:[32,2,1],state:3},
{pos:[33,2,1],state:3},
{pos:[34,2,1],state:3},
{pos:[35,2,1],state:3},
{pos:[36,2,1],state:3},
{pos:[37,2,1],state:3},
{pos:[43,2,1],state:3},
{pos:[44,2,1],state:3},
{pos:[45,2,1],state:3},
{pos:[46,2,1],state:3},
{pos:[47,2,1],state:3},
{pos:[0,2,2],state:3},
{pos:[1,2,2],state:3},
{pos:[4,2,2],state:1},
{pos:[11,2,2],state:1},
{pos:[18,2,2],state:1},
{pos:[25,2,2],state:1},
{pos:[32,2,2],state:1},
{pos:[39,2,2],state:1},
{pos:[46,2,2],state:3},
{pos:[47,2,2],state:3},
{pos:[0,2,3],state:3},
{pos:[1,2,3],state:3},
{pos:[46,2,3],state:3},
{pos:[47,2,3],state:3},
{pos:[0,2,4],state:3},
{pos:[1,2,4],state:3},
{pos:[46,2,4],state:3},
{pos:[47,2,4],state:3},
{pos:[0,2,5],state:3},
{pos:[1,2,5],state:3},
{pos:[2,2,5],state:1},
{pos:[45,2,5],state:1},
{pos:[46,2,5],state:3},
{pos:[47,2,5],state:3},
{pos:[0,2,6],state:3},
{pos:[1,2,6],state:3},
{pos:[46,2,6],state:3},
{pos:[47,2,6],state:3},
{pos:[0,2,7],state:3},
{pos:[1,2,7],state:3},
{pos:[46,2,7],state:3},
{pos:[47,2,7],state:3},
{pos:[0,2,8],state:3},
{pos:[1,2,8],state:3},
{pos:[10,2,8],state:1},
{pos:[11,2,8],state:1},
{pos:[12,2,8],state:1},
{pos:[18,2,8],state:1},
{pos:[19,2,8],state:1},
{pos:[20,2,8],state:1},
{pos:[29,2,8],state:1},
{pos:[30,2,8],state:1},
{pos:[31,2,8],state:1},
{pos:[37,2,8],state:1},
{pos:[38,2,8],state:1},
{pos:[39,2,8],state:1},
{pos:[46,2,8],state:3},
{pos:[47,2,8],state:3},
{pos:[0,2,9],state:3},
{pos:[1,2,9],state:3},
{pos:[10,2,9],state:1},
{pos:[11,2,9],state:1},
{pos:[12,2,9],state:1},
{pos:[18,2,9],state:1},
{pos:[19,2,9],state:1},
{pos:[20,2,9],state:1},
{pos:[29,2,9],state:1},
{pos:[30,2,9],state:1},
{pos:[31,2,9],state:1},
{pos:[37,2,9],state:1},
{pos:[38,2,9],state:1},
{pos:[39,2,9],state:1},
{pos:[46,2,9],state:3},
{pos:[47,2,9],state:3},
{pos:[0,2,10],state:3},
{pos:[1,2,10],state:3},
{pos:[10,2,10],state:1},
{pos:[11,2,10],state:1},
{pos:[12,2,10],state:1},
{pos:[18,2,10],state:1},
{pos:[19,2,10],state:1},
{pos:[20,2,10],state:1},
{pos:[29,2,10],state:1},
{pos:[30,2,10],state:1},
{pos:[31,2,10],state:1},
{pos:[37,2,10],state:1},
{pos:[38,2,10],state:1},
{pos:[39,2,10],state:1},
{pos:[46,2,10],state:3},
{pos:[47,2,10],state:3},
{pos:[0,2,11],state:3},
{pos:[1,2,11],state:3},
{pos:[10,2,11],state:1},
{pos:[11,2,11],state:1},
{pos:[12,2,11],state:1},
{pos:[18,2,11],state:1},
{pos:[19,2,11],state:1},
{pos:[20,2,11],state:1},
{pos:[29,2,11],state:1},
{pos:[30,2,11],state:1},
{pos:[31,2,11],state:1},
{pos:[37,2,11],state:1},
{pos:[38,2,11],state:1},
{pos:[39,2,11],state:1},
{pos:[46,2,11],state:3},
{pos:[47,2,11],state:3},
{pos:[0,2,12],state:3},
{pos:[1,2,12],state:3},
{pos:[10,2,12],state:1},
{pos:[11,2,12],state:1},
{pos:[12,2,12],state:1},
{pos:[18,2,12],state:1},
{pos:[19,2,12],state:1},
{pos:[20,2,12],state:1},
{pos:[29,2,12],state:1},
{pos:[30,2,12],state:1},
{pos:[31,2,12],state:1},
{pos:[37,2,12],state:1},
{pos:[38,2,12],state:1},
{pos:[39,2,12],state:1},
{pos:[46,2,12],state:3},
{pos:[47,2,12],state:3},
{pos:[0,2,13],state:3},
{pos:[1,2,13],state:3},
{pos:[2,2,13],state:1},
{pos:[45,2,13],state:1},
{pos:[46,2,13],state:3},
{pos:[47,2,13],state:3},
{pos:[0,2,14],state:3},
{pos:[1,2,14],state:3},
{pos:[46,2,14],state:3},
{pos:[47,2,14],state:3},
{pos:[0,2,15],state:3},
{pos:[1,2,15],state:3},
{pos:[46,2,15],state:3},
{pos:[47,2,15],state:3},
{pos:[0,2,16],state:3},
{pos:[1,2,16],state:3},
{pos:[46,2,16],state:3},
{pos:[47,2,16],state:3},
{pos:[0,2,17],state:3},
{pos:[1,2,17],state:3},
{pos:[0,2,18],state:3},
{pos:[1,2,18],state:3},
{pos:[0,2,19],state:3},
{pos:[1,2,19],state:3},
{pos:[0,2,20],state:3},
{pos:[1,2,20],state:3},
{pos:[0,2,21],state:3},
{pos:[1,2,21],state:3},
{pos:[2,2,21],state:1},
{pos:[45,2,21],state:1},
{pos:[0,2,22],state:3},
{pos:[1,2,22],state:3},
{pos:[46,2,22],state:3},
{pos:[47,2,22],state:3},
{pos:[0,2,23],state:3},
{pos:[1,2,23],state:3},
{pos:[46,2,23],state:3},
{pos:[47,2,23],state:3},
{pos:[0,2,24],state:3},
{pos:[1,2,24],state:3},
{pos:[46,2,24],state:3},
{pos:[47,2,24],state:3},
{pos:[0,2,25],state:3},
{pos:[1,2,25],state:3},
{pos:[46,2,25],state:3},
{pos:[47,2,25],state:3},
{pos:[0,2,26],state:3},
{pos:[1,2,26],state:3},
{pos:[46,2,26],state:3},
{pos:[47,2,26],state:3},
{pos:[0,2,27],state:3},
{pos:[1,2,27],state:3},
{pos:[46,2,27],state:3},
{pos:[47,2,27],state:3},
{pos:[0,2,28],state:3},
{pos:[1,2,28],state:3},
{pos:[10,2,28],state:1},
{pos:[11,2,28],state:1},
{pos:[12,2,28],state:1},
{pos:[18,2,28],state:1},
{pos:[19,2,28],state:1},
{pos:[20,2,28],state:1},
{pos:[29,2,28],state:1},
{pos:[30,2,28],state:1},
{pos:[31,2,28],state:1},
{pos:[37,2,28],state:1},
{pos:[38,2,28],state:1},
{pos:[39,2,28],state:1},
{pos:[46,2,28],state:3},
{pos:[47,2,28],state:3},
{pos:[0,2,29],state:3},
{pos:[1,2,29],state:3},
{pos:[2,2,29],state:1},
{pos:[10,2,29],state:1},
{pos:[11,2,29],state:1},
{pos:[12,2,29],state:1},
{pos:[18,2,29],state:1},
{pos:[19,2,29],state:1},
{pos:[20,2,29],state:1},
{pos:[29,2,29],state:1},
{pos:[30,2,29],state:1},
{pos:[31,2,29],state:1},
{pos:[37,2,29],state:1},
{pos:[38,2,29],state:1},
{pos:[39,2,29],state:1},
{pos:[45,2,29],state:1},
{pos:[46,2,29],state:3},
{pos:[47,2,29],state:3},
{pos:[0,2,30],state:3},
{pos:[1,2,30],state:3},
{pos:[10,2,30],state:1},
{pos:[11,2,30],state:1},
{pos:[12,2,30],state:1},
{pos:[18,2,30],state:1},
{pos:[19,2,30],state:1},
{pos:[20,2,30],state:1},
{pos:[29,2,30],state:1},
{pos:[30,2,30],state:1},
{pos:[31,2,30],state:1},
{pos:[37,2,30],state:1},
{pos:[38,2,30],state:1},
{pos:[39,2,30],state:1},
{pos:[46,2,30],state:3},
{pos:[47,2,30],state:3},
{pos:[0,2,31],state:3},
{pos:[1,2,31],state:3},
{pos:[10,2,31],state:1},
{pos:[11,2,31],state:1},
{pos:[12,2,31],state:1},
{pos:[18,2,31],state:1},
{pos:[19,2,31],state:1},
{pos:[20,2,31],state:1},
{pos:[29,2,31],state:1},
{pos:[30,2,31],state:1},
{pos:[31,2,31],state:1},
{pos:[37,2,31],state:1},
{pos:[38,2,31],state:1},
{pos:[39,2,31],state:1},
{pos:[46,2,31],state:3},
{pos:[47,2,31],state:3},
{pos:[0,2,32],state:3},
{pos:[1,2,32],state:3},
{pos:[10,2,32],state:1},
{pos:[11,2,32],state:1},
{pos:[12,2,32],state:1},
{pos:[18,2,32],state:1},
{pos:[19,2,32],state:1},
{pos:[20,2,32],state:1},
{pos:[29,2,32],state:1},
{pos:[30,2,32],state:1},
{pos:[31,2,32],state:1},
{pos:[37,2,32],state:1},
{pos:[38,2,32],state:1},
{pos:[39,2,32],state:1},
{pos:[46,2,32],state:3},
{pos:[47,2,32],state:3},
{pos:[0,2,33],state:3},
{pos:[1,2,33],state:3},
{pos:[46,2,33],state:3},
{pos:[47,2,33],state:3},
{pos:[0,2,34],state:3},
{pos:[1,2,34],state:3},
{pos:[46,2,34],state:3},
{pos:[47,2,34],state:3},
{pos:[0,2,35],state:3},
{pos:[1,2,35],state:3},
{pos:[46,2,35],state:3},
{pos:[47,2,35],state:3},
{pos:[0,2,36],state:3},
{pos:[1,2,36],state:3},
{pos:[46,2,36],state:3},
{pos:[47,2,36],state:3},
{pos:[0,2,37],state:3},
{pos:[1,2,37],state:3},
{pos:[4,2,37],state:1},
{pos:[11,2,37],state:1},
{pos:[18,2,37],state:1},
{pos:[25,2,37],state:1},
{pos:[32,2,37],state:1},
{pos:[39,2,37],state:1},
{pos:[46,2,37],state:3},
{pos:[47,2,37],state:3},
{pos:[0,2,38],state:3},
{pos:[1,2,38],state:3},
{pos:[2,2,38],state:3},
{pos:[3,2,38],state:3},
{pos:[4,2,38],state:3},
{pos:[5,2,38],state:3},
{pos:[6,2,38],state:3},
{pos:[7,2,38],state:3},
{pos:[8,2,38],state:3},
{pos:[9,2,38],state:3},
{pos:[10,2,38],state:3},
{pos:[11,2,38],state:3},
{pos:[12,2,38],state:3},
{pos:[13,2,38],state:3},
{pos:[14,2,38],state:3},
{pos:[15,2,38],state:3},
{pos:[16,2,38],state:3},
{pos:[17,2,38],state:3},
{pos:[18,2,38],state:3},
{pos:[19,2,38],state:3},
{pos:[20,2,38],state:3},
{pos:[21,2,38],state:3},
{pos:[22,2,38],state:3},
{pos:[23,2,38],state:3},
{pos:[24,2,38],state:3},
{pos:[25,2,38],state:3},
{pos:[26,2,38],state:3},
{pos:[27,2,38],state:3},
{pos:[28,2,38],state:3},
{pos:[29,2,38],state:3},
{pos:[30,2,38],state:3},
{pos:[31,2,38],state:3},
{pos:[32,2,38],state:3},
{pos:[33,2,38],state:3},
{pos:[34,2,38],state:3},
{pos:[35,2,38],state:3},
{pos:[36,2,38],state:3},
{pos:[37,2,38],state:3},
{pos:[38,2,38],state:3},
{pos:[39,2,38],state:3},
{pos:[40,2,38],state:3},
{pos:[41,2,38],state:3},
{pos:[42,2,38],state:3},
{pos:[43,2,38],state:3},
{pos:[44,2,38],state:3},
{pos:[45,2,38],state:3},
{pos:[46,2,38],state:3},
{pos:[47,2,38],state:3},
{pos:[0,2,39],state:3},
{pos:[1,2,39],state:3},
{pos:[2,2,39],state:3},
{pos:[3,2,39],state:3},
{pos:[4,2,39],state:3},
{pos:[5,2,39],state:3},
{pos:[6,2,39],state:3},
{pos:[7,2,39],state:3},
{pos:[8,2,39],state:3},
{pos:[9,2,39],state:3},
{pos:[10,2,39],state:3},
{pos:[11,2,39],state:3},
{pos:[12,2,39],state:3},
{pos:[13,2,39],state:3},
{pos:[14,2,39],state:3},
{pos:[15,2,39],state:3},
{pos:[16,2,39],state:3},
{pos:[17,2,39],state:3},
{pos:[18,2,39],state:3},
{pos:[19,2,39],state:3},
{pos:[20,2,39],state:3},
{pos:[21,2,39],state:3},
{pos:[22,2,39],state:3},
{pos:[23,2,39],state:3},
{pos:[24,2,39],state:3},
{pos:[25,2,39],state:3},
{pos:[26,2,39],state:3},
{pos:[27,2,39],state:3},
{pos:[28,2,39],state:3},
{pos:[29,2,39],state:3},
{pos:[30,2,39],state:3},
{pos:[31,2,39],state:3},
{pos:[32,2,39],state:3},
{pos:[33,2,39],state:3},
{pos:[34,2,39],state:3},
{pos:[35,2,39],state:3},
{pos:[36,2,39],state:3},
{pos:[37,2,39],state:3},
{pos:[38,2,39],state:3},
{pos:[39,2,39],state:3},
{pos:[40,2,39],state:3},
{pos:[41,2,39],state:3},
{pos:[42,2,39],state:3},
{pos:[43,2,39],state:3},
{pos:[44,2,39],state:3},
{pos:[45,2,39],state:3},
{pos:[46,2,39],state:3},
{pos:[47,2,39],state:3},
{pos:[0,3,0],state:3},
{pos:[1,3,0],state:3},
{pos:[2,3,0],state:3},
{pos:[3,3,0],state:3},
{pos:[4,3,0],state:3},
{pos:[5,3,0],state:3},
{pos:[6,3,0],state:3},
{pos:[7,3,0],state:3},
{pos:[8,3,0],state:3},
{pos:[9,3,0],state:3},
{pos:[10,3,0],state:3},
{pos:[11,3,0],state:3},
{pos:[12,3,0],state:3},
{pos:[13,3,0],state:3},
{pos:[14,3,0],state:3},
{pos:[15,3,0],state:3},
{pos:[16,3,0],state:3},
{pos:[17,3,0],state:3},
{pos:[18,3,0],state:3},
{pos:[19,3,0],state:3},
{pos:[20,3,0],state:3},
{pos:[21,3,0],state:3},
{pos:[22,3,0],state:3},
{pos:[23,3,0],state:3},
{pos:[24,3,0],state:3},
{pos:[25,3,0],state:3},
{pos:[26,3,0],state:3},
{pos:[27,3,0],state:3},
{pos:[28,3,0],state:3},
{pos:[29,3,0],state:3},
{pos:[30,3,0],state:3},
{pos:[31,3,0],state:3},
{pos:[32,3,0],state:3},
{pos:[33,3,0],state:3},
{pos:[34,3,0],state:3},
{pos:[35,3,0],state:3},
{pos:[36,3,0],state:3},
{pos:[37,3,0],state:3},
{pos:[43,3,0],state:3},
{pos:[44,3,0],state:3},
{pos:[45,3,0],state:3},
{pos:[46,3,0],state:3},
{pos:[47,3,0],state:3},
{pos:[0,3,1],state:3},
{pos:[1,3,1],state:3},
{pos:[2,3,1],state:3},
{pos:[3,3,1],state:3},
{pos:[4,3,1],state:3},
{pos:[5,3,1],state:3},
{pos:[6,3,1],state:3},
{pos:[7,3,1],state:3},
{pos:[8,3,1],state:3},
{pos:[9,3,1],state:3},
{pos:[10,3,1],state:3},
{pos:[11,3,1],state:3},
{pos:[12,3,1],state:3},
{pos:[13,3,1],state:3},
{pos:[14,3,1],state:3},
{pos:[15,3,1],state:3},
{pos:[16,3,1],state:3},
{pos:[17,3,1],state:3},
{pos:[18,3,1],state:3},
{pos:[19,3,1],state:3},
{pos:[20,3,1],state:3},
{pos:[21,3,1],state:3},
{pos:[22,3,1],state:3},
{pos:[23,3,1],state:3},
{pos:[24,3,1],state:3},
{pos:[25,3,1],state:3},
{pos:[26,3,1],state:3},
{pos:[27,3,1],state:3},
{pos:[28,3,1],state:3},
{pos:[29,3,1],state:3},
{pos:[30,3,1],state:3},
{pos:[31,3,1],state:3},
{pos:[32,3,1],state:3},
{pos:[33,3,1],state:3},
{pos:[34,3,1],state:3},
{pos:[35,3,1],state:3},
{pos:[36,3,1],state:3},
{pos:[37,3,1],state:3},
{pos:[43,3,1],state:3},
{pos:[44,3,1],state:3},
{pos:[45,3,1],state:3},
{pos:[46,3,1],state:3},
{pos:[47,3,1],state:3},
{pos:[0,3,2],state:3},
{pos:[1,3,2],state:3},
{pos:[4,3,2],state:1},
{pos:[11,3,2],state:1},
{pos:[18,3,2],state:1},
{pos:[25,3,2],state:1},
{pos:[32,3,2],state:1},
{pos:[39,3,2],state:1},
{pos:[46,3,2],state:3},
{pos:[47,3,2],state:3},
{pos:[0,3,3],state:3},
{pos:[1,3,3],state:3},
{pos:[46,3,3],state:3},
{pos:[47,3,3],state:3},
{pos:[0,3,4],state:3},
{pos:[1,3,4],state:3},
{pos:[46,3,4],state:3},
{pos:[47,3,4],state:3},
{pos:[0,3,5],state:3},
{pos:[1,3,5],state:3},
{pos:[2,3,5],state:1},
{pos:[45,3,5],state:1},
{pos:[46,3,5],state:3},
{pos:[47,3,5],state:3},
{pos:[0,3,6],state:3},
{pos:[1,3,6],state:3},
{pos:[46,3,6],state:3},
{pos:[47,3,6],state:3},
{pos:[0,3,7],state:3},
{pos:[1,3,7],state:3},
{pos:[46,3,7],state:3},
{pos:[47,3,7],state:3},
{pos:[0,3,8],state:3},
{pos:[1,3,8],state:3},
{pos:[10,3,8],state:1},
{pos:[11,3,8],state:1},
{pos:[12,3,8],state:1},
{pos:[18,3,8],state:1},
{pos:[19,3,8],state:1},
{pos:[20,3,8],state:1},
{pos:[29,3,8],state:1},
{pos:[30,3,8],state:1},
{pos:[31,3,8],state:1},
{pos:[37,3,8],state:1},
{pos:[38,3,8],state:1},
{pos:[39,3,8],state:1},
{pos:[46,3,8],state:3},
{pos:[47,3,8],state:3},
{pos:[0,3,9],state:3},
{pos:[1,3,9],state:3},
{pos:[10,3,9],state:1},
{pos:[11,3,9],state:1},
{pos:[12,3,9],state:1},
{pos:[18,3,9],state:1},
{pos:[19,3,9],state:1},
{pos:[20,3,9],state:1},
{pos:[29,3,9],state:1},
{pos:[30,3,9],state:1},
{pos:[31,3,9],state:1},
{pos:[37,3,9],state:1},
{pos:[38,3,9],state:1},
{pos:[39,3,9],state:1},
{pos:[46,3,9],state:3},
{pos:[47,3,9],state:3},
{pos:[0,3,10],state:3},
{pos:[1,3,10],state:3},
{pos:[10,3,10],state:1},
{pos:[11,3,10],state:1},
{pos:[12,3,10],state:1},
{pos:[18,3,10],state:1},
{pos:[19,3,10],state:1},
{pos:[20,3,10],state:1},
{pos:[29,3,10],state:1},
{pos:[30,3,10],state:1},
{pos:[31,3,10],state:1},
{pos:[37,3,10],state:1},
{pos:[38,3,10],state:1},
{pos:[39,3,10],state:1},
{pos:[46,3,10],state:3},
{pos:[47,3,10],state:3},
{pos:[0,3,11],state:3},
{pos:[1,3,11],state:3},
{pos:[10,3,11],state:1},
{pos:[11,3,11],state:1},
{pos:[12,3,11],state:1},
{pos:[18,3,11],state:1},
{pos:[19,3,11],state:1},
{pos:[20,3,11],state:1},
{pos:[29,3,11],state:1},
{pos:[30,3,11],state:1},
{pos:[31,3,11],state:1},
{pos:[37,3,11],state:1},
{pos:[38,3,11],state:1},
{pos:[39,3,11],state:1},
{pos:[46,3,11],state:3},
{pos:[47,3,11],state:3},
{pos:[0,3,12],state:3},
{pos:[1,3,12],state:3},
{pos:[10,3,12],state:1},
{pos:[11,3,12],state:1},
{pos:[12,3,12],state:1},
{pos:[18,3,12],state:1},
{pos:[19,3,12],state:1},
{pos:[20,3,12],state:1},
{pos:[29,3,12],state:1},
{pos:[30,3,12],state:1},
{pos:[31,3,12],state:1},
{pos:[37,3,12],state:1},
{pos:[38,3,12],state:1},
{pos:[39,3,12],state:1},
{pos:[46,3,12],state:3},
{pos:[47,3,12],state:3},
{pos:[0,3,13],state:3},
{pos:[1,3,13],state:3},
{pos:[2,3,13],state:1},
{pos:[45,3,13],state:1},
{pos:[46,3,13],state:3},
{pos:[47,3,13],state:3},
{pos:[0,3,14],state:3},
{pos:[1,3,14],state:3},
{pos:[46,3,14],state:3},
{pos:[47,3,14],state:3},
{pos:[0,3,15],state:3},
{pos:[1,3,15],state:3},
{pos:[46,3,15],state:3},
{pos:[47,3,15],state:3},
{pos:[0,3,16],state:3},
{pos:[1,3,16],state:3},
{pos:[46,3,16],state:3},
{pos:[47,3,16],state:3},
{pos:[0,3,17],state:3},
{pos:[1,3,17],state:3},
{pos:[0,3,18],state:3},
{pos:[1,3,18],state:3},
{pos:[0,3,19],state:3},
{pos:[1,3,19],state:3},
{pos:[0,3,20],state:3},
{pos:[1,3,20],state:3},
{pos:[0,3,21],state:3},
{pos:[1,3,21],state:3},
{pos:[2,3,21],state:1},
{pos:[45,3,21],state:1},
{pos:[0,3,22],state:3},
{pos:[1,3,22],state:3},
{pos:[46,3,22],state:3},
{pos:[47,3,22],state:3},
{pos:[0,3,23],state:3},
{pos:[1,3,23],state:3},
{pos:[46,3,23],state:3},
{pos:[47,3,23],state:3},
{pos:[0,3,24],state:3},
{pos:[1,3,24],state:3},
{pos:[46,3,24],state:3},
{pos:[47,3,24],state:3},
{pos:[0,3,25],state:3},
{pos:[1,3,25],state:3},
{pos:[46,3,25],state:3},
{pos:[47,3,25],state:3},
{pos:[0,3,26],state:3},
{pos:[1,3,26],state:3},
{pos:[46,3,26],state:3},
{pos:[47,3,26],state:3},
{pos:[0,3,27],state:3},
{pos:[1,3,27],state:3},
{pos:[46,3,27],state:3},
{pos:[47,3,27],state:3},
{pos:[0,3,28],state:3},
{pos:[1,3,28],state:3},
{pos:[10,3,28],state:1},
{pos:[11,3,28],state:1},
{pos:[12,3,28],state:1},
{pos:[18,3,28],state:1},
{pos:[19,3,28],state:1},
{pos:[20,3,28],state:1},
{pos:[29,3,28],state:1},
{pos:[30,3,28],state:1},
{pos:[31,3,28],state:1},
{pos:[37,3,28],state:1},
{pos:[38,3,28],state:1},
{pos:[39,3,28],state:1},
{pos:[46,3,28],state:3},
{pos:[47,3,28],state:3},
{pos:[0,3,29],state:3},
{pos:[1,3,29],state:3},
{pos:[2,3,29],state:1},
{pos:[10,3,29],state:1},
{pos:[11,3,29],state:1},
{pos:[12,3,29],state:1},
{pos:[18,3,29],state:1},
{pos:[19,3,29],state:1},
{pos:[20,3,29],state:1},
{pos:[29,3,29],state:1},
{pos:[30,3,29],state:1},
{pos:[31,3,29],state:1},
{pos:[37,3,29],state:1},
{pos:[38,3,29],state:1},
{pos:[39,3,29],state:1},
{pos:[45,3,29],state:1},
{pos:[46,3,29],state:3},
{pos:[47,3,29],state:3},
{pos:[0,3,30],state:3},
{pos:[1,3,30],state:3},
{pos:[10,3,30],state:1},
{pos:[11,3,30],state:1},
{pos:[12,3,30],state:1},
{pos:[18,3,30],state:1},
{pos:[19,3,30],state:1},
{pos:[20,3,30],state:1},
{pos:[29,3,30],state:1},
{pos:[30,3,30],state:1},
{pos:[31,3,30],state:1},
{pos:[37,3,30],state:1},
{pos:[38,3,30],state:1},
{pos:[39,3,30],state:1},
{pos:[46,3,30],state:3},
{pos:[47,3,30],state:3},
{pos:[0,3,31],state:3},
{pos:[1,3,31],state:3},
{pos:[10,3,31],state:1},
{pos:[11,3,31],state:1},
{pos:[12,3,31],state:1},
{pos:[18,3,31],state:1},
{pos:[19,3,31],state:1},
{pos:[20,3,31],state:1},
{pos:[29,3,31],state:1},
{pos:[30,3,31],state:1},
{pos:[31,3,31],state:1},
{pos:[37,3,31],state:1},
{pos:[38,3,31],state:1},
{pos:[39,3,31],state:1},
{pos:[46,3,31],state:3},
{pos:[47,3,31],state:3},
{pos:[0,3,32],state:3},
{pos:[1,3,32],state:3},
{pos:[10,3,32],state:1},
{pos:[11,3,32],state:1},
{pos:[12,3,32],state:1},
{pos:[18,3,32],state:1},
{pos:[19,3,32],state:1},
{pos:[20,3,32],state:1},
{pos:[29,3,32],state:1},
{pos:[30,3,32],state:1},
{pos:[31,3,32],state:1},
{pos:[37,3,32],state:1},
{pos:[38,3,32],state:1},
{pos:[39,3,32],state:1},
{pos:[46,3,32],state:3},
{pos:[47,3,32],state:3},
{pos:[0,3,33],state:3},
{pos:[1,3,33],state:3},
{pos:[46,3,33],state:3},
{pos:[47,3,33],state:3},
{pos:[0,3,34],state:3},
{pos:[1,3,34],state:3},
{pos:[46,3,34],state:3},
{pos:[47,3,34],state:3},
{pos:[0,3,35],state:3},
{pos:[1,3,35],state:3},
{pos:[46,3,35],state:3},
{pos:[47,3,35],state:3},
{pos:[0,3,36],state:3},
{pos:[1,3,36],state:3},
{pos:[46,3,36],state:3},
{pos:[47,3,36],state:3},
{pos:[0,3,37],state:3},
{pos:[1,3,37],state:3},
{pos:[4,3,37],state:1},
{pos:[11,3,37],state:1},
{pos:[18,3,37],state:1},
{pos:[25,3,37],state:1},
{pos:[32,3,37],state:1},
{pos:[39,3,37],state:1},
{pos:[46,3,37],state:3},
{pos:[47,3,37],state:3},
{pos:[0,3,38],state:3},
{pos:[1,3,38],state:3},
{pos:[2,3,38],state:3},
{pos:[3,3,38],state:3},
{pos:[4,3,38],state:3},
{pos:[5,3,38],state:3},
{pos:[6,3,38],state:3},
{pos:[7,3,38],state:3},
{pos:[8,3,38],state:3},
{pos:[9,3,38],state:3},
{pos:[10,3,38],state:3},
{pos:[11,3,38],state:3},
{pos:[12,3,38],state:3},
{pos:[13,3,38],state:3},
{pos:[14,3,38],state:3},
{pos:[15,3,38],state:3},
{pos:[16,3,38],state:3},
{pos:[17,3,38],state:3},
{pos:[18,3,38],state:3},
{pos:[19,3,38],state:3},
{pos:[20,3,38],state:3},
{pos:[21,3,38],state:3},
{pos:[22,3,38],state:3},
{pos:[23,3,38],state:3},
{pos:[24,3,38],state:3},
{pos:[25,3,38],state:3},
{pos:[26,3,38],state:3},
{pos:[27,3,38],state:3},
{pos:[28,3,38],state:3},
{pos:[29,3,38],state:3},
{pos:[30,3,38],state:3},
{pos:[31,3,38],state:3},
{pos:[32,3,38],state:3},
{pos:[33,3,38],state:3},
{pos:[34,3,38],state:3},
{pos:[35,3,38],state:3},
{pos:[36,3,38],state:3},
{pos:[37,3,38],state:3},
{pos:[38,3,38],state:3},
{pos:[39,3,38],state:3},
{pos:[40,3,38],state:3},
{pos:[41,3,38],state:3},
{pos:[42,3,38],state:3},
{pos:[43,3,38],state:3},
{pos:[44,3,38],state:3},
{pos:[45,3,38],state:3},
{pos:[46,3,38],state:3},
{pos:[47,3,38],state:3},
{pos:[0,3,39],state:3},
{pos:[1,3,39],state:3},
{pos:[2,3,39],state:3},
{pos:[3,3,39],state:3},
{pos:[4,3,39],state:3},
{pos:[5,3,39],state:3},
{pos:[6,3,39],state:3},
{pos:[7,3,39],state:3},
{pos:[8,3,39],state:3},
{pos:[9,3,39],state:3},
{pos:[10,3,39],state:3},
{pos:[11,3,39],state:3},
{pos:[12,3,39],state:3},
{pos:[13,3,39],state:3},
{pos:[14,3,39],state:3},
{pos:[15,3,39],state:3},
{pos:[16,3,39],state:3},
{pos:[17,3,39],state:3},
{pos:[18,3,39],state:3},
{pos:[19,3,39],state:3},
{pos:[20,3,39],state:3},
{pos:[21,3,39],state:3},
{pos:[22,3,39],state:3},
{pos:[23,3,39],state:3},
{pos:[24,3,39],state:3},
{pos:[25,3,39],state:3},
{pos:[26,3,39],state:3},
{pos:[27,3,39],state:3},
{pos:[28,3,39],state:3},
{pos:[29,3,39],state:3},
{pos:[30,3,39],state:3},
{pos:[31,3,39],state:3},
{pos:[32,3,39],state:3},
{pos:[33,3,39],state:3},
{pos:[34,3,39],state:3},
{pos:[35,3,39],state:3},
{pos:[36,3,39],state:3},
{pos:[37,3,39],state:3},
{pos:[38,3,39],state:3},
{pos:[39,3,39],state:3},
{pos:[40,3,39],state:3},
{pos:[41,3,39],state:3},
{pos:[42,3,39],state:3},
{pos:[43,3,39],state:3},
{pos:[44,3,39],state:3},
{pos:[45,3,39],state:3},
{pos:[46,3,39],state:3},
{pos:[47,3,39],state:3},
{pos:[0,4,0],state:3},
{pos:[1,4,0],state:3},
{pos:[2,4,0],state:3},
{pos:[3,4,0],state:3},
{pos:[4,4,0],state:3},
{pos:[5,4,0],state:3},
{pos:[6,4,0],state:3},
{pos:[7,4,0],state:3},
{pos:[8,4,0],state:3},
{pos:[9,4,0],state:3},
{pos:[10,4,0],state:3},
{pos:[11,4,0],state:3},
{pos:[12,4,0],state:3},
{pos:[13,4,0],state:3},
{pos:[14,4,0],state:3},
{pos:[15,4,0],state:3},
{pos:[16,4,0],state:3},
{pos:[17,4,0],state:3},
{pos:[18,4,0],state:3},
{pos:[19,4,0],state:3},
{pos:[20,4,0],state:3},
{pos:[21,4,0],state:3},
{pos:[22,4,0],state:3},
{pos:[23,4,0],state:3},
{pos:[24,4,0],state:3},
{pos:[25,4,0],state:3},
{pos:[26,4,0],state:3},
{pos:[27,4,0],state:3},
{pos:[28,4,0],state:3},
{pos:[29,4,0],state:3},
{pos:[30,4,0],state:3},
{pos:[31,4,0],state:3},
{pos:[32,4,0],state:3},
{pos:[33,4,0],state:3},
{pos:[34,4,0],state:3},
{pos:[35,4,0],state:3},
{pos:[36,4,0],state:3},
{pos:[37,4,0],state:3},
{pos:[43,4,0],state:3},
{pos:[44,4,0],state:3},
{pos:[45,4,0],state:3},
{pos:[46,4,0],state:3},
{pos:[47,4,0],state:3},
{pos:[0,4,1],state:3},
{pos:[1,4,1],state:3},
{pos:[2,4,1],state:3},
{pos:[3,4,1],state:3},
{pos:[4,4,1],state:3},
{pos:[5,4,1],state:3},
{pos:[6,4,1],state:3},
{pos:[7,4,1],state:3},
{pos:[8,4,1],state:3},
{pos:[9,4,1],state:3},
{pos:[10,4,1],state:3},
{pos:[11,4,1],state:3},
{pos:[12,4,1],state:3},
{pos:[13,4,1],state:3},
{pos:[14,4,1],state:3},
{pos:[15,4,1],state:3},
{pos:[16,4,1],state:3},
{pos:[17,4,1],state:3},
{pos:[18,4,1],state:3},
{pos:[19,4,1],state:3},
{pos:[20,4,1],state:3},
{pos:[21,4,1],state:3},
{pos:[22,4,1],state:3},
{pos:[23,4,1],state:3},
{pos:[24,4,1],state:3},
{pos:[25,4,1],state:3},
{pos:[26,4,1],state:3},
{pos:[27,4,1],state:3},
{pos:[28,4,1],state:3},
{pos:[29,4,1],state:3},
{pos:[30,4,1],state:3},
{pos:[31,4,1],state:3},
{pos:[32,4,1],state:3},
{pos:[33,4,1],state:3},
{pos:[34,4,1],state:3},
{pos:[35,4,1],state:3},
{pos:[36,4,1],state:3},
{pos:[37,4,1],state:3},
{pos:[43,4,1],state:3},
{pos:[44,4,1],state:3},
{pos:[45,4,1],state:3},
{pos:[46,4,1],state:3},
{pos:[47,4,1],state:3},
{pos:[0,4,2],state:3},
{pos:[1,4,2],state:3},
{pos:[4,4,2],state:1},
{pos:[11,4,2],state:1},
{pos:[18,4,2],state:1},
{pos:[25,4,2],state:1},
{pos:[32,4,2],state:1},
{pos:[39,4,2],state:1},
{pos:[46,4,2],state:3},
{pos:[47,4,2],state:3},
{pos:[0,4,3],state:3},
{pos:[1,4,3],state:3},
{pos:[46,4,3],state:3},
{pos:[47,4,3],state:3},
{pos:[0,4,4],state:3},
{pos:[1,4,4],state:3},
{pos:[46,4,4],state:3},
{pos:[47,4,4],state:3},
{pos:[0,4,5],state:3},
{pos:[1,4,5],state:3},
{pos:[2,4,5],state:1},
{pos:[45,4,5],state:1},
{pos:[46,4,5],state:3},
{pos:[47,4,5],state:3},
{pos:[0,4,6],state:3},
{pos:[1,4,6],state:3},
{pos:[46,4,6],state:3},
{pos:[47,4,6],state:3},
{pos:[0,4,7],state:3},
{pos:[1,4,7],state:3},
{pos:[46,4,7],state:3},
{pos:[47,4,7],state:3},
{pos:[0,4,8],state:3},
{pos:[1,4,8],state:3},
{pos:[46,4,8],state:3},
{pos:[47,4,8],state:3},
{pos:[0,4,9],state:3},
{pos:[1,4,9],state:3},
{pos:[46,4,9],state:3},
{pos:[47,4,9],state:3},
{pos:[0,4,10],state:3},
{pos:[1,4,10],state:3},
{pos:[46,4,10],state:3},
{pos:[47,4,10],state:3},
{pos:[0,4,11],state:3},
{pos:[1,4,11],state:3},
{pos:[46,4,11],state:3},
{pos:[47,4,11],state:3},
{pos:[0,4,12],state:3},
{pos:[1,4,12],state:3},
{pos:[46,4,12],state:3},
{pos:[47,4,12],state:3},
{pos:[0,4,13],state:3},
{pos:[1,4,13],state:3},
{pos:[2,4,13],state:1},
{pos:[45,4,13],state:1},
{pos:[46,4,13],state:3},
{pos:[47,4,13],state:3},
{pos:[0,4,14],state:3},
{pos:[1,4,14],state:3},
{pos:[46,4,14],state:3},
{pos:[47,4,14],state:3},
{pos:[0,4,15],state:3},
{pos:[1,4,15],state:3},
{pos:[46,4,15],state:3},
{pos:[47,4,15],state:3},
{pos:[0,4,16],state:3},
{pos:[1,4,16],state:3},
{pos:[46,4,16],state:3},
{pos:[47,4,16],state:3},
{pos:[0,4,17],state:3},
{pos:[1,4,17],state:3},
{pos:[0,4,18],state:3},
{pos:[1,4,18],state:3},
{pos:[0,4,19],state:3},
{pos:[1,4,19],state:3},
{pos:[0,4,20],state:3},
{pos:[1,4,20],state:3},
{pos:[0,4,21],state:3},
{pos:[1,4,21],state:3},
{pos:[2,4,21],state:1},
{pos:[45,4,21],state:1},
{pos:[0,4,22],state:3},
{pos:[1,4,22],state:3},
{pos:[46,4,22],state:3},
{pos:[47,4,22],state:3},
{pos:[0,4,23],state:3},
{pos:[1,4,23],state:3},
{pos:[46,4,23],state:3},
{pos:[47,4,23],state:3},
{pos:[0,4,24],state:3},
{pos:[1,4,24],state:3},
{pos:[46,4,24],state:3},
{pos:[47,4,24],state:3},
{pos:[0,4,25],state:3},
{pos:[1,4,25],state:3},
{pos:[46,4,25],state:3},
{pos:[47,4,25],state:3},
{pos:[0,4,26],state:3},
{pos:[1,4,26],state:3},
{pos:[46,4,26],state:3},
{pos:[47,4,26],state:3},
{pos:[0,4,27],state:3},
{pos:[1,4,27],state:3},
{pos:[46,4,27],state:3},
{pos:[47,4,27],state:3},
{pos:[0,4,28],state:3},
{pos:[1,4,28],state:3},
{pos:[46,4,28],state:3},
{pos:[47,4,28],state:3},
{pos:[0,4,29],state:3},
{pos:[1,4,29],state:3},
{pos:[2,4,29],state:1},
{pos:[45,4,29],state:1},
{pos:[46,4,29],state:3},
{pos:[47,4,29],state:3},
{pos:[0,4,30],state:3},
{pos:[1,4,30],state:3},
{pos:[46,4,30],state:3},
{pos:[47,4,30],state:3},
{pos:[0,4,31],state:3},
{pos:[1,4,31],state:3},
{pos:[46,4,31],state:3},
{pos:[47,4,31],state:3},
{pos:[0,4,32],state:3},
{pos:[1,4,32],state:3},
{pos:[46,4,32],state:3},
{pos:[47,4,32],state:3},
{pos:[0,4,33],state:3},
{pos:[1,4,33],state:3},
{pos:[46,4,33],state:3},
{pos:[47,4,33],state:3},
{pos:[0,4,34],state:3},
{pos:[1,4,34],state:3},
{pos:[46,4,34],state:3},
{pos:[47,4,34],state:3},
{pos:[0,4,35],state:3},
{pos:[1,4,35],state:3},
{pos:[46,4,35],state:3},
{pos:[47,4,35],state:3},
{pos:[0,4,36],state:3},
{pos:[1,4,36],state:3},
{pos:[46,4,36],state:3},
{pos:[47,4,36],state:3},
{pos:[0,4,37],state:3},
{pos:[1,4,37],state:3},
{pos:[4,4,37],state:1},
{pos:[11,4,37],state:1},
{pos:[18,4,37],state:1},
{pos:[25,4,37],state:1},
{pos:[32,4,37],state:1},
{pos:[39,4,37],state:1},
{pos:[46,4,37],state:3},
{pos:[47,4,37],state:3},
{pos:[0,4,38],state:3},
{pos:[1,4,38],state:3},
{pos:[2,4,38],state:3},
{pos:[3,4,38],state:3},
{pos:[4,4,38],state:3},
{pos:[5,4,38],state:3},
{pos:[6,4,38],state:3},
{pos:[7,4,38],state:3},
{pos:[8,4,38],state:3},
{pos:[9,4,38],state:3},
{pos:[10,4,38],state:3},
{pos:[11,4,38],state:3},
{pos:[12,4,38],state:3},
{pos:[13,4,38],state:3},
{pos:[14,4,38],state:3},
{pos:[15,4,38],state:3},
{pos:[16,4,38],state:3},
{pos:[17,4,38],state:3},
{pos:[18,4,38],state:3},
{pos:[19,4,38],state:3},
{pos:[20,4,38],state:3},
{pos:[21,4,38],state:3},
{pos:[22,4,38],state:3},
{pos:[23,4,38],state:3},
{pos:[24,4,38],state:3},
{pos:[25,4,38],state:3},
{pos:[26,4,38],state:3},
{pos:[27,4,38],state:3},
{pos:[28,4,38],state:3},
{pos:[29,4,38],state:3},
{pos:[30,4,38],state:3},
{pos:[31,4,38],state:3},
{pos:[32,4,38],state:3},
{pos:[33,4,38],state:3},
{pos:[34,4,38],state:3},
{pos:[35,4,38],state:3},
{pos:[36,4,38],state:3},
{pos:[37,4,38],state:3},
{pos:[38,4,38],state:3},
{pos:[39,4,38],state:3},
{pos:[40,4,38],state:3},
{pos:[41,4,38],state:3},
{pos:[42,4,38],state:3},
{pos:[43,4,38],state:3},
{pos:[44,4,38],state:3},
{pos:[45,4,38],state:3},
{pos:[46,4,38],state:3},
{pos:[47,4,38],state:3},
{pos:[0,4,39],state:3},
{pos:[1,4,39],state:3},
{pos:[2,4,39],state:3},
{pos:[3,4,39],state:3},
{pos:[4,4,39],state:3},
{pos:[5,4,39],state:3},
{pos:[6,4,39],state:3},
{pos:[7,4,39],state:3},
{pos:[8,4,39],state:3},
{pos:[9,4,39],state:3},
{pos:[10,4,39],state:3},
{pos:[11,4,39],state:3},
{pos:[12,4,39],state:3},
{pos:[13,4,39],state:3},
{pos:[14,4,39],state:3},
{pos:[15,4,39],state:3},
{pos:[16,4,39],state:3},
{pos:[17,4,39],state:3},
{pos:[18,4,39],state:3},
{pos:[19,4,39],state:3},
{pos:[20,4,39],state:3},
{pos:[21,4,39],state:3},
{pos:[22,4,39],state:3},
{pos:[23,4,39],state:3},
{pos:[24,4,39],state:3},
{pos:[25,4,39],state:3},
{pos:[26,4,39],state:3},
{pos:[27,4,39],state:3},
{pos:[28,4,39],state:3},
{pos:[29,4,39],state:3},
{pos:[30,4,39],state:3},
{pos:[31,4,39],state:3},
{pos:[32,4,39],state:3},
{pos:[33,4,39],state:3},
{pos:[34,4,39],state:3},
{pos:[35,4,39],state:3},
{pos:[36,4,39],state:3},
{pos:[37,4,39],state:3},
{pos:[38,4,39],state:3},
{pos:[39,4,39],state:3},
{pos:[40,4,39],state:3},
{pos:[41,4,39],state:3},
{pos:[42,4,39],state:3},
{pos:[43,4,39],state:3},
{pos:[44,4,39],state:3},
{pos:[45,4,39],state:3},
{pos:[46,4,39],state:3},
{pos:[47,4,39],state:3},
{pos:[0,5,0],state:3},
{pos:[1,5,0],state:3},
{pos:[2,5,0],state:3},
{pos:[3,5,0],state:3},
{pos:[4,5,0],state:3},
{pos:[5,5,0],state:3},
{pos:[6,5,0],state:3},
{pos:[7,5,0],state:3},
{pos:[8,5,0],state:3},
{pos:[9,5,0],state:3},
{pos:[10,5,0],state:3},
{pos:[11,5,0],state:3},
{pos:[12,5,0],state:3},
{pos:[13,5,0],state:3},
{pos:[14,5,0],state:3},
{pos:[15,5,0],state:3},
{pos:[16,5,0],state:3},
{pos:[17,5,0],state:3},
{pos:[18,5,0],state:3},
{pos:[19,5,0],state:3},
{pos:[20,5,0],state:3},
{pos:[21,5,0],state:3},
{pos:[22,5,0],state:3},
{pos:[23,5,0],state:3},
{pos:[24,5,0],state:3},
{pos:[25,5,0],state:3},
{pos:[26,5,0],state:3},
{pos:[27,5,0],state:3},
{pos:[28,5,0],state:3},
{pos:[29,5,0],state:3},
{pos:[30,5,0],state:3},
{pos:[31,5,0],state:3},
{pos:[32,5,0],state:3},
{pos:[33,5,0],state:3},
{pos:[34,5,0],state:3},
{pos:[35,5,0],state:3},
{pos:[36,5,0],state:3},
{pos:[37,5,0],state:3},
{pos:[43,5,0],state:3},
{pos:[44,5,0],state:3},
{pos:[45,5,0],state:3},
{pos:[46,5,0],state:3},
{pos:[47,5,0],state:3},
{pos:[0,5,1],state:3},
{pos:[1,5,1],state:3},
{pos:[2,5,1],state:3},
{pos:[3,5,1],state:3},
{pos:[4,5,1],state:3},
{pos:[5,5,1],state:3},
{pos:[6,5,1],state:3},
{pos:[7,5,1],state:3},
{pos:[8,5,1],state:3},
{pos:[9,5,1],state:3},
{pos:[10,5,1],state:3},
{pos:[11,5,1],state:3},
{pos:[12,5,1],state:3},
{pos:[13,5,1],state:3},
{pos:[14,5,1],state:3},
{pos:[15,5,1],state:3},
{pos:[16,5,1],state:3},
{pos:[17,5,1],state:3},
{pos:[18,5,1],state:3},
{pos:[19,5,1],state:3},
{pos:[20,5,1],state:3},
{pos:[21,5,1],state:3},
{pos:[22,5,1],state:3},
{pos:[23,5,1],state:3},
{pos:[24,5,1],state:3},
{pos:[25,5,1],state:3},
{pos:[26,5,1],state:3},
{pos:[27,5,1],state:3},
{pos:[28,5,1],state:3},
{pos:[29,5,1],state:3},
{pos:[30,5,1],state:3},
{pos:[31,5,1],state:3},
{pos:[32,5,1],state:3},
{pos:[33,5,1],state:3},
{pos:[34,5,1],state:3},
{pos:[35,5,1],state:3},
{pos:[36,5,1],state:3},
{pos:[37,5,1],state:3},
{pos:[43,5,1],state:3},
{pos:[44,5,1],state:3},
{pos:[45,5,1],state:3},
{pos:[46,5,1],state:3},
{pos:[47,5,1],state:3},
{pos:[0,5,2],state:3},
{pos:[1,5,2],state:3},
{pos:[4,5,2],state:1},
{pos:[11,5,2],state:1},
{pos:[18,5,2],state:1},
{pos:[25,5,2],state:1},
{pos:[32,5,2],state:1},
{pos:[39,5,2],state:1},
{pos:[46,5,2],state:3},
{pos:[47,5,2],state:3},
{pos:[0,5,3],state:3},
{pos:[1,5,3],state:3},
{pos:[46,5,3],state:3},
{pos:[47,5,3],state:3},
{pos:[0,5,4],state:3},
{pos:[1,5,4],state:3},
{pos:[46,5,4],state:3},
{pos:[47,5,4],state:3},
{pos:[0,5,5],state:3},
{pos:[1,5,5],state:3},
{pos:[2,5,5],state:1},
{pos:[45,5,5],state:1},
{pos:[46,5,5],state:3},
{pos:[47,5,5],state:3},
{pos:[0,5,6],state:3},
{pos:[1,5,6],state:3},
{pos:[46,5,6],state:3},
{pos:[47,5,6],state:3},
{pos:[0,5,7],state:3},
{pos:[1,5,7],state:3},
{pos:[46,5,7],state:3},
{pos:[47,5,7],state:3},
{pos:[0,5,8],state:3},
{pos:[1,5,8],state:3},
{pos:[46,5,8],state:3},
{pos:[47,5,8],state:3},
{pos:[0,5,9],state:3},
{pos:[1,5,9],state:3},
{pos:[46,5,9],state:3},
{pos:[47,5,9],state:3},
{pos:[0,5,10],state:3},
{pos:[1,5,10],state:3},
{pos:[46,5,10],state:3},
{pos:[47,5,10],state:3},
{pos:[0,5,11],state:3},
{pos:[1,5,11],state:3},
{pos:[46,5,11],state:3},
{pos:[47,5,11],state:3},
{pos:[0,5,12],state:3},
{pos:[1,5,12],state:3},
{pos:[46,5,12],state:3},
{pos:[47,5,12],state:3},
{pos:[0,5,13],state:3},
{pos:[1,5,13],state:3},
{pos:[2,5,13],state:1},
{pos:[45,5,13],state:1},
{pos:[46,5,13],state:3},
{pos:[47,5,13],state:3},
{pos:[0,5,14],state:3},
{pos:[1,5,14],state:3},
{pos:[46,5,14],state:3},
{pos:[47,5,14],state:3},
{pos:[0,5,15],state:3},
{pos:[1,5,15],state:3},
{pos:[46,5,15],state:3},
{pos:[47,5,15],state:3},
{pos:[0,5,16],state:3},
{pos:[1,5,16],state:3},
{pos:[46,5,16],state:3},
{pos:[47,5,16],state:3},
{pos:[0,5,17],state:3},
{pos:[1,5,17],state:3},
{pos:[0,5,18],state:3},
{pos:[1,5,18],state:3},
{pos:[0,5,19],state:3},
{pos:[1,5,19],state:3},
{pos:[0,5,20],state:3},
{pos:[1,5,20],state:3},
{pos:[0,5,21],state:3},
{pos:[1,5,21],state:3},
{pos:[2,5,21],state:1},
{pos:[45,5,21],state:1},
{pos:[0,5,22],state:3},
{pos:[1,5,22],state:3},
{pos:[46,5,22],state:3},
{pos:[47,5,22],state:3},
{pos:[0,5,23],state:3},
{pos:[1,5,23],state:3},
{pos:[46,5,23],state:3},
{pos:[47,5,23],state:3},
{pos:[0,5,24],state:3},
{pos:[1,5,24],state:3},
{pos:[46,5,24],state:3},
{pos:[47,5,24],state:3},
{pos:[0,5,25],state:3},
{pos:[1,5,25],state:3},
{pos:[46,5,25],state:3},
{pos:[47,5,25],state:3},
{pos:[0,5,26],state:3},
{pos:[1,5,26],state:3},
{pos:[46,5,26],state:3},
{pos:[47,5,26],state:3},
{pos:[0,5,27],state:3},
{pos:[1,5,27],state:3},
{pos:[46,5,27],state:3},
{pos:[47,5,27],state:3},
{pos:[0,5,28],state:3},
{pos:[1,5,28],state:3},
{pos:[46,5,28],state:3},
{pos:[47,5,28],state:3},
{pos:[0,5,29],state:3},
{pos:[1,5,29],state:3},
{pos:[2,5,29],state:1},
{pos:[45,5,29],state:1},
{pos:[46,5,29],state:3},
{pos:[47,5,29],state:3},
{pos:[0,5,30],state:3},
{pos:[1,5,30],state:3},
{pos:[46,5,30],state:3},
{pos:[47,5,30],state:3},
{pos:[0,5,31],state:3},
{pos:[1,5,31],state:3},
{pos:[46,5,31],state:3},
{pos:[47,5,31],state:3},
{pos:[0,5,32],state:3},
{pos:[1,5,32],state:3},
{pos:[46,5,32],state:3},
{pos:[47,5,32],state:3},
{pos:[0,5,33],state:3},
{pos:[1,5,33],state:3},
{pos:[46,5,33],state:3},
{pos:[47,5,33],state:3},
{pos:[0,5,34],state:3},
{pos:[1,5,34],state:3},
{pos:[46,5,34],state:3},
{pos:[47,5,34],state:3},
{pos:[0,5,35],state:3},
{pos:[1,5,35],state:3},
{pos:[46,5,35],state:3},
{pos:[47,5,35],state:3},
{pos:[0,5,36],state:3},
{pos:[1,5,36],state:3},
{pos:[46,5,36],state:3},
{pos:[47,5,36],state:3},
{pos:[0,5,37],state:3},
{pos:[1,5,37],state:3},
{pos:[4,5,37],state:1},
{pos:[11,5,37],state:1},
{pos:[18,5,37],state:1},
{pos:[25,5,37],state:1},
{pos:[32,5,37],state:1},
{pos:[39,5,37],state:1},
{pos:[46,5,37],state:3},
{pos:[47,5,37],state:3},
{pos:[0,5,38],state:3},
{pos:[1,5,38],state:3},
{pos:[2,5,38],state:3},
{pos:[3,5,38],state:3},
{pos:[4,5,38],state:3},
{pos:[5,5,38],state:3},
{pos:[6,5,38],state:3},
{pos:[7,5,38],state:3},
{pos:[8,5,38],state:3},
{pos:[9,5,38],state:3},
{pos:[10,5,38],state:3},
{pos:[11,5,38],state:3},
{pos:[12,5,38],state:3},
{pos:[13,5,38],state:3},
{pos:[14,5,38],state:3},
{pos:[15,5,38],state:3},
{pos:[16,5,38],state:3},
{pos:[17,5,38],state:3},
{pos:[18,5,38],state:3},
{pos:[19,5,38],state:3},
{pos:[20,5,38],state:3},
{pos:[21,5,38],state:3},
{pos:[22,5,38],state:3},
{pos:[23,5,38],state:3},
{pos:[24,5,38],state:3},
{pos:[25,5,38],state:3},
{pos:[26,5,38],state:3},
{pos:[27,5,38],state:3},
{pos:[28,5,38],state:3},
{pos:[29,5,38],state:3},
{pos:[30,5,38],state:3},
{pos:[31,5,38],state:3},
{pos:[32,5,38],state:3},
{pos:[33,5,38],state:3},
{pos:[34,5,38],state:3},
{pos:[35,5,38],state:3},
{pos:[36,5,38],state:3},
{pos:[37,5,38],state:3},
{pos:[38,5,38],state:3},
{pos:[39,5,38],state:3},
{pos:[40,5,38],state:3},
{pos:[41,5,38],state:3},
{pos:[42,5,38],state:3},
{pos:[43,5,38],state:3},
{pos:[44,5,38],state:3},
{pos:[45,5,38],state:3},
{pos:[46,5,38],state:3},
{pos:[47,5,38],state:3},
{pos:[0,5,39],state:3},
{pos:[1,5,39],state:3},
{pos:[2,5,39],state:3},
{pos:[3,5,39],state:3},
{pos:[4,5,39],state:3},
{pos:[5,5,39],state:3},
{pos:[6,5,39],state:3},
{pos:[7,5,39],state:3},
{pos:[8,5,39],state:3},
{pos:[9,5,39],state:3},
{pos:[10,5,39],state:3},
{pos:[11,5,39],state:3},
{pos:[12,5,39],state:3},
{pos:[13,5,39],state:3},
{pos:[14,5,39],state:3},
{pos:[15,5,39],state:3},
{pos:[16,5,39],state:3},
{pos:[17,5,39],state:3},
{pos:[18,5,39],state:3},
{pos:[19,5,39],state:3},
{pos:[20,5,39],state:3},
{pos:[21,5,39],state:3},
{pos:[22,5,39],state:3},
{pos:[23,5,39],state:3},
{pos:[24,5,39],state:3},
{pos:[25,5,39],state:3},
{pos:[26,5,39],state:3},
{pos:[27,5,39],state:3},
{pos:[28,5,39],state:3},
{pos:[29,5,39],state:3},
{pos:[30,5,39],state:3},
{pos:[31,5,39],state:3},
{pos:[32,5,39],state:3},
{pos:[33,5,39],state:3},
{pos:[34,5,39],state:3},
{pos:[35,5,39],state:3},
{pos:[36,5,39],state:3},
{pos:[37,5,39],state:3},
{pos:[38,5,39],state:3},
{pos:[39,5,39],state:3},
{pos:[40,5,39],state:3},
{pos:[41,5,39],state:3},
{pos:[42,5,39],state:3},
{pos:[43,5,39],state:3},
{pos:[44,5,39],state:3},
{pos:[45,5,39],state:3},
{pos:[46,5,39],state:3},
{pos:[47,5,39],state:3},
{pos:[0,6,0],state:3},
{pos:[1,6,0],state:3},
{pos:[2,6,0],state:3},
{pos:[3,6,0],state:3},
{pos:[4,6,0],state:3},
{pos:[5,6,0],state:3},
{pos:[6,6,0],state:3},
{pos:[7,6,0],state:3},
{pos:[8,6,0],state:3},
{pos:[9,6,0],state:3},
{pos:[10,6,0],state:3},
{pos:[11,6,0],state:3},
{pos:[12,6,0],state:3},
{pos:[13,6,0],state:3},
{pos:[14,6,0],state:3},
{pos:[15,6,0],state:3},
{pos:[16,6,0],state:3},
{pos:[17,6,0],state:3},
{pos:[18,6,0],state:3},
{pos:[19,6,0],state:3},
{pos:[20,6,0],state:3},
{pos:[21,6,0],state:3},
{pos:[22,6,0],state:3},
{pos:[23,6,0],state:3},
{pos:[24,6,0],state:3},
{pos:[25,6,0],state:3},
{pos:[26,6,0],state:3},
{pos:[27,6,0],state:3},
{pos:[28,6,0],state:3},
{pos:[29,6,0],state:3},
{pos:[30,6,0],state:3},
{pos:[31,6,0],state:3},
{pos:[32,6,0],state:3},
{pos:[33,6,0],state:3},
{pos:[34,6,0],state:3},
{pos:[35,6,0],state:3},
{pos:[36,6,0],state:3},
{pos:[37,6,0],state:3},
{pos:[38,6,0],state:3},
{pos:[39,6,0],state:3},
{pos:[40,6,0],state:3},
{pos:[41,6,0],state:3},
{pos:[42,6,0],state:3},
{pos:[43,6,0],state:3},
{pos:[44,6,0],state:3},
{pos:[45,6,0],state:3},
{pos:[46,6,0],state:3},
{pos:[47,6,0],state:3},
{pos:[0,6,1],state:3},
{pos:[1,6,1],state:3},
{pos:[2,6,1],state:3},
{pos:[3,6,1],state:3},
{pos:[4,6,1],state:3},
{pos:[5,6,1],state:3},
{pos:[6,6,1],state:3},
{pos:[7,6,1],state:3},
{pos:[8,6,1],state:3},
{pos:[9,6,1],state:3},
{pos:[10,6,1],state:3},
{pos:[11,6,1],state:3},
{pos:[12,6,1],state:3},
{pos:[13,6,1],state:3},
{pos:[14,6,1],state:3},
{pos:[15,6,1],state:3},
{pos:[16,6,1],state:3},
{pos:[17,6,1],state:3},
{pos:[18,6,1],state:3},
{pos:[19,6,1],state:3},
{pos:[20,6,1],state:3},
{pos:[21,6,1],state:3},
{pos:[22,6,1],state:3},
{pos:[23,6,1],state:3},
{pos:[24,6,1],state:3},
{pos:[25,6,1],state:3},
{pos:[26,6,1],state:3},
{pos:[27,6,1],state:3},
{pos:[28,6,1],state:3},
{pos:[29,6,1],state:3},
{pos:[30,6,1],state:3},
{pos:[31,6,1],state:3},
{pos:[32,6,1],state:3},
{pos:[33,6,1],state:3},
{pos:[34,6,1],state:3},
{pos:[35,6,1],state:3},
{pos:[36,6,1],state:3},
{pos:[37,6,1],state:3},
{pos:[38,6,1],state:3},
{pos:[39,6,1],state:3},
{pos:[40,6,1],state:3},
{pos:[41,6,1],state:3},
{pos:[42,6,1],state:3},
{pos:[43,6,1],state:3},
{pos:[44,6,1],state:3},
{pos:[45,6,1],state:3},
{pos:[46,6,1],state:3},
{pos:[47,6,1],state:3},
{pos:[0,6,2],state:3},
{pos:[1,6,2],state:3},
{pos:[46,6,2],state:3},
{pos:[47,6,2],state:3},
{pos:[0,6,3],state:3},
{pos:[1,6,3],state:3},
{pos:[3,6,3],state:4},
{pos:[44,6,3],state:4},
{pos:[46,6,3],state:3},
{pos:[47,6,3],state:3},
