{DataVersion:3465,size:[47,22,44],palette:[{Name:"minecraft:bone_block"},{Name:"minecraft:chest"},{Name:"minecraft:cracked_deepslate_bricks"},{Name:"minecraft:soul_lantern"},{Name:"minecraft:structure_block"},{Name:"minecraft:tuff"}],entities:[],blocks:[
{pos:[0,0,0],state:5},
{pos:[1,0,0],state:5},
{pos:[2,0,0],state:5},
{pos:[3,0,0],state:5},
{pos:[4,0,0],state:5},
{pos:[5,0,0],state:5},
{pos:[6,0,0],state:5},
{pos:[7,0,0],state:5},
{pos:[8,0,0],state:5},
{pos:[9,0,0],state:5},
{pos:[10,0,0],state:5},
{pos:[11,0,0],state:5},
{pos:[12,0,0],state:5},
{pos:[13,0,0],state:5},
{pos:[14,0,0],state:5},
{pos:[15,0,0],state:5},
{pos:[16,0,0],state:5},
{pos:[17,0,0],state:5},
{pos:[18,0,0],state:5},
{pos:[19,0,0],state:5},
{pos:[20,0,0],state:5},
{pos:[21,0,0],state:5},
{pos:[22,0,0],state:5},
{pos:[23,0,0],state:5},
{pos:[24,0,0],state:5},
{pos:[25,0,0],state:5},
{pos:[26,0,0],state:5},
{pos:[27,0,0],state:5},
{pos:[28,0,0],state:5},
{pos:[29,0,0],state:5},
{pos:[30,0,0],state:5},
{pos:[31,0,0],state:5},
{pos:[32,0,0],state:5},
{pos:[33,0,0],state:5},
{pos:[34,0,0],state:5},
{pos:[35,0,0],state:5},
{pos:[36,0,0],state:5},
{pos:[37,0,0],state:5},
{pos:[38,0,0],state:5},
{pos:[39,0,0],state:5},
{pos:[40,0,0],state:5},
{pos:[41,0,0],state:5},
{pos:[42,0,0],state:5},
{pos:[43,0,0],state:5},
{pos:[44,0,0],state:5},
{pos:[45,0,0],state:5},
{pos:[46,0,0],state:5},
{pos:[0,0,1],state:5},
{pos:[1,0,1],state:5},
{pos:[2,0,1],state:5},
{pos:[3,0,1],state:5},
{pos:[4,0,1],state:5},
{pos:[5,0,1],state:5},
{pos:[6,0,1],state:5},
{pos:[7,0,1],state:5},
{pos:[8,0,1],state:5},
{pos:[9,0,1],state:5},
{pos:[10,0,1],state:5},
{pos:[11,0,1],state:5},
{pos:[12,0,1],state:5},
{pos:[13,0,1],state:5},
{pos:[14,0,1],state:5},
{pos:[15,0,1],state:5},
{pos:[16,0,1],state:5},
{pos:[17,0,1],state:5},
{pos:[18,0,1],state:5},
{pos:[19,0,1],state:5},
{pos:[20,0,1],state:5},
{pos:[21,0,1],state:5},
{pos:[22,0,1],state:5},
{pos:[23,0,1],state:5},
{pos:[24,0,1],state:5},
{pos:[25,0,1],state:5},
{pos:[26,0,1],state:5},
{pos:[27,0,1],state:5},
{pos:[28,0,1],state:5},
{pos:[29,0,1],state:5},
{pos:[30,0,1],state:5},
{pos:[31,0,1],state:5},
{pos:[32,0,1],state:5},
{pos:[33,0,1],state:5},
{pos:[34,0,1],state:5},
{pos:[35,0,1],state:5},
{pos:[36,0,1],state:5},
{pos:[37,0,1],state:5},
{pos:[38,0,1],state:5},
{pos:[39,0,1],state:5},
{pos:[40,0,1],state:5},
{pos:[41,0,1],state:5},
{pos:[42,0,1],state:5},
{pos:[43,0,1],state:5},
{pos:[44,0,1],state:5},
{pos:[45,0,1],state:5},
{pos:[46,0,1],state:5},
{pos:[0,0,2],state:5},
{pos:[1,0,2],state:5},
{pos:[2,0,2],state:5},
{pos:[3,0,2],state:5},
{pos:[4,0,2],state:5},
{pos:[5,0,2],state:5},
{pos:[6,0,2],state:5},
{pos:[7,0,2],state:5},
{pos:[8,0,2],state:5},
{pos:[9,0,2],state:5},
{pos:[10,0,2],state:5},
{pos:[11,0,2],state:5},
{pos:[12,0,2],state:5},
{pos:[13,0,2],state:5},
{pos:[14,0,2],state:5},
{pos:[15,0,2],state:5},
{pos:[16,0,2],state:5},
{pos:[17,0,2],state:5},
{pos:[18,0,2],state:5},
{pos:[19,0,2],state:5},
{pos:[20,0,2],state:5},
{pos:[21,0,2],state:5},
{pos:[22,0,2],state:5},
{pos:[23,0,2],state:5},
{pos:[24,0,2],state:5},
{pos:[25,0,2],state:5},
{pos:[26,0,2],state:5},
{pos:[27,0,2],state:5},
{pos:[28,0,2],state:5},
{pos:[29,0,2],state:5},
{pos:[30,0,2],state:5},
{pos:[31,0,2],state:5},
{pos:[32,0,2],state:5},
{pos:[33,0,2],state:5},
{pos:[34,0,2],state:5},
{pos:[35,0,2],state:5},
{pos:[36,0,2],state:5},
{pos:[37,0,2],state:5},
{pos:[38,0,2],state:5},
{pos:[39,0,2],state:5},
{pos:[40,0,2],state:5},
{pos:[41,0,2],state:5},
{pos:[42,0,2],state:5},
{pos:[43,0,2],state:5},
{pos:[44,0,2],state:5},
{pos:[45,0,2],state:5},
{pos:[46,0,2],state:5},
{pos:[0,0,3],state:5},
{pos:[1,0,3],state:5},
{pos:[2,0,3],state:5},
{pos:[3,0,3],state:5},
{pos:[4,0,3],state:5},
{pos:[5,0,3],state:5},
{pos:[6,0,3],state:5},
{pos:[7,0,3],state:5},
{pos:[8,0,3],state:5},
{pos:[9,0,3],state:5},
{pos:[10,0,3],state:5},
{pos:[11,0,3],state:5},
{pos:[12,0,3],state:5},
{pos:[13,0,3],state:5},
{pos:[14,0,3],state:5},
{pos:[15,0,3],state:5},
{pos:[16,0,3],state:5},
{pos:[17,0,3],state:5},
{pos:[18,0,3],state:5},
{pos:[19,0,3],state:5},
{pos:[20,0,3],state:5},
{pos:[21,0,3],state:5},
{pos:[22,0,3],state:5},
{pos:[23,0,3],state:5},
{pos:[24,0,3],state:5},
{pos:[25,0,3],state:5},
{pos:[26,0,3],state:5},
{pos:[27,0,3],state:5},
{pos:[28,0,3],state:5},
{pos:[29,0,3],state:5},
{pos:[30,0,3],state:5},
{pos:[31,0,3],state:5},
{pos:[32,0,3],state:5},
{pos:[33,0,3],state:5},
{pos:[34,0,3],state:5},
{pos:[35,0,3],state:5},
{pos:[36,0,3],state:5},
{pos:[37,0,3],state:5},
{pos:[38,0,3],state:5},
{pos:[39,0,3],state:5},
{pos:[40,0,3],state:5},
{pos:[41,0,3],state:5},
{pos:[42,0,3],state:5},
{pos:[43,0,3],state:5},
{pos:[44,0,3],state:5},
{pos:[45,0,3],state:5},
{pos:[46,0,3],state:5},
{pos:[0,0,4],state:5},
{pos:[1,0,4],state:5},
{pos:[2,0,4],state:5},
{pos:[3,0,4],state:5},
{pos:[4,0,4],state:5},
{pos:[5,0,4],state:5},
{pos:[6,0,4],state:5},
{pos:[7,0,4],state:5},
{pos:[8,0,4],state:5},
{pos:[9,0,4],state:5},
{pos:[10,0,4],state:5},
{pos:[11,0,4],state:5},
{pos:[12,0,4],state:5},
{pos:[13,0,4],state:5},
{pos:[14,0,4],state:5},
{pos:[15,0,4],state:5},
{pos:[16,0,4],state:5},
{pos:[17,0,4],state:5},
{pos:[18,0,4],state:5},
{pos:[19,0,4],state:5},
{pos:[20,0,4],state:5},
{pos:[21,0,4],state:5},
{pos:[22,0,4],state:5},
{pos:[23,0,4],state:5},
{pos:[24,0,4],state:5},
{pos:[25,0,4],state:5},
{pos:[26,0,4],state:5},
{pos:[27,0,4],state:5},
{pos:[28,0,4],state:5},
{pos:[29,0,4],state:5},
{pos:[30,0,4],state:5},
{pos:[31,0,4],state:5},
{pos:[32,0,4],state:5},
{pos:[33,0,4],state:5},
{pos:[34,0,4],state:5},
{pos:[35,0,4],state:5},
{pos:[36,0,4],state:5},
{pos:[37,0,4],state:5},
{pos:[38,0,4],state:5},
{pos:[39,0,4],state:5},
{pos:[40,0,4],state:5},
{pos:[41,0,4],state:5},
{pos:[42,0,4],state:5},
{pos:[43,0,4],state:5},
{pos:[44,0,4],state:5},
{pos:[45,0,4],state:5},
{pos:[46,0,4],state:5},
{pos:[0,0,5],state:5},
{pos:[1,0,5],state:5},
{pos:[2,0,5],state:5},
{pos:[3,0,5],state:5},
{pos:[4,0,5],state:5},
{pos:[5,0,5],state:5},
{pos:[6,0,5],state:5},
{pos:[7,0,5],state:5},
{pos:[8,0,5],state:5},
{pos:[9,0,5],state:5},
{pos:[10,0,5],state:5},
{pos:[11,0,5],state:5},
{pos:[12,0,5],state:5},
{pos:[13,0,5],state:5},
{pos:[14,0,5],state:5},
{pos:[15,0,5],state:5},
{pos:[16,0,5],state:5},
{pos:[17,0,5],state:5},
{pos:[18,0,5],state:5},
{pos:[19,0,5],state:5},
{pos:[20,0,5],state:5},
{pos:[21,0,5],state:5},
{pos:[22,0,5],state:5},
{pos:[23,0,5],state:5},
{pos:[24,0,5],state:5},
{pos:[25,0,5],state:5},
{pos:[26,0,5],state:5},
{pos:[27,0,5],state:5},
{pos:[28,0,5],state:5},
{pos:[29,0,5],state:5},
{pos:[30,0,5],state:5},
{pos:[31,0,5],state:5},
{pos:[32,0,5],state:5},
{pos:[33,0,5],state:5},
{pos:[34,0,5],state:5},
{pos:[35,0,5],state:5},
{pos:[36,0,5],state:5},
{pos:[37,0,5],state:5},
{pos:[38,0,5],state:5},
{pos:[39,0,5],state:5},
{pos:[40,0,5],state:5},
{pos:[41,0,5],state:5},
{pos:[42,0,5],state:5},
{pos:[43,0,5],state:5},
{pos:[44,0,5],state:5},
{pos:[45,0,5],state:5},
{pos:[46,0,5],state:5},
{pos:[0,0,6],state:5},
{pos:[1,0,6],state:5},
{pos:[2,0,6],state:5},
{pos:[3,0,6],state:5},
{pos:[4,0,6],state:5},
{pos:[5,0,6],state:5},
{pos:[6,0,6],state:5},
{pos:[7,0,6],state:5},
{pos:[8,0,6],state:5},
{pos:[9,0,6],state:5},
{pos:[10,0,6],state:5},
{pos:[11,0,6],state:5},
{pos:[12,0,6],state:5},
{pos:[13,0,6],state:5},
{pos:[14,0,6],state:5},
{pos:[15,0,6],state:5},
{pos:[16,0,6],state:5},
{pos:[17,0,6],state:5},
{pos:[18,0,6],state:5},
{pos:[19,0,6],state:5},
{pos:[20,0,6],state:5},
{pos:[21,0,6],state:5},
{pos:[22,0,6],state:5},
{pos:[23,0,6],state:5},
{pos:[24,0,6],state:5},
{pos:[25,0,6],state:5},
{pos:[26,0,6],state:5},
{pos:[27,0,6],state:5},
{pos:[28,0,6],state:5},
{pos:[29,0,6],state:5},
{pos:[30,0,6],state:5},
{pos:[31,0,6],state:5},
{pos:[32,0,6],state:5},
{pos:[33,0,6],state:5},
{pos:[34,0,6],state:5},
{pos:[35,0,6],state:5},
{pos:[36,0,6],state:5},
{pos:[37,0,6],state:5},
{pos:[38,0,6],state:5},
{pos:[39,0,6],state:5},
{pos:[40,0,6],state:5},
{pos:[41,0,6],state:5},
{pos:[42,0,6],state:5},
{pos:[43,0,6],state:5},
{pos:[44,0,6],state:5},
{pos:[45,0,6],state:5},
{pos:[46,0,6],state:5},
{pos:[0,0,7],state:5},
{pos:[1,0,7],state:5},
{pos:[2,0,7],state:5},
{pos:[3,0,7],state:5},
{pos:[4,0,7],state:5},
{pos:[5,0,7],state:5},
{pos:[6,0,7],state:5},
{pos:[7,0,7],state:5},
{pos:[8,0,7],state:5},
{pos:[9,0,7],state:5},
{pos:[10,0,7],state:5},
{pos:[11,0,7],state:5},
{pos:[12,0,7],state:5},
{pos:[13,0,7],state:5},
{pos:[14,0,7],state:5},
{pos:[15,0,7],state:5},
{pos:[16,0,7],state:5},
{pos:[17,0,7],state:5},
{pos:[18,0,7],state:5},
{pos:[19,0,7],state:5},
{pos:[20,0,7],state:5},
{pos:[21,0,7],state:5},
{pos:[22,0,7],state:5},
{pos:[23,0,7],state:5},
{pos:[24,0,7],state:5},
{pos:[25,0,7],state:5},
{pos:[26,0,7],state:5},
{pos:[27,0,7],state:5},
{pos:[28,0,7],state:5},
{pos:[29,0,7],state:5},
{pos:[30,0,7],state:5},
{pos:[31,0,7],state:5},
{pos:[32,0,7],state:5},
{pos:[33,0,7],state:5},
{pos:[34,0,7],state:5},
{pos:[35,0,7],state:5},
{pos:[36,0,7],state:5},
{pos:[37,0,7],state:5},
{pos:[38,0,7],state:5},
{pos:[39,0,7],state:5},
{pos:[40,0,7],state:5},
{pos:[41,0,7],state:5},
{pos:[42,0,7],state:5},
{pos:[43,0,7],state:5},
{pos:[44,0,7],state:5},
{pos:[45,0,7],state:5},
{pos:[46,0,7],state:5},
{pos:[0,0,8],state:5},
{pos:[1,0,8],state:5},
{pos:[2,0,8],state:5},
{pos:[3,0,8],state:5},
{pos:[4,0,8],state:5},
{pos:[5,0,8],state:5},
{pos:[6,0,8],state:5},
{pos:[7,0,8],state:5},
{pos:[8,0,8],state:5},
{pos:[9,0,8],state:5},
{pos:[10,0,8],state:5},
{pos:[11,0,8],state:5},
{pos:[12,0,8],state:5},
{pos:[13,0,8],state:5},
{pos:[14,0,8],state:5},
{pos:[15,0,8],state:5},
{pos:[16,0,8],state:5},
{pos:[17,0,8],state:5},
{pos:[18,0,8],state:5},
{pos:[19,0,8],state:5},
{pos:[20,0,8],state:5},
{pos:[21,0,8],state:5},
{pos:[22,0,8],state:5},
{pos:[23,0,8],state:5},
{pos:[24,0,8],state:5},
{pos:[25,0,8],state:5},
{pos:[26,0,8],state:5},
{pos:[27,0,8],state:5},
{pos:[28,0,8],state:5},
{pos:[29,0,8],state:5},
{pos:[30,0,8],state:5},
{pos:[31,0,8],state:5},
{pos:[32,0,8],state:5},
{pos:[33,0,8],state:5},
{pos:[34,0,8],state:5},
{pos:[35,0,8],state:5},
{pos:[36,0,8],state:5},
{pos:[37,0,8],state:5},
{pos:[38,0,8],state:5},
{pos:[39,0,8],state:5},
{pos:[40,0,8],state:5},
{pos:[41,0,8],state:5},
{pos:[42,0,8],state:5},
{pos:[43,0,8],state:5},
{pos:[44,0,8],state:5},
{pos:[45,0,8],state:5},
{pos:[46,0,8],state:5},
{pos:[0,0,9],state:5},
{pos:[1,0,9],state:5},
{pos:[2,0,9],state:5},
{pos:[3,0,9],state:5},
{pos:[4,0,9],state:5},
{pos:[5,0,9],state:5},
{pos:[6,0,9],state:5},
{pos:[7,0,9],state:5},
{pos:[8,0,9],state:5},
{pos:[9,0,9],state:5},
{pos:[10,0,9],state:5},
{pos:[11,0,9],state:5},
{pos:[12,0,9],state:5},
{pos:[13,0,9],state:5},
{pos:[14,0,9],state:5},
{pos:[15,0,9],state:5},
{pos:[16,0,9],state:5},
{pos:[17,0,9],state:5},
{pos:[18,0,9],state:5},
{pos:[19,0,9],state:5},
{pos:[20,0,9],state:5},
{pos:[21,0,9],state:5},
{pos:[22,0,9],state:5},
{pos:[23,0,9],state:5},
{pos:[24,0,9],state:5},
{pos:[25,0,9],state:5},
{pos:[26,0,9],state:5},
{pos:[27,0,9],state:5},
{pos:[28,0,9],state:5},
{pos:[29,0,9],state:5},
{pos:[30,0,9],state:5},
{pos:[31,0,9],state:5},
{pos:[32,0,9],state:5},
{pos:[33,0,9],state:5},
{pos:[34,0,9],state:5},
{pos:[35,0,9],state:5},
{pos:[36,0,9],state:5},
{pos:[37,0,9],state:5},
{pos:[38,0,9],state:5},
{pos:[39,0,9],state:5},
{pos:[40,0,9],state:5},
{pos:[41,0,9],state:5},
{pos:[42,0,9],state:5},
{pos:[43,0,9],state:5},
{pos:[44,0,9],state:5},
{pos:[45,0,9],state:5},
{pos:[46,0,9],state:5},
{pos:[0,0,10],state:5},
{pos:[1,0,10],state:5},
{pos:[2,0,10],state:5},
{pos:[3,0,10],state:5},
{pos:[4,0,10],state:5},
{pos:[5,0,10],state:5},
{pos:[6,0,10],state:5},
{pos:[7,0,10],state:5},
{pos:[8,0,10],state:5},
{pos:[9,0,10],state:5},
{pos:[10,0,10],state:5},
{pos:[11,0,10],state:5},
{pos:[12,0,10],state:5},
{pos:[13,0,10],state:5},
{pos:[14,0,10],state:5},
{pos:[15,0,10],state:5},
{pos:[16,0,10],state:5},
{pos:[17,0,10],state:5},
{pos:[18,0,10],state:5},
{pos:[19,0,10],state:5},
{pos:[20,0,10],state:5},
{pos:[21,0,10],state:5},
{pos:[22,0,10],state:5},
{pos:[23,0,10],state:5},
{pos:[24,0,10],state:5},
{pos:[25,0,10],state:5},
{pos:[26,0,10],state:5},
{pos:[27,0,10],state:5},
{pos:[28,0,10],state:5},
{pos:[29,0,10],state:5},
{pos:[30,0,10],state:5},
{pos:[31,0,10],state:5},
{pos:[32,0,10],state:5},
{pos:[33,0,10],state:5},
{pos:[34,0,10],state:5},
{pos:[35,0,10],state:5},
{pos:[36,0,10],state:5},
{pos:[37,0,10],state:5},
{pos:[38,0,10],state:5},
{pos:[39,0,10],state:5},
{pos:[40,0,10],state:5},
{pos:[41,0,10],state:5},
{pos:[42,0,10],state:5},
{pos:[43,0,10],state:5},
{pos:[44,0,10],state:5},
{pos:[45,0,10],state:5},
{pos:[46,0,10],state:5},
{pos:[0,0,11],state:5},
{pos:[1,0,11],state:5},
{pos:[2,0,11],state:5},
{pos:[3,0,11],state:5},
{pos:[4,0,11],state:5},
{pos:[5,0,11],state:5},
{pos:[6,0,11],state:5},
{pos:[7,0,11],state:5},
{pos:[8,0,11],state:5},
{pos:[9,0,11],state:5},
{pos:[10,0,11],state:5},
{pos:[11,0,11],state:5},
{pos:[12,0,11],state:5},
{pos:[13,0,11],state:5},
{pos:[14,0,11],state:5},
{pos:[15,0,11],state:5},
{pos:[16,0,11],state:5},
{pos:[17,0,11],state:5},
{pos:[18,0,11],state:5},
{pos:[19,0,11],state:5},
{pos:[20,0,11],state:5},
{pos:[21,0,11],state:5},
{pos:[22,0,11],state:5},
{pos:[23,0,11],state:5},
{pos:[24,0,11],state:5},
{pos:[25,0,11],state:5},
{pos:[26,0,11],state:5},
{pos:[27,0,11],state:5},
{pos:[28,0,11],state:5},
{pos:[29,0,11],state:5},
{pos:[30,0,11],state:5},
{pos:[31,0,11],state:5},
{pos:[32,0,11],state:5},
{pos:[33,0,11],state:5},
{pos:[34,0,11],state:5},
{pos:[35,0,11],state:5},
{pos:[36,0,11],state:5},
{pos:[37,0,11],state:5},
{pos:[38,0,11],state:5},
{pos:[39,0,11],state:5},
{pos:[40,0,11],state:5},
{pos:[41,0,11],state:5},
{pos:[42,0,11],state:5},
{pos:[43,0,11],state:5},
{pos:[44,0,11],state:5},
{pos:[45,0,11],state:5},
{pos:[46,0,11],state:5},
{pos:[0,0,12],state:5},
{pos:[1,0,12],state:5},
{pos:[2,0,12],state:5},
{pos:[3,0,12],state:5},
{pos:[4,0,12],state:5},
{pos:[5,0,12],state:5},
{pos:[6,0,12],state:5},
{pos:[7,0,12],state:5},
{pos:[8,0,12],state:5},
{pos:[9,0,12],state:5},
{pos:[10,0,12],state:5},
{pos:[11,0,12],state:5},
{pos:[12,0,12],state:5},
{pos:[13,0,12],state:5},
{pos:[14,0,12],state:5},
{pos:[15,0,12],state:5},
{pos:[16,0,12],state:5},
{pos:[17,0,12],state:5},
{pos:[18,0,12],state:5},
{pos:[19,0,12],state:5},
{pos:[20,0,12],state:5},
{pos:[21,0,12],state:5},
{pos:[22,0,12],state:5},
{pos:[23,0,12],state:5},
{pos:[24,0,12],state:5},
{pos:[25,0,12],state:5},
{pos:[26,0,12],state:5},
{pos:[27,0,12],state:5},
{pos:[28,0,12],state:5},
{pos:[29,0,12],state:5},
{pos:[30,0,12],state:5},
{pos:[31,0,12],state:5},
{pos:[32,0,12],state:5},
{pos:[33,0,12],state:5},
{pos:[34,0,12],state:5},
{pos:[35,0,12],state:5},
{pos:[36,0,12],state:5},
{pos:[37,0,12],state:5},
{pos:[38,0,12],state:5},
{pos:[39,0,12],state:5},
{pos:[40,0,12],state:5},
{pos:[41,0,12],state:5},
{pos:[42,0,12],state:5},
{pos:[43,0,12],state:5},
{pos:[44,0,12],state:5},
{pos:[45,0,12],state:5},
{pos:[46,0,12],state:5},
{pos:[0,0,13],state:5},
{pos:[1,0,13],state:5},
{pos:[2,0,13],state:5},
{pos:[3,0,13],state:5},
{pos:[4,0,13],state:5},
{pos:[5,0,13],state:5},
{pos:[6,0,13],state:5},
{pos:[7,0,13],state:5},
{pos:[8,0,13],state:5},
{pos:[9,0,13],state:5},
{pos:[10,0,13],state:5},
{pos:[11,0,13],state:5},
{pos:[12,0,13],state:5},
{pos:[13,0,13],state:5},
{pos:[14,0,13],state:5},
{pos:[15,0,13],state:5},
{pos:[16,0,13],state:5},
{pos:[17,0,13],state:5},
{pos:[18,0,13],state:5},
{pos:[19,0,13],state:5},
{pos:[20,0,13],state:5},
{pos:[21,0,13],state:5},
{pos:[22,0,13],state:5},
{pos:[23,0,13],state:5},
{pos:[24,0,13],state:5},
{pos:[25,0,13],state:5},
{pos:[26,0,13],state:5},
{pos:[27,0,13],state:5},
{pos:[28,0,13],state:5},
{pos:[29,0,13],state:5},
{pos:[30,0,13],state:5},
{pos:[31,0,13],state:5},
{pos:[32,0,13],state:5},
{pos:[33,0,13],state:5},
{pos:[34,0,13],state:5},
{pos:[35,0,13],state:5},
{pos:[36,0,13],state:5},
{pos:[37,0,13],state:5},
{pos:[38,0,13],state:5},
{pos:[39,0,13],state:5},
{pos:[40,0,13],state:5},
{pos:[41,0,13],state:5},
{pos:[42,0,13],state:5},
{pos:[43,0,13],state:5},
{pos:[44,0,13],state:5},
{pos:[45,0,13],state:5},
{pos:[46,0,13],state:5},
{pos:[0,0,14],state:5},
{pos:[1,0,14],state:5},
{pos:[2,0,14],state:5},
{pos:[3,0,14],state:5},
{pos:[4,0,14],state:5},
{pos:[5,0,14],state:5},
{pos:[6,0,14],state:5},
{pos:[7,0,14],state:5},
{pos:[8,0,14],state:5},
{pos:[9,0,14],state:5},
{pos:[10,0,14],state:5},
{pos:[11,0,14],state:5},
{pos:[12,0,14],state:5},
{pos:[13,0,14],state:5},
{pos:[14,0,14],state:5},
{pos:[15,0,14],state:5},
{pos:[16,0,14],state:5},
{pos:[17,0,14],state:5},
{pos:[18,0,14],state:5},
{pos:[19,0,14],state:5},
{pos:[20,0,14],state:5},
{pos:[21,0,14],state:5},
{pos:[22,0,14],state:5},
{pos:[23,0,14],state:5},
{pos:[24,0,14],state:5},
{pos:[25,0,14],state:5},
{pos:[26,0,14],state:5},
{pos:[27,0,14],state:5},
{pos:[28,0,14],state:5},
{pos:[29,0,14],state:5},
{pos:[30,0,14],state:5},
{pos:[31,0,14],state:5},
{pos:[32,0,14],state:5},
{pos:[33,0,14],state:5},
{pos:[34,0,14],state:5},
{pos:[35,0,14],state:5},
{pos:[36,0,14],state:5},
{pos:[37,0,14],state:5},
{pos:[38,0,14],state:5},
{pos:[39,0,14],state:5},
{pos:[40,0,14],state:5},
{pos:[41,0,14],state:5},
{pos:[42,0,14],state:5},
{pos:[43,0,14],state:5},
{pos:[44,0,14],state:5},
{pos:[45,0,14],state:5},
{pos:[46,0,14],state:5},
{pos:[0,0,15],state:5},
{pos:[1,0,15],state:5},
{pos:[2,0,15],state:5},
{pos:[3,0,15],state:5},
{pos:[4,0,15],state:5},
{pos:[5,0,15],state:5},
{pos:[6,0,15],state:5},
{pos:[7,0,15],state:5},
{pos:[8,0,15],state:5},
{pos:[9,0,15],state:5},
{pos:[10,0,15],state:5},
{pos:[11,0,15],state:5},
{pos:[12,0,15],state:5},
{pos:[13,0,15],state:5},
{pos:[14,0,15],state:5},
{pos:[15,0,15],state:5},
{pos:[16,0,15],state:5},
{pos:[17,0,15],state:5},
{pos:[18,0,15],state:5},
{pos:[19,0,15],state:5},
{pos:[20,0,15],state:5},
{pos:[21,0,15],state:5},
{pos:[22,0,15],state:5},
{pos:[23,0,15],state:5},
{pos:[24,0,15],state:5},
{pos:[25,0,15],state:5},
{pos:[26,0,15],state:5},
{pos:[27,0,15],state:5},
{pos:[28,0,15],state:5},
{pos:[29,0,15],state:5},
{pos:[30,0,15],state:5},
{pos:[31,0,15],state:5},
{pos:[32,0,15],state:5},
{pos:[33,0,15],state:5},
{pos:[34,0,15],state:5},
{pos:[35,0,15],state:5},
{pos:[36,0,15],state:5},
{pos:[37,0,15],state:5},
{pos:[38,0,15],state:5},
{pos:[39,0,15],state:5},
{pos:[40,0,15],state:5},
{pos:[41,0,15],state:5},
{pos:[42,0,15],state:5},
{pos:[43,0,15],state:5},
{pos:[44,0,15],state:5},
{pos:[45,0,15],state:5},
{pos:[46,0,15],state:5},
{pos:[0,0,16],state:5},
{pos:[1,0,16],state:5},
{pos:[2,0,16],state:5},
{pos:[3,0,16],state:5},
{pos:[4,0,16],state:5},
{pos:[5,0,16],state:5},
{pos:[6,0,16],state:5},
{pos:[7,0,16],state:5},
{pos:[8,0,16],state:5},
{pos:[9,0,16],state:5},
{pos:[10,0,16],state:5},
{pos:[11,0,16],state:5},
{pos:[12,0,16],state:5},
{pos:[13,0,16],state:5},
{pos:[14,0,16],state:5},
{pos:[15,0,16],state:5},
{pos:[16,0,16],state:5},
{pos:[17,0,16],state:5},
{pos:[18,0,16],state:5},
{pos:[19,0,16],state:5},
{pos:[20,0,16],state:5},
{pos:[21,0,16],state:5},
{pos:[22,0,16],state:5},
{pos:[23,0,16],state:5},
{pos:[24,0,16],state:5},
{pos:[25,0,16],state:5},
{pos:[26,0,16],state:5},
{pos:[27,0,16],state:5},
{pos:[28,0,16],state:5},
{pos:[29,0,16],state:5},
{pos:[30,0,16],state:5},
{pos:[31,0,16],state:5},
{pos:[32,0,16],state:5},
{pos:[33,0,16],state:5},
{pos:[34,0,16],state:5},
{pos:[35,0,16],state:5},
{pos:[36,0,16],state:5},
{pos:[37,0,16],state:5},
{pos:[38,0,16],state:5},
{pos:[39,0,16],state:5},
{pos:[40,0,16],state:5},
{pos:[41,0,16],state:5},
{pos:[42,0,16],state:5},
{pos:[43,0,16],state:5},
{pos:[44,0,16],state:5},
{pos:[45,0,16],state:5},
{pos:[46,0,16],state:5},
{pos:[0,0,17],state:5},
{pos:[1,0,17],state:5},
{pos:[2,0,17],state:5},
{pos:[3,0,17],state:5},
{pos:[4,0,17],state:5},
{pos:[5,0,17],state:5},
{pos:[6,0,17],state:5},
{pos:[7,0,17],state:5},
{pos:[8,0,17],state:5},
{pos:[9,0,17],state:5},
{pos:[10,0,17],state:5},
{pos:[11,0,17],state:5},
{pos:[12,0,17],state:5},
{pos:[13,0,17],state:5},
{pos:[14,0,17],state:5},
{pos:[15,0,17],state:5},
{pos:[16,0,17],state:5},
{pos:[17,0,17],state:5},
{pos:[18,0,17],state:5},
{pos:[19,0,17],state:5},
{pos:[20,0,17],state:5},
{pos:[21,0,17],state:5},
{pos:[22,0,17],state:5},
{pos:[23,0,17],state:5},
{pos:[24,0,17],state:5},
{pos:[25,0,17],state:5},
{pos:[26,0,17],state:5},
{pos:[27,0,17],state:5},
{pos:[28,0,17],state:5},
{pos:[29,0,17],state:5},
{pos:[30,0,17],state:5},
{pos:[31,0,17],state:5},
{pos:[32,0,17],state:5},
{pos:[33,0,17],state:5},
{pos:[34,0,17],state:5},
{pos:[35,0,17],state:5},
{pos:[36,0,17],state:5},
{pos:[37,0,17],state:5},
{pos:[38,0,17],state:5},
{pos:[39,0,17],state:5},
{pos:[40,0,17],state:5},
{pos:[41,0,17],state:5},
{pos:[42,0,17],state:5},
{pos:[43,0,17],state:5},
{pos:[44,0,17],state:5},
{pos:[45,0,17],state:5},
{pos:[46,0,17],state:5},
{pos:[0,0,18],state:5},
{pos:[1,0,18],state:5},
{pos:[2,0,18],state:5},
{pos:[3,0,18],state:5},
{pos:[4,0,18],state:5},
{pos:[5,0,18],state:5},
{pos:[6,0,18],state:5},
{pos:[7,0,18],state:5},
{pos:[8,0,18],state:5},
{pos:[9,0,18],state:5},
{pos:[10,0,18],state:5},
{pos:[11,0,18],state:5},
{pos:[12,0,18],state:5},
{pos:[13,0,18],state:5},
{pos:[14,0,18],state:5},
{pos:[15,0,18],state:5},
{pos:[16,0,18],state:5},
{pos:[17,0,18],state:5},
{pos:[18,0,18],state:5},
{pos:[19,0,18],state:5},
{pos:[20,0,18],state:5},
{pos:[21,0,18],state:5},
{pos:[22,0,18],state:5},
{pos:[23,0,18],state:5},
{pos:[24,0,18],state:5},
{pos:[25,0,18],state:5},
{pos:[26,0,18],state:5},
{pos:[27,0,18],state:5},
{pos:[28,0,18],state:5},
{pos:[29,0,18],state:5},
{pos:[30,0,18],state:5},
{pos:[31,0,18],state:5},
{pos:[32,0,18],state:5},
{pos:[33,0,18],state:5},
{pos:[34,0,18],state:5},
{pos:[35,0,18],state:5},
{pos:[36,0,18],state:5},
{pos:[37,0,18],state:5},
{pos:[38,0,18],state:5},
{pos:[39,0,18],state:5},
{pos:[40,0,18],state:5},
{pos:[41,0,18],state:5},
{pos:[42,0,18],state:5},
{pos:[43,0,18],state:5},
{pos:[44,0,18],state:5},
{pos:[45,0,18],state:5},
{pos:[46,0,18],state:5},
{pos:[0,0,19],state:5},
{pos:[1,0,19],state:5},
{pos:[2,0,19],state:5},
{pos:[3,0,19],state:5},
{pos:[4,0,19],state:5},
{pos:[5,0,19],state:5},
{pos:[6,0,19],state:5},
{pos:[7,0,19],state:5},
{pos:[8,0,19],state:5},
{pos:[9,0,19],state:5},
{pos:[10,0,19],state:5},
{pos:[11,0,19],state:5},
{pos:[12,0,19],state:5},
{pos:[13,0,19],state:5},
{pos:[14,0,19],state:5},
{pos:[15,0,19],state:5},
{pos:[16,0,19],state:5},
{pos:[17,0,19],state:5},
{pos:[18,0,19],state:5},
{pos:[19,0,19],state:5},
{pos:[20,0,19],state:5},
{pos:[21,0,19],state:5},
{pos:[22,0,19],state:5},
{pos:[23,0,19],state:5},
{pos:[24,0,19],state:5},
{pos:[25,0,19],state:5},
{pos:[26,0,19],state:5},
{pos:[27,0,19],state:5},
{pos:[28,0,19],state:5},
{pos:[29,0,19],state:5},
{pos:[30,0,19],state:5},
{pos:[31,0,19],state:5},
{pos:[32,0,19],state:5},
{pos:[33,0,19],state:5},
{pos:[34,0,19],state:5},
{pos:[35,0,19],state:5},
{pos:[36,0,19],state:5},
{pos:[37,0,19],state:5},
{pos:[38,0,19],state:5},
{pos:[39,0,19],state:5},
{pos:[40,0,19],state:5},
{pos:[41,0,19],state:5},
{pos:[42,0,19],state:5},
{pos:[43,0,19],state:5},
{pos:[44,0,19],state:5},
{pos:[45,0,19],state:5},
{pos:[46,0,19],state:5},
{pos:[0,0,20],state:5},
{pos:[1,0,20],state:5},
{pos:[2,0,20],state:5},
{pos:[3,0,20],state:5},
{pos:[4,0,20],state:5},
{pos:[5,0,20],state:5},
{pos:[6,0,20],state:5},
{pos:[7,0,20],state:5},
{pos:[8,0,20],state:5},
{pos:[9,0,20],state:5},
{pos:[10,0,20],state:5},
{pos:[11,0,20],state:5},
{pos:[12,0,20],state:5},
{pos:[13,0,20],state:5},
{pos:[14,0,20],state:5},
{pos:[15,0,20],state:5},
{pos:[16,0,20],state:5},
{pos:[17,0,20],state:5},
{pos:[18,0,20],state:5},
{pos:[19,0,20],state:5},
{pos:[20,0,20],state:5},
{pos:[21,0,20],state:5},
{pos:[22,0,20],state:5},
{pos:[23,0,20],state:5},
{pos:[24,0,20],state:5},
{pos:[25,0,20],state:5},
{pos:[26,0,20],state:5},
{pos:[27,0,20],state:5},
{pos:[28,0,20],state:5},
{pos:[29,0,20],state:5},
{pos:[30,0,20],state:5},
{pos:[31,0,20],state:5},
{pos:[32,0,20],state:5},
{pos:[33,0,20],state:5},
{pos:[34,0,20],state:5},
{pos:[35,0,20],state:5},
{pos:[36,0,20],state:5},
{pos:[37,0,20],state:5},
{pos:[38,0,20],state:5},
{pos:[39,0,20],state:5},
{pos:[40,0,20],state:5},
{pos:[41,0,20],state:5},
{pos:[42,0,20],state:5},
{pos:[43,0,20],state:5},
{pos:[44,0,20],state:5},
{pos:[45,0,20],state:5},
{pos:[46,0,20],state:5},
{pos:[0,0,21],state:5},
{pos:[1,0,21],state:5},
{pos:[2,0,21],state:5},
{pos:[3,0,21],state:5},
{pos:[4,0,21],state:5},
{pos:[5,0,21],state:5},
{pos:[6,0,21],state:5},
{pos:[7,0,21],state:5},
{pos:[8,0,21],state:5},
{pos:[9,0,21],state:5},
{pos:[10,0,21],state:5},
{pos:[11,0,21],state:5},
{pos:[12,0,21],state:5},
{pos:[13,0,21],state:5},
{pos:[14,0,21],state:5},
{pos:[15,0,21],state:5},
{pos:[16,0,21],state:5},
{pos:[17,0,21],state:5},
{pos:[18,0,21],state:5},
{pos:[19,0,21],state:5},
{pos:[20,0,21],state:5},
{pos:[21,0,21],state:5},
{pos:[22,0,21],state:5},
{pos:[23,0,21],state:5},
{pos:[24,0,21],state:5},
{pos:[25,0,21],state:5},
{pos:[26,0,21],state:5},
{pos:[27,0,21],state:5},
{pos:[28,0,21],state:5},
{pos:[29,0,21],state:5},
{pos:[30,0,21],state:5},
{pos:[31,0,21],state:5},
{pos:[32,0,21],state:5},
{pos:[33,0,21],state:5},
{pos:[34,0,21],state:5},
{pos:[35,0,21],state:5},
{pos:[36,0,21],state:5},
{pos:[37,0,21],state:5},
{pos:[38,0,21],state:5},
{pos:[39,0,21],state:5},
{pos:[40,0,21],state:5},
{pos:[41,0,21],state:5},
{pos:[42,0,21],state:5},
{pos:[43,0,21],state:5},
{pos:[44,0,21],state:5},
{pos:[45,0,21],state:5},
{pos:[46,0,21],state:5},
{pos:[0,0,22],state:5},
{pos:[1,0,22],state:5},
{pos:[2,0,22],state:5},
{pos:[3,0,22],state:5},
{pos:[4,0,22],state:5},
{pos:[5,0,22],state:5},
{pos:[6,0,22],state:5},
{pos:[7,0,22],state:5},
{pos:[8,0,22],state:5},
{pos:[9,0,22],state:5},
{pos:[10,0,22],state:5},
{pos:[11,0,22],state:5},
{pos:[12,0,22],state:5},
{pos:[13,0,22],state:5},
{pos:[14,0,22],state:5},
{pos:[15,0,22],state:5},
{pos:[16,0,22],state:5},
{pos:[17,0,22],state:5},
{pos:[18,0,22],state:5},
{pos:[19,0,22],state:5},
{pos:[20,0,22],state:5},
{pos:[21,0,22],state:5},
{pos:[22,0,22],state:5},
{pos:[23,0,22],state:5},
{pos:[24,0,22],state:5},
{pos:[25,0,22],state:5},
{pos:[26,0,22],state:5},
{pos:[27,0,22],state:5},
{pos:[28,0,22],state:5},
{pos:[29,0,22],state:5},
{pos:[30,0,22],state:5},
{pos:[31,0,22],state:5},
{pos:[32,0,22],state:5},
{pos:[33,0,22],state:5},
{pos:[34,0,22],state:5},
{pos:[35,0,22],state:5},
{pos:[36,0,22],state:5},
{pos:[37,0,22],state:5},
{pos:[38,0,22],state:5},
{pos:[39,0,22],state:5},
{pos:[40,0,22],state:5},
{pos:[41,0,22],state:5},
{pos:[42,0,22],state:5},
{pos:[43,0,22],state:5},
{pos:[44,0,22],state:5},
{pos:[45,0,22],state:5},
{pos:[46,0,22],state:5},
{pos:[0,0,23],state:5},
{pos:[1,0,23],state:5},
{pos:[2,0,23],state:5},
{pos:[3,0,23],state:5},
{pos:[4,0,23],state:5},
{pos:[5,0,23],state:5},
{pos:[6,0,23],state:5},
{pos:[7,0,23],state:5},
{pos:[8,0,23],state:5},
{pos:[9,0,23],state:5},
{pos:[10,0,23],state:5},
{pos:[11,0,23],state:5},
{pos:[12,0,23],state:5},
{pos:[13,0,23],state:5},
{pos:[14,0,23],state:5},
{pos:[15,0,23],state:5},
{pos:[16,0,23],state:5},
{pos:[17,0,23],state:5},
{pos:[18,0,23],state:5},
{pos:[19,0,23],state:5},
{pos:[20,0,23],state:5},
{pos:[21,0,23],state:5},
{pos:[22,0,23],state:5},
{pos:[23,0,23],state:5},
{pos:[24,0,23],state:5},
{pos:[25,0,23],state:5},
{pos:[26,0,23],state:5},
{pos:[27,0,23],state:5},
{pos:[28,0,23],state:5},
{pos:[29,0,23],state:5},
{pos:[30,0,23],state:5},
{pos:[31,0,23],state:5},
{pos:[32,0,23],state:5},
{pos:[33,0,23],state:5},
{pos:[34,0,23],state:5},
{pos:[35,0,23],state:5},
{pos:[36,0,23],state:5},
{pos:[37,0,23],state:5},
{pos:[38,0,23],state:5},
{pos:[39,0,23],state:5},
{pos:[40,0,23],state:5},
{pos:[41,0,23],state:5},
{pos:[42,0,23],state:5},
{pos:[43,0,23],state:5},
{pos:[44,0,23],state:5},
{pos:[45,0,23],state:5},
{pos:[46,0,23],state:5},
{pos:[0,0,24],state:5},
{pos:[1,0,24],state:5},
{pos:[2,0,24],state:5},
{pos:[3,0,24],state:5},
{pos:[4,0,24],state:5},
{pos:[5,0,24],state:5},
{pos:[6,0,24],state:5},
{pos:[7,0,24],state:5},
{pos:[8,0,24],state:5},
{pos:[9,0,24],state:5},
{pos:[10,0,24],state:5},
{pos:[11,0,24],state:5},
{pos:[12,0,24],state:5},
{pos:[13,0,24],state:5},
{pos:[14,0,24],state:5},
{pos:[15,0,24],state:5},
{pos:[16,0,24],state:5},
{pos:[17,0,24],state:5},
{pos:[18,0,24],state:5},
{pos:[19,0,24],state:5},
{pos:[20,0,24],state:5},
{pos:[21,0,24],state:5},
{pos:[22,0,24],state:5},
{pos:[23,0,24],state:5},
{pos:[24,0,24],state:5},
{pos:[25,0,24],state:5},
{pos:[26,0,24],state:5},
{pos:[27,0,24],state:5},
{pos:[28,0,24],state:5},
{pos:[29,0,24],state:5},
{pos:[30,0,24],state:5},
{pos:[31,0,24],state:5},
{pos:[32,0,24],state:5},
{pos:[33,0,24],state:5},
{pos:[34,0,24],state:5},
{pos:[35,0,24],state:5},
{pos:[36,0,24],state:5},
{pos:[37,0,24],state:5},
{pos:[38,0,24],state:5},
{pos:[39,0,24],state:5},
{pos:[40,0,24],state:5},
{pos:[41,0,24],state:5},
{pos:[42,0,24],state:5},
{pos:[43,0,24],state:5},
{pos:[44,0,24],state:5},
{pos:[45,0,24],state:5},
{pos:[46,0,24],state:5},
{pos:[0,0,25],state:5},
{pos:[1,0,25],state:5},
{pos:[2,0,25],state:5},
{pos:[3,0,25],state:5},
{pos:[4,0,25],state:5},
{pos:[5,0,25],state:5},
{pos:[6,0,25],state:5},
{pos:[7,0,25],state:5},
{pos:[8,0,25],state:5},
{pos:[9,0,25],state:5},
{pos:[10,0,25],state:5},
{pos:[11,0,25],state:5},
{pos:[12,0,25],state:5},
{pos:[13,0,25],state:5},
{pos:[14,0,25],state:5},
{pos:[15,0,25],state:5},
{pos:[16,0,25],state:5},
{pos:[17,0,25],state:5},
{pos:[18,0,25],state:5},
{pos:[19,0,25],state:5},
{pos:[20,0,25],state:5},
{pos:[21,0,25],state:5},
{pos:[22,0,25],state:5},
{pos:[23,0,25],state:5},
{pos:[24,0,25],state:5},
{pos:[25,0,25],state:5},
{pos:[26,0,25],state:5},
{pos:[27,0,25],state:5},
{pos:[28,0,25],state:5},
{pos:[29,0,25],state:5},
{pos:[30,0,25],state:5},
{pos:[31,0,25],state:5},
{pos:[32,0,25],state:5},
{pos:[33,0,25],state:5},
{pos:[34,0,25],state:5},
{pos:[35,0,25],state:5},
{pos:[36,0,25],state:5},
{pos:[37,0,25],state:5},
{pos:[38,0,25],state:5},
{pos:[39,0,25],state:5},
{pos:[40,0,25],state:5},
{pos:[41,0,25],state:5},
{pos:[42,0,25],state:5},
{pos:[43,0,25],state:5},
{pos:[44,0,25],state:5},
{pos:[45,0,25],state:5},
{pos:[46,0,25],state:5},
{pos:[0,0,26],state:5},
{pos:[1,0,26],state:5},
{pos:[2,0,26],state:5},
{pos:[3,0,26],state:5},
{pos:[4,0,26],state:5},
{pos:[5,0,26],state:5},
{pos:[6,0,26],state:5},
{pos:[7,0,26],state:5},
{pos:[8,0,26],state:5},
{pos:[9,0,26],state:5},
{pos:[10,0,26],state:5},
{pos:[11,0,26],state:5},
{pos:[12,0,26],state:5},
{pos:[13,0,26],state:5},
{pos:[14,0,26],state:5},
{pos:[15,0,26],state:5},
{pos:[16,0,26],state:5},
{pos:[17,0,26],state:5},
{pos:[18,0,26],state:5},
{pos:[19,0,26],state:5},
{pos:[20,0,26],state:5},
{pos:[21,0,26],state:5},
{pos:[22,0,26],state:5},
{pos:[23,0,26],state:5},
{pos:[24,0,26],state:5},
{pos:[25,0,26],state:5},
{pos:[26,0,26],state:5},
{pos:[27,0,26],state:5},
{pos:[28,0,26],state:5},
{pos:[29,0,26],state:5},
{pos:[30,0,26],state:5},
{pos:[31,0,26],state:5},
{pos:[32,0,26],state:5},
{pos:[33,0,26],state:5},
{pos:[34,0,26],state:5},
{pos:[35,0,26],state:5},
{pos:[36,0,26],state:5},
{pos:[37,0,26],state:5},
{pos:[38,0,26],state:5},
{pos:[39,0,26],state:5},
{pos:[40,0,26],state:5},
{pos:[41,0,26],state:5},
{pos:[42,0,26],state:5},
{pos:[43,0,26],state:5},
{pos:[44,0,26],state:5},
{pos:[45,0,26],state:5},
{pos:[46,0,26],state:5},
{pos:[0,0,27],state:5},
{pos:[1,0,27],state:5},
{pos:[2,0,27],state:5},
{pos:[3,0,27],state:5},
{pos:[4,0,27],state:5},
{pos:[5,0,27],state:5},
{pos:[6,0,27],state:5},
{pos:[7,0,27],state:5},
{pos:[8,0,27],state:5},
{pos:[9,0,27],state:5},
{pos:[10,0,27],state:5},
{pos:[11,0,27],state:5},
{pos:[12,0,27],state:5},
{pos:[13,0,27],state:5},
{pos:[14,0,27],state:5},
{pos:[15,0,27],state:5},
{pos:[16,0,27],state:5},
{pos:[17,0,27],state:5},
{pos:[18,0,27],state:5},
{pos:[19,0,27],state:5},
{pos:[20,0,27],state:5},
{pos:[21,0,27],state:5},
{pos:[22,0,27],state:5},
{pos:[23,0,27],state:5},
{pos:[24,0,27],state:5},
{pos:[25,0,27],state:5},
{pos:[26,0,27],state:5},
{pos:[27,0,27],state:5},
{pos:[28,0,27],state:5},
{pos:[29,0,27],state:5},
{pos:[30,0,27],state:5},
{pos:[31,0,27],state:5},
{pos:[32,0,27],state:5},
{pos:[33,0,27],state:5},
{pos:[34,0,27],state:5},
{pos:[35,0,27],state:5},
{pos:[36,0,27],state:5},
{pos:[37,0,27],state:5},
{pos:[38,0,27],state:5},
{pos:[39,0,27],state:5},
{pos:[40,0,27],state:5},
{pos:[41,0,27],state:5},
{pos:[42,0,27],state:5},
{pos:[43,0,27],state:5},
{pos:[44,0,27],state:5},
{pos:[45,0,27],state:5},
{pos:[46,0,27],state:5},
{pos:[0,0,28],state:5},
{pos:[1,0,28],state:5},
{pos:[2,0,28],state:5},
{pos:[3,0,28],state:5},
{pos:[4,0,28],state:5},
{pos:[5,0,28],state:5},
{pos:[6,0,28],state:5},
{pos:[7,0,28],state:5},
{pos:[8,0,28],state:5},
{pos:[9,0,28],state:5},
{pos:[10,0,28],state:5},
{pos:[11,0,28],state:5},
{pos:[12,0,28],state:5},
{pos:[13,0,28],state:5},
{pos:[14,0,28],state:5},
{pos:[15,0,28],state:5},
{pos:[16,0,28],state:5},
{pos:[17,0,28],state:5},
{pos:[18,0,28],state:5},
{pos:[19,0,28],state:5},
{pos:[20,0,28],state:5},
{pos:[21,0,28],state:5},
{pos:[22,0,28],state:5},
{pos:[23,0,28],state:5},
{pos:[24,0,28],state:5},
{pos:[25,0,28],state:5},
{pos:[26,0,28],state:5},
{pos:[27,0,28],state:5},
{pos:[28,0,28],state:5},
{pos:[29,0,28],state:5},
{pos:[30,0,28],state:5},
{pos:[31,0,28],state:5},
{pos:[32,0,28],state:5},
{pos:[33,0,28],state:5},
{pos:[34,0,28],state:5},
{pos:[35,0,28],state:5},
{pos:[36,0,28],state:5},
{pos:[37,0,28],state:5},
{pos:[38,0,28],state:5},
{pos:[39,0,28],state:5},
{pos:[40,0,28],state:5},
{pos:[41,0,28],state:5},
{pos:[42,0,28],state:5},
{pos:[43,0,28],state:5},
{pos:[44,0,28],state:5},
{pos:[45,0,28],state:5},
{pos:[46,0,28],state:5},
{pos:[0,0,29],state:5},
{pos:[1,0,29],state:5},
{pos:[2,0,29],state:5},
{pos:[3,0,29],state:5},
{pos:[4,0,29],state:5},
{pos:[5,0,29],state:5},
{pos:[6,0,29],state:5},
{pos:[7,0,29],state:5},
{pos:[8,0,29],state:5},
{pos:[9,0,29],state:5},
{pos:[10,0,29],state:5},
{pos:[11,0,29],state:5},
{pos:[12,0,29],state:5},
{pos:[13,0,29],state:5},
{pos:[14,0,29],state:5},
{pos:[15,0,29],state:5},
{pos:[16,0,29],state:5},
{pos:[17,0,29],state:5},
{pos:[18,0,29],state:5},
{pos:[19,0,29],state:5},
{pos:[20,0,29],state:5},
{pos:[21,0,29],state:5},
{pos:[22,0,29],state:5},
{pos:[23,0,29],state:5},
{pos:[24,0,29],state:5},
{pos:[25,0,29],state:5},
{pos:[26,0,29],state:5},
{pos:[27,0,29],state:5},
{pos:[28,0,29],state:5},
{pos:[29,0,29],state:5},
{pos:[30,0,29],state:5},
{pos:[31,0,29],state:5},
{pos:[32,0,29],state:5},
{pos:[33,0,29],state:5},
{pos:[34,0,29],state:5},
{pos:[35,0,29],state:5},
{pos:[36,0,29],state:5},
{pos:[37,0,29],state:5},
{pos:[38,0,29],state:5},
{pos:[39,0,29],state:5},
{pos:[40,0,29],state:5},
{pos:[41,0,29],state:5},
{pos:[42,0,29],state:5},
{pos:[43,0,29],state:5},
{pos:[44,0,29],state:5},
{pos:[45,0,29],state:5},
{pos:[46,0,29],state:5},
{pos:[0,0,30],state:5},
{pos:[1,0,30],state:5},
{pos:[2,0,30],state:5},
{pos:[3,0,30],state:5},
{pos:[4,0,30],state:5},
{pos:[5,0,30],state:5},
{pos:[6,0,30],state:5},
{pos:[7,0,30],state:5},
{pos:[8,0,30],state:5},
{pos:[9,0,30],state:5},
{pos:[10,0,30],state:5},
{pos:[11,0,30],state:5},
{pos:[12,0,30],state:5},
{pos:[13,0,30],state:5},
{pos:[14,0,30],state:5},
{pos:[15,0,30],state:5},
{pos:[16,0,30],state:5},
{pos:[17,0,30],state:5},
{pos:[18,0,30],state:5},
{pos:[19,0,30],state:5},
{pos:[20,0,30],state:5},
{pos:[21,0,30],state:5},
{pos:[22,0,30],state:5},
{pos:[23,0,30],state:5},
{pos:[24,0,30],state:5},
{pos:[25,0,30],state:5},
{pos:[26,0,30],state:5},
{pos:[27,0,30],state:5},
{pos:[28,0,30],state:5},
{pos:[29,0,30],state:5},
{pos:[30,0,30],state:5},
{pos:[31,0,30],state:5},
{pos:[32,0,30],state:5},
{pos:[33,0,30],state:5},
{pos:[34,0,30],state:5},
{pos:[35,0,30],state:5},
{pos:[36,0,30],state:5},
{pos:[37,0,30],state:5},
{pos:[38,0,30],state:5},
{pos:[39,0,30],state:5},
{pos:[40,0,30],state:5},
{pos:[41,0,30],state:5},
{pos:[42,0,30],state:5},
{pos:[43,0,30],state:5},
{pos:[44,0,30],state:5},
{pos:[45,0,30],state:5},
{pos:[46,0,30],state:5},
{pos:[0,0,31],state:5},
{pos:[1,0,31],state:5},
{pos:[2,0,31],state:5},
{pos:[3,0,31],state:5},
{pos:[4,0,31],state:5},
{pos:[5,0,31],state:5},
{pos:[6,0,31],state:5},
{pos:[7,0,31],state:5},
{pos:[8,0,31],state:5},
{pos:[9,0,31],state:5},
{pos:[10,0,31],state:5},
{pos:[11,0,31],state:5},
{pos:[12,0,31],state:5},
{pos:[13,0,31],state:5},
{pos:[14,0,31],state:5},
{pos:[15,0,31],state:5},
{pos:[16,0,31],state:5},
{pos:[17,0,31],state:5},
{pos:[18,0,31],state:5},
{pos:[19,0,31],state:5},
{pos:[20,0,31],state:5},
{pos:[21,0,31],state:5},
{pos:[22,0,31],state:5},
{pos:[23,0,31],state:5},
{pos:[24,0,31],state:5},
{pos:[25,0,31],state:5},
{pos:[26,0,31],state:5},
{pos:[27,0,31],state:5},
{pos:[28,0,31],state:5},
{pos:[29,0,31],state:5},
{pos:[30,0,31],state:5},
{pos:[31,0,31],state:5},
{pos:[32,0,31],state:5},
{pos:[33,0,31],state:5},
{pos:[34,0,31],state:5},
{pos:[35,0,31],state:5},
{pos:[36,0,31],state:5},
{pos:[37,0,31],state:5},
{pos:[38,0,31],state:5},
{pos:[39,0,31],state:5},
{pos:[40,0,31],state:5},
{pos:[41,0,31],state:5},
{pos:[42,0,31],state:5},
{pos:[43,0,31],state:5},
{pos:[44,0,31],state:5},
{pos:[45,0,31],state:5},
{pos:[46,0,31],state:5},
{pos:[0,0,32],state:5},
{pos:[1,0,32],state:5},
{pos:[2,0,32],state:5},
{pos:[3,0,32],state:5},
{pos:[4,0,32],state:5},
{pos:[5,0,32],state:5},
{pos:[6,0,32],state:5},
{pos:[7,0,32],state:5},
{pos:[8,0,32],state:5},
{pos:[9,0,32],state:5},
{pos:[10,0,32],state:5},
{pos:[11,0,32],state:5},
{pos:[12,0,32],state:5},
{pos:[13,0,32],state:5},
{pos:[14,0,32],state:5},
{pos:[15,0,32],state:5},
{pos:[16,0,32],state:5},
{pos:[17,0,32],state:5},
{pos:[18,0,32],state:5},
{pos:[19,0,32],state:5},
{pos:[20,0,32],state:5},
{pos:[21,0,32],state:5},
{pos:[22,0,32],state:5},
{pos:[23,0,32],state:5},
{pos:[24,0,32],state:5},
{pos:[25,0,32],state:5},
{pos:[26,0,32],state:5},
{pos:[27,0,32],state:5},
{pos:[28,0,32],state:5},
{pos:[29,0,32],state:5},
{pos:[30,0,32],state:5},
{pos:[31,0,32],state:5},
{pos:[32,0,32],state:5},
{pos:[33,0,32],state:5},
{pos:[34,0,32],state:5},
{pos:[35,0,32],state:5},
{pos:[36,0,32],state:5},
{pos:[37,0,32],state:5},
{pos:[38,0,32],state:5},
{pos:[39,0,32],state:5},
{pos:[40,0,32],state:5},
{pos:[41,0,32],state:5},
{pos:[42,0,32],state:5},
{pos:[43,0,32],state:5},
{pos:[44,0,32],state:5},
{pos:[45,0,32],state:5},
{pos:[46,0,32],state:5},
{pos:[0,0,33],state:5},
{pos:[1,0,33],state:5},
{pos:[2,0,33],state:5},
{pos:[3,0,33],state:5},
{pos:[4,0,33],state:5},
{pos:[5,0,33],state:5},
{pos:[6,0,33],state:5},
{pos:[7,0,33],state:5},
{pos:[8,0,33],state:5},
{pos:[9,0,33],state:5},
{pos:[10,0,33],state:5},
{pos:[11,0,33],state:5},
{pos:[12,0,33],state:5},
{pos:[13,0,33],state:5},
{pos:[14,0,33],state:5},
{pos:[15,0,33],state:5},
{pos:[16,0,33],state:5},
{pos:[17,0,33],state:5},
{pos:[18,0,33],state:5},
{pos:[19,0,33],state:5},
{pos:[20,0,33],state:5},
{pos:[21,0,33],state:5},
{pos:[22,0,33],state:5},
{pos:[23,0,33],state:5},
{pos:[24,0,33],state:5},
{pos:[25,0,33],state:5},
{pos:[26,0,33],state:5},
{pos:[27,0,33],state:5},
{pos:[28,0,33],state:5},
{pos:[29,0,33],state:5},
{pos:[30,0,33],state:5},
{pos:[31,0,33],state:5},
{pos:[32,0,33],state:5},
{pos:[33,0,33],state:5},
{pos:[34,0,33],state:5},
{pos:[35,0,33],state:5},
{pos:[36,0,33],state:5},
{pos:[37,0,33],state:5},
{pos:[38,0,33],state:5},
{pos:[39,0,33],state:5},
{pos:[40,0,33],state:5},
{pos:[41,0,33],state:5},
{pos:[42,0,33],state:5},
{pos:[43,0,33],state:5},
{pos:[44,0,33],state:5},
{pos:[45,0,33],state:5},
{pos:[46,0,33],state:5},
{pos:[0,0,34],state:5},
{pos:[1,0,34],state:5},
{pos:[2,0,34],state:5},
{pos:[3,0,34],state:5},
{pos:[4,0,34],state:5},
{pos:[5,0,34],state:5},
{pos:[6,0,34],state:5},
{pos:[7,0,34],state:5},
{pos:[8,0,34],state:5},
{pos:[9,0,34],state:5},
{pos:[10,0,34],state:5},
{pos:[11,0,34],state:5},
{pos:[12,0,34],state:5},
{pos:[13,0,34],state:5},
{pos:[14,0,34],state:5},
{pos:[15,0,34],state:5},
{pos:[16,0,34],state:5},
{pos:[17,0,34],state:5},
{pos:[18,0,34],state:5},
{pos:[19,0,34],state:5},
{pos:[20,0,34],state:5},
{pos:[21,0,34],state:5},
{pos:[22,0,34],state:5},
{pos:[23,0,34],state:5},
{pos:[24,0,34],state:5},
{pos:[25,0,34],state:5},
{pos:[26,0,34],state:5},
{pos:[27,0,34],state:5},
{pos:[28,0,34],state:5},
{pos:[29,0,34],state:5},
{pos:[30,0,34],state:5},
{pos:[31,0,34],state:5},
{pos:[32,0,34],state:5},
{pos:[33,0,34],state:5},
{pos:[34,0,34],state:5},
{pos:[35,0,34],state:5},
{pos:[36,0,34],state:5},
{pos:[37,0,34],state:5},
{pos:[38,0,34],state:5},
{pos:[39,0,34],state:5},
{pos:[40,0,34],state:5},
{pos:[41,0,34],state:5},
{pos:[42,0,34],state:5},
{pos:[43,0,34],state:5},
{pos:[44,0,34],state:5},
{pos:[45,0,34],state:5},
{pos:[46,0,34],state:5},
{pos:[0,0,35],state:5},
{pos:[1,0,35],state:5},
{pos:[2,0,35],state:5},
{pos:[3,0,35],state:5},
{pos:[4,0,35],state:5},
{pos:[5,0,35],state:5},
{pos:[6,0,35],state:5},
{pos:[7,0,35],state:5},
{pos:[8,0,35],state:5},
{pos:[9,0,35],state:5},
{pos:[10,0,35],state:5},
{pos:[11,0,35],state:5},
{pos:[12,0,35],state:5},
{pos:[13,0,35],state:5},
{pos:[14,0,35],state:5},
{pos:[15,0,35],state:5},
{pos:[16,0,35],state:5},
{pos:[17,0,35],state:5},
{pos:[18,0,35],state:5},
{pos:[19,0,35],state:5},
{pos:[20,0,35],state:5},
{pos:[21,0,35],state:5},
{pos:[22,0,35],state:5},
{pos:[23,0,35],state:5},
{pos:[24,0,35],state:5},
{pos:[25,0,35],state:5},
{pos:[26,0,35],state:5},
{pos:[27,0,35],state:5},
{pos:[28,0,35],state:5},
{pos:[29,0,35],state:5},
{pos:[30,0,35],state:5},
{pos:[31,0,35],state:5},
{pos:[32,0,35],state:5},
{pos:[33,0,35],state:5},
{pos:[34,0,35],state:5},
{pos:[35,0,35],state:5},
{pos:[36,0,35],state:5},
{pos:[37,0,35],state:5},
{pos:[38,0,35],state:5},
{pos:[39,0,35],state:5},
{pos:[40,0,35],state:5},
{pos:[41,0,35],state:5},
{pos:[42,0,35],state:5},
{pos:[43,0,35],state:5},
{pos:[44,0,35],state:5},
{pos:[45,0,35],state:5},
{pos:[46,0,35],state:5},
{pos:[0,0,36],state:5},
{pos:[1,0,36],state:5},
{pos:[2,0,36],state:5},
{pos:[3,0,36],state:5},
{pos:[4,0,36],state:5},
{pos:[5,0,36],state:5},
{pos:[6,0,36],state:5},
{pos:[7,0,36],state:5},
{pos:[8,0,36],state:5},
{pos:[9,0,36],state:5},
{pos:[10,0,36],state:5},
{pos:[11,0,36],state:5},
{pos:[12,0,36],state:5},
{pos:[13,0,36],state:5},
{pos:[14,0,36],state:5},
{pos:[15,0,36],state:5},
{pos:[16,0,36],state:5},
{pos:[17,0,36],state:5},
{pos:[18,0,36],state:5},
{pos:[19,0,36],state:5},
{pos:[20,0,36],state:5},
{pos:[21,0,36],state:5},
{pos:[22,0,36],state:5},
{pos:[23,0,36],state:5},
{pos:[24,0,36],state:5},
{pos:[25,0,36],state:5},
{pos:[26,0,36],state:5},
{pos:[27,0,36],state:5},
{pos:[28,0,36],state:5},
{pos:[29,0,36],state:5},
{pos:[30,0,36],state:5},
{pos:[31,0,36],state:5},
{pos:[32,0,36],state:5},
{pos:[33,0,36],state:5},
{pos:[34,0,36],state:5},
{pos:[35,0,36],state:5},
{pos:[36,0,36],state:5},
{pos:[37,0,36],state:5},
{pos:[38,0,36],state:5},
{pos:[39,0,36],state:5},
{pos:[40,0,36],state:5},
{pos:[41,0,36],state:5},
{pos:[42,0,36],state:5},
{pos:[43,0,36],state:5},
{pos:[44,0,36],state:5},
{pos:[45,0,36],state:5},
{pos:[46,0,36],state:5},
{pos:[0,0,37],state:5},
{pos:[1,0,37],state:5},
{pos:[2,0,37],state:5},
{pos:[3,0,37],state:5},
{pos:[4,0,37],state:5},
{pos:[5,0,37],state:5},
{pos:[6,0,37],state:5},
{pos:[7,0,37],state:5},
{pos:[8,0,37],state:5},
{pos:[9,0,37],state:5},
{pos:[10,0,37],state:5},
{pos:[11,0,37],state:5},
{pos:[12,0,37],state:5},
{pos:[13,0,37],state:5},
{pos:[14,0,37],state:5},
{pos:[15,0,37],state:5},
{pos:[16,0,37],state:5},
{pos:[17,0,37],state:5},
{pos:[18,0,37],state:5},
{pos:[19,0,37],state:5},
{pos:[20,0,37],state:5},
{pos:[21,0,37],state:5},
{pos:[22,0,37],state:5},
{pos:[23,0,37],state:5},
{pos:[24,0,37],state:5},
{pos:[25,0,37],state:5},
{pos:[26,0,37],state:5},
{pos:[27,0,37],state:5},
{pos:[28,0,37],state:5},
{pos:[29,0,37],state:5},
{pos:[30,0,37],state:5},
{pos:[31,0,37],state:5},
{pos:[32,0,37],state:5},
{pos:[33,0,37],state:5},
{pos:[34,0,37],state:5},
{pos:[35,0,37],state:5},
{pos:[36,0,37],state:5},
{pos:[37,0,37],state:5},
{pos:[38,0,37],state:5},
{pos:[39,0,37],state:5},
{pos:[40,0,37],state:5},
{pos:[41,0,37],state:5},
{pos:[42,0,37],state:5},
{pos:[43,0,37],state:5},
{pos:[44,0,37],state:5},
{pos:[45,0,37],state:5},
{pos:[46,0,37],state:5},
{pos:[0,0,38],state:5},
{pos:[1,0,38],state:5},
{pos:[2,0,38],state:5},
{pos:[3,0,38],state:5},
{pos:[4,0,38],state:5},
{pos:[5,0,38],state:5},
{pos:[6,0,38],state:5},
{pos:[7,0,38],state:5},
{pos:[8,0,38],state:5},
{pos:[9,0,38],state:5},
{pos:[10,0,38],state:5},
{pos:[11,0,38],state:5},
{pos:[12,0,38],state:5},
{pos:[13,0,38],state:5},
{pos:[14,0,38],state:5},
{pos:[15,0,38],state:5},
{pos:[16,0,38],state:5},
{pos:[17,0,38],state:5},
{pos:[18,0,38],state:5},
{pos:[19,0,38],state:5},
{pos:[20,0,38],state:5},
{pos:[21,0,38],state:5},
{pos:[22,0,38],state:5},
{pos:[23,0,38],state:5},
{pos:[24,0,38],state:5},
{pos:[25,0,38],state:5},
{pos:[26,0,38],state:5},
{pos:[27,0,38],state:5},
{pos:[28,0,38],state:5},
{pos:[29,0,38],state:5},
{pos:[30,0,38],state:5},
{pos:[31,0,38],state:5},
{pos:[32,0,38],state:5},
{pos:[33,0,38],state:5},
{pos:[34,0,38],state:5},
{pos:[35,0,38],state:5},
{pos:[36,0,38],state:5},
{pos:[37,0,38],state:5},
{pos:[38,0,38],state:5},
{pos:[39,0,38],state:5},
{pos:[40,0,38],state:5},
{pos:[41,0,38],state:5},
{pos:[42,0,38],state:5},
{pos:[43,0,38],state:5},
{pos:[44,0,38],state:5},
{pos:[45,0,38],state:5},
{pos:[46,0,38],state:5},
{pos:[0,0,39],state:5},
{pos:[1,0,39],state:5},
{pos:[2,0,39],state:5},
{pos:[3,0,39],state:5},
{pos:[4,0,39],state:5},
{pos:[5,0,39],state:5},
{pos:[6,0,39],state:5},
{pos:[7,0,39],state:5},
{pos:[8,0,39],state:5},
{pos:[9,0,39],state:5},
{pos:[10,0,39],state:5},
{pos:[11,0,39],state:5},
{pos:[12,0,39],state:5},
{pos:[13,0,39],state:5},
{pos:[14,0,39],state:5},
{pos:[15,0,39],state:5},
{pos:[16,0,39],state:5},
{pos:[17,0,39],state:5},
{pos:[18,0,39],state:5},
{pos:[19,0,39],state:5},
{pos:[20,0,39],state:5},
{pos:[21,0,39],state:5},
{pos:[22,0,39],state:5},
{pos:[23,0,39],state:5},
{pos:[24,0,39],state:5},
{pos:[25,0,39],state:5},
{pos:[26,0,39],state:5},
{pos:[27,0,39],state:5},
{pos:[28,0,39],state:5},
{pos:[29,0,39],state:5},
{pos:[30,0,39],state:5},
{pos:[31,0,39],state:5},
{pos:[32,0,39],state:5},
{pos:[33,0,39],state:5},
{pos:[34,0,39],state:5},
{pos:[35,0,39],state:5},
{pos:[36,0,39],state:5},
{pos:[37,0,39],state:5},
{pos:[38,0,39],state:5},
{pos:[39,0,39],state:5},
{pos:[40,0,39],state:5},
{pos:[41,0,39],state:5},
{pos:[42,0,39],state:5},
{pos:[43,0,39],state:5},
{pos:[44,0,39],state:5},
{pos:[45,0,39],state:5},
{pos:[46,0,39],state:5},
{pos:[0,0,40],state:5},
{pos:[1,0,40],state:5},
{pos:[2,0,40],state:5},
{pos:[3,0,40],state:5},
{pos:[4,0,40],state:5},
{pos:[5,0,40],state:5},
{pos:[6,0,40],state:5},
{pos:[7,0,40],state:5},
{pos:[8,0,40],state:5},
{pos:[9,0,40],state:5},
{pos:[10,0,40],state:5},
{pos:[11,0,40],state:5},
{pos:[12,0,40],state:5},
{pos:[13,0,40],state:5},
{pos:[14,0,40],state:5},
{pos:[15,0,40],state:5},
{pos:[16,0,40],state:5},
{pos:[17,0,40],state:5},
{pos:[18,0,40],state:5},
{pos:[19,0,40],state:5},
{pos:[20,0,40],state:5},
{pos:[21,0,40],state:5},
{pos:[22,0,40],state:5},
{pos:[23,0,40],state:5},
{pos:[24,0,40],state:5},
{pos:[25,0,40],state:5},
{pos:[26,0,40],state:5},
{pos:[27,0,40],state:5},
{pos:[28,0,40],state:5},
{pos:[29,0,40],state:5},
{pos:[30,0,40],state:5},
{pos:[31,0,40],state:5},
{pos:[32,0,40],state:5},
{pos:[33,0,40],state:5},
{pos:[34,0,40],state:5},
{pos:[35,0,40],state:5},
{pos:[36,0,40],state:5},
{pos:[37,0,40],state:5},
{pos:[38,0,40],state:5},
{pos:[39,0,40],state:5},
{pos:[40,0,40],state:5},
{pos:[41,0,40],state:5},
{pos:[42,0,40],state:5},
{pos:[43,0,40],state:5},
{pos:[44,0,40],state:5},
{pos:[45,0,40],state:5},
{pos:[46,0,40],state:5},
{pos:[0,0,41],state:5},
{pos:[1,0,41],state:5},
{pos:[2,0,41],state:5},
{pos:[3,0,41],state:5},
{pos:[4,0,41],state:5},
{pos:[5,0,41],state:5},
{pos:[6,0,41],state:5},
{pos:[7,0,41],state:5},
{pos:[8,0,41],state:5},
{pos:[9,0,41],state:5},
{pos:[10,0,41],state:5},
{pos:[11,0,41],state:5},
{pos:[12,0,41],state:5},
{pos:[13,0,41],state:5},
{pos:[14,0,41],state:5},
{pos:[15,0,41],state:5},
{pos:[16,0,41],state:5},
{pos:[17,0,41],state:5},
{pos:[18,0,41],state:5},
{pos:[19,0,41],state:5},
{pos:[20,0,41],state:5},
{pos:[21,0,41],state:5},
{pos:[22,0,41],state:5},
{pos:[23,0,41],state:5},
{pos:[24,0,41],state:5},
{pos:[25,0,41],state:5},
{pos:[26,0,41],state:5},
{pos:[27,0,41],state:5},
{pos:[28,0,41],state:5},
{pos:[29,0,41],state:5},
{pos:[30,0,41],state:5},
{pos:[31,0,41],state:5},
{pos:[32,0,41],state:5},
{pos:[33,0,41],state:5},
{pos:[34,0,41],state:5},
{pos:[35,0,41],state:5},
{pos:[36,0,41],state:5},
{pos:[37,0,41],state:5},
{pos:[38,0,41],state:5},
{pos:[39,0,41],state:5},
{pos:[40,0,41],state:5},
{pos:[41,0,41],state:5},
{pos:[42,0,41],state:5},
{pos:[43,0,41],state:5},
{pos:[44,0,41],state:5},
{pos:[45,0,41],state:5},
{pos:[46,0,41],state:5},
{pos:[0,0,42],state:5},
{pos:[1,0,42],state:5},
{pos:[2,0,42],state:5},
{pos:[3,0,42],state:5},
{pos:[4,0,42],state:5},
{pos:[5,0,42],state:5},
{pos:[6,0,42],state:5},
{pos:[7,0,42],state:5},
{pos:[8,0,42],state:5},
{pos:[9,0,42],state:5},
{pos:[10,0,42],state:5},
{pos:[11,0,42],state:5},
{pos:[12,0,42],state:5},
{pos:[13,0,42],state:5},
{pos:[14,0,42],state:5},
{pos:[15,0,42],state:5},
{pos:[16,0,42],state:5},
{pos:[17,0,42],state:5},
{pos:[18,0,42],state:5},
{pos:[19,0,42],state:5},
{pos:[20,0,42],state:5},
{pos:[21,0,42],state:5},
{pos:[22,0,42],state:5},
{pos:[23,0,42],state:5},
{pos:[24,0,42],state:5},
{pos:[25,0,42],state:5},
{pos:[26,0,42],state:5},
{pos:[27,0,42],state:5},
{pos:[28,0,42],state:5},
{pos:[29,0,42],state:5},
{pos:[30,0,42],state:5},
{pos:[31,0,42],state:5},
{pos:[32,0,42],state:5},
{pos:[33,0,42],state:5},
{pos:[34,0,42],state:5},
{pos:[35,0,42],state:5},
{pos:[36,0,42],state:5},
{pos:[37,0,42],state:5},
{pos:[38,0,42],state:5},
{pos:[39,0,42],state:5},
{pos:[40,0,42],state:5},
{pos:[41,0,42],state:5},
{pos:[42,0,42],state:5},
{pos:[43,0,42],state:5},
{pos:[44,0,42],state:5},
{pos:[45,0,42],state:5},
{pos:[46,0,42],state:5},
{pos:[0,0,43],state:5},
{pos:[1,0,43],state:5},
{pos:[2,0,43],state:5},
{pos:[3,0,43],state:5},
{pos:[4,0,43],state:5},
{pos:[5,0,43],state:5},
{pos:[6,0,43],state:5},
{pos:[7,0,43],state:5},
{pos:[8,0,43],state:5},
{pos:[9,0,43],state:5},
{pos:[10,0,43],state:5},
{pos:[11,0,43],state:5},
{pos:[12,0,43],state:5},
{pos:[13,0,43],state:5},
{pos:[14,0,43],state:5},
{pos:[15,0,43],state:5},
{pos:[16,0,43],state:5},
{pos:[17,0,43],state:5},
{pos:[18,0,43],state:5},
{pos:[19,0,43],state:5},
{pos:[20,0,43],state:5},
{pos:[21,0,43],state:5},
{pos:[22,0,43],state:5},
{pos:[23,0,43],state:5},
{pos:[24,0,43],state:5},
{pos:[25,0,43],state:5},
{pos:[26,0,43],state:5},
{pos:[27,0,43],state:5},
{pos:[28,0,43],state:5},
{pos:[29,0,43],state:5},
{pos:[30,0,43],state:5},
{pos:[31,0,43],state:5},
{pos:[32,0,43],state:5},
{pos:[33,0,43],state:5},
{pos:[34,0,43],state:5},
{pos:[35,0,43],state:5},
{pos:[36,0,43],state:5},
{pos:[37,0,43],state:5},
{pos:[38,0,43],state:5},
{pos:[39,0,43],state:5},
{pos:[40,0,43],state:5},
{pos:[41,0,43],state:5},
{pos:[42,0,43],state:5},
{pos:[43,0,43],state:5},
{pos:[44,0,43],state:5},
{pos:[45,0,43],state:5},
{pos:[46,0,43],state:5},
{pos:[0,1,0],state:2},
{pos:[1,1,0],state:2},
{pos:[2,1,0],state:2},
{pos:[3,1,0],state:2},
{pos:[4,1,0],state:2},
{pos:[5,1,0],state:2},
{pos:[6,1,0],state:2},
{pos:[7,1,0],state:2},
{pos:[8,1,0],state:2},
{pos:[9,1,0],state:2},
{pos:[10,1,0],state:2},
{pos:[11,1,0],state:2},
{pos:[12,1,0],state:2},
{pos:[13,1,0],state:2},
{pos:[14,1,0],state:2},
{pos:[15,1,0],state:2},
{pos:[16,1,0],state:2},
{pos:[17,1,0],state:2},
{pos:[18,1,0],state:2},
{pos:[19,1,0],state:2},
{pos:[20,1,0],state:2},
{pos:[21,1,0],state:2},
{pos:[22,1,0],state:2},
{pos:[23,1,0],state:2},
{pos:[24,1,0],state:2},
{pos:[25,1,0],state:2},
{pos:[26,1,0],state:2},
{pos:[27,1,0],state:2},
{pos:[28,1,0],state:2},
{pos:[34,1,0],state:2},
{pos:[35,1,0],state:2},
{pos:[36,1,0],state:2},
{pos:[37,1,0],state:2},
{pos:[38,1,0],state:2},
{pos:[39,1,0],state:2},
{pos:[40,1,0],state:2},
{pos:[41,1,0],state:2},
{pos:[42,1,0],state:2},
{pos:[43,1,0],state:2},
{pos:[44,1,0],state:2},
{pos:[45,1,0],state:2},
{pos:[46,1,0],state:2},
{pos:[0,1,1],state:2},
{pos:[1,1,1],state:2},
{pos:[2,1,1],state:2},
{pos:[3,1,1],state:2},
{pos:[4,1,1],state:2},
{pos:[5,1,1],state:2},
{pos:[6,1,1],state:2},
{pos:[7,1,1],state:2},
{pos:[8,1,1],state:2},
{pos:[9,1,1],state:2},
{pos:[10,1,1],state:2},
{pos:[11,1,1],state:2},
{pos:[12,1,1],state:2},
{pos:[13,1,1],state:2},
{pos:[14,1,1],state:2},
{pos:[15,1,1],state:2},
{pos:[16,1,1],state:2},
{pos:[17,1,1],state:2},
{pos:[18,1,1],state:2},
{pos:[19,1,1],state:2},
{pos:[20,1,1],state:2},
{pos:[21,1,1],state:2},
{pos:[22,1,1],state:2},
{pos:[23,1,1],state:2},
{pos:[24,1,1],state:2},
{pos:[25,1,1],state:2},
{pos:[26,1,1],state:2},
{pos:[27,1,1],state:2},
{pos:[28,1,1],state:2},
{pos:[34,1,1],state:2},
{pos:[35,1,1],state:2},
{pos:[36,1,1],state:2},
{pos:[37,1,1],state:2},
{pos:[38,1,1],state:2},
{pos:[39,1,1],state:2},
{pos:[40,1,1],state:2},
{pos:[41,1,1],state:2},
{pos:[42,1,1],state:2},
{pos:[43,1,1],state:2},
{pos:[44,1,1],state:2},
{pos:[45,1,1],state:2},
{pos:[46,1,1],state:2},
{pos:[0,1,2],state:2},
{pos:[1,1,2],state:2},
{pos:[4,1,2],state:0},
{pos:[11,1,2],state:0},
{pos:[18,1,2],state:0},
{pos:[25,1,2],state:0},
{pos:[32,1,2],state:0},
{pos:[39,1,2],state:0},
{pos:[45,1,2],state:2},
{pos:[46,1,2],state:2},
{pos:[0,1,3],state:2},
{pos:[1,1,3],state:2},
{pos:[45,1,3],state:2},
{pos:[46,1,3],state:2},
{pos:[0,1,4],state:2},
{pos:[1,1,4],state:2},
{pos:[45,1,4],state:2},
{pos:[46,1,4],state:2},
{pos:[0,1,5],state:2},
{pos:[1,1,5],state:2},
{pos:[2,1,5],state:0},
{pos:[44,1,5],state:0},
{pos:[45,1,5],state:2},
{pos:[46,1,5],state:2},
{pos:[0,1,6],state:2},
{pos:[1,1,6],state:2},
{pos:[45,1,6],state:2},
{pos:[46,1,6],state:2},
{pos:[0,1,7],state:2},
{pos:[1,1,7],state:2},
{pos:[45,1,7],state:2},
{pos:[46,1,7],state:2},
{pos:[0,1,8],state:2},
{pos:[1,1,8],state:2},
{pos:[45,1,8],state:2},
{pos:[46,1,8],state:2},
{pos:[0,1,9],state:2},
{pos:[1,1,9],state:2},
{pos:[5,1,9],state:0},
{pos:[6,1,9],state:0},
{pos:[7,1,9],state:0},
{pos:[8,1,9],state:0},
{pos:[9,1,9],state:0},
{pos:[10,1,9],state:0},
{pos:[36,1,9],state:0},
{pos:[37,1,9],state:0},
{pos:[38,1,9],state:0},
{pos:[39,1,9],state:0},
{pos:[40,1,9],state:0},
{pos:[41,1,9],state:0},
{pos:[45,1,9],state:2},
{pos:[46,1,9],state:2},
{pos:[0,1,10],state:2},
{pos:[1,1,10],state:2},
{pos:[5,1,10],state:0},
{pos:[6,1,10],state:0},
{pos:[7,1,10],state:0},
{pos:[8,1,10],state:0},
{pos:[9,1,10],state:0},
{pos:[10,1,10],state:0},
{pos:[36,1,10],state:0},
{pos:[37,1,10],state:0},
{pos:[38,1,10],state:0},
{pos:[39,1,10],state:0},
{pos:[40,1,10],state:0},
{pos:[41,1,10],state:0},
{pos:[45,1,10],state:2},
{pos:[46,1,10],state:2},
{pos:[0,1,11],state:2},
{pos:[1,1,11],state:2},
{pos:[5,1,11],state:0},
{pos:[6,1,11],state:0},
{pos:[7,1,11],state:0},
{pos:[8,1,11],state:0},
{pos:[9,1,11],state:0},
{pos:[10,1,11],state:0},
{pos:[36,1,11],state:0},
{pos:[37,1,11],state:0},
{pos:[38,1,11],state:0},
{pos:[39,1,11],state:0},
{pos:[40,1,11],state:0},
{pos:[41,1,11],state:0},
{pos:[45,1,11],state:2},
{pos:[46,1,11],state:2},
{pos:[0,1,12],state:2},
{pos:[1,1,12],state:2},
{pos:[45,1,12],state:2},
{pos:[46,1,12],state:2},
{pos:[0,1,13],state:2},
{pos:[1,1,13],state:2},
{pos:[2,1,13],state:0},
{pos:[44,1,13],state:0},
{pos:[45,1,13],state:2},
{pos:[46,1,13],state:2},
{pos:[0,1,14],state:2},
{pos:[1,1,14],state:2},
{pos:[45,1,14],state:2},
{pos:[46,1,14],state:2},
{pos:[0,1,15],state:2},
{pos:[1,1,15],state:2},
{pos:[45,1,15],state:2},
{pos:[46,1,15],state:2},
{pos:[0,1,16],state:2},
{pos:[1,1,16],state:2},
{pos:[14,1,16],state:4,nbt:{mode:"DATA",metadata:"enemy:melee:1"}},
{pos:[23,1,16],state:4,nbt:{mode:"DATA",metadata:"objective:2"}},
{pos:[45,1,16],state:2},
{pos:[46,1,16],state:2},
{pos:[0,1,17],state:2},
{pos:[1,1,17],state:2},
{pos:[5,1,17],state:0},
{pos:[6,1,17],state:0},
{pos:[7,1,17],state:0},
{pos:[8,1,17],state:0},
{pos:[9,1,17],state:0},
{pos:[10,1,17],state:0},
{pos:[36,1,17],state:0},
{pos:[37,1,17],state:0},
{pos:[38,1,17],state:0},
{pos:[39,1,17],state:0},
{pos:[40,1,17],state:0},
{pos:[41,1,17],state:0},
{pos:[45,1,17],state:2},
{pos:[46,1,17],state:2},
{pos:[0,1,18],state:2},
{pos:[1,1,18],state:2},
{pos:[5,1,18],state:0},
{pos:[6,1,18],state:0},
{pos:[7,1,18],state:0},
{pos:[8,1,18],state:0},
{pos:[9,1,18],state:0},
{pos:[10,1,18],state:0},
{pos:[36,1,18],state:0},
{pos:[37,1,18],state:0},
{pos:[38,1,18],state:0},
{pos:[39,1,18],state:0},
{pos:[40,1,18],state:0},
{pos:[41,1,18],state:0},
{pos:[45,1,18],state:2},
{pos:[46,1,18],state:2},
{pos:[0,1,19],state:2},
{pos:[1,1,19],state:2},
{pos:[5,1,19],state:0},
{pos:[6,1,19],state:0},
{pos:[7,1,19],state:0},
{pos:[8,1,19],state:0},
{pos:[9,1,19],state:0},
{pos:[10,1,19],state:0},
{pos:[36,1,19],state:0},
{pos:[37,1,19],state:0},
{pos:[38,1,19],state:0},
{pos:[39,1,19],state:0},
{pos:[40,1,19],state:0},
{pos:[41,1,19],state:0},
{pos:[45,1,19],state:2},
{pos:[46,1,19],state:2},
{pos:[0,1,20],state:2},
{pos:[1,1,20],state:2},
{pos:[45,1,20],state:2},
{pos:[46,1,20],state:2},
{pos:[0,1,21],state:2},
{pos:[1,1,21],state:2},
{pos:[2,1,21],state:0},
{pos:[44,1,21],state:0},
{pos:[45,1,21],state:2},
{pos:[46,1,21],state:2},
{pos:[0,1,22],state:2},
{pos:[1,1,22],state:2},
{pos:[2,1,22],state:2},
{pos:[3,1,22],state:2},
{pos:[4,1,22],state:2},
{pos:[5,1,22],state:2},
{pos:[6,1,22],state:4,nbt:{mode:"DATA",metadata:"shortcut:catacomb_loop"}},
{pos:[7,1,22],state:2},
{pos:[8,1,22],state:2},
{pos:[9,1,22],state:2},
{pos:[10,1,22],state:2},
{pos:[11,1,22],state:2},
{pos:[12,1,22],state:2},
{pos:[13,1,22],state:2},
{pos:[14,1,22],state:2},
{pos:[15,1,22],state:2},
{pos:[16,1,22],state:2},
{pos:[17,1,22],state:2},
{pos:[18,1,22],state:2},
{pos:[19,1,22],state:2},
{pos:[20,1,22],state:2},
{pos:[21,1,22],state:2},
{pos:[22,1,22],state:2},
{pos:[23,1,22],state:2},
{pos:[24,1,22],state:2},
{pos:[25,1,22],state:2},
{pos:[26,1,22],state:2},
{pos:[27,1,22],state:2},
{pos:[28,1,22],state:2},
{pos:[34,1,22],state:2},
{pos:[35,1,22],state:2},
{pos:[36,1,22],state:2},
{pos:[37,1,22],state:2},
{pos:[38,1,22],state:2},
{pos:[39,1,22],state:2},
{pos:[40,1,22],state:2},
{pos:[41,1,22],state:2},
{pos:[42,1,22],state:2},
{pos:[43,1,22],state:2},
{pos:[44,1,22],state:2},
{pos:[45,1,22],state:2},
{pos:[46,1,22],state:2},
{pos:[0,1,23],state:2},
{pos:[1,1,23],state:2},
{pos:[45,1,23],state:2},
{pos:[46,1,23],state:2},
{pos:[0,1,24],state:2},
{pos:[1,1,24],state:2},
{pos:[45,1,24],state:2},
{pos:[46,1,24],state:2},
{pos:[0,1,25],state:2},
{pos:[1,1,25],state:2},
{pos:[45,1,25],state:2},
{pos:[46,1,25],state:2},
{pos:[0,1,26],state:2},
{pos:[1,1,26],state:2},
{pos:[5,1,26],state:0},
{pos:[6,1,26],state:0},
{pos:[7,1,26],state:0},
{pos:[8,1,26],state:0},
{pos:[9,1,26],state:0},
{pos:[10,1,26],state:0},
{pos:[36,1,26],state:0},
{pos:[37,1,26],state:0},
{pos:[38,1,26],state:0},
{pos:[39,1,26],state:0},
{pos:[40,1,26],state:0},
{pos:[41,1,26],state:0},
{pos:[45,1,26],state:2},
{pos:[46,1,26],state:2},
{pos:[0,1,27],state:2},
{pos:[1,1,27],state:2},
{pos:[5,1,27],state:0},
{pos:[6,1,27],state:0},
{pos:[7,1,27],state:0},
{pos:[8,1,27],state:0},
{pos:[9,1,27],state:0},
{pos:[10,1,27],state:0},
{pos:[36,1,27],state:0},
{pos:[37,1,27],state:0},
{pos:[38,1,27],state:0},
{pos:[39,1,27],state:0},
{pos:[40,1,27],state:0},
{pos:[41,1,27],state:0},
{pos:[45,1,27],state:2},
{pos:[46,1,27],state:2},
{pos:[0,1,28],state:2},
{pos:[1,1,28],state:2},
{pos:[5,1,28],state:0},
{pos:[6,1,28],state:0},
{pos:[7,1,28],state:0},
{pos:[8,1,28],state:0},
{pos:[9,1,28],state:0},
{pos:[10,1,28],state:0},
{pos:[36,1,28],state:0},
{pos:[37,1,28],state:0},
{pos:[38,1,28],state:0},
{pos:[39,1,28],state:0},
{pos:[40,1,28],state:0},
{pos:[41,1,28],state:0},
{pos:[45,1,28],state:2},
{pos:[46,1,28],state:2},
{pos:[0,1,29],state:2},
{pos:[1,1,29],state:2},
{pos:[2,1,29],state:0},
{pos:[44,1,29],state:0},
{pos:[45,1,29],state:2},
{pos:[46,1,29],state:2},
{pos:[0,1,30],state:2},
{pos:[1,1,30],state:2},
{pos:[45,1,30],state:2},
{pos:[46,1,30],state:2},
{pos:[0,1,31],state:2},
{pos:[1,1,31],state:2},
{pos:[38,1,31],state:4,nbt:{mode:"DATA",metadata:"secret:bone_chapel"}},
{pos:[39,1,31],state:1,nbt:{id:"minecraft:chest",LootTable:"minecraft:chests/simple_dungeon"}},
{pos:[45,1,31],state:2},
{pos:[46,1,31],state:2},
{pos:[0,1,32],state:2},
{pos:[1,1,32],state:2},
{pos:[45,1,32],state:2},
{pos:[46,1,32],state:2},
{pos:[0,1,33],state:2},
{pos:[1,1,33],state:2},
{pos:[45,1,33],state:2},
{pos:[46,1,33],state:2},
{pos:[0,1,34],state:2},
{pos:[1,1,34],state:2},
{pos:[5,1,34],state:0},
{pos:[6,1,34],state:0},
{pos:[7,1,34],state:0},
{pos:[8,1,34],state:0},
{pos:[9,1,34],state:0},
{pos:[10,1,34],state:0},
{pos:[36,1,34],state:0},
{pos:[37,1,34],state:0},
{pos:[38,1,34],state:0},
{pos:[39,1,34],state:0},
{pos:[40,1,34],state:0},
{pos:[41,1,34],state:0},
{pos:[45,1,34],state:2},
{pos:[46,1,34],state:2},
{pos:[0,1,35],state:2},
{pos:[1,1,35],state:2},
{pos:[5,1,35],state:0},
{pos:[6,1,35],state:0},
{pos:[7,1,35],state:0},
{pos:[8,1,35],state:0},
{pos:[9,1,35],state:0},
{pos:[10,1,35],state:0},
{pos:[36,1,35],state:0},
{pos:[37,1,35],state:0},
{pos:[38,1,35],state:0},
{pos:[39,1,35],state:0},
{pos:[40,1,35],state:0},
{pos:[41,1,35],state:0},
{pos:[45,1,35],state:2},
{pos:[46,1,35],state:2},
{pos:[0,1,36],state:2},
{pos:[1,1,36],state:2},
{pos:[5,1,36],state:0},
{pos:[6,1,36],state:0},
{pos:[7,1,36],state:0},
{pos:[8,1,36],state:0},
{pos:[9,1,36],state:0},
{pos:[10,1,36],state:0},
{pos:[36,1,36],state:0},
{pos:[37,1,36],state:0},
{pos:[38,1,36],state:0},
{pos:[39,1,36],state:0},
{pos:[40,1,36],state:0},
{pos:[41,1,36],state:0},
{pos:[45,1,36],state:2},
{pos:[46,1,36],state:2},
{pos:[0,1,37],state:2},
{pos:[1,1,37],state:2},
{pos:[2,1,37],state:0},
{pos:[44,1,37],state:0},
{pos:[45,1,37],state:2},
{pos:[46,1,37],state:2},
{pos:[0,1,38],state:2},
{pos:[1,1,38],state:2},
{pos:[45,1,38],state:2},
{pos:[46,1,38],state:2},
{pos:[0,1,39],state:2},
{pos:[1,1,39],state:2},
{pos:[45,1,39],state:2},
{pos:[46,1,39],state:2},
{pos:[0,1,40],state:2},
{pos:[1,1,40],state:2},
{pos:[45,1,40],state:2},
{pos:[46,1,40],state:2},
{pos:[0,1,41],state:2},
{pos:[1,1,41],state:2},
{pos:[4,1,41],state:0},
{pos:[11,1,41],state:0},
{pos:[18,1,41],state:0},
{pos:[23,1,41],state:4,nbt:{mode:"DATA",metadata:"door:1"}},
{pos:[25,1,41],state:0},
{pos:[32,1,41],state:0},
{pos:[39,1,41],state:0},
{pos:[45,1,41],state:2},
{pos:[46,1,41],state:2},
{pos:[0,1,42],state:2},
{pos:[1,1,42],state:2},
{pos:[2,1,42],state:2},
{pos:[3,1,42],state:2},
{pos:[4,1,42],state:2},
{pos:[5,1,42],state:2},
{pos:[6,1,42],state:2},
{pos:[7,1,42],state:2},
{pos:[8,1,42],state:2},
{pos:[9,1,42],state:2},
{pos:[10,1,42],state:2},
{pos:[11,1,42],state:2},
{pos:[12,1,42],state:2},
{pos:[13,1,42],state:2},
{pos:[14,1,42],state:2},
{pos:[15,1,42],state:2},
{pos:[16,1,42],state:2},
{pos:[17,1,42],state:2},
{pos:[18,1,42],state:2},
{pos:[19,1,42],state:2},
{pos:[20,1,42],state:2},
{pos:[26,1,42],state:2},
{pos:[27,1,42],state:2},
{pos:[28,1,42],state:2},
{pos:[29,1,42],state:2},
{pos:[30,1,42],state:2},
{pos:[31,1,42],state:2},
{pos:[32,1,42],state:2},
{pos:[33,1,42],state:2},
{pos:[34,1,42],state:2},
{pos:[35,1,42],state:2},
{pos:[36,1,42],state:2},
{pos:[37,1,42],state:2},
{pos:[38,1,42],state:2},
{pos:[39,1,42],state:2},
{pos:[40,1,42],state:2},
{pos:[41,1,42],state:2},
{pos:[42,1,42],state:2},
{pos:[43,1,42],state:2},
{pos:[44,1,42],state:2},
{pos:[45,1,42],state:2},
{pos:[46,1,42],state:2},
{pos:[0,1,43],state:2},
{pos:[1,1,43],state:2},
{pos:[2,1,43],state:2},
{pos:[3,1,43],state:2},
{pos:[4,1,43],state:2},
{pos:[5,1,43],state:2},
{pos:[6,1,43],state:2},
{pos:[7,1,43],state:2},
{pos:[8,1,43],state:2},
{pos:[9,1,43],state:2},
{pos:[10,1,43],state:2},
{pos:[11,1,43],state:2},
{pos:[12,1,43],state:2},
{pos:[13,1,43],state:2},
{pos:[14,1,43],state:2},
{pos:[15,1,43],state:2},
{pos:[16,1,43],state:2},
{pos:[17,1,43],state:2},
{pos:[18,1,43],state:2},
{pos:[19,1,43],state:2},
{pos:[20,1,43],state:2},
{pos:[26,1,43],state:2},
{pos:[27,1,43],state:2},
{pos:[28,1,43],state:2},
{pos:[29,1,43],state:2},
{pos:[30,1,43],state:2},
{pos:[31,1,43],state:2},
{pos:[32,1,43],state:2},
{pos:[33,1,43],state:2},
{pos:[34,1,43],state:2},
{pos:[35,1,43],state:2},
{pos:[36,1,43],state:2},
{pos:[37,1,43],state:2},
{pos:[38,1,43],state:2},
{pos:[39,1,43],state:2},
{pos:[40,1,43],state:2},
{pos:[41,1,43],state:2},
{pos:[42,1,43],state:2},
{pos:[43,1,43],state:2},
{pos:[44,1,43],state:2},
{pos:[45,1,43],state:2},
{pos:[46,1,43],state:2},
{pos:[0,2,0],state:2},
{pos:[1,2,0],state:2},
{pos:[2,2,0],state:2},
{pos:[3,2,0],state:2},
{pos:[4,2,0],state:2},
{pos:[5,2,0],state:2},
{pos:[6,2,0],state:2},
{pos:[7,2,0],state:2},
{pos:[8,2,0],state:2},
{pos:[9,2,0],state:2},
{pos:[10,2,0],state:2},
{pos:[11,2,0],state:2},
{pos:[12,2,0],state:2},
{pos:[13,2,0],state:2},
{pos:[14,2,0],state:2},
{pos:[15,2,0],state:2},
{pos:[16,2,0],state:2},
{pos:[17,2,0],state:2},
{pos:[18,2,0],state:2},
{pos:[19,2,0],state:2},
{pos:[20,2,0],state:2},
{pos:[21,2,0],state:2},
{pos:[22,2,0],state:2},
{pos:[23,2,0],state:2},
{pos:[24,2,0],state:2},
{pos:[25,2,0],state:2},
{pos:[26,2,0],state:2},
{pos:[27,2,0],state:2},
{pos:[28,2,0],state:2},
{pos:[34,2,0],state:2},
{pos:[35,2,0],state:2},
{pos:[36,2,0],state:2},
{pos:[37,2,0],state:2},
{pos:[38,2,0],state:2},
{pos:[39,2,0],state:2},
{pos:[40,2,0],state:2},
{pos:[41,2,0],state:2},
{pos:[42,2,0],state:2},
{pos:[43,2,0],state:2},
{pos:[44,2,0],state:2},
{pos:[45,2,0],state:2},
{pos:[46,2,0],state:2},
{pos:[0,2,1],state:2},
{pos:[1,2,1],state:2},
{pos:[2,2,1],state:2},
{pos:[3,2,1],state:2},
{pos:[4,2,1],state:2},
{pos:[5,2,1],state:2},
{pos:[6,2,1],state:2},
{pos:[7,2,1],state:2},
{pos:[8,2,1],state:2},
{pos:[9,2,1],state:2},
{pos:[10,2,1],state:2},
{pos:[11,2,1],state:2},
{pos:[12,2,1],state:2},
{pos:[13,2,1],state:2},
{pos:[14,2,1],state:2},
{pos:[15,2,1],state:2},
{pos:[16,2,1],state:2},
{pos:[17,2,1],state:2},
{pos:[18,2,1],state:2},
{pos:[19,2,1],state:2},
{pos:[20,2,1],state:2},
{pos:[21,2,1],state:2},
{pos:[22,2,1],state:2},
{pos:[23,2,1],state:2},
{pos:[24,2,1],state:2},
{pos:[25,2,1],state:2},
{pos:[26,2,1],state:2},
{pos:[27,2,1],state:2},
{pos:[28,2,1],state:2},
{pos:[34,2,1],state:2},
{pos:[35,2,1],state:2},
{pos:[36,2,1],state:2},
{pos:[37,2,1],state:2},
{pos:[38,2,1],state:2},
{pos:[39,2,1],state:2},
{pos:[40,2,1],state:2},
{pos:[41,2,1],state:2},
{pos:[42,2,1],state:2},
{pos:[43,2,1],state:2},
{pos:[44,2,1],state:2},
{pos:[45,2,1],state:2},
{pos:[46,2,1],state:2},
{pos:[0,2,2],state:2},
{pos:[1,2,2],state:2},
{pos:[4,2,2],state:0},
{pos:[11,2,2],state:0},
{pos:[18,2,2],state:0},
{pos:[25,2,2],state:0},
{pos:[32,2,2],state:0},
{pos:[39,2,2],state:0},
{pos:[45,2,2],state:2},
{pos:[46,2,2],state:2},
{pos:[0,2,3],state:2},
{pos:[1,2,3],state:2},
{pos:[45,2,3],state:2},
{pos:[46,2,3],state:2},
{pos:[0,2,4],state:2},
{pos:[1,2,4],state:2},
{pos:[45,2,4],state:2},
{pos:[46,2,4],state:2},
{pos:[0,2,5],state:2},
{pos:[1,2,5],state:2},
{pos:[2,2,5],state:0},
{pos:[44,2,5],state:0},
{pos:[45,2,5],state:2},
{pos:[46,2,5],state:2},
{pos:[0,2,6],state:2},
{pos:[1,2,6],state:2},
{pos:[45,2,6],state:2},
{pos:[46,2,6],state:2},
{pos:[0,2,7],state:2},
{pos:[1,2,7],state:2},
{pos:[45,2,7],state:2},
{pos:[46,2,7],state:2},
{pos:[0,2,8],state:2},
{pos:[1,2,8],state:2},
{pos:[45,2,8],state:2},
{pos:[46,2,8],state:2},
{pos:[0,2,9],state:2},
{pos:[1,2,9],state:2},
{pos:[5,2,9],state:0},
{pos:[6,2,9],state:0},
{pos:[7,2,9],state:0},
{pos:[8,2,9],state:0},
{pos:[9,2,9],state:0},
{pos:[10,2,9],state:0},
{pos:[36,2,9],state:0},
{pos:[37,2,9],state:0},
{pos:[38,2,9],state:0},
{pos:[39,2,9],state:0},
{pos:[40,2,9],state:0},
{pos:[41,2,9],state:0},
{pos:[45,2,9],state:2},
{pos:[46,2,9],state:2},
{pos:[0,2,10],state:2},
{pos:[1,2,10],state:2},
{pos:[5,2,10],state:0},
{pos:[6,2,10],state:0},
{pos:[7,2,10],state:0},
{pos:[8,2,10],state:0},
{pos:[9,2,10],state:0},
{pos:[10,2,10],state:0},
{pos:[36,2,10],state:0},
{pos:[37,2,10],state:0},
{pos:[38,2,10],state:0},
{pos:[39,2,10],state:0},
{pos:[40,2,10],state:0},
{pos:[41,2,10],state:0},
{pos:[45,2,10],state:2},
{pos:[46,2,10],state:2},
{pos:[0,2,11],state:2},
{pos:[1,2,11],state:2},
{pos:[5,2,11],state:0},
{pos:[6,2,11],state:0},
{pos:[7,2,11],state:0},
{pos:[8,2,11],state:0},
{pos:[9,2,11],state:0},
{pos:[10,2,11],state:0},
{pos:[36,2,11],state:0},
{pos:[37,2,11],state:0},
{pos:[38,2,11],state:0},
{pos:[39,2,11],state:0},
{pos:[40,2,11],state:0},
{pos:[41,2,11],state:0},
{pos:[45,2,11],state:2},
{pos:[46,2,11],state:2},
{pos:[0,2,12],state:2},
{pos:[1,2,12],state:2},
{pos:[45,2,12],state:2},
{pos:[46,2,12],state:2},
{pos:[0,2,13],state:2},
{pos:[1,2,13],state:2},
{pos:[2,2,13],state:0},
{pos:[44,2,13],state:0},
{pos:[45,2,13],state:2},
{pos:[46,2,13],state:2},
{pos:[0,2,14],state:2},
{pos:[1,2,14],state:2},
{pos:[45,2,14],state:2},
{pos:[46,2,14],state:2},
{pos:[0,2,15],state:2},
{pos:[1,2,15],state:2},
{pos:[45,2,15],state:2},
{pos:[46,2,15],state:2},
{pos:[0,2,16],state:2},
{pos:[1,2,16],state:2},
{pos:[45,2,16],state:2},
{pos:[46,2,16],state:2},
{pos:[0,2,17],state:2},
{pos:[1,2,17],state:2},
{pos:[5,2,17],state:0},
{pos:[6,2,17],state:0},
{pos:[7,2,17],state:0},
{pos:[8,2,17],state:0},
{pos:[9,2,17],state:0},
{pos:[10,2,17],state:0},
{pos:[36,2,17],state:0},
{pos:[37,2,17],state:0},
{pos:[38,2,17],state:0},
{pos:[39,2,17],state:0},
{pos:[40,2,17],state:0},
{pos:[41,2,17],state:0},
{pos:[45,2,17],state:2},
{pos:[46,2,17],state:2},
{pos:[0,2,18],state:2},
{pos:[1,2,18],state:2},
{pos:[5,2,18],state:0},
{pos:[6,2,18],state:0},
{pos:[7,2,18],state:0},
{pos:[8,2,18],state:0},
{pos:[9,2,18],state:0},
{pos:[10,2,18],state:0},
{pos:[36,2,18],state:0},
{pos:[37,2,18],state:0},
{pos:[38,2,18],state:0},
{pos:[39,2,18],state:0},
{pos:[40,2,18],state:0},
{pos:[41,2,18],state:0},
{pos:[45,2,18],state:2},
{pos:[46,2,18],state:2},
{pos:[0,2,19],state:2},
{pos:[1,2,19],state:2},
{pos:[5,2,19],state:0},
{pos:[6,2,19],state:0},
{pos:[7,2,19],state:0},
{pos:[8,2,19],state:0},
{pos:[9,2,19],state:0},
{pos:[10,2,19],state:0},
{pos:[36,2,19],state:0},
{pos:[37,2,19],state:0},
{pos:[38,2,19],state:0},
{pos:[39,2,19],state:0},
{pos:[40,2,19],state:0},
{pos:[41,2,19],state:0},
{pos:[45,2,19],state:2},
{pos:[46,2,19],state:2},
{pos:[0,2,20],state:2},
{pos:[1,2,20],state:2},
{pos:[45,2,20],state:2},
{pos:[46,2,20],state:2},
{pos:[0,2,21],state:2},
{pos:[1,2,21],state:2},
{pos:[2,2,21],state:0},
{pos:[44,2,21],state:0},
{pos:[45,2,21],state:2},
{pos:[46,2,21],state:2},
{pos:[0,2,22],state:2},
{pos:[1,2,22],state:2},
{pos:[2,2,22],state:2},
{pos:[3,2,22],state:2},
{pos:[4,2,22],state:2},
{pos:[5,2,22],state:2},
{pos:[6,2,22],state:2},
{pos:[7,2,22],state:2},
{pos:[8,2,22],state:2},
{pos:[9,2,22],state:2},
{pos:[10,2,22],state:2},
{pos:[11,2,22],state:2},
{pos:[12,2,22],state:2},
{pos:[13,2,22],state:2},
{pos:[14,2,22],state:2},
{pos:[15,2,22],state:2},
{pos:[16,2,22],state:2},
{pos:[17,2,22],state:2},
{pos:[18,2,22],state:2},
{pos:[19,2,22],state:2},
{pos:[20,2,22],state:2},
{pos:[21,2,22],state:2},
{pos:[22,2,22],state:2},
{pos:[23,2,22],state:2},
{pos:[24,2,22],state:2},
{pos:[25,2,22],state:2},
{pos:[26,2,22],state:2},
{pos:[27,2,22],state:2},
{pos:[28,2,22],state:2},
{pos:[34,2,22],state:2},
{pos:[35,2,22],state:2},
{pos:[36,2,22],state:2},
{pos:[37,2,22],state:2},
{pos:[38,2,22],state:2},
{pos:[39,2,22],state:2},
{pos:[40,2,22],state:2},
{pos:[41,2,22],state:2},
{pos:[42,2,22],state:2},
{pos:[43,2,22],state:2},
{pos:[44,2,22],state:2},
{pos:[45,2,22],state:2},
{pos:[46,2,22],state:2},
{pos:[0,2,23],state:2},
{pos:[1,2,23],state:2},
{pos:[45,2,23],state:2},
{pos:[46,2,23],state:2},
{pos:[0,2,24],state:2},
{pos:[1,2,24],state:2},
{pos:[45,2,24],state:2},
{pos:[46,2,24],state:2},
{pos:[0,2,25],state:2},
{pos:[1,2,25],state:2},
{pos:[45,2,25],state:2},
{pos:[46,2,25],state:2},
{pos:[0,2,26],state:2},
{pos:[1,2,26],state:2},
{pos:[5,2,26],state:0},
{pos:[6,2,26],state:0},
{pos:[7,2,26],state:0},
{pos:[8,2,26],state:0},
{pos:[9,2,26],state:0},
{pos:[10,2,26],state:0},
{pos:[36,2,26],state:0},
{pos:[37,2,26],state:0},
{pos:[38,2,26],state:0},
{pos:[39,2,26],state:0},
{pos:[40,2,26],state:0},
{pos:[41,2,26],state:0},
{pos:[45,2,26],state:2},
{pos:[46,2,26],state:2},
{pos:[0,2,27],state:2},
{pos:[1,2,27],state:2},
{pos:[5,2,27],state:0},
{pos:[6,2,27],state:0},
{pos:[7,2,27],state:0},
{pos:[8,2,27],state:0},
{pos:[9,2,27],state:0},
{pos:[10,2,27],state:0},
{pos:[36,2,27],state:0},
{pos:[37,2,27],state:0},
{pos:[38,2,27],state:0},
{pos:[39,2,27],state:0},
{pos:[40,2,27],state:0},
{pos:[41,2,27],state:0},
{pos:[45,2,27],state:2},
{pos:[46,2,27],state:2},
{pos:[0,2,28],state:2},
{pos:[1,2,28],state:2},
{pos:[5,2,28],state:0},
{pos:[6,2,28],state:0},
{pos:[7,2,28],state:0},
{pos:[8,2,28],state:0},
{pos:[9,2,28],state:0},
{pos:[10,2,28],state:0},
{pos:[36,2,28],state:0},
{pos:[37,2,28],state:0},
{pos:[38,2,28],state:0},
{pos:[39,2,28],state:0},
{pos:[40,2,28],state:0},
{pos:[41,2,28],state:0},
{pos:[45,2,28],state:2},
{pos:[46,2,28],state:2},
{pos:[0,2,29],state:2},
{pos:[1,2,29],state:2},
{pos:[2,2,29],state:0},
{pos:[44,2,29],state:0},
{pos:[45,2,29],state:2},
{pos:[46,2,29],state:2},
{pos:[0,2,30],state:2},
{pos:[1,2,30],state:2},
{pos:[45,2,30],state:2},
{pos:[46,2,30],state:2},
{pos:[0,2,31],state:2},
{pos:[1,2,31],state:2},
{pos:[45,2,31],state:2},
{pos:[46,2,31],state:2},
{pos:[0,2,32],state:2},
{pos:[1,2,32],state:2},
{pos:[45,2,32],state:2},
{pos:[46,2,32],state:2},
{pos:[0,2,33],state:2},
{pos:[1,2,33],state:2},
{pos:[45,2,33],state:2},
{pos:[46,2,33],state:2},
{pos:[0,2,34],state:2},
{pos:[1,2,34],state:2},
{pos:[5,2,34],state:0},
{pos:[6,2,34],state:0},
{pos:[7,2,34],state:0},
{pos:[8,2,34],state:0},
{pos:[9,2,34],state:0},
{pos:[10,2,34],state:0},
{pos:[36,2,34],state:0},
{pos:[37,2,34],state:0},
{pos:[38,2,34],state:0},
{pos:[39,2,34],state:0},
{pos:[40,2,34],state:0},
{pos:[41,2,34],state:0},
{pos:[45,2,34],state:2},
{pos:[46,2,34],state:2},
{pos:[0,2,35],state:2},
{pos:[1,2,35],state:2},
{pos:[5,2,35],state:0},
{pos:[6,2,35],state:0},
{pos:[7,2,35],state:0},
{pos:[8,2,35],state:0},
{pos:[9,2,35],state:0},
{pos:[10,2,35],state:0},
{pos:[36,2,35],state:0},
{pos:[37,2,35],state:0},
{pos:[38,2,35],state:0},
{pos:[39,2,35],state:0},
{pos:[40,2,35],state:0},
{pos:[41,2,35],state:0},
{pos:[45,2,35],state:2},
{pos:[46,2,35],state:2},
{pos:[0,2,36],state:2},
{pos:[1,2,36],state:2},
{pos:[5,2,36],state:0},
{pos:[6,2,36],state:0},
{pos:[7,2,36],state:0},
{pos:[8,2,36],state:0},
{pos:[9,2,36],state:0},
{pos:[10,2,36],state:0},
{pos:[36,2,36],state:0},
{pos:[37,2,36],state:0},
{pos:[38,2,36],state:0},
{pos:[39,2,36],state:0},
{pos:[40,2,36],state:0},
{pos:[41,2,36],state:0},
{pos:[45,2,36],state:2},
{pos:[46,2,36],state:2},
{pos:[0,2,37],state:2},
{pos:[1,2,37],state:2},
{pos:[2,2,37],state:0},
{pos:[44,2,37],state:0},
{pos:[45,2,37],state:2},
{pos:[46,2,37],state:2},
{pos:[0,2,38],state:2},
{pos:[1,2,38],state:2},
{pos:[45,2,38],state:2},
{pos:[46,2,38],state:2},
{pos:[0,2,39],state:2},
{pos:[1,2,39],state:2},
{pos:[45,2,39],state:2},
{pos:[46,2,39],state:2},
{pos:[0,2,40],state:2},
{pos:[1,2,40],state:2},
{pos:[45,2,40],state:2},
{pos:[46,2,40],state:2},
{pos:[0,2,41],state:2},
{pos:[1,2,41],state:2},
{pos:[4,2,41],state:0},
{pos:[11,2,41],state:0},
{pos:[18,2,41],state:0},
{pos:[25,2,41],state:0},
{pos:[32,2,41],state:0},
{pos:[39,2,41],state:0},
{pos:[45,2,41],state:2},
{pos:[46,2,41],state:2},
{pos:[0,2,42],state:2},
{pos:[1,2,42],state:2},
{pos:[2,2,42],state:2},
{pos:[3,2,42],state:2},
{pos:[4,2,42],state:2},
{pos:[5,2,42],state:2},
{pos:[6,2,42],state:2},
{pos:[7,2,42],state:2},
{pos:[8,2,42],state:2},
{pos:[9,2,42],state:2},
{pos:[10,2,42],state:2},
{pos:[11,2,42],state:2},
{pos:[12,2,42],state:2},
{pos:[13,2,42],state:2},
{pos:[14,2,42],state:2},
{pos:[15,2,42],state:2},
{pos:[16,2,42],state:2},
{pos:[17,2,42],state:2},
{pos:[18,2,42],state:2},
{pos:[19,2,42],state:2},
{pos:[20,2,42],state:2},
{pos:[26,2,42],state:2},
{pos:[27,2,42],state:2},
{pos:[28,2,42],state:2},
{pos:[29,2,42],state:2},
{pos:[30,2,42],state:2},
{pos:[31,2,42],state:2},
{pos:[32,2,42],state:2},
{pos:[33,2,42],state:2},
{pos:[34,2,42],state:2},
{pos:[35,2,42],state:2},
{pos:[36,2,42],state:2},
{pos:[37,2,42],state:2},
{pos:[38,2,42],state:2},
{pos:[39,2,42],state:2},
{pos:[40,2,42],state:2},
{pos:[41,2,42],state:2},
{pos:[42,2,42],state:2},
{pos:[43,2,42],state:2},
{pos:[44,2,42],state:2},
{pos:[45,2,42],state:2},
{pos:[46,2,42],state:2},
{pos:[0,2,43],state:2},
{pos:[1,2,43],state:2},
{pos:[2,2,43],state:2},
{pos:[3,2,43],state:2},
{pos:[4,2,43],state:2},
{pos:[5,2,43],state:2},
{pos:[6,2,43],state:2},
{pos:[7,2,43],state:2},
{pos:[8,2,43],state:2},
{pos:[9,2,43],state:2},
{pos:[10,2,43],state:2},
{pos:[11,2,43],state:2},
{pos:[12,2,43],state:2},
{pos:[13,2,43],state:2},
{pos:[14,2,43],state:2},
{pos:[15,2,43],state:2},
{pos:[16,2,43],state:2},
{pos:[17,2,43],state:2},
{pos:[18,2,43],state:2},
{pos:[19,2,43],state:2},
{pos:[20,2,43],state:2},
{pos:[26,2,43],state:2},
{pos:[27,2,43],state:2},
{pos:[28,2,43],state:2},
{pos:[29,2,43],state:2},
{pos:[30,2,43],state:2},
{pos:[31,2,43],state:2},
{pos:[32,2,43],state:2},
{pos:[33,2,43],state:2},
{pos:[34,2,43],state:2},
{pos:[35,2,43],state:2},
{pos:[36,2,43],state:2},
{pos:[37,2,43],state:2},
{pos:[38,2,43],state:2},
{pos:[39,2,43],state:2},
{pos:[40,2,43],state:2},
{pos:[41,2,43],state:2},
{pos:[42,2,43],state:2},
{pos:[43,2,43],state:2},
{pos:[44,2,43],state:2},
{pos:[45,2,43],state:2},
{pos:[46,2,43],state:2},
{pos:[0,3,0],state:2},
{pos:[1,3,0],state:2},
{pos:[2,3,0],state:2},
{pos:[3,3,0],state:2},
{pos:[4,3,0],state:2},
{pos:[5,3,0],state:2},
{pos:[6,3,0],state:2},
{pos:[7,3,0],state:2},
{pos:[8,3,0],state:2},
{pos:[9,3,0],state:2},
{pos:[10,3,0],state:2},
{pos:[11,3,0],state:2},
{pos:[12,3,0],state:2},
{pos:[13,3,0],state:2},
{pos:[14,3,0],state:2},
{pos:[15,3,0],state:2},
{pos:[16,3,0],state:2},
{pos:[17,3,0],state:2},
{pos:[18,3,0],state:2},
{pos:[19,3,0],state:2},
{pos:[20,3,0],state:2},
{pos:[21,3,0],state:2},
{pos:[22,3,0],state:2},
{pos:[23,3,0],state:2},
{pos:[24,3,0],state:2},
{pos:[25,3,0],state:2},
{pos:[26,3,0],state:2},
{pos:[27,3,0],state:2},
{pos:[28,3,0],state:2},
{pos:[34,3,0],state:2},
{pos:[35,3,0],state:2},
{pos:[36,3,0],state:2},
{pos:[37,3,0],state:2},
{pos:[38,3,0],state:2},
{pos:[39,3,0],state:2},
{pos:[40,3,0],state:2},
{pos:[41,3,0],state:2},
{pos:[42,3,0],state:2},
{pos:[43,3,0],state:2},
{pos:[44,3,0],state:2},
{pos:[45,3,0],state:2},
{pos:[46,3,0],state:2},
{pos:[0,3,1],state:2},
{pos:[1,3,1],state:2},
{pos:[2,3,1],state:2},
{pos:[3,3,1],state:2},
{pos:[4,3,1],state:2},
{pos:[5,3,1],state:2},
{pos:[6,3,1],state:2},
{pos:[7,3,1],state:2},
{pos:[8,3,1],state:2},
{pos:[9,3,1],state:2},
{pos:[10,3,1],state:2},
{pos:[11,3,1],state:2},
{pos:[12,3,1],state:2},
{pos:[13,3,1],state:2},
{pos:[14,3,1],state:2},
{pos:[15,3,1],state:2},
{pos:[16,3,1],state:2},
{pos:[17,3,1],state:2},
{pos:[18,3,1],state:2},
{pos:[19,3,1],state:2},
{pos:[20,3,1],state:2},
{pos:[21,3,1],state:2},
{pos:[22,3,1],state:2},
{pos:[23,3,1],state:2},
{pos:[24,3,1],state:2},
{pos:[25,3,1],state:2},
{pos:[26,3,1],state:2},
{pos:[27,3,1],state:2},
{pos:[28,3,1],state:2},
{pos:[34,3,1],state:2},
{pos:[35,3,1],state:2},
{pos:[36,3,1],state:2},
{pos:[37,3,1],state:2},
{pos:[38,3,1],state:2},
{pos:[39,3,1],state:2},
{pos:[40,3,1],state:2},
{pos:[41,3,1],state:2},
{pos:[42,3,1],state:2},
{pos:[43,3,1],state:2},
{pos:[44,3,1],state:2},
{pos:[45,3,1],state:2},
{pos:[46,3,1],state:2},
{pos:[0,3,2],state:2},
{pos:[1,3,2],state:2},
{pos:[4,3,2],state:0},
{pos:[11,3,2],state:0},
{pos:[18,3,2],state:0},
{pos:[25,3,2],state:0},
{pos:[32,3,2],state:0},
{pos:[39,3,2],state:0},
{pos:[45,3,2],state:2},
{pos:[46,3,2],state:2},
{pos:[0,3,3],state:2},
{pos:[1,3,3],state:2},
{pos:[45,3,3],state:2},
{pos:[46,3,3],state:2},
{pos:[0,3,4],state:2},
{pos:[1,3,4],state:2},
{pos:[45,3,4],state:2},
{pos:[46,3,4],state:2},
{pos:[0,3,5],state:2},
{pos:[1,3,5],state:2},
{pos:[2,3,5],state:0},
{pos:[44,3,5],state:0},
{pos:[45,3,5],state:2},
{pos:[46,3,5],state:2},
{pos:[0,3,6],state:2},
{pos:[1,3,6],state:2},
{pos:[45,3,6],state:2},
{pos:[46,3,6],state:2},
{pos:[0,3,7],state:2},
{pos:[1,3,7],state:2},
{pos:[45,3,7],state:2},
{pos:[46,3,7],state:2},
{pos:[0,3,8],state:2},
{pos:[1,3,8],state:2},
{pos:[45,3,8],state:2},
{pos:[46,3,8],state:2},
{pos:[0,3,9],state:2},
{pos:[1,3,9],state:2},
{pos:[45,3,9],state:2},
{pos:[46,3,9],state:2},
{pos:[0,3,10],state:2},
{pos:[1,3,10],state:2},
{pos:[45,3,10],state:2},
{pos:[46,3,10],state:2},
{pos:[0,3,11],state:2},
{pos:[1,3,11],state:2},
{pos:[45,3,11],state:2},
{pos:[46,3,11],state:2},
{pos:[0,3,12],state:2},
{pos:[1,3,12],state:2},
{pos:[45,3,12],state:2},
{pos:[46,3,12],state:2},
{pos:[0,3,13],state:2},
{pos:[1,3,13],state:2},
{pos:[2,3,13],state:0},
{pos:[44,3,13],state:0},
{pos:[45,3,13],state:2},
{pos:[46,3,13],state:2},
{pos:[0,3,14],state:2},
{pos:[1,3,14],state:2},
{pos:[45,3,14],state:2},
{pos:[46,3,14],state:2},
{pos:[0,3,15],state:2},
{pos:[1,3,15],state:2},
{pos:[45,3,15],state:2},
{pos:[46,3,15],state:2},
{pos:[0,3,16],state:2},
{pos:[1,3,16],state:2},
{pos:[45,3,16],state:2},
{pos:[46,3,16],state:2},
{pos:[0,3,17],state:2},
{pos:[1,3,17],state:2},
{pos:[45,3,17],state:2},
{pos:[46,3,17],state:2},
{pos:[0,3,18],state:2},
{pos:[1,3,18],state:2},
{pos:[45,3,18],state:2},
{pos:[46,3,18],state:2},
{pos:[0,3,19],state:2},
{pos:[1,3,19],state:2},
{pos:[45,3,19],state:2},
{pos:[46,3,19],state:2},
{pos:[0,3,20],state:2},
{pos:[1,3,20],state:2},
{pos:[45,3,20],state:2},
{pos:[46,3,20],state:2},
{pos:[0,3,21],state:2},
{pos:[1,3,21],state:2},
{pos:[2,3,21],state:0},
{pos:[44,3,21],state:0},
{pos:[45,3,21],state:2},
{pos:[46,3,21],state:2},
{pos:[0,3,22],state:2},
{pos:[1,3,22],state:2},
{pos:[2,3,22],state:2},
{pos:[3,3,22],state:2},
{pos:[4,3,22],state:2},
{pos:[5,3,22],state:2},
{pos:[6,3,22],state:2},
{pos:[7,3,22],state:2},
{pos:[8,3,22],state:2},
{pos:[9,3,22],state:2},
{pos:[10,3,22],state:2},
{pos:[11,3,22],state:2},
{pos:[12,3,22],state:2},
{pos:[13,3,22],state:2},
{pos:[14,3,22],state:2},
{pos:[15,3,22],state:2},
{pos:[16,3,22],state:2},
{pos:[17,3,22],state:2},
{pos:[18,3,22],state:2},
{pos:[19,3,22],state:2},
{pos:[20,3,22],state:2},
{pos:[21,3,22],state:2},
{pos:[22,3,22],state:2},
{pos:[23,3,22],state:2},
{pos:[24,3,22],state:2},
{pos:[25,3,22],state:2},
{pos:[26,3,22],state:2},
{pos:[27,3,22],state:2},
{pos:[28,3,22],state:2},
{pos:[34,3,22],state:2},
{pos:[35,3,22],state:2},
{pos:[36,3,22],state:2},
{pos:[37,3,22],state:2},
{pos:[38,3,22],state:2},
{pos:[39,3,22],state:2},
{pos:[40,3,22],state:2},
{pos:[41,3,22],state:2},
{pos:[42,3,22],state:2},
{pos:[43,3,22],state:2},
{pos:[44,3,22],state:2},
{pos:[45,3,22],state:2},
{pos:[46,3,22],state:2},
{pos:[0,3,23],state:2},
{pos:[1,3,23],state:2},
{pos:[45,3,23],state:2},
{pos:[46,3,23],state:2},
{pos:[0,3,24],state:2},
{pos:[1,3,24],state:2},
{pos:[45,3,24],state:2},
{pos:[46,3,24],state:2},
{pos:[0,3,25],state:2},
{pos:[1,3,25],state:2},
{pos:[45,3,25],state:2},
{pos:[46,3,25],state:2},
{pos:[0,3,26],state:2},
{pos:[1,3,26],state:2},
{pos:[45,3,26],state:2},
{pos:[46,3,26],state:2},
{pos:[0,3,27],state:2},
{pos:[1,3,27],state:2},
{pos:[45,3,27],state:2},
{pos:[46,3,27],state:2},
{pos:[0,3,28],state:2},
{pos:[1,3,28],state:2},
{pos:[45,3,28],state:2},
{pos:[46,3,28],state:2},
{pos:[0,3,29],state:2},
{pos:[1,3,29],state:2},
{pos:[2,3,29],state:0},
{pos:[44,3,29],state:0},
{pos:[45,3,29],state:2},
{pos:[46,3,29],state:2},
{pos:[0,3,30],state:2},
{pos:[1,3,30],state:2},
{pos:[45,3,30],state:2},
{pos:[46,3,30],state:2},
{pos:[0,3,31],state:2},
{pos:[1,3,31],state:2},
{pos:[45,3,31],state:2},
{pos:[46,3,31],state:2},
{pos:[0,3,32],state:2},
{pos:[1,3,32],state:2},
{pos:[45,3,32],state:2},
{pos:[46,3,32],state:2},
{pos:[0,3,33],state:2},
{pos:[1,3,33],state:2},
{pos:[45,3,33],state:2},
{pos:[46,3,33],state:2},
{pos:[0,3,34],state:2},
{pos:[1,3,34],state:2},
{pos:[45,3,34],state:2},
{pos:[46,3,34],state:2},
{pos:[0,3,35],state:2},
{pos:[1,3,35],state:2},
{pos:[45,3,35],state:2},
{pos:[46,3,35],state:2},
{pos:[0,3,36],state:2},
{pos:[1,3,36],state:2},
{pos:[45,3,36],state:2},
{pos:[46,3,36],state:2},
{pos:[0,3,37],state:2},
{pos:[1,3,37],state:2},
{pos:[2,3,37],state:0},
{pos:[44,3,37],state:0},
{pos:[45,3,37],state:2},
{pos:[46,3,37],state:2},
{pos:[0,3,38],state:2},
{pos:[1,3,38],state:2},
{pos:[45,3,38],state:2},
{pos:[46,3,38],state:2},
{pos:[0,3,39],state:2},
{pos:[1,3,39],state:2},
{pos:[45,3,39],state:2},
{pos:[46,3,39],state:2},
{pos:[0,3,40],state:2},
{pos:[1,3,40],state:2},
{pos:[45,3,40],state:2},
{pos:[46,3,40],state:2},
{pos:[0,3,41],state:2},
{pos:[1,3,41],state:2},
{pos:[4,3,41],state:0},
{pos:[11,3,41],state:0},
{pos:[18,3,41],state:0},
{pos:[25,3,41],state:0},
{pos:[32,3,41],state:0},
{pos:[39,3,41],state:0},
{pos:[45,3,41],state:2},
{pos:[46,3,41],state:2},
{pos:[0,3,42],state:2},
{pos:[1,3,42],state:2},
{pos:[2,3,42],state:2},
{pos:[3,3,42],state:2},
{pos:[4,3,42],state:2},
{pos:[5,3,42],state:2},
{pos:[6,3,42],state:2},
{pos:[7,3,42],state:2},
{pos:[8,3,42],state:2},
{pos:[9,3,42],state:2},
{pos:[10,3,42],state:2},
{pos:[11,3,42],state:2},
{pos:[12,3,42],state:2},
{pos:[13,3,42],state:2},
{pos:[14,3,42],state:2},
{pos:[15,3,42],state:2},
{pos:[16,3,42],state:2},
{pos:[17,3,42],state:2},
{pos:[18,3,42],state:2},
{pos:[19,3,42],state:2},
{pos:[20,3,42],state:2},
{pos:[26,3,42],state:2},
{pos:[27,3,42],state:2},
{pos:[28,3,42],state:2},
{pos:[29,3,42],state:2},
{pos:[30,3,42],state:2},
{pos:[31,3,42],state:2},
{pos:[32,3,42],state:2},
{pos:[33,3,42],state:2},
{pos:[34,3,42],state:2},
{pos:[35,3,42],state:2},
{pos:[36,3,42],state:2},
{pos:[37,3,42],state:2},
{pos:[38,3,42],state:2},
{pos:[39,3,42],state:2},
{pos:[40,3,42],state:2},
{pos:[41,3,42],state:2},
{pos:[42,3,42],state:2},
{pos:[43,3,42],state:2},
{pos:[44,3,42],state:2},
{pos:[45,3,42],state:2},
{pos:[46,3,42],state:2},
{pos:[0,3,43],state:2},
{pos:[1,3,43],state:2},
{pos:[2,3,43],state:2},
{pos:[3,3,43],state:2},
{pos:[4,3,43],state:2},
{pos:[5,3,43],state:2},
{pos:[6,3,43],state:2},
{pos:[7,3,43],state:2},
{pos:[8,3,43],state:2},
{pos:[9,3,43],state:2},
{pos:[10,3,43],state:2},
{pos:[11,3,43],state:2},
{pos:[12,3,43],state:2},
{pos:[13,3,43],state:2},
{pos:[14,3,43],state:2},
{pos:[15,3,43],state:2},
{pos:[16,3,43],state:2},
{pos:[17,3,43],state:2},
{pos:[18,3,43],state:2},
{pos:[19,3,43],state:2},
{pos:[20,3,43],state:2},
{pos:[26,3,43],state:2},
{pos:[27,3,43],state:2},
{pos:[28,3,43],state:2},
{pos:[29,3,43],state:2},
{pos:[30,3,43],state:2},
{pos:[31,3,43],state:2},
{pos:[32,3,43],state:2},
{pos:[33,3,43],state:2},
{pos:[34,3,43],state:2},
{pos:[35,3,43],state:2},
{pos:[36,3,43],state:2},
{pos:[37,3,43],state:2},
{pos:[38,3,43],state:2},
{pos:[39,3,43],state:2},
{pos:[40,3,43],state:2},
{pos:[41,3,43],state:2},
{pos:[42,3,43],state:2},
{pos:[43,3,43],state:2},
{pos:[44,3,43],state:2},
{pos:[45,3,43],state:2},
{pos:[46,3,43],state:2},
{pos:[0,4,0],state:2},
{pos:[1,4,0],state:2},
{pos:[2,4,0],state:2},
{pos:[3,4,0],state:2},
{pos:[4,4,0],state:2},
{pos:[5,4,0],state:2},
{pos:[6,4,0],state:2},
{pos:[7,4,0],state:2},
{pos:[8,4,0],state:2},
{pos:[9,4,0],state:2},
{pos:[10,4,0],state:2},
{pos:[11,4,0],state:2},
{pos:[12,4,0],state:2},
{pos:[13,4,0],state:2},
{pos:[14,4,0],state:2},
{pos:[15,4,0],state:2},
{pos:[16,4,0],state:2},
{pos:[17,4,0],state:2},
{pos:[18,4,0],state:2},
{pos:[19,4,0],state:2},
{pos:[20,4,0],state:2},
{pos:[21,4,0],state:2},
{pos:[22,4,0],state:2},
{pos:[23,4,0],state:2},
{pos:[24,4,0],state:2},
{pos:[25,4,0],state:2},
{pos:[26,4,0],state:2},
{pos:[27,4,0],state:2},
{pos:[28,4,0],state:2},
{pos:[34,4,0],state:2},
{pos:[35,4,0],state:2},
{pos:[36,4,0],state:2},
{pos:[37,4,0],state:2},
{pos:[38,4,0],state:2},
{pos:[39,4,0],state:2},
{pos:[40,4,0],state:2},
{pos:[41,4,0],state:2},
{pos:[42,4,0],state:2},
{pos:[43,4,0],state:2},
{pos:[44,4,0],state:2},
{pos:[45,4,0],state:2},
{pos:[46,4,0],state:2},
{pos:[0,4,1],state:2},
{pos:[1,4,1],state:2},
{pos:[2,4,1],state:2},
{pos:[3,4,1],state:2},
{pos:[4,4,1],state:2},
{pos:[5,4,1],state:2},
{pos:[6,4,1],state:2},
{pos:[7,4,1],state:2},
{pos:[8,4,1],state:2},
{pos:[9,4,1],state:2},
{pos:[10,4,1],state:2},
{pos:[11,4,1],state:2},
{pos:[12,4,1],state:2},
{pos:[13,4,1],state:2},
{pos:[14,4,1],state:2},
{pos:[15,4,1],state:2},
{pos:[16,4,1],state:2},
{pos:[17,4,1],state:2},
{pos:[18,4,1],state:2},
{pos:[19,4,1],state:2},
{pos:[20,4,1],state:2},
{pos:[21,4,1],state:2},
{pos:[22,4,1],state:2},
{pos:[23,4,1],state:2},
{pos:[24,4,1],state:2},
{pos:[25,4,1],state:2},
{pos:[26,4,1],state:2},
{pos:[27,4,1],state:2},
{pos:[28,4,1],state:2},
{pos:[34,4,1],state:2},
{pos:[35,4,1],state:2},
{pos:[36,4,1],state:2},
{pos:[37,4,1],state:2},
{pos:[38,4,1],state:2},
{pos:[39,4,1],state:2},
{pos:[40,4,1],state:2},
{pos:[41,4,1],state:2},
{pos:[42,4,1],state:2},
{pos:[43,4,1],state:2},
{pos:[44,4,1],state:2},
{pos:[45,4,1],state:2},
{pos:[46,4,1],state:2},
{pos:[0,4,2],state:2},
{pos:[1,4,2],state:2},
{pos:[4,4,2],state:0},
{pos:[11,4,2],state:0},
{pos:[18,4,2],state:0},
{pos:[25,4,2],state:0},
{pos:[32,4,2],state:0},
{pos:[39,4,2],state:0},
{pos:[45,4,2],state:2},
{pos:[46,4,2],state:2},
{pos:[0,4,3],state:2},
{pos:[1,4,3],state:2},
{pos:[45,4,3],state:2},
{pos:[46,4,3],state:2},
{pos:[0,4,4],state:2},
{pos:[1,4,4],state:2},
{pos:[45,4,4],state:2},
{pos:[46,4,4],state:2},
{pos:[0,4,5],state:2},
{pos:[1,4,5],state:2},
{pos:[2,4,5],state:0},
{pos:[44,4,5],state:0},
{pos:[45,4,5],state:2},
{pos:[46,4,5],state:2},
{pos:[0,4,6],state:2},
{pos:[1,4,6],state:2},
{pos:[45,4,6],state:2},
{pos:[46,4,6],state:2},
{pos:[0,4,7],state:2},
{pos:[1,4,7],state:2},
{pos:[45,4,7],state:2},
{pos:[46,4,7],state:2},
{pos:[0,4,8],state:2},
{pos:[1,4,8],state:2},
{pos:[45,4,8],state:2},
{pos:[46,4,8],state:2},
{pos:[0,4,9],state:2},
{pos:[1,4,9],state:2},
{pos:[45,4,9],state:2},
{pos:[46,4,9],state:2},
{pos:[0,4,10],state:2},
{pos:[1,4,10],state:2},
{pos:[45,4,10],state:2},
{pos:[46,4,10],state:2},
{pos:[0,4,11],state:2},
{pos:[1,4,11],state:2},
{pos:[45,4,11],state:2},
{pos:[46,4,11],state:2},
{pos:[0,4,12],state:2},
{pos:[1,4,12],state:2},
{pos:[45,4,12],state:2},
{pos:[46,4,12],state:2},
{pos:[0,4,13],state:2},
{pos:[1,4,13],state:2},
{pos:[2,4,13],state:0},
{pos:[44,4,13],state:0},
{pos:[45,4,13],state:2},
{pos:[46,4,13],state:2},
{pos:[0,4,14],state:2},
{pos:[1,4,14],state:2},
{pos:[45,4,14],state:2},
{pos:[46,4,14],state:2},
{pos:[0,4,15],state:2},
{pos:[1,4,15],state:2},
{pos:[45,4,15],state:2},
{pos:[46,4,15],state:2},
{pos:[0,4,16],state:2},
{pos:[1,4,16],state:2},
{pos:[45,4,16],state:2},
{pos:[46,4,16],state:2},
{pos:[0,4,17],state:2},
{pos:[1,4,17],state:2},
{pos:[45,4,17],state:2},
{pos:[46,4,17],state:2},
{pos:[0,4,18],state:2},
{pos:[1,4,18],state:2},
{pos:[45,4,18],state:2},
{pos:[46,4,18],state:2},
{pos:[0,4,19],state:2},
{pos:[1,4,19],state:2},
{pos:[45,4,19],state:2},
{pos:[46,4,19],state:2},
{pos:[0,4,20],state:2},
{pos:[1,4,20],state:2},
{pos:[45,4,20],state:2},
{pos:[46,4,20],state:2},
{pos:[0,4,21],state:2},
{pos:[1,4,21],state:2},
{pos:[2,4,21],state:0},
{pos:[44,4,21],state:0},
{pos:[45,4,21],state:2},
{pos:[46,4,21],state:2},
{pos:[0,4,22],state:2},
{pos:[1,4,22],state:2},
{pos:[2,4,22],state:2},
{pos:[3,4,22],state:2},
{pos:[4,4,22],state:2},
{pos:[5,4,22],state:2},
{pos:[6,4,22],state:2},
{pos:[7,4,22],state:2},
{pos:[8,4,22],state:2},
{pos:[9,4,22],state:2},
{pos:[10,4,22],state:2},
{pos:[11,4,22],state:2},
{pos:[12,4,22],state:2},
{pos:[13,4,22],state:2},
{pos:[14,4,22],state:2},
{pos:[15,4,22],state:2},
{pos:[16,4,22],state:2},
{pos:[17,4,22],state:2},
{pos:[18,4,22],state:2},
{pos:[19,4,22],state:2},
{pos:[20,4,22],state:2},
{pos:[21,4,22],state:2},
{pos:[22,4,22],state:2},
{pos:[23,4,22],state:2},
{pos:[24,4,22],state:2},
{pos:[25,4,22],state:2},
{pos:[26,4,22],state:2},
{pos:[27,4,22],state:2},
{pos:[28,4,22],state:2},
{pos:[34,4,22],state:2},
{pos:[35,4,22],state:2},
{pos:[36,4,22],state:2},
{pos:[37,4,22],state:2},
{pos:[38,4,22],state:2},
{pos:[39,4,22],state:2},
{pos:[40,4,22],state:2},
{pos:[41,4,22],state:2},
{pos:[42,4,22],state:2},
{pos:[43,4,22],state:2},
{pos:[44,4,22],state:2},
{pos:[45,4,22],state:2},
{pos:[46,4,22],state:2},
{pos:[0,4,23],state:2},
{pos:[1,4,23],state:2},
{pos:[45,4,23],state:2},
{pos:[46,4,23],state:2},
{pos:[0,4,24],state:2},
{pos:[1,4,24],state:2},
{pos:[45,4,24],state:2},
{pos:[46,4,24],state:2},
{pos:[0,4,25],state:2},
{pos:[1,4,25],state:2},
{pos:[45,4,25],state:2},
{pos:[46,4,25],state:2},
{pos:[0,4,26],state:2},
{pos:[1,4,26],state:2},
{pos:[45,4,26],state:2},
{pos:[46,4,26],state:2},
{pos:[0,4,27],state:2},
{pos:[1,4,27],state:2},
{pos:[45,4,27],state:2},
{pos:[46,4,27],state:2},
{pos:[0,4,28],state:2},
{pos:[1,4,28],state:2},
{pos:[45,4,28],state:2},
{pos:[46,4,28],state:2},
{pos:[0,4,29],state:2},
{pos:[1,4,29],state:2},
{pos:[2,4,29],state:0},
{pos:[44,4,29],state:0},
{pos:[45,4,29],state:2},
{pos:[46,4,29],state:2},
{pos:[0,4,30],state:2},
{pos:[1,4,30],state:2},
{pos:[45,4,30],state:2},
{pos:[46,4,30],state:2},
{pos:[0,4,31],state:2},
{pos:[1,4,31],state:2},
{pos:[45,4,31],state:2},
{pos:[46,4,31],state:2},
{pos:[0,4,32],state:2},
{pos:[1,4,32],state:2},
{pos:[45,4,32],state:2},
{pos:[46,4,32],state:2},
{pos:[0,4,33],state:2},
{pos:[1,4,33],state:2},
{pos:[45,4,33],state:2},
{pos:[46,4,33],state:2},
{pos:[0,4,34],state:2},
{pos:[1,4,34],state:2},
{pos:[45,4,34],state:2},
{pos:[46,4,34],state:2},
{pos:[0,4,35],state:2},
{pos:[1,4,35],state:2},
{pos:[45,4,35],state:2},
{pos:[46,4,35],state:2},
{pos:[0,4,36],state:2},
{pos:[1,4,36],state:2},
{pos:[45,4,36],state:2},
{pos:[46,4,36],state:2},
{pos:[0,4,37],state:2},
{pos:[1,4,37],state:2},
{pos:[2,4,37],state:0},
{pos:[44,4,37],state:0},
{pos:[45,4,37],state:2},
{pos:[46,4,37],state:2},
{pos:[0,4,38],state:2},
{pos:[1,4,38],state:2},
{pos:[45,4,38],state:2},
{pos:[46,4,38],state:2},
{pos:[0,4,39],state:2},
{pos:[1,4,39],state:2},
{pos:[45,4,39],state:2},
{pos:[46,4,39],state:2},
{pos:[0,4,40],state:2},
{pos:[1,4,40],state:2},
{pos:[45,4,40],state:2},
{pos:[46,4,40],state:2},
{pos:[0,4,41],state:2},
{pos:[1,4,41],state:2},
{pos:[4,4,41],state:0},
{pos:[11,4,41],state:0},
{pos:[18,4,41],state:0},
{pos:[25,4,41],state:0},
{pos:[32,4,41],state:0},
{pos:[39,4,41],state:0},
{pos:[45,4,41],state:2},
{pos:[46,4,41],state:2},
{pos:[0,4,42],state:2},
{pos:[1,4,42],state:2},
{pos:[2,4,42],state:2},
{pos:[3,4,42],state:2},
{pos:[4,4,42],state:2},
{pos:[5,4,42],state:2},
{pos:[6,4,42],state:2},
{pos:[7,4,42],state:2},
{pos:[8,4,42],state:2},
{pos:[9,4,42],state:2},
{pos:[10,4,42],state:2},
{pos:[11,4,42],state:2},
{pos:[12,4,42],state:2},
{pos:[13,4,42],state:2},
{pos:[14,4,42],state:2},
{pos:[15,4,42],state:2},
{pos:[16,4,42],state:2},
{pos:[17,4,42],state:2},
{pos:[18,4,42],state:2},
{pos:[19,4,42],state:2},
{pos:[20,4,42],state:2},
{pos:[26,4,42],state:2},
{pos:[27,4,42],state:2},
{pos:[28,4,42],state:2},
{pos:[29,4,42],state:2},
{pos:[30,4,42],state:2},
{pos:[31,4,42],state:2},
{pos:[32,4,42],state:2},
{pos:[33,4,42],state:2},
{pos:[34,4,42],state:2},
{pos:[35,4,42],state:2},
{pos:[36,4,42],state:2},
{pos:[37,4,42],state:2},
{pos:[38,4,42],state:2},
{pos:[39,4,42],state:2},
{pos:[40,4,42],state:2},
{pos:[41,4,42],state:2},
{pos:[42,4,42],state:2},
{pos:[43,4,42],state:2},
{pos:[44,4,42],state:2},
{pos:[45,4,42],state:2},
{pos:[46,4,42],state:2},
{pos:[0,4,43],state:2},
{pos:[1,4,43],state:2},
{pos:[2,4,43],state:2},
{pos:[3,4,43],state:2},
{pos:[4,4,43],state:2},
{pos:[5,4,43],state:2},
{pos:[6,4,43],state:2},
{pos:[7,4,43],state:2},
{pos:[8,4,43],state:2},
{pos:[9,4,43],state:2},
{pos:[10,4,43],state:2},
{pos:[11,4,43],state:2},
{pos:[12,4,43],state:2},
{pos:[13,4,43],state:2},
{pos:[14,4,43],state:2},
{pos:[15,4,43],state:2},
{pos:[16,4,43],state:2},
{pos:[17,4,43],state:2},
{pos:[18,4,43],state:2},
{pos:[19,4,43],state:2},
{pos:[20,4,43],state:2},
{pos:[26,4,43],state:2},
{pos:[27,4,43],state:2},
{pos:[28,4,43],state:2},
{pos:[29,4,43],state:2},
{pos:[30,4,43],state:2},
{pos:[31,4,43],state:2},
{pos:[32,4,43],state:2},
{pos:[33,4,43],state:2},
{pos:[34,4,43],state:2},
{pos:[35,4,43],state:2},
{pos:[36,4,43],state:2},
{pos:[37,4,43],state:2},
{pos:[38,4,43],state:2},
{pos:[39,4,43],state:2},
{pos:[40,4,43],state:2},
{pos:[41,4,43],state:2},
{pos:[42,4,43],state:2},
{pos:[43,4,43],state:2},
{pos:[44,4,43],state:2},
{pos:[45,4,43],state:2},
{pos:[46,4,43],state:2},
{pos:[0,5,0],state:2},
{pos:[1,5,0],state:2},
{pos:[2,5,0],state:2},
{pos:[3,5,0],state:2},
{pos:[4,5,0],state:2},
{pos:[5,5,0],state:2},
{pos:[6,5,0],state:2},
{pos:[7,5,0],state:2},
{pos:[8,5,0],state:2},
{pos:[9,5,0],state:2},
{pos:[10,5,0],state:2},
{pos:[11,5,0],state:2},
{pos:[12,5,0],state:2},
{pos:[13,5,0],state:2},
{pos:[14,5,0],state:2},
{pos:[15,5,0],state:2},
{pos:[16,5,0],state:2},
{pos:[17,5,0],state:2},
{pos:[18,5,0],state:2},
{pos:[19,5,0],state:2},
{pos:[20,5,0],state:2},
{pos:[21,5,0],state:2},
{pos:[22,5,0],state:2},
{pos:[23,5,0],state:2},
{pos:[24,5,0],state:2},
{pos:[25,5,0],state:2},
{pos:[26,5,0],state:2},
{pos:[27,5,0],state:2},
{pos:[28,5,0],state:2},
{pos:[34,5,0],state:2},
{pos:[35,5,0],state:2},
{pos:[36,5,0],state:2},
{pos:[37,5,0],state:2},
{pos:[38,5,0],state:2},
{pos:[39,5,0],state:2},
{pos:[40,5,0],state:2},
{pos:[41,5,0],state:2},
{pos:[42,5,0],state:2},
{pos:[43,5,0],state:2},
{pos:[44,5,0],state:2},
{pos:[45,5,0],state:2},
{pos:[46,5,0],state:2},
{pos:[0,5,1],state:2},
{pos:[1,5,1],state:2},
{pos:[2,5,1],state:2},
{pos:[3,5,1],state:2},
{pos:[4,5,1],state:2},
{pos:[5,5,1],state:2},
{pos:[6,5,1],state:2},
{pos:[7,5,1],state:2},
{pos:[8,5,1],state:2},
{pos:[9,5,1],state:2},
{pos:[10,5,1],state:2},
{pos:[11,5,1],state:2},
{pos:[12,5,1],state:2},
{pos:[13,5,1],state:2},
{pos:[14,5,1],state:2},
{pos:[15,5,1],state:2},
{pos:[16,5,1],state:2},
{pos:[17,5,1],state:2},
{pos:[18,5,1],state:2},
{pos:[19,5,1],state:2},
{pos:[20,5,1],state:2},
{pos:[21,5,1],state:2},
{pos:[22,5,1],state:2},
{pos:[23,5,1],state:2},
{pos:[24,5,1],state:2},
{pos:[25,5,1],state:2},
{pos:[26,5,1],state:2},
{pos:[27,5,1],state:2},
{pos:[28,5,1],state:2},
{pos:[34,5,1],state:2},
{pos:[35,5,1],state:2},
{pos:[36,5,1],state:2},
{pos:[37,5,1],state:2},
{pos:[38,5,1],state:2},
{pos:[39,5,1],state:2},
{pos:[40,5,1],state:2},
{pos:[41,5,1],state:2},
{pos:[42,5,1],state:2},
{pos:[43,5,1],state:2},
{pos:[44,5,1],state:2},
{pos:[45,5,1],state:2},
{pos:[46,5,1],state:2},
{pos:[0,5,2],state:2},
{pos:[1,5,2],state:2},
{pos:[4,5,2],state:0},
{pos:[11,5,2],state:0},
{pos:[18,5,2],state:0},
{pos:[25,5,2],state:0},
{pos:[32,5,2],state:0},
{pos:[39,5,2],state:0},
{pos:[45,5,2],state:2},
{pos:[46,5,2],state:2},
{pos:[0,5,3],state:2},
{pos:[1,5,3],state:2},
{pos:[45,5,3],state:2},
{pos:[46,5,3],state:2},
{pos:[0,5,4],state:2},
{pos:[1,5,4],state:2},
{pos:[45,5,4],state:2},
{pos:[46,5,4],state:2},
{pos:[0,5,5],state:2},
{pos:[1,5,5],state:2},
{pos:[2,5,5],state:0},
{pos:[44,5,5],state:0},
{pos:[45,5,5],state:2},
{pos:[46,5,5],state:2},
{pos:[0,5,6],state:2},
{pos:[1,5,6],state:2},
{pos:[45,5,6],state:2},
{pos:[46,5,6],state:2},
{pos:[0,5,7],state:2},
{pos:[1,5,7],state:2},
{pos:[45,5,7],state:2},
{pos:[46,5,7],state:2},
{pos:[0,5,8],state:2},
{pos:[1,5,8],state:2},
{pos:[45,5,8],state:2},
{pos:[46,5,8],state:2},
{pos:[0,5,9],state:2},
{pos:[1,5,9],state:2},
{pos:[45,5,9],state:2},
{pos:[46,5,9],state:2},
{pos:[0,5,10],state:2},
{pos:[1,5,10],state:2},
{pos:[45,5,10],state:2},
{pos:[46,5,10],state:2},
{pos:[0,5,11],state:2},
{pos:[1,5,11],state:2},
{pos:[45,5,11],state:2},
{pos:[46,5,11],state:2},
{pos:[0,5,12],state:2},
{pos:[1,5,12],state:2},
{pos:[45,5,12],state:2},
{pos:[46,5,12],state:2},
{pos:[0,5,13],state:2},
{pos:[1,5,13],state:2},
{pos:[2,5,13],state:0},
{pos:[44,5,13],state:0},
{pos:[45,5,13],state:2},
{pos:[46,5,13],state:2},
{pos:[0,5,14],state:2},
{pos:[1,5,14],state:2},
{pos:[45,5,14],state:2},
{pos:[46,5,14],state:2},
{pos:[0,5,15],state:2},
{pos:[1,5,15],state:2},
{pos:[45,5,15],state:2},
{pos:[46,5,15],state:2},
{pos:[0,5,16],state:2},
{pos:[1,5,16],state:2},
{pos:[45,5,16],state:2},
{pos:[46,5,16],state:2},
{pos:[0,5,17],state:2},
