{DataVersion:3465,size:[47,20,34],palette:[{Name:"minecraft:deepslate_bricks"},{Name:"minecraft:polished_deepslate"},{Name:"minecraft:sculk"},{Name:"minecraft:sea_lantern"},{Name:"minecraft:structure_block"}],entities:[],blocks:[
{pos:[0,0,0],state:1},
{pos:[1,0,0],state:1},
{pos:[2,0,0],state:1},
{pos:[3,0,0],state:1},
{pos:[4,0,0],state:1},
{pos:[5,0,0],state:1},
{pos:[6,0,0],state:1},
{pos:[7,0,0],state:1},
{pos:[8,0,0],state:1},
{pos:[9,0,0],state:1},
{pos:[10,0,0],state:1},
{pos:[11,0,0],state:1},
{pos:[12,0,0],state:1},
{pos:[13,0,0],state:1},
{pos:[14,0,0],state:1},
{pos:[15,0,0],state:1},
{pos:[16,0,0],state:1},
{pos:[17,0,0],state:1},
{pos:[18,0,0],state:1},
{pos:[19,0,0],state:1},
{pos:[20,0,0],state:1},
{pos:[21,0,0],state:1},
{pos:[22,0,0],state:1},
{pos:[23,0,0],state:1},
{pos:[24,0,0],state:1},
{pos:[25,0,0],state:1},
{pos:[26,0,0],state:1},
{pos:[27,0,0],state:1},
{pos:[28,0,0],state:1},
{pos:[29,0,0],state:1},
{pos:[30,0,0],state:1},
{pos:[31,0,0],state:1},
{pos:[32,0,0],state:1},
{pos:[33,0,0],state:1},
{pos:[34,0,0],state:1},
{pos:[35,0,0],state:1},
{pos:[36,0,0],state:1},
{pos:[37,0,0],state:1},
{pos:[38,0,0],state:1},
{pos:[39,0,0],state:1},
{pos:[40,0,0],state:1},
{pos:[41,0,0],state:1},
{pos:[42,0,0],state:1},
{pos:[43,0,0],state:1},
{pos:[44,0,0],state:1},
{pos:[45,0,0],state:1},
{pos:[46,0,0],state:1},
{pos:[0,0,1],state:1},
{pos:[1,0,1],state:1},
{pos:[2,0,1],state:1},
{pos:[3,0,1],state:1},
{pos:[4,0,1],state:1},
{pos:[5,0,1],state:1},
{pos:[6,0,1],state:1},
{pos:[7,0,1],state:1},
{pos:[8,0,1],state:1},
{pos:[9,0,1],state:1},
{pos:[10,0,1],state:1},
{pos:[11,0,1],state:1},
{pos:[12,0,1],state:1},
{pos:[13,0,1],state:1},
{pos:[14,0,1],state:1},
{pos:[15,0,1],state:1},
{pos:[16,0,1],state:1},
{pos:[17,0,1],state:1},
{pos:[18,0,1],state:1},
{pos:[19,0,1],state:1},
{pos:[20,0,1],state:1},
{pos:[21,0,1],state:1},
{pos:[22,0,1],state:1},
{pos:[23,0,1],state:1},
{pos:[24,0,1],state:1},
{pos:[25,0,1],state:1},
{pos:[26,0,1],state:1},
{pos:[27,0,1],state:1},
{pos:[28,0,1],state:1},
{pos:[29,0,1],state:1},
{pos:[30,0,1],state:1},
{pos:[31,0,1],state:1},
{pos:[32,0,1],state:1},
{pos:[33,0,1],state:1},
{pos:[34,0,1],state:1},
{pos:[35,0,1],state:1},
{pos:[36,0,1],state:1},
{pos:[37,0,1],state:1},
{pos:[38,0,1],state:1},
{pos:[39,0,1],state:1},
{pos:[40,0,1],state:1},
{pos:[41,0,1],state:1},
{pos:[42,0,1],state:1},
{pos:[43,0,1],state:1},
{pos:[44,0,1],state:1},
{pos:[45,0,1],state:1},
{pos:[46,0,1],state:1},
{pos:[0,0,2],state:1},
{pos:[1,0,2],state:1},
{pos:[2,0,2],state:1},
{pos:[3,0,2],state:1},
{pos:[4,0,2],state:1},
{pos:[5,0,2],state:1},
{pos:[6,0,2],state:1},
{pos:[7,0,2],state:1},
{pos:[8,0,2],state:1},
{pos:[9,0,2],state:1},
{pos:[10,0,2],state:1},
{pos:[11,0,2],state:1},
{pos:[12,0,2],state:1},
{pos:[13,0,2],state:1},
{pos:[14,0,2],state:1},
{pos:[15,0,2],state:1},
{pos:[16,0,2],state:1},
{pos:[17,0,2],state:1},
{pos:[18,0,2],state:1},
{pos:[19,0,2],state:1},
{pos:[20,0,2],state:1},
{pos:[21,0,2],state:1},
{pos:[22,0,2],state:1},
{pos:[23,0,2],state:1},
{pos:[24,0,2],state:1},
{pos:[25,0,2],state:1},
{pos:[26,0,2],state:1},
{pos:[27,0,2],state:1},
{pos:[28,0,2],state:1},
{pos:[29,0,2],state:1},
{pos:[30,0,2],state:1},
{pos:[31,0,2],state:1},
{pos:[32,0,2],state:1},
{pos:[33,0,2],state:1},
{pos:[34,0,2],state:1},
{pos:[35,0,2],state:1},
{pos:[36,0,2],state:1},
{pos:[37,0,2],state:1},
{pos:[38,0,2],state:1},
{pos:[39,0,2],state:1},
{pos:[40,0,2],state:1},
{pos:[41,0,2],state:1},
{pos:[42,0,2],state:1},
{pos:[43,0,2],state:1},
{pos:[44,0,2],state:1},
{pos:[45,0,2],state:1},
{pos:[46,0,2],state:1},
{pos:[0,0,3],state:1},
{pos:[1,0,3],state:1},
{pos:[2,0,3],state:1},
{pos:[3,0,3],state:1},
{pos:[4,0,3],state:1},
{pos:[5,0,3],state:1},
{pos:[6,0,3],state:1},
{pos:[7,0,3],state:1},
{pos:[8,0,3],state:1},
{pos:[9,0,3],state:1},
{pos:[10,0,3],state:1},
{pos:[11,0,3],state:1},
{pos:[12,0,3],state:1},
{pos:[13,0,3],state:1},
{pos:[14,0,3],state:1},
{pos:[15,0,3],state:1},
{pos:[16,0,3],state:1},
{pos:[17,0,3],state:1},
{pos:[18,0,3],state:1},
{pos:[19,0,3],state:1},
{pos:[20,0,3],state:1},
{pos:[21,0,3],state:1},
{pos:[22,0,3],state:1},
{pos:[23,0,3],state:1},
{pos:[24,0,3],state:1},
{pos:[25,0,3],state:1},
{pos:[26,0,3],state:1},
{pos:[27,0,3],state:1},
{pos:[28,0,3],state:1},
{pos:[29,0,3],state:1},
{pos:[30,0,3],state:1},
{pos:[31,0,3],state:1},
{pos:[32,0,3],state:1},
{pos:[33,0,3],state:1},
{pos:[34,0,3],state:1},
{pos:[35,0,3],state:1},
{pos:[36,0,3],state:1},
{pos:[37,0,3],state:1},
{pos:[38,0,3],state:1},
{pos:[39,0,3],state:1},
{pos:[40,0,3],state:1},
{pos:[41,0,3],state:1},
{pos:[42,0,3],state:1},
{pos:[43,0,3],state:1},
{pos:[44,0,3],state:1},
{pos:[45,0,3],state:1},
{pos:[46,0,3],state:1},
{pos:[0,0,4],state:1},
{pos:[1,0,4],state:1},
{pos:[2,0,4],state:1},
{pos:[3,0,4],state:1},
{pos:[4,0,4],state:1},
{pos:[5,0,4],state:1},
{pos:[6,0,4],state:1},
{pos:[7,0,4],state:1},
{pos:[8,0,4],state:1},
{pos:[9,0,4],state:1},
{pos:[10,0,4],state:1},
{pos:[11,0,4],state:1},
{pos:[12,0,4],state:1},
{pos:[13,0,4],state:1},
{pos:[14,0,4],state:1},
{pos:[15,0,4],state:1},
{pos:[16,0,4],state:1},
{pos:[17,0,4],state:1},
{pos:[18,0,4],state:1},
{pos:[19,0,4],state:1},
{pos:[20,0,4],state:1},
{pos:[21,0,4],state:1},
{pos:[22,0,4],state:1},
{pos:[23,0,4],state:1},
{pos:[24,0,4],state:1},
{pos:[25,0,4],state:1},
{pos:[26,0,4],state:1},
{pos:[27,0,4],state:1},
{pos:[28,0,4],state:1},
{pos:[29,0,4],state:1},
{pos:[30,0,4],state:1},
{pos:[31,0,4],state:1},
{pos:[32,0,4],state:1},
{pos:[33,0,4],state:1},
{pos:[34,0,4],state:1},
{pos:[35,0,4],state:1},
{pos:[36,0,4],state:1},
{pos:[37,0,4],state:1},
{pos:[38,0,4],state:1},
{pos:[39,0,4],state:1},
{pos:[40,0,4],state:1},
{pos:[41,0,4],state:1},
{pos:[42,0,4],state:1},
{pos:[43,0,4],state:1},
{pos:[44,0,4],state:1},
{pos:[45,0,4],state:1},
{pos:[46,0,4],state:1},
{pos:[0,0,5],state:1},
{pos:[1,0,5],state:1},
{pos:[3,0,5],state:1},
{pos:[7,0,5],state:1},
{pos:[11,0,5],state:1},
{pos:[15,0,5],state:1},
{pos:[18,0,5],state:1},
{pos:[19,0,5],state:1},
{pos:[20,0,5],state:1},
{pos:[21,0,5],state:1},
{pos:[22,0,5],state:1},
{pos:[23,0,5],state:1},
{pos:[24,0,5],state:1},
{pos:[25,0,5],state:1},
{pos:[26,0,5],state:1},
{pos:[27,0,5],state:1},
{pos:[28,0,5],state:1},
{pos:[31,0,5],state:1},
{pos:[35,0,5],state:1},
{pos:[39,0,5],state:1},
{pos:[43,0,5],state:1},
{pos:[45,0,5],state:1},
{pos:[46,0,5],state:1},
{pos:[0,0,6],state:1},
{pos:[1,0,6],state:1},
{pos:[2,0,6],state:1},
{pos:[6,0,6],state:1},
{pos:[10,0,6],state:1},
{pos:[14,0,6],state:1},
{pos:[18,0,6],state:1},
{pos:[19,0,6],state:1},
{pos:[20,0,6],state:1},
{pos:[21,0,6],state:1},
{pos:[22,0,6],state:1},
{pos:[23,0,6],state:1},
{pos:[24,0,6],state:1},
{pos:[25,0,6],state:1},
{pos:[26,0,6],state:1},
{pos:[27,0,6],state:1},
{pos:[28,0,6],state:1},
{pos:[30,0,6],state:1},
{pos:[34,0,6],state:1},
{pos:[38,0,6],state:1},
{pos:[42,0,6],state:1},
{pos:[45,0,6],state:1},
{pos:[46,0,6],state:1},
{pos:[0,0,7],state:1},
{pos:[1,0,7],state:1},
{pos:[5,0,7],state:1},
{pos:[9,0,7],state:1},
{pos:[13,0,7],state:1},
{pos:[17,0,7],state:1},
{pos:[18,0,7],state:1},
{pos:[19,0,7],state:1},
{pos:[20,0,7],state:1},
{pos:[21,0,7],state:1},
{pos:[22,0,7],state:1},
{pos:[23,0,7],state:1},
{pos:[24,0,7],state:1},
{pos:[25,0,7],state:1},
{pos:[26,0,7],state:1},
{pos:[27,0,7],state:1},
{pos:[28,0,7],state:1},
{pos:[29,0,7],state:1},
{pos:[33,0,7],state:1},
{pos:[37,0,7],state:1},
{pos:[41,0,7],state:1},
{pos:[45,0,7],state:1},
{pos:[46,0,7],state:1},
{pos:[0,0,8],state:1},
{pos:[1,0,8],state:1},
{pos:[4,0,8],state:1},
{pos:[8,0,8],state:1},
{pos:[12,0,8],state:1},
{pos:[16,0,8],state:1},
{pos:[18,0,8],state:1},
{pos:[19,0,8],state:1},
{pos:[20,0,8],state:1},
{pos:[21,0,8],state:1},
{pos:[22,0,8],state:1},
{pos:[23,0,8],state:1},
{pos:[24,0,8],state:1},
{pos:[25,0,8],state:1},
{pos:[26,0,8],state:1},
{pos:[27,0,8],state:1},
{pos:[28,0,8],state:1},
{pos:[32,0,8],state:1},
{pos:[36,0,8],state:1},
{pos:[40,0,8],state:1},
{pos:[44,0,8],state:1},
{pos:[45,0,8],state:1},
{pos:[46,0,8],state:1},
{pos:[0,0,9],state:1},
{pos:[1,0,9],state:1},
{pos:[3,0,9],state:1},
{pos:[7,0,9],state:1},
{pos:[11,0,9],state:1},
{pos:[15,0,9],state:1},
{pos:[18,0,9],state:1},
{pos:[19,0,9],state:1},
{pos:[20,0,9],state:1},
{pos:[21,0,9],state:1},
{pos:[22,0,9],state:1},
{pos:[23,0,9],state:1},
{pos:[24,0,9],state:1},
{pos:[25,0,9],state:1},
{pos:[26,0,9],state:1},
{pos:[27,0,9],state:1},
{pos:[28,0,9],state:1},
{pos:[31,0,9],state:1},
{pos:[35,0,9],state:1},
{pos:[39,0,9],state:1},
{pos:[43,0,9],state:1},
{pos:[45,0,9],state:1},
{pos:[46,0,9],state:1},
{pos:[0,0,10],state:1},
{pos:[1,0,10],state:1},
{pos:[2,0,10],state:1},
{pos:[6,0,10],state:1},
{pos:[10,0,10],state:1},
{pos:[14,0,10],state:1},
{pos:[18,0,10],state:1},
{pos:[19,0,10],state:1},
{pos:[20,0,10],state:1},
{pos:[21,0,10],state:1},
{pos:[22,0,10],state:1},
{pos:[23,0,10],state:1},
{pos:[24,0,10],state:1},
{pos:[25,0,10],state:1},
{pos:[26,0,10],state:1},
{pos:[27,0,10],state:1},
{pos:[28,0,10],state:1},
{pos:[30,0,10],state:1},
{pos:[34,0,10],state:1},
{pos:[38,0,10],state:1},
{pos:[42,0,10],state:1},
{pos:[45,0,10],state:1},
{pos:[46,0,10],state:1},
{pos:[0,0,11],state:1},
{pos:[1,0,11],state:1},
{pos:[5,0,11],state:1},
{pos:[9,0,11],state:1},
{pos:[13,0,11],state:1},
{pos:[17,0,11],state:1},
{pos:[18,0,11],state:1},
{pos:[19,0,11],state:1},
{pos:[20,0,11],state:1},
{pos:[21,0,11],state:1},
{pos:[22,0,11],state:1},
{pos:[23,0,11],state:1},
{pos:[24,0,11],state:1},
{pos:[25,0,11],state:1},
{pos:[26,0,11],state:1},
{pos:[27,0,11],state:1},
{pos:[28,0,11],state:1},
{pos:[29,0,11],state:1},
{pos:[33,0,11],state:1},
{pos:[37,0,11],state:1},
{pos:[41,0,11],state:1},
{pos:[45,0,11],state:1},
{pos:[46,0,11],state:1},
{pos:[0,0,12],state:1},
{pos:[1,0,12],state:1},
{pos:[4,0,12],state:1},
{pos:[8,0,12],state:1},
{pos:[12,0,12],state:1},
{pos:[16,0,12],state:1},
{pos:[18,0,12],state:1},
{pos:[19,0,12],state:1},
{pos:[20,0,12],state:1},
{pos:[21,0,12],state:1},
{pos:[22,0,12],state:1},
{pos:[23,0,12],state:1},
{pos:[24,0,12],state:1},
{pos:[25,0,12],state:1},
{pos:[26,0,12],state:1},
{pos:[27,0,12],state:1},
{pos:[28,0,12],state:1},
{pos:[32,0,12],state:1},
{pos:[36,0,12],state:1},
{pos:[40,0,12],state:1},
{pos:[44,0,12],state:1},
{pos:[45,0,12],state:1},
{pos:[46,0,12],state:1},
{pos:[0,0,13],state:1},
{pos:[1,0,13],state:1},
{pos:[3,0,13],state:1},
{pos:[7,0,13],state:1},
{pos:[11,0,13],state:1},
{pos:[15,0,13],state:1},
{pos:[18,0,13],state:1},
{pos:[19,0,13],state:1},
{pos:[20,0,13],state:1},
{pos:[21,0,13],state:1},
{pos:[22,0,13],state:1},
{pos:[23,0,13],state:1},
{pos:[24,0,13],state:1},
{pos:[25,0,13],state:1},
{pos:[26,0,13],state:1},
{pos:[27,0,13],state:1},
{pos:[28,0,13],state:1},
{pos:[31,0,13],state:1},
{pos:[35,0,13],state:1},
{pos:[39,0,13],state:1},
{pos:[43,0,13],state:1},
{pos:[45,0,13],state:1},
{pos:[46,0,13],state:1},
{pos:[0,0,14],state:1},
{pos:[1,0,14],state:1},
{pos:[2,0,14],state:1},
{pos:[6,0,14],state:1},
{pos:[10,0,14],state:1},
{pos:[14,0,14],state:1},
{pos:[18,0,14],state:1},
{pos:[19,0,14],state:1},
{pos:[20,0,14],state:1},
{pos:[21,0,14],state:1},
{pos:[22,0,14],state:1},
{pos:[23,0,14],state:1},
{pos:[24,0,14],state:1},
{pos:[25,0,14],state:1},
{pos:[26,0,14],state:1},
{pos:[27,0,14],state:1},
{pos:[28,0,14],state:1},
{pos:[30,0,14],state:1},
{pos:[34,0,14],state:1},
{pos:[38,0,14],state:1},
{pos:[42,0,14],state:1},
{pos:[45,0,14],state:1},
{pos:[46,0,14],state:1},
{pos:[0,0,15],state:1},
{pos:[1,0,15],state:1},
{pos:[5,0,15],state:1},
{pos:[9,0,15],state:1},
{pos:[13,0,15],state:1},
{pos:[17,0,15],state:1},
{pos:[18,0,15],state:1},
{pos:[19,0,15],state:1},
{pos:[20,0,15],state:1},
{pos:[21,0,15],state:1},
{pos:[22,0,15],state:1},
{pos:[23,0,15],state:1},
{pos:[24,0,15],state:1},
{pos:[25,0,15],state:1},
{pos:[26,0,15],state:1},
{pos:[27,0,15],state:1},
{pos:[28,0,15],state:1},
{pos:[29,0,15],state:1},
{pos:[33,0,15],state:1},
{pos:[37,0,15],state:1},
{pos:[41,0,15],state:1},
{pos:[45,0,15],state:1},
{pos:[46,0,15],state:1},
{pos:[0,0,16],state:1},
{pos:[1,0,16],state:1},
{pos:[4,0,16],state:1},
{pos:[8,0,16],state:1},
{pos:[9,0,16],state:1},
{pos:[10,0,16],state:1},
{pos:[11,0,16],state:1},
{pos:[12,0,16],state:1},
{pos:[16,0,16],state:1},
{pos:[18,0,16],state:1},
{pos:[19,0,16],state:1},
{pos:[20,0,16],state:1},
{pos:[21,0,16],state:1},
{pos:[22,0,16],state:1},
{pos:[23,0,16],state:1},
{pos:[24,0,16],state:1},
{pos:[25,0,16],state:1},
{pos:[26,0,16],state:1},
{pos:[27,0,16],state:1},
{pos:[28,0,16],state:1},
{pos:[32,0,16],state:1},
{pos:[35,0,16],state:1},
{pos:[36,0,16],state:1},
{pos:[37,0,16],state:1},
{pos:[40,0,16],state:1},
{pos:[44,0,16],state:1},
{pos:[45,0,16],state:1},
{pos:[46,0,16],state:1},
{pos:[0,0,17],state:1},
{pos:[1,0,17],state:1},
{pos:[3,0,17],state:1},
{pos:[7,0,17],state:1},
{pos:[9,0,17],state:1},
{pos:[10,0,17],state:1},
{pos:[11,0,17],state:1},
{pos:[15,0,17],state:1},
{pos:[18,0,17],state:1},
{pos:[19,0,17],state:1},
{pos:[20,0,17],state:1},
{pos:[21,0,17],state:1},
{pos:[22,0,17],state:1},
{pos:[23,0,17],state:1},
{pos:[24,0,17],state:1},
{pos:[25,0,17],state:1},
{pos:[26,0,17],state:1},
{pos:[27,0,17],state:1},
{pos:[28,0,17],state:1},
{pos:[31,0,17],state:1},
{pos:[35,0,17],state:1},
{pos:[36,0,17],state:1},
{pos:[37,0,17],state:1},
{pos:[39,0,17],state:1},
{pos:[43,0,17],state:1},
{pos:[45,0,17],state:1},
{pos:[46,0,17],state:1},
{pos:[0,0,18],state:1},
{pos:[1,0,18],state:1},
{pos:[2,0,18],state:1},
{pos:[6,0,18],state:1},
{pos:[9,0,18],state:1},
{pos:[10,0,18],state:1},
{pos:[11,0,18],state:1},
{pos:[14,0,18],state:1},
{pos:[18,0,18],state:1},
{pos:[19,0,18],state:1},
{pos:[20,0,18],state:1},
{pos:[21,0,18],state:1},
{pos:[22,0,18],state:1},
{pos:[23,0,18],state:1},
{pos:[24,0,18],state:1},
{pos:[25,0,18],state:1},
{pos:[26,0,18],state:1},
{pos:[27,0,18],state:1},
{pos:[28,0,18],state:1},
{pos:[30,0,18],state:1},
{pos:[34,0,18],state:1},
{pos:[35,0,18],state:1},
{pos:[36,0,18],state:1},
{pos:[37,0,18],state:1},
{pos:[38,0,18],state:1},
{pos:[42,0,18],state:1},
{pos:[45,0,18],state:1},
{pos:[46,0,18],state:1},
{pos:[0,0,19],state:1},
{pos:[1,0,19],state:1},
{pos:[5,0,19],state:1},
{pos:[9,0,19],state:1},
{pos:[13,0,19],state:1},
{pos:[17,0,19],state:1},
{pos:[18,0,19],state:1},
{pos:[19,0,19],state:1},
{pos:[20,0,19],state:1},
{pos:[21,0,19],state:1},
{pos:[22,0,19],state:1},
{pos:[23,0,19],state:1},
{pos:[24,0,19],state:1},
{pos:[25,0,19],state:1},
{pos:[26,0,19],state:1},
{pos:[27,0,19],state:1},
{pos:[28,0,19],state:1},
{pos:[29,0,19],state:1},
{pos:[33,0,19],state:1},
{pos:[37,0,19],state:1},
{pos:[41,0,19],state:1},
{pos:[45,0,19],state:1},
{pos:[46,0,19],state:1},
{pos:[0,0,20],state:1},
{pos:[1,0,20],state:1},
{pos:[4,0,20],state:1},
{pos:[8,0,20],state:1},
{pos:[12,0,20],state:1},
{pos:[16,0,20],state:1},
{pos:[18,0,20],state:1},
{pos:[19,0,20],state:1},
{pos:[20,0,20],state:1},
{pos:[21,0,20],state:1},
{pos:[22,0,20],state:1},
{pos:[23,0,20],state:1},
{pos:[24,0,20],state:1},
{pos:[25,0,20],state:1},
{pos:[26,0,20],state:1},
{pos:[27,0,20],state:1},
{pos:[28,0,20],state:1},
{pos:[32,0,20],state:1},
{pos:[36,0,20],state:1},
{pos:[40,0,20],state:1},
{pos:[44,0,20],state:1},
{pos:[45,0,20],state:1},
{pos:[46,0,20],state:1},
{pos:[0,0,21],state:1},
{pos:[1,0,21],state:1},
{pos:[3,0,21],state:1},
{pos:[7,0,21],state:1},
{pos:[11,0,21],state:1},
{pos:[15,0,21],state:1},
{pos:[18,0,21],state:1},
{pos:[19,0,21],state:1},
{pos:[20,0,21],state:1},
{pos:[21,0,21],state:1},
{pos:[22,0,21],state:1},
{pos:[23,0,21],state:1},
{pos:[24,0,21],state:1},
{pos:[25,0,21],state:1},
{pos:[26,0,21],state:1},
{pos:[27,0,21],state:1},
{pos:[28,0,21],state:1},
{pos:[31,0,21],state:1},
{pos:[35,0,21],state:1},
{pos:[39,0,21],state:1},
{pos:[43,0,21],state:1},
{pos:[45,0,21],state:1},
{pos:[46,0,21],state:1},
{pos:[0,0,22],state:1},
{pos:[1,0,22],state:1},
{pos:[2,0,22],state:1},
{pos:[6,0,22],state:1},
{pos:[10,0,22],state:1},
{pos:[14,0,22],state:1},
{pos:[18,0,22],state:1},
{pos:[19,0,22],state:1},
{pos:[20,0,22],state:1},
{pos:[21,0,22],state:1},
{pos:[22,0,22],state:1},
{pos:[23,0,22],state:1},
{pos:[24,0,22],state:1},
{pos:[25,0,22],state:1},
{pos:[26,0,22],state:1},
{pos:[27,0,22],state:1},
{pos:[28,0,22],state:1},
{pos:[30,0,22],state:1},
{pos:[34,0,22],state:1},
{pos:[38,0,22],state:1},
{pos:[42,0,22],state:1},
{pos:[45,0,22],state:1},
{pos:[46,0,22],state:1},
{pos:[0,0,23],state:1},
{pos:[1,0,23],state:1},
{pos:[5,0,23],state:1},
{pos:[9,0,23],state:1},
{pos:[13,0,23],state:1},
{pos:[17,0,23],state:1},
{pos:[18,0,23],state:1},
{pos:[19,0,23],state:1},
{pos:[20,0,23],state:1},
{pos:[21,0,23],state:1},
{pos:[22,0,23],state:1},
{pos:[23,0,23],state:1},
{pos:[24,0,23],state:1},
{pos:[25,0,23],state:1},
{pos:[26,0,23],state:1},
{pos:[27,0,23],state:1},
{pos:[28,0,23],state:1},
{pos:[29,0,23],state:1},
{pos:[33,0,23],state:1},
{pos:[37,0,23],state:1},
{pos:[41,0,23],state:1},
{pos:[45,0,23],state:1},
{pos:[46,0,23],state:1},
{pos:[0,0,24],state:1},
{pos:[1,0,24],state:1},
{pos:[4,0,24],state:1},
{pos:[8,0,24],state:1},
{pos:[12,0,24],state:1},
{pos:[16,0,24],state:1},
{pos:[18,0,24],state:1},
{pos:[19,0,24],state:1},
{pos:[20,0,24],state:1},
{pos:[21,0,24],state:1},
{pos:[22,0,24],state:1},
{pos:[23,0,24],state:1},
{pos:[24,0,24],state:1},
{pos:[25,0,24],state:1},
{pos:[26,0,24],state:1},
{pos:[27,0,24],state:1},
{pos:[28,0,24],state:1},
{pos:[32,0,24],state:1},
{pos:[36,0,24],state:1},
{pos:[40,0,24],state:1},
{pos:[44,0,24],state:1},
{pos:[45,0,24],state:1},
{pos:[46,0,24],state:1},
{pos:[0,0,25],state:1},
{pos:[1,0,25],state:1},
{pos:[3,0,25],state:1},
{pos:[7,0,25],state:1},
{pos:[11,0,25],state:1},
{pos:[15,0,25],state:1},
{pos:[18,0,25],state:1},
{pos:[19,0,25],state:1},
{pos:[20,0,25],state:1},
{pos:[21,0,25],state:1},
{pos:[22,0,25],state:1},
{pos:[23,0,25],state:1},
{pos:[24,0,25],state:1},
{pos:[25,0,25],state:1},
{pos:[26,0,25],state:1},
{pos:[27,0,25],state:1},
{pos:[28,0,25],state:1},
{pos:[31,0,25],state:1},
{pos:[35,0,25],state:1},
{pos:[39,0,25],state:1},
{pos:[43,0,25],state:1},
{pos:[45,0,25],state:1},
{pos:[46,0,25],state:1},
{pos:[0,0,26],state:1},
{pos:[1,0,26],state:1},
{pos:[2,0,26],state:1},
{pos:[6,0,26],state:1},
{pos:[10,0,26],state:1},
{pos:[14,0,26],state:1},
{pos:[18,0,26],state:1},
{pos:[19,0,26],state:1},
{pos:[20,0,26],state:1},
{pos:[21,0,26],state:1},
{pos:[22,0,26],state:1},
{pos:[23,0,26],state:1},
{pos:[24,0,26],state:1},
{pos:[25,0,26],state:1},
{pos:[26,0,26],state:1},
{pos:[27,0,26],state:1},
{pos:[28,0,26],state:1},
{pos:[30,0,26],state:1},
{pos:[34,0,26],state:1},
{pos:[38,0,26],state:1},
{pos:[42,0,26],state:1},
{pos:[45,0,26],state:1},
{pos:[46,0,26],state:1},
{pos:[0,0,27],state:1},
{pos:[1,0,27],state:1},
{pos:[5,0,27],state:1},
{pos:[9,0,27],state:1},
{pos:[13,0,27],state:1},
{pos:[17,0,27],state:1},
{pos:[18,0,27],state:1},
{pos:[19,0,27],state:1},
{pos:[20,0,27],state:1},
{pos:[21,0,27],state:1},
{pos:[22,0,27],state:1},
{pos:[23,0,27],state:1},
{pos:[24,0,27],state:1},
{pos:[25,0,27],state:1},
{pos:[26,0,27],state:1},
{pos:[27,0,27],state:1},
{pos:[28,0,27],state:1},
{pos:[29,0,27],state:1},
{pos:[33,0,27],state:1},
{pos:[37,0,27],state:1},
{pos:[41,0,27],state:1},
{pos:[45,0,27],state:1},
{pos:[46,0,27],state:1},
{pos:[0,0,28],state:1},
{pos:[1,0,28],state:1},
{pos:[4,0,28],state:1},
{pos:[8,0,28],state:1},
{pos:[12,0,28],state:1},
{pos:[16,0,28],state:1},
{pos:[18,0,28],state:1},
{pos:[19,0,28],state:1},
{pos:[20,0,28],state:1},
{pos:[21,0,28],state:1},
{pos:[22,0,28],state:1},
{pos:[23,0,28],state:1},
{pos:[24,0,28],state:1},
{pos:[25,0,28],state:1},
{pos:[26,0,28],state:1},
{pos:[27,0,28],state:1},
{pos:[28,0,28],state:1},
{pos:[32,0,28],state:1},
{pos:[36,0,28],state:1},
{pos:[40,0,28],state:1},
{pos:[44,0,28],state:1},
{pos:[45,0,28],state:1},
{pos:[46,0,28],state:1},
{pos:[0,0,29],state:1},
{pos:[1,0,29],state:1},
{pos:[2,0,29],state:1},
{pos:[3,0,29],state:1},
{pos:[4,0,29],state:1},
{pos:[5,0,29],state:1},
{pos:[6,0,29],state:1},
{pos:[7,0,29],state:1},
{pos:[8,0,29],state:1},
{pos:[9,0,29],state:1},
{pos:[10,0,29],state:1},
{pos:[11,0,29],state:1},
{pos:[12,0,29],state:1},
{pos:[13,0,29],state:1},
{pos:[14,0,29],state:1},
{pos:[15,0,29],state:1},
{pos:[16,0,29],state:1},
{pos:[17,0,29],state:1},
{pos:[18,0,29],state:1},
{pos:[19,0,29],state:1},
{pos:[20,0,29],state:1},
{pos:[21,0,29],state:1},
{pos:[22,0,29],state:1},
{pos:[23,0,29],state:1},
{pos:[24,0,29],state:1},
{pos:[25,0,29],state:1},
{pos:[26,0,29],state:1},
{pos:[27,0,29],state:1},
{pos:[28,0,29],state:1},
{pos:[29,0,29],state:1},
{pos:[30,0,29],state:1},
{pos:[31,0,29],state:1},
{pos:[32,0,29],state:1},
{pos:[33,0,29],state:1},
{pos:[34,0,29],state:1},
{pos:[35,0,29],state:1},
{pos:[36,0,29],state:1},
{pos:[37,0,29],state:1},
{pos:[38,0,29],state:1},
{pos:[39,0,29],state:1},
{pos:[40,0,29],state:1},
{pos:[41,0,29],state:1},
{pos:[42,0,29],state:1},
{pos:[43,0,29],state:1},
{pos:[44,0,29],state:1},
{pos:[45,0,29],state:1},
{pos:[46,0,29],state:1},
{pos:[0,0,30],state:1},
{pos:[1,0,30],state:1},
{pos:[2,0,30],state:1},
{pos:[3,0,30],state:1},
{pos:[4,0,30],state:1},
{pos:[5,0,30],state:1},
{pos:[6,0,30],state:1},
{pos:[7,0,30],state:1},
{pos:[8,0,30],state:1},
{pos:[9,0,30],state:1},
{pos:[10,0,30],state:1},
{pos:[11,0,30],state:1},
{pos:[12,0,30],state:1},
{pos:[13,0,30],state:1},
{pos:[14,0,30],state:1},
{pos:[15,0,30],state:1},
{pos:[16,0,30],state:1},
{pos:[17,0,30],state:1},
{pos:[18,0,30],state:1},
{pos:[19,0,30],state:1},
{pos:[20,0,30],state:1},
{pos:[21,0,30],state:1},
{pos:[22,0,30],state:1},
{pos:[23,0,30],state:1},
{pos:[24,0,30],state:1},
{pos:[25,0,30],state:1},
{pos:[26,0,30],state:1},
{pos:[27,0,30],state:1},
{pos:[28,0,30],state:1},
{pos:[29,0,30],state:1},
{pos:[30,0,30],state:1},
{pos:[31,0,30],state:1},
{pos:[32,0,30],state:1},
{pos:[33,0,30],state:1},
{pos:[34,0,30],state:1},
{pos:[35,0,30],state:1},
{pos:[36,0,30],state:1},
{pos:[37,0,30],state:1},
{pos:[38,0,30],state:1},
{pos:[39,0,30],state:1},
{pos:[40,0,30],state:1},
{pos:[41,0,30],state:1},
{pos:[42,0,30],state:1},
{pos:[43,0,30],state:1},
{pos:[44,0,30],state:1},
{pos:[45,0,30],state:1},
{pos:[46,0,30],state:1},
{pos:[0,0,31],state:1},
{pos:[1,0,31],state:1},
{pos:[2,0,31],state:1},
{pos:[3,0,31],state:1},
{pos:[4,0,31],state:1},
{pos:[5,0,31],state:1},
{pos:[6,0,31],state:1},
{pos:[7,0,31],state:1},
{pos:[8,0,31],state:1},
{pos:[9,0,31],state:1},
{pos:[10,0,31],state:1},
{pos:[11,0,31],state:1},
{pos:[12,0,31],state:1},
{pos:[13,0,31],state:1},
{pos:[14,0,31],state:1},
{pos:[15,0,31],state:1},
{pos:[16,0,31],state:1},
{pos:[17,0,31],state:1},
{pos:[18,0,31],state:1},
{pos:[19,0,31],state:1},
{pos:[20,0,31],state:1},
{pos:[21,0,31],state:1},
{pos:[22,0,31],state:1},
{pos:[23,0,31],state:1},
{pos:[24,0,31],state:1},
{pos:[25,0,31],state:1},
{pos:[26,0,31],state:1},
{pos:[27,0,31],state:1},
{pos:[28,0,31],state:1},
{pos:[29,0,31],state:1},
{pos:[30,0,31],state:1},
{pos:[31,0,31],state:1},
{pos:[32,0,31],state:1},
{pos:[33,0,31],state:1},
{pos:[34,0,31],state:1},
{pos:[35,0,31],state:1},
{pos:[36,0,31],state:1},
{pos:[37,0,31],state:1},
{pos:[38,0,31],state:1},
{pos:[39,0,31],state:1},
{pos:[40,0,31],state:1},
{pos:[41,0,31],state:1},
{pos:[42,0,31],state:1},
{pos:[43,0,31],state:1},
{pos:[44,0,31],state:1},
{pos:[45,0,31],state:1},
{pos:[46,0,31],state:1},
{pos:[0,0,32],state:1},
{pos:[1,0,32],state:1},
{pos:[2,0,32],state:1},
{pos:[3,0,32],state:1},
{pos:[4,0,32],state:1},
{pos:[5,0,32],state:1},
{pos:[6,0,32],state:1},
{pos:[7,0,32],state:1},
{pos:[8,0,32],state:1},
{pos:[9,0,32],state:1},
{pos:[10,0,32],state:1},
{pos:[11,0,32],state:1},
{pos:[12,0,32],state:1},
{pos:[13,0,32],state:1},
{pos:[14,0,32],state:1},
{pos:[15,0,32],state:1},
{pos:[16,0,32],state:1},
{pos:[17,0,32],state:1},
{pos:[18,0,32],state:1},
{pos:[19,0,32],state:1},
{pos:[20,0,32],state:1},
{pos:[21,0,32],state:1},
{pos:[22,0,32],state:1},
{pos:[23,0,32],state:1},
{pos:[24,0,32],state:1},
{pos:[25,0,32],state:1},
{pos:[26,0,32],state:1},
{pos:[27,0,32],state:1},
{pos:[28,0,32],state:1},
{pos:[29,0,32],state:1},
{pos:[30,0,32],state:1},
{pos:[31,0,32],state:1},
{pos:[32,0,32],state:1},
{pos:[33,0,32],state:1},
{pos:[34,0,32],state:1},
{pos:[35,0,32],state:1},
{pos:[36,0,32],state:1},
{pos:[37,0,32],state:1},
{pos:[38,0,32],state:1},
{pos:[39,0,32],state:1},
{pos:[40,0,32],state:1},
{pos:[41,0,32],state:1},
{pos:[42,0,32],state:1},
{pos:[43,0,32],state:1},
{pos:[44,0,32],state:1},
{pos:[45,0,32],state:1},
{pos:[46,0,32],state:1},
{pos:[0,0,33],state:1},
{pos:[1,0,33],state:1},
{pos:[2,0,33],state:1},
{pos:[3,0,33],state:1},
{pos:[4,0,33],state:1},
{pos:[5,0,33],state:1},
{pos:[6,0,33],state:1},
{pos:[7,0,33],state:1},
{pos:[8,0,33],state:1},
{pos:[9,0,33],state:1},
{pos:[10,0,33],state:1},
{pos:[11,0,33],state:1},
{pos:[12,0,33],state:1},
{pos:[13,0,33],state:1},
{pos:[14,0,33],state:1},
{pos:[15,0,33],state:1},
{pos:[16,0,33],state:1},
{pos:[17,0,33],state:1},
{pos:[18,0,33],state:1},
{pos:[19,0,33],state:1},
{pos:[20,0,33],state:1},
{pos:[21,0,33],state:1},
{pos:[22,0,33],state:1},
{pos:[23,0,33],state:1},
{pos:[24,0,33],state:1},
{pos:[25,0,33],state:1},
{pos:[26,0,33],state:1},
{pos:[27,0,33],state:1},
{pos:[28,0,33],state:1},
{pos:[29,0,33],state:1},
{pos:[30,0,33],state:1},
{pos:[31,0,33],state:1},
{pos:[32,0,33],state:1},
{pos:[33,0,33],state:1},
{pos:[34,0,33],state:1},
{pos:[35,0,33],state:1},
{pos:[36,0,33],state:1},
{pos:[37,0,33],state:1},
{pos:[38,0,33],state:1},
{pos:[39,0,33],state:1},
{pos:[40,0,33],state:1},
{pos:[41,0,33],state:1},
{pos:[42,0,33],state:1},
{pos:[43,0,33],state:1},
{pos:[44,0,33],state:1},
{pos:[45,0,33],state:1},
{pos:[46,0,33],state:1},
{pos:[0,1,0],state:0},
{pos:[1,1,0],state:0},
{pos:[2,1,0],state:0},
{pos:[3,1,0],state:0},
{pos:[4,1,0],state:0},
{pos:[5,1,0],state:0},
{pos:[6,1,0],state:0},
{pos:[7,1,0],state:0},
{pos:[8,1,0],state:0},
{pos:[9,1,0],state:0},
{pos:[10,1,0],state:0},
{pos:[11,1,0],state:0},
{pos:[12,1,0],state:0},
{pos:[13,1,0],state:0},
{pos:[14,1,0],state:0},
{pos:[15,1,0],state:0},
{pos:[16,1,0],state:0},
{pos:[17,1,0],state:0},
{pos:[18,1,0],state:0},
{pos:[19,1,0],state:0},
{pos:[20,1,0],state:0},
{pos:[26,1,0],state:0},
{pos:[27,1,0],state:0},
{pos:[28,1,0],state:0},
{pos:[29,1,0],state:0},
{pos:[30,1,0],state:0},
{pos:[31,1,0],state:0},
{pos:[32,1,0],state:0},
{pos:[33,1,0],state:0},
{pos:[34,1,0],state:0},
{pos:[35,1,0],state:0},
{pos:[36,1,0],state:0},
{pos:[37,1,0],state:0},
{pos:[38,1,0],state:0},
{pos:[39,1,0],state:0},
{pos:[40,1,0],state:0},
{pos:[41,1,0],state:0},
{pos:[42,1,0],state:0},
{pos:[43,1,0],state:0},
{pos:[44,1,0],state:0},
{pos:[45,1,0],state:0},
{pos:[46,1,0],state:0},
{pos:[0,1,1],state:0},
{pos:[1,1,1],state:0},
{pos:[2,1,1],state:0},
{pos:[3,1,1],state:0},
{pos:[4,1,1],state:0},
{pos:[5,1,1],state:0},
{pos:[6,1,1],state:0},
{pos:[7,1,1],state:0},
{pos:[8,1,1],state:0},
{pos:[9,1,1],state:0},
{pos:[10,1,1],state:0},
{pos:[11,1,1],state:0},
{pos:[12,1,1],state:0},
{pos:[13,1,1],state:0},
{pos:[14,1,1],state:0},
{pos:[15,1,1],state:0},
{pos:[16,1,1],state:0},
{pos:[17,1,1],state:0},
{pos:[18,1,1],state:0},
{pos:[19,1,1],state:0},
{pos:[20,1,1],state:0},
{pos:[26,1,1],state:0},
{pos:[27,1,1],state:0},
{pos:[28,1,1],state:0},
{pos:[29,1,1],state:0},
{pos:[30,1,1],state:0},
{pos:[31,1,1],state:0},
{pos:[32,1,1],state:0},
{pos:[33,1,1],state:0},
{pos:[34,1,1],state:0},
{pos:[35,1,1],state:0},
{pos:[36,1,1],state:0},
{pos:[37,1,1],state:0},
{pos:[38,1,1],state:0},
{pos:[39,1,1],state:0},
{pos:[40,1,1],state:0},
{pos:[41,1,1],state:0},
{pos:[42,1,1],state:0},
{pos:[43,1,1],state:0},
{pos:[44,1,1],state:0},
{pos:[45,1,1],state:0},
{pos:[46,1,1],state:0},
{pos:[0,1,2],state:0},
{pos:[1,1,2],state:0},
{pos:[4,1,2],state:2},
{pos:[11,1,2],state:2},
{pos:[18,1,2],state:2},
{pos:[25,1,2],state:2},
{pos:[32,1,2],state:2},
{pos:[39,1,2],state:2},
{pos:[45,1,2],state:0},
{pos:[46,1,2],state:0},
{pos:[0,1,3],state:0},
{pos:[1,1,3],state:0},
{pos:[45,1,3],state:0},
{pos:[46,1,3],state:0},
{pos:[0,1,4],state:0},
{pos:[1,1,4],state:0},
{pos:[45,1,4],state:0},
{pos:[46,1,4],state:0},
{pos:[0,1,5],state:0},
{pos:[1,1,5],state:0},
{pos:[2,1,5],state:2},
{pos:[44,1,5],state:2},
{pos:[45,1,5],state:0},
{pos:[46,1,5],state:0},
{pos:[0,1,6],state:0},
{pos:[1,1,6],state:0},
{pos:[45,1,6],state:0},
{pos:[46,1,6],state:0},
{pos:[0,1,7],state:0},
{pos:[1,1,7],state:0},
{pos:[17,1,7],state:2},
{pos:[29,1,7],state:2},
{pos:[45,1,7],state:0},
{pos:[46,1,7],state:0},
{pos:[0,1,8],state:0},
{pos:[1,1,8],state:0},
{pos:[45,1,8],state:0},
{pos:[46,1,8],state:0},
{pos:[0,1,9],state:0},
{pos:[1,1,9],state:0},
{pos:[45,1,9],state:0},
{pos:[46,1,9],state:0},
{pos:[0,1,10],state:0},
{pos:[1,1,10],state:0},
{pos:[45,1,10],state:0},
{pos:[46,1,10],state:0},
{pos:[0,1,11],state:0},
{pos:[1,1,11],state:0},
{pos:[45,1,11],state:0},
{pos:[46,1,11],state:0},
{pos:[0,1,12],state:0},
{pos:[1,1,12],state:0},
{pos:[45,1,12],state:0},
{pos:[46,1,12],state:0},
{pos:[0,1,13],state:0},
{pos:[1,1,13],state:0},
{pos:[2,1,13],state:2},
{pos:[44,1,13],state:2},
{pos:[45,1,13],state:0},
{pos:[46,1,13],state:0},
{pos:[0,1,14],state:0},
{pos:[1,1,14],state:0},
{pos:[17,1,14],state:2},
{pos:[29,1,14],state:2},
{pos:[45,1,14],state:0},
{pos:[46,1,14],state:0},
{pos:[0,1,15],state:0},
{pos:[1,1,15],state:0},
{pos:[45,1,15],state:0},
{pos:[46,1,15],state:0},
{pos:[0,1,16],state:0},
{pos:[1,1,16],state:0},
{pos:[45,1,16],state:0},
{pos:[46,1,16],state:0},
{pos:[0,1,17],state:0},
{pos:[1,1,17],state:0},
{pos:[10,1,17],state:4,nbt:{mode:"DATA",metadata:"enemy:ranged:2"}},
{pos:[23,1,17],state:4,nbt:{mode:"DATA",metadata:"objective:3"}},
{pos:[36,1,17],state:4,nbt:{mode:"DATA",metadata:"enemy:ranged:3"}},
{pos:[45,1,17],state:0},
{pos:[46,1,17],state:0},
{pos:[0,1,18],state:0},
{pos:[1,1,18],state:0},
{pos:[45,1,18],state:0},
{pos:[46,1,18],state:0},
{pos:[0,1,19],state:0},
{pos:[1,1,19],state:0},
{pos:[45,1,19],state:0},
{pos:[46,1,19],state:0},
{pos:[0,1,20],state:0},
{pos:[1,1,20],state:0},
{pos:[45,1,20],state:0},
{pos:[46,1,20],state:0},
{pos:[0,1,21],state:0},
{pos:[1,1,21],state:0},
{pos:[2,1,21],state:2},
{pos:[17,1,21],state:2},
{pos:[29,1,21],state:2},
{pos:[44,1,21],state:2},
{pos:[45,1,21],state:0},
{pos:[46,1,21],state:0},
{pos:[0,1,22],state:0},
{pos:[1,1,22],state:0},
{pos:[45,1,22],state:0},
{pos:[46,1,22],state:0},
{pos:[0,1,23],state:0},
{pos:[1,1,23],state:0},
{pos:[45,1,23],state:0},
{pos:[46,1,23],state:0},
{pos:[0,1,24],state:0},
{pos:[1,1,24],state:0},
{pos:[45,1,24],state:0},
{pos:[46,1,24],state:0},
{pos:[0,1,25],state:0},
{pos:[1,1,25],state:0},
{pos:[45,1,25],state:0},
{pos:[46,1,25],state:0},
{pos:[0,1,26],state:0},
{pos:[1,1,26],state:0},
{pos:[45,1,26],state:0},
{pos:[46,1,26],state:0},
{pos:[0,1,27],state:0},
{pos:[1,1,27],state:0},
{pos:[45,1,27],state:0},
{pos:[46,1,27],state:0},
{pos:[0,1,28],state:0},
{pos:[1,1,28],state:0},
{pos:[17,1,28],state:2},
{pos:[29,1,28],state:2},
{pos:[45,1,28],state:0},
{pos:[46,1,28],state:0},
{pos:[0,1,29],state:0},
{pos:[1,1,29],state:0},
{pos:[2,1,29],state:2},
{pos:[44,1,29],state:2},
{pos:[45,1,29],state:0},
{pos:[46,1,29],state:0},
{pos:[0,1,30],state:0},
{pos:[1,1,30],state:0},
{pos:[45,1,30],state:0},
{pos:[46,1,30],state:0},
{pos:[0,1,31],state:0},
{pos:[1,1,31],state:0},
{pos:[4,1,31],state:2},
{pos:[11,1,31],state:2},
{pos:[15,1,31],state:4,nbt:{mode:"DATA",metadata:"door:2"}},
{pos:[18,1,31],state:2},
{pos:[25,1,31],state:2},
{pos:[32,1,31],state:2},
{pos:[39,1,31],state:2},
{pos:[45,1,31],state:0},
{pos:[46,1,31],state:0},
{pos:[0,1,32],state:0},
{pos:[1,1,32],state:0},
{pos:[2,1,32],state:0},
{pos:[3,1,32],state:0},
{pos:[4,1,32],state:0},
{pos:[5,1,32],state:0},
{pos:[6,1,32],state:0},
{pos:[7,1,32],state:0},
{pos:[8,1,32],state:0},
{pos:[9,1,32],state:0},
{pos:[10,1,32],state:0},
{pos:[11,1,32],state:0},
{pos:[12,1,32],state:0},
{pos:[18,1,32],state:0},
{pos:[19,1,32],state:0},
{pos:[20,1,32],state:0},
{pos:[21,1,32],state:0},
{pos:[22,1,32],state:0},
{pos:[23,1,32],state:0},
{pos:[24,1,32],state:0},
{pos:[25,1,32],state:0},
{pos:[26,1,32],state:0},
{pos:[27,1,32],state:0},
{pos:[28,1,32],state:0},
{pos:[29,1,32],state:0},
{pos:[30,1,32],state:0},
{pos:[31,1,32],state:0},
{pos:[32,1,32],state:0},
{pos:[33,1,32],state:0},
{pos:[34,1,32],state:0},
{pos:[35,1,32],state:0},
{pos:[36,1,32],state:0},
{pos:[37,1,32],state:0},
{pos:[38,1,32],state:0},
{pos:[39,1,32],state:0},
{pos:[40,1,32],state:0},
{pos:[41,1,32],state:0},
{pos:[42,1,32],state:0},
{pos:[43,1,32],state:0},
{pos:[44,1,32],state:0},
{pos:[45,1,32],state:0},
{pos:[46,1,32],state:0},
{pos:[0,1,33],state:0},
{pos:[1,1,33],state:0},
{pos:[2,1,33],state:0},
{pos:[3,1,33],state:0},
{pos:[4,1,33],state:0},
{pos:[5,1,33],state:0},
{pos:[6,1,33],state:0},
{pos:[7,1,33],state:0},
{pos:[8,1,33],state:0},
{pos:[9,1,33],state:0},
{pos:[10,1,33],state:0},
{pos:[11,1,33],state:0},
{pos:[12,1,33],state:0},
{pos:[18,1,33],state:0},
{pos:[19,1,33],state:0},
{pos:[20,1,33],state:0},
{pos:[21,1,33],state:0},
{pos:[22,1,33],state:0},
{pos:[23,1,33],state:0},
{pos:[24,1,33],state:0},
{pos:[25,1,33],state:0},
{pos:[26,1,33],state:0},
{pos:[27,1,33],state:0},
{pos:[28,1,33],state:0},
{pos:[29,1,33],state:0},
{pos:[30,1,33],state:0},
{pos:[31,1,33],state:0},
{pos:[32,1,33],state:0},
{pos:[33,1,33],state:0},
{pos:[34,1,33],state:0},
{pos:[35,1,33],state:0},
{pos:[36,1,33],state:0},
{pos:[37,1,33],state:0},
{pos:[38,1,33],state:0},
{pos:[39,1,33],state:0},
{pos:[40,1,33],state:0},
{pos:[41,1,33],state:0},
{pos:[42,1,33],state:0},
{pos:[43,1,33],state:0},
{pos:[44,1,33],state:0},
{pos:[45,1,33],state:0},
{pos:[46,1,33],state:0},
{pos:[0,2,0],state:0},
{pos:[1,2,0],state:0},
{pos:[2,2,0],state:0},
{pos:[3,2,0],state:0},
{pos:[4,2,0],state:0},
{pos:[5,2,0],state:0},
{pos:[6,2,0],state:0},
{pos:[7,2,0],state:0},
{pos:[8,2,0],state:0},
{pos:[9,2,0],state:0},
{pos:[10,2,0],state:0},
{pos:[11,2,0],state:0},
{pos:[12,2,0],state:0},
{pos:[13,2,0],state:0},
{pos:[14,2,0],state:0},
{pos:[15,2,0],state:0},
{pos:[16,2,0],state:0},
{pos:[17,2,0],state:0},
{pos:[18,2,0],state:0},
{pos:[19,2,0],state:0},
{pos:[20,2,0],state:0},
{pos:[26,2,0],state:0},
{pos:[27,2,0],state:0},
{pos:[28,2,0],state:0},
{pos:[29,2,0],state:0},
{pos:[30,2,0],state:0},
{pos:[31,2,0],state:0},
{pos:[32,2,0],state:0},
{pos:[33,2,0],state:0},
{pos:[34,2,0],state:0},
{pos:[35,2,0],state:0},
{pos:[36,2,0],state:0},
{pos:[37,2,0],state:0},
{pos:[38,2,0],state:0},
{pos:[39,2,0],state:0},
{pos:[40,2,0],state:0},
{pos:[41,2,0],state:0},
{pos:[42,2,0],state:0},
{pos:[43,2,0],state:0},
{pos:[44,2,0],state:0},
{pos:[45,2,0],state:0},
{pos:[46,2,0],state:0},
{pos:[0,2,1],state:0},
{pos:[1,2,1],state:0},
{pos:[2,2,1],state:0},
{pos:[3,2,1],state:0},
{pos:[4,2,1],state:0},
{pos:[5,2,1],state:0},
{pos:[6,2,1],state:0},
{pos:[7,2,1],state:0},
{pos:[8,2,1],state:0},
{pos:[9,2,1],state:0},
{pos:[10,2,1],state:0},
{pos:[11,2,1],state:0},
{pos:[12,2,1],state:0},
{pos:[13,2,1],state:0},
{pos:[14,2,1],state:0},
{pos:[15,2,1],state:0},
{pos:[16,2,1],state:0},
{pos:[17,2,1],state:0},
{pos:[18,2,1],state:0},
{pos:[19,2,1],state:0},
{pos:[20,2,1],state:0},
{pos:[26,2,1],state:0},
{pos:[27,2,1],state:0},
{pos:[28,2,1],state:0},
{pos:[29,2,1],state:0},
{pos:[30,2,1],state:0},
{pos:[31,2,1],state:0},
{pos:[32,2,1],state:0},
{pos:[33,2,1],state:0},
{pos:[34,2,1],state:0},
{pos:[35,2,1],state:0},
{pos:[36,2,1],state:0},
{pos:[37,2,1],state:0},
{pos:[38,2,1],state:0},
{pos:[39,2,1],state:0},
{pos:[40,2,1],state:0},
{pos:[41,2,1],state:0},
{pos:[42,2,1],state:0},
{pos:[43,2,1],state:0},
{pos:[44,2,1],state:0},
{pos:[45,2,1],state:0},
{pos:[46,2,1],state:0},
{pos:[0,2,2],state:0},
{pos:[1,2,2],state:0},
{pos:[4,2,2],state:2},
{pos:[11,2,2],state:2},
{pos:[18,2,2],state:2},
{pos:[25,2,2],state:2},
{pos:[32,2,2],state:2},
{pos:[39,2,2],state:2},
{pos:[45,2,2],state:0},
{pos:[46,2,2],state:0},
{pos:[0,2,3],state:0},
{pos:[1,2,3],state:0},
{pos:[45,2,3],state:0},
{pos:[46,2,3],state:0},
{pos:[0,2,4],state:0},
{pos:[1,2,4],state:0},
{pos:[45,2,4],state:0},
{pos:[46,2,4],state:0},
{pos:[0,2,5],state:0},
{pos:[1,2,5],state:0},
{pos:[2,2,5],state:2},
{pos:[44,2,5],state:2},
{pos:[45,2,5],state:0},
{pos:[46,2,5],state:0},
{pos:[0,2,6],state:0},
{pos:[1,2,6],state:0},
{pos:[45,2,6],state:0},
{pos:[46,2,6],state:0},
{pos:[0,2,7],state:0},
{pos:[1,2,7],state:0},
{pos:[17,2,7],state:2},
{pos:[29,2,7],state:2},
{pos:[45,2,7],state:0},
{pos:[46,2,7],state:0},
{pos:[0,2,8],state:0},
{pos:[1,2,8],state:0},
{pos:[45,2,8],state:0},
{pos:[46,2,8],state:0},
{pos:[0,2,9],state:0},
{pos:[1,2,9],state:0},
{pos:[45,2,9],state:0},
{pos:[46,2,9],state:0},
{pos:[0,2,10],state:0},
{pos:[1,2,10],state:0},
{pos:[45,2,10],state:0},
{pos:[46,2,10],state:0},
{pos:[0,2,11],state:0},
{pos:[1,2,11],state:0},
{pos:[45,2,11],state:0},
{pos:[46,2,11],state:0},
{pos:[0,2,12],state:0},
{pos:[1,2,12],state:0},
{pos:[45,2,12],state:0},
{pos:[46,2,12],state:0},
{pos:[0,2,13],state:0},
{pos:[1,2,13],state:0},
{pos:[2,2,13],state:2},
{pos:[44,2,13],state:2},
{pos:[45,2,13],state:0},
{pos:[46,2,13],state:0},
{pos:[0,2,14],state:0},
{pos:[1,2,14],state:0},
{pos:[17,2,14],state:2},
{pos:[29,2,14],state:2},
{pos:[45,2,14],state:0},
{pos:[46,2,14],state:0},
{pos:[0,2,15],state:0},
{pos:[1,2,15],state:0},
{pos:[45,2,15],state:0},
{pos:[46,2,15],state:0},
{pos:[0,2,16],state:0},
{pos:[1,2,16],state:0},
{pos:[45,2,16],state:0},
{pos:[46,2,16],state:0},
{pos:[0,2,17],state:0},
{pos:[1,2,17],state:0},
{pos:[45,2,17],state:0},
{pos:[46,2,17],state:0},
{pos:[0,2,18],state:0},
{pos:[1,2,18],state:0},
{pos:[45,2,18],state:0},
{pos:[46,2,18],state:0},
{pos:[0,2,19],state:0},
{pos:[1,2,19],state:0},
{pos:[45,2,19],state:0},
{pos:[46,2,19],state:0},
{pos:[0,2,20],state:0},
{pos:[1,2,20],state:0},
{pos:[45,2,20],state:0},
{pos:[46,2,20],state:0},
{pos:[0,2,21],state:0},
{pos:[1,2,21],state:0},
{pos:[2,2,21],state:2},
{pos:[17,2,21],state:2},
{pos:[29,2,21],state:2},
{pos:[44,2,21],state:2},
{pos:[45,2,21],state:0},
{pos:[46,2,21],state:0},
{pos:[0,2,22],state:0},
{pos:[1,2,22],state:0},
{pos:[45,2,22],state:0},
{pos:[46,2,22],state:0},
{pos:[0,2,23],state:0},
{pos:[1,2,23],state:0},
{pos:[45,2,23],state:0},
{pos:[46,2,23],state:0},
{pos:[0,2,24],state:0},
{pos:[1,2,24],state:0},
{pos:[45,2,24],state:0},
{pos:[46,2,24],state:0},
{pos:[0,2,25],state:0},
{pos:[1,2,25],state:0},
{pos:[45,2,25],state:0},
{pos:[46,2,25],state:0},
{pos:[0,2,26],state:0},
{pos:[1,2,26],state:0},
{pos:[45,2,26],state:0},
{pos:[46,2,26],state:0},
{pos:[0,2,27],state:0},
{pos:[1,2,27],state:0},
{pos:[45,2,27],state:0},
{pos:[46,2,27],state:0},
{pos:[0,2,28],state:0},
{pos:[1,2,28],state:0},
{pos:[17,2,28],state:2},
{pos:[29,2,28],state:2},
{pos:[45,2,28],state:0},
{pos:[46,2,28],state:0},
{pos:[0,2,29],state:0},
{pos:[1,2,29],state:0},
{pos:[2,2,29],state:2},
{pos:[44,2,29],state:2},
{pos:[45,2,29],state:0},
{pos:[46,2,29],state:0},
{pos:[0,2,30],state:0},
{pos:[1,2,30],state:0},
{pos:[45,2,30],state:0},
{pos:[46,2,30],state:0},
{pos:[0,2,31],state:0},
{pos:[1,2,31],state:0},
{pos:[4,2,31],state:2},
{pos:[11,2,31],state:2},
{pos:[18,2,31],state:2},
{pos:[25,2,31],state:2},
{pos:[32,2,31],state:2},
{pos:[39,2,31],state:2},
{pos:[45,2,31],state:0},
{pos:[46,2,31],state:0},
{pos:[0,2,32],state:0},
{pos:[1,2,32],state:0},
{pos:[2,2,32],state:0},
{pos:[3,2,32],state:0},
{pos:[4,2,32],state:0},
{pos:[5,2,32],state:0},
{pos:[6,2,32],state:0},
{pos:[7,2,32],state:0},
{pos:[8,2,32],state:0},
{pos:[9,2,32],state:0},
{pos:[10,2,32],state:0},
{pos:[11,2,32],state:0},
{pos:[12,2,32],state:0},
{pos:[18,2,32],state:0},
{pos:[19,2,32],state:0},
{pos:[20,2,32],state:0},
{pos:[21,2,32],state:0},
{pos:[22,2,32],state:0},
{pos:[23,2,32],state:0},
{pos:[24,2,32],state:0},
{pos:[25,2,32],state:0},
{pos:[26,2,32],state:0},
{pos:[27,2,32],state:0},
{pos:[28,2,32],state:0},
{pos:[29,2,32],state:0},
{pos:[30,2,32],state:0},
{pos:[31,2,32],state:0},
{pos:[32,2,32],state:0},
{pos:[33,2,32],state:0},
{pos:[34,2,32],state:0},
{pos:[35,2,32],state:0},
{pos:[36,2,32],state:0},
{pos:[37,2,32],state:0},
{pos:[38,2,32],state:0},
{pos:[39,2,32],state:0},
{pos:[40,2,32],state:0},
{pos:[41,2,32],state:0},
{pos:[42,2,32],state:0},
{pos:[43,2,32],state:0},
{pos:[44,2,32],state:0},
{pos:[45,2,32],state:0},
{pos:[46,2,32],state:0},
{pos:[0,2,33],state:0},
{pos:[1,2,33],state:0},
{pos:[2,2,33],state:0},
{pos:[3,2,33],state:0},
{pos:[4,2,33],state:0},
{pos:[5,2,33],state:0},
{pos:[6,2,33],state:0},
{pos:[7,2,33],state:0},
{pos:[8,2,33],state:0},
{pos:[9,2,33],state:0},
{pos:[10,2,33],state:0},
{pos:[11,2,33],state:0},
{pos:[12,2,33],state:0},
{pos:[18,2,33],state:0},
{pos:[19,2,33],state:0},
{pos:[20,2,33],state:0},
{pos:[21,2,33],state:0},
{pos:[22,2,33],state:0},
{pos:[23,2,33],state:0},
{pos:[24,2,33],state:0},
{pos:[25,2,33],state:0},
{pos:[26,2,33],state:0},
{pos:[27,2,33],state:0},
{pos:[28,2,33],state:0},
{pos:[29,2,33],state:0},
{pos:[30,2,33],state:0},
{pos:[31,2,33],state:0},
{pos:[32,2,33],state:0},
{pos:[33,2,33],state:0},
{pos:[34,2,33],state:0},
{pos:[35,2,33],state:0},
{pos:[36,2,33],state:0},
{pos:[37,2,33],state:0},
{pos:[38,2,33],state:0},
{pos:[39,2,33],state:0},
{pos:[40,2,33],state:0},
{pos:[41,2,33],state:0},
{pos:[42,2,33],state:0},
{pos:[43,2,33],state:0},
{pos:[44,2,33],state:0},
{pos:[45,2,33],state:0},
{pos:[46,2,33],state:0},
{pos:[0,3,0],state:0},
{pos:[1,3,0],state:0},
{pos:[2,3,0],state:0},
{pos:[3,3,0],state:0},
{pos:[4,3,0],state:0},
{pos:[5,3,0],state:0},
{pos:[6,3,0],state:0},
{pos:[7,3,0],state:0},
{pos:[8,3,0],state:0},
{pos:[9,3,0],state:0},
{pos:[10,3,0],state:0},
{pos:[11,3,0],state:0},
{pos:[12,3,0],state:0},
{pos:[13,3,0],state:0},
{pos:[14,3,0],state:0},
{pos:[15,3,0],state:0},
{pos:[16,3,0],state:0},
{pos:[17,3,0],state:0},
{pos:[18,3,0],state:0},
{pos:[19,3,0],state:0},
{pos:[20,3,0],state:0},
{pos:[26,3,0],state:0},
{pos:[27,3,0],state:0},
{pos:[28,3,0],state:0},
{pos:[29,3,0],state:0},
{pos:[30,3,0],state:0},
{pos:[31,3,0],state:0},
{pos:[32,3,0],state:0},
{pos:[33,3,0],state:0},
{pos:[34,3,0],state:0},
{pos:[35,3,0],state:0},
{pos:[36,3,0],state:0},
{pos:[37,3,0],state:0},
{pos:[38,3,0],state:0},
{pos:[39,3,0],state:0},
{pos:[40,3,0],state:0},
{pos:[41,3,0],state:0},
{pos:[42,3,0],state:0},
{pos:[43,3,0],state:0},
{pos:[44,3,0],state:0},
{pos:[45,3,0],state:0},
{pos:[46,3,0],state:0},
{pos:[0,3,1],state:0},
{pos:[1,3,1],state:0},
{pos:[2,3,1],state:0},
{pos:[3,3,1],state:0},
{pos:[4,3,1],state:0},
{pos:[5,3,1],state:0},
{pos:[6,3,1],state:0},
{pos:[7,3,1],state:0},
{pos:[8,3,1],state:0},
{pos:[9,3,1],state:0},
{pos:[10,3,1],state:0},
{pos:[11,3,1],state:0},
{pos:[12,3,1],state:0},
{pos:[13,3,1],state:0},
{pos:[14,3,1],state:0},
{pos:[15,3,1],state:0},
{pos:[16,3,1],state:0},
{pos:[17,3,1],state:0},
{pos:[18,3,1],state:0},
{pos:[19,3,1],state:0},
{pos:[20,3,1],state:0},
{pos:[26,3,1],state:0},
{pos:[27,3,1],state:0},
{pos:[28,3,1],state:0},
{pos:[29,3,1],state:0},
{pos:[30,3,1],state:0},
{pos:[31,3,1],state:0},
{pos:[32,3,1],state:0},
{pos:[33,3,1],state:0},
{pos:[34,3,1],state:0},
{pos:[35,3,1],state:0},
{pos:[36,3,1],state:0},
{pos:[37,3,1],state:0},
{pos:[38,3,1],state:0},
{pos:[39,3,1],state:0},
{pos:[40,3,1],state:0},
{pos:[41,3,1],state:0},
{pos:[42,3,1],state:0},
{pos:[43,3,1],state:0},
{pos:[44,3,1],state:0},
{pos:[45,3,1],state:0},
{pos:[46,3,1],state:0},
{pos:[0,3,2],state:0},
{pos:[1,3,2],state:0},
{pos:[4,3,2],state:2},
{pos:[11,3,2],state:2},
{pos:[18,3,2],state:2},
{pos:[25,3,2],state:2},
{pos:[32,3,2],state:2},
{pos:[39,3,2],state:2},
{pos:[45,3,2],state:0},
{pos:[46,3,2],state:0},
{pos:[0,3,3],state:0},
{pos:[1,3,3],state:0},
{pos:[45,3,3],state:0},
{pos:[46,3,3],state:0},
{pos:[0,3,4],state:0},
{pos:[1,3,4],state:0},
{pos:[45,3,4],state:0},
{pos:[46,3,4],state:0},
{pos:[0,3,5],state:0},
{pos:[1,3,5],state:0},
{pos:[2,3,5],state:2},
{pos:[44,3,5],state:2},
{pos:[45,3,5],state:0},
{pos:[46,3,5],state:0},
{pos:[0,3,6],state:0},
{pos:[1,3,6],state:0},
{pos:[45,3,6],state:0},
{pos:[46,3,6],state:0},
{pos:[0,3,7],state:0},
{pos:[1,3,7],state:0},
{pos:[17,3,7],state:2},
{pos:[29,3,7],state:2},
{pos:[45,3,7],state:0},
{pos:[46,3,7],state:0},
{pos:[0,3,8],state:0},
{pos:[1,3,8],state:0},
{pos:[45,3,8],state:0},
{pos:[46,3,8],state:0},
{pos:[0,3,9],state:0},
{pos:[1,3,9],state:0},
{pos:[45,3,9],state:0},
{pos:[46,3,9],state:0},
{pos:[0,3,10],state:0},
{pos:[1,3,10],state:0},
{pos:[45,3,10],state:0},
{pos:[46,3,10],state:0},
{pos:[0,3,11],state:0},
{pos:[1,3,11],state:0},
{pos:[45,3,11],state:0},
{pos:[46,3,11],state:0},
{pos:[0,3,12],state:0},
{pos:[1,3,12],state:0},
{pos:[45,3,12],state:0},
{pos:[46,3,12],state:0},
{pos:[0,3,13],state:0},
{pos:[1,3,13],state:0},
{pos:[2,3,13],state:2},
{pos:[44,3,13],state:2},
{pos:[45,3,13],state:0},
{pos:[46,3,13],state:0},
{pos:[0,3,14],state:0},
{pos:[1,3,14],state:0},
{pos:[17,3,14],state:2},
{pos:[29,3,14],state:2},
{pos:[45,3,14],state:0},
{pos:[46,3,14],state:0},
{pos:[0,3,15],state:0},
{pos:[1,3,15],state:0},
{pos:[45,3,15],state:0},
{pos:[46,3,15],state:0},
{pos:[0,3,16],state:0},
{pos:[1,3,16],state:0},
{pos:[45,3,16],state:0},
{pos:[46,3,16],state:0},
{pos:[0,3,17],state:0},
{pos:[1,3,17],state:0},
{pos:[45,3,17],state:0},
{pos:[46,3,17],state:0},
{pos:[0,3,18],state:0},
{pos:[1,3,18],state:0},
{pos:[45,3,18],state:0},
{pos:[46,3,18],state:0},
{pos:[0,3,19],state:0},
{pos:[1,3,19],state:0},
{pos:[45,3,19],state:0},
{pos:[46,3,19],state:0},
{pos:[0,3,20],state:0},
{pos:[1,3,20],state:0},
{pos:[45,3,20],state:0},
{pos:[46,3,20],state:0},
{pos:[0,3,21],state:0},
{pos:[1,3,21],state:0},
{pos:[2,3,21],state:2},
{pos:[17,3,21],state:2},
{pos:[29,3,21],state:2},
{pos:[44,3,21],state:2},
{pos:[45,3,21],state:0},
{pos:[46,3,21],state:0},
{pos:[0,3,22],state:0},
{pos:[1,3,22],state:0},
{pos:[45,3,22],state:0},
{pos:[46,3,22],state:0},
{pos:[0,3,23],state:0},
{pos:[1,3,23],state:0},
{pos:[45,3,23],state:0},
{pos:[46,3,23],state:0},
{pos:[0,3,24],state:0},
{pos:[1,3,24],state:0},
{pos:[45,3,24],state:0},
{pos:[46,3,24],state:0},
{pos:[0,3,25],state:0},
{pos:[1,3,25],state:0},
{pos:[45,3,25],state:0},
{pos:[46,3,25],state:0},
{pos:[0,3,26],state:0},
{pos:[1,3,26],state:0},
{pos:[45,3,26],state:0},
{pos:[46,3,26],state:0},
{pos:[0,3,27],state:0},
{pos:[1,3,27],state:0},
{pos:[45,3,27],state:0},
{pos:[46,3,27],state:0},
{pos:[0,3,28],state:0},
{pos:[1,3,28],state:0},
{pos:[17,3,28],state:2},
{pos:[29,3,28],state:2},
{pos:[45,3,28],state:0},
{pos:[46,3,28],state:0},
{pos:[0,3,29],state:0},
{pos:[1,3,29],state:0},
{pos:[2,3,29],state:2},
{pos:[44,3,29],state:2},
{pos:[45,3,29],state:0},
{pos:[46,3,29],state:0},
{pos:[0,3,30],state:0},
{pos:[1,3,30],state:0},
{pos:[45,3,30],state:0},
{pos:[46,3,30],state:0},
{pos:[0,3,31],state:0},
{pos:[1,3,31],state:0},
{pos:[4,3,31],state:2},
{pos:[11,3,31],state:2},
{pos:[18,3,31],state:2},
{pos:[25,3,31],state:2},
{pos:[32,3,31],state:2},
{pos:[39,3,31],state:2},
{pos:[45,3,31],state:0},
{pos:[46,3,31],state:0},
{pos:[0,3,32],state:0},
{pos:[1,3,32],state:0},
{pos:[2,3,32],state:0},
{pos:[3,3,32],state:0},
{pos:[4,3,32],state:0},
{pos:[5,3,32],state:0},
{pos:[6,3,32],state:0},
{pos:[7,3,32],state:0},
{pos:[8,3,32],state:0},
{pos:[9,3,32],state:0},
{pos:[10,3,32],state:0},
{pos:[11,3,32],state:0},
{pos:[12,3,32],state:0},
{pos:[18,3,32],state:0},
{pos:[19,3,32],state:0},
{pos:[20,3,32],state:0},
{pos:[21,3,32],state:0},
{pos:[22,3,32],state:0},
{pos:[23,3,32],state:0},
{pos:[24,3,32],state:0},
{pos:[25,3,32],state:0},
{pos:[26,3,32],state:0},
{pos:[27,3,32],state:0},
{pos:[28,3,32],state:0},
{pos:[29,3,32],state:0},
{pos:[30,3,32],state:0},
{pos:[31,3,32],state:0},
{pos:[32,3,32],state:0},
{pos:[33,3,32],state:0},
{pos:[34,3,32],state:0},
{pos:[35,3,32],state:0},
{pos:[36,3,32],state:0},
{pos:[37,3,32],state:0},
{pos:[38,3,32],state:0},
{pos:[39,3,32],state:0},
{pos:[40,3,32],state:0},
{pos:[41,3,32],state:0},
{pos:[42,3,32],state:0},
{pos:[43,3,32],state:0},
{pos:[44,3,32],state:0},
{pos:[45,3,32],state:0},
{pos:[46,3,32],state:0},
{pos:[0,3,33],state:0},
{pos:[1,3,33],state:0},
{pos:[2,3,33],state:0},
{pos:[3,3,33],state:0},
{pos:[4,3,33],state:0},
{pos:[5,3,33],state:0},
{pos:[6,3,33],state:0},
{pos:[7,3,33],state:0},
{pos:[8,3,33],state:0},
{pos:[9,3,33],state:0},
{pos:[10,3,33],state:0},
{pos:[11,3,33],state:0},
{pos:[12,3,33],state:0},
{pos:[18,3,33],state:0},
{pos:[19,3,33],state:0},
{pos:[20,3,33],state:0},
{pos:[21,3,33],state:0},
{pos:[22,3,33],state:0},
{pos:[23,3,33],state:0},
{pos:[24,3,33],state:0},
{pos:[25,3,33],state:0},
{pos:[26,3,33],state:0},
{pos:[27,3,33],state:0},
{pos:[28,3,33],state:0},
{pos:[29,3,33],state:0},
{pos:[30,3,33],state:0},
{pos:[31,3,33],state:0},
{pos:[32,3,33],state:0},
{pos:[33,3,33],state:0},
{pos:[34,3,33],state:0},
{pos:[35,3,33],state:0},
{pos:[36,3,33],state:0},
{pos:[37,3,33],state:0},
{pos:[38,3,33],state:0},
{pos:[39,3,33],state:0},
{pos:[40,3,33],state:0},
{pos:[41,3,33],state:0},
{pos:[42,3,33],state:0},
{pos:[43,3,33],state:0},
{pos:[44,3,33],state:0},
{pos:[45,3,33],state:0},
{pos:[46,3,33],state:0},
{pos:[0,4,0],state:0},
{pos:[1,4,0],state:0},
{pos:[2,4,0],state:0},
{pos:[3,4,0],state:0},
{pos:[4,4,0],state:0},
{pos:[5,4,0],state:0},
{pos:[6,4,0],state:0},
{pos:[7,4,0],state:0},
{pos:[8,4,0],state:0},
{pos:[9,4,0],state:0},
{pos:[10,4,0],state:0},
{pos:[11,4,0],state:0},
{pos:[12,4,0],state:0},
{pos:[13,4,0],state:0},
{pos:[14,4,0],state:0},
{pos:[15,4,0],state:0},
{pos:[16,4,0],state:0},
{pos:[17,4,0],state:0},
{pos:[18,4,0],state:0},
{pos:[19,4,0],state:0},
{pos:[20,4,0],state:0},
{pos:[26,4,0],state:0},
{pos:[27,4,0],state:0},
{pos:[28,4,0],state:0},
{pos:[29,4,0],state:0},
{pos:[30,4,0],state:0},
{pos:[31,4,0],state:0},
{pos:[32,4,0],state:0},
{pos:[33,4,0],state:0},
{pos:[34,4,0],state:0},
{pos:[35,4,0],state:0},
{pos:[36,4,0],state:0},
{pos:[37,4,0],state:0},
{pos:[38,4,0],state:0},
{pos:[39,4,0],state:0},
{pos:[40,4,0],state:0},
{pos:[41,4,0],state:0},
{pos:[42,4,0],state:0},
{pos:[43,4,0],state:0},
{pos:[44,4,0],state:0},
{pos:[45,4,0],state:0},
{pos:[46,4,0],state:0},
{pos:[0,4,1],state:0},
{pos:[1,4,1],state:0},
{pos:[2,4,1],state:0},
{pos:[3,4,1],state:0},
{pos:[4,4,1],state:0},
{pos:[5,4,1],state:0},
{pos:[6,4,1],state:0},
{pos:[7,4,1],state:0},
{pos:[8,4,1],state:0},
{pos:[9,4,1],state:0},
{pos:[10,4,1],state:0},
{pos:[11,4,1],state:0},
{pos:[12,4,1],state:0},
{pos:[13,4,1],state:0},
{pos:[14,4,1],state:0},
{pos:[15,4,1],state:0},
{pos:[16,4,1],state:0},
{pos:[17,4,1],state:0},
{pos:[18,4,1],state:0},
{pos:[19,4,1],state:0},
{pos:[20,4,1],state:0},
{pos:[26,4,1],state:0},
{pos:[27,4,1],state:0},
{pos:[28,4,1],state:0},
{pos:[29,4,1],state:0},
{pos:[30,4,1],state:0},
{pos:[31,4,1],state:0},
{pos:[32,4,1],state:0},
{pos:[33,4,1],state:0},
{pos:[34,4,1],state:0},
{pos:[35,4,1],state:0},
{pos:[36,4,1],state:0},
{pos:[37,4,1],state:0},
{pos:[38,4,1],state:0},
{pos:[39,4,1],state:0},
{pos:[40,4,1],state:0},
{pos:[41,4,1],state:0},
{pos:[42,4,1],state:0},
{pos:[43,4,1],state:0},
{pos:[44,4,1],state:0},
{pos:[45,4,1],state:0},
{pos:[46,4,1],state:0},
{pos:[0,4,2],state:0},
{pos:[1,4,2],state:0},
{pos:[4,4,2],state:2},
{pos:[11,4,2],state:2},
{pos:[18,4,2],state:2},
{pos:[25,4,2],state:2},
{pos:[32,4,2],state:2},
{pos:[39,4,2],state:2},
{pos:[45,4,2],state:0},
{pos:[46,4,2],state:0},
{pos:[0,4,3],state:0},
{pos:[1,4,3],state:0},
{pos:[45,4,3],state:0},
{pos:[46,4,3],state:0},
{pos:[0,4,4],state:0},
{pos:[1,4,4],state:0},
{pos:[45,4,4],state:0},
{pos:[46,4,4],state:0},
{pos:[0,4,5],state:0},
{pos:[1,4,5],state:0},
{pos:[2,4,5],state:2},
{pos:[44,4,5],state:2},
{pos:[45,4,5],state:0},
{pos:[46,4,5],state:0},
{pos:[0,4,6],state:0},
{pos:[1,4,6],state:0},
{pos:[45,4,6],state:0},
{pos:[46,4,6],state:0},
{pos:[0,4,7],state:0},
{pos:[1,4,7],state:0},
{pos:[17,4,7],state:2},
{pos:[29,4,7],state:2},
{pos:[45,4,7],state:0},
{pos:[46,4,7],state:0},
{pos:[0,4,8],state:0},
{pos:[1,4,8],state:0},
{pos:[45,4,8],state:0},
{pos:[46,4,8],state:0},
{pos:[0,4,9],state:0},
{pos:[1,4,9],state:0},
{pos:[45,4,9],state:0},
{pos:[46,4,9],state:0},
{pos:[0,4,10],state:0},
{pos:[1,4,10],state:0},
{pos:[45,4,10],state:0},
{pos:[46,4,10],state:0},
{pos:[0,4,11],state:0},
{pos:[1,4,11],state:0},
{pos:[45,4,11],state:0},
{pos:[46,4,11],state:0},
{pos:[0,4,12],state:0},
{pos:[1,4,12],state:0},
{pos:[45,4,12],state:0},
{pos:[46,4,12],state:0},
{pos:[0,4,13],state:0},
{pos:[1,4,13],state:0},
{pos:[2,4,13],state:2},
{pos:[44,4,13],state:2},
{pos:[45,4,13],state:0},
{pos:[46,4,13],state:0},
{pos:[0,4,14],state:0},
{pos:[1,4,14],state:0},
{pos:[17,4,14],state:2},
{pos:[29,4,14],state:2},
{pos:[45,4,14],state:0},
{pos:[46,4,14],state:0},
{pos:[0,4,15],state:0},
{pos:[1,4,15],state:0},
{pos:[45,4,15],state:0},
{pos:[46,4,15],state:0},
{pos:[0,4,16],state:0},
{pos:[1,4,16],state:0},
{pos:[45,4,16],state:0},
{pos:[46,4,16],state:0},
{pos:[0,4,17],state:0},
{pos:[1,4,17],state:0},
{pos:[45,4,17],state:0},
{pos:[46,4,17],state:0},
{pos:[0,4,18],state:0},
{pos:[1,4,18],state:0},
{pos:[45,4,18],state:0},
{pos:[46,4,18],state:0},
{pos:[0,4,19],state:0},
{pos:[1,4,19],state:0},
{pos:[45,4,19],state:0},
{pos:[46,4,19],state:0},
{pos:[0,4,20],state:0},
{pos:[1,4,20],state:0},
{pos:[45,4,20],state:0},
{pos:[46,4,20],state:0},
{pos:[0,4,21],state:0},
{pos:[1,4,21],state:0},
{pos:[2,4,21],state:2},
{pos:[17,4,21],state:2},
{pos:[29,4,21],state:2},
{pos:[44,4,21],state:2},
{pos:[45,4,21],state:0},
{pos:[46,4,21],state:0},
{pos:[0,4,22],state:0},
{pos:[1,4,22],state:0},
{pos:[45,4,22],state:0},
{pos:[46,4,22],state:0},
{pos:[0,4,23],state:0},
{pos:[1,4,23],state:0},
{pos:[45,4,23],state:0},
{pos:[46,4,23],state:0},
{pos:[0,4,24],state:0},
{pos:[1,4,24],state:0},
{pos:[45,4,24],state:0},
{pos:[46,4,24],state:0},
{pos:[0,4,25],state:0},
{pos:[1,4,25],state:0},
{pos:[45,4,25],state:0},
{pos:[46,4,25],state:0},
{pos:[0,4,26],state:0},
{pos:[1,4,26],state:0},
{pos:[45,4,26],state:0},
{pos:[46,4,26],state:0},
{pos:[0,4,27],state:0},
{pos:[1,4,27],state:0},
{pos:[45,4,27],state:0},
{pos:[46,4,27],state:0},
{pos:[0,4,28],state:0},
{pos:[1,4,28],state:0},
{pos:[17,4,28],state:2},
{pos:[29,4,28],state:2},
{pos:[45,4,28],state:0},
{pos:[46,4,28],state:0},
{pos:[0,4,29],state:0},
{pos:[1,4,29],state:0},
{pos:[2,4,29],state:2},
{pos:[44,4,29],state:2},
{pos:[45,4,29],state:0},
{pos:[46,4,29],state:0},
{pos:[0,4,30],state:0},
{pos:[1,4,30],state:0},
{pos:[45,4,30],state:0},
{pos:[46,4,30],state:0},
{pos:[0,4,31],state:0},
{pos:[1,4,31],state:0},
{pos:[4,4,31],state:2},
{pos:[11,4,31],state:2},
{pos:[18,4,31],state:2},
{pos:[25,4,31],state:2},
{pos:[32,4,31],state:2},
{pos:[39,4,31],state:2},
{pos:[45,4,31],state:0},
{pos:[46,4,31],state:0},
{pos:[0,4,32],state:0},
{pos:[1,4,32],state:0},
{pos:[2,4,32],state:0},
{pos:[3,4,32],state:0},
{pos:[4,4,32],state:0},
{pos:[5,4,32],state:0},
{pos:[6,4,32],state:0},
{pos:[7,4,32],state:0},
{pos:[8,4,32],state:0},
{pos:[9,4,32],state:0},
{pos:[10,4,32],state:0},
{pos:[11,4,32],state:0},
{pos:[12,4,32],state:0},
{pos:[18,4,32],state:0},
{pos:[19,4,32],state:0},
{pos:[20,4,32],state:0},
{pos:[21,4,32],state:0},
{pos:[22,4,32],state:0},
{pos:[23,4,32],state:0},
{pos:[24,4,32],state:0},
{pos:[25,4,32],state:0},
{pos:[26,4,32],state:0},
{pos:[27,4,32],state:0},
{pos:[28,4,32],state:0},
{pos:[29,4,32],state:0},
{pos:[30,4,32],state:0},
{pos:[31,4,32],state:0},
{pos:[32,4,32],state:0},
{pos:[33,4,32],state:0},
{pos:[34,4,32],state:0},
{pos:[35,4,32],state:0},
{pos:[36,4,32],state:0},
{pos:[37,4,32],state:0},
{pos:[38,4,32],state:0},
{pos:[39,4,32],state:0},
{pos:[40,4,32],state:0},
{pos:[41,4,32],state:0},
{pos:[42,4,32],state:0},
{pos:[43,4,32],state:0},
{pos:[44,4,32],state:0},
{pos:[45,4,32],state:0},
{pos:[46,4,32],state:0},
{pos:[0,4,33],state:0},
{pos:[1,4,33],state:0},
{pos:[2,4,33],state:0},
{pos:[3,4,33],state:0},
{pos:[4,4,33],state:0},
{pos:[5,4,33],state:0},
{pos:[6,4,33],state:0},
{pos:[7,4,33],state:0},
{pos:[8,4,33],state:0},
{pos:[9,4,33],state:0},
{pos:[10,4,33],state:0},
{pos:[11,4,33],state:0},
{pos:[12,4,33],state:0},
{pos:[18,4,33],state:0},
{pos:[19,4,33],state:0},
{pos:[20,4,33],state:0},
{pos:[21,4,33],state:0},
{pos:[22,4,33],state:0},
{pos:[23,4,33],state:0},
{pos:[24,4,33],state:0},
{pos:[25,4,33],state:0},
{pos:[26,4,33],state:0},
{pos:[27,4,33],state:0},
{pos:[28,4,33],state:0},
{pos:[29,4,33],state:0},
{pos:[30,4,33],state:0},
{pos:[31,4,33],state:0},
{pos:[32,4,33],state:0},
{pos:[33,4,33],state:0},
{pos:[34,4,33],state:0},
{pos:[35,4,33],state:0},
{pos:[36,4,33],state:0},
{pos:[37,4,33],state:0},
{pos:[38,4,33],state:0},
{pos:[39,4,33],state:0},
{pos:[40,4,33],state:0},
{pos:[41,4,33],state:0},
{pos:[42,4,33],state:0},
{pos:[43,4,33],state:0},
{pos:[44,4,33],state:0},
{pos:[45,4,33],state:0},
{pos:[46,4,33],state:0},
{pos:[0,5,0],state:0},
{pos:[1,5,0],state:0},
{pos:[2,5,0],state:0},
{pos:[3,5,0],state:0},
{pos:[4,5,0],state:0},
{pos:[5,5,0],state:0},
{pos:[6,5,0],state:0},
{pos:[7,5,0],state:0},
{pos:[8,5,0],state:0},
{pos:[9,5,0],state:0},
{pos:[10,5,0],state:0},
{pos:[11,5,0],state:0},
{pos:[12,5,0],state:0},
{pos:[13,5,0],state:0},
{pos:[14,5,0],state:0},
{pos:[15,5,0],state:0},
{pos:[16,5,0],state:0},
{pos:[17,5,0],state:0},
{pos:[18,5,0],state:0},
{pos:[19,5,0],state:0},
{pos:[20,5,0],state:0},
{pos:[26,5,0],state:0},
{pos:[27,5,0],state:0},
{pos:[28,5,0],state:0},
{pos:[29,5,0],state:0},
{pos:[30,5,0],state:0},
{pos:[31,5,0],state:0},
{pos:[32,5,0],state:0},
{pos:[33,5,0],state:0},
{pos:[34,5,0],state:0},
{pos:[35,5,0],state:0},
{pos:[36,5,0],state:0},
{pos:[37,5,0],state:0},
{pos:[38,5,0],state:0},
{pos:[39,5,0],state:0},
{pos:[40,5,0],state:0},
{pos:[41,5,0],state:0},
{pos:[42,5,0],state:0},
{pos:[43,5,0],state:0},
{pos:[44,5,0],state:0},
{pos:[45,5,0],state:0},
{pos:[46,5,0],state:0},
{pos:[0,5,1],state:0},
{pos:[1,5,1],state:0},
{pos:[2,5,1],state:0},
{pos:[3,5,1],state:0},
{pos:[4,5,1],state:0},
{pos:[5,5,1],state:0},
{pos:[6,5,1],state:0},
{pos:[7,5,1],state:0},
{pos:[8,5,1],state:0},
{pos:[9,5,1],state:0},
{pos:[10,5,1],state:0},
{pos:[11,5,1],state:0},
{pos:[12,5,1],state:0},
{pos:[13,5,1],state:0},
{pos:[14,5,1],state:0},
{pos:[15,5,1],state:0},
{pos:[16,5,1],state:0},
{pos:[17,5,1],state:0},
{pos:[18,5,1],state:0},
{pos:[19,5,1],state:0},
{pos:[20,5,1],state:0},
{pos:[26,5,1],state:0},
{pos:[27,5,1],state:0},
{pos:[28,5,1],state:0},
{pos:[29,5,1],state:0},
{pos:[30,5,1],state:0},
{pos:[31,5,1],state:0},
{pos:[32,5,1],state:0},
{pos:[33,5,1],state:0},
{pos:[34,5,1],state:0},
{pos:[35,5,1],state:0},
{pos:[36,5,1],state:0},
{pos:[37,5,1],state:0},
{pos:[38,5,1],state:0},
{pos:[39,5,1],state:0},
{pos:[40,5,1],state:0},
{pos:[41,5,1],state:0},
{pos:[42,5,1],state:0},
{pos:[43,5,1],state:0},
{pos:[44,5,1],state:0},
{pos:[45,5,1],state:0},
{pos:[46,5,1],state:0},
{pos:[0,5,2],state:0},
{pos:[1,5,2],state:0},
{pos:[4,5,2],state:2},
{pos:[11,5,2],state:2},
{pos:[18,5,2],state:2},
{pos:[25,5,2],state:2},
{pos:[32,5,2],state:2},
{pos:[39,5,2],state:2},
{pos:[45,5,2],state:0},
{pos:[46,5,2],state:0},
{pos:[0,5,3],state:0},
{pos:[1,5,3],state:0},
{pos:[45,5,3],state:0},
{pos:[46,5,3],state:0},
{pos:[0,5,4],state:0},
{pos:[1,5,4],state:0},
{pos:[45,5,4],state:0},
{pos:[46,5,4],state:0},
{pos:[0,5,5],state:0},
{pos:[1,5,5],state:0},
{pos:[2,5,5],state:2},
{pos:[44,5,5],state:2},
{pos:[45,5,5],state:0},
{pos:[46,5,5],state:0},
{pos:[0,5,6],state:0},
{pos:[1,5,6],state:0},
{pos:[45,5,6],state:0},
{pos:[46,5,6],state:0},
{pos:[0,5,7],state:0},
{pos:[1,5,7],state:0},
{pos:[17,5,7],state:2},
{pos:[29,5,7],state:2},
{pos:[45,5,7],state:0},
{pos:[46,5,7],state:0},
{pos:[0,5,8],state:0},
{pos:[1,5,8],state:0},
{pos:[45,5,8],state:0},
{pos:[46,5,8],state:0},
{pos:[0,5,9],state:0},
{pos:[1,5,9],state:0},
{pos:[45,5,9],state:0},
{pos:[46,5,9],state:0},
{pos:[0,5,10],state:0},
{pos:[1,5,10],state:0},
{pos:[45,5,10],state:0},
{pos:[46,5,10],state:0},
{pos:[0,5,11],state:0},
{pos:[1,5,11],state:0},
{pos:[45,5,11],state:0},
{pos:[46,5,11],state:0},
{pos:[0,5,12],state:0},
{pos:[1,5,12],state:0},
{pos:[45,5,12],state:0},
{pos:[46,5,12],state:0},
{pos:[0,5,13],state:0},
{pos:[1,5,13],state:0},
{pos:[2,5,13],state:2},
{pos:[44,5,13],state:2},
{pos:[45,5,13],state:0},
{pos:[46,5,13],state:0},
{pos:[0,5,14],state:0},
{pos:[1,5,14],state:0},
{pos:[17,5,14],state:2},
{pos:[29,5,14],state:2},
{pos:[45,5,14],state:0},
{pos:[46,5,14],state:0},
{pos:[0,5,15],state:0},
{pos:[1,5,15],state:0},
{pos:[45,5,15],state:0},
{pos:[46,5,15],state:0},
{pos:[0,5,16],state:0},
{pos:[1,5,16],state:0},
{pos:[45,5,16],state:0},
{pos:[46,5,16],state:0},
{pos:[0,5,17],state:0},
{pos:[1,5,17],state:0},
{pos:[45,5,17],state:0},
{pos:[46,5,17],state:0},
{pos:[0,5,18],state:0},
{pos:[1,5,18],state:0},
{pos:[45,5,18],state:0},
{pos:[46,5,18],state:0},
{pos:[0,5,19],state:0},
{pos:[1,5,19],state:0},
{pos:[45,5,19],state:0},
{pos:[46,5,19],state:0},
{pos:[0,5,20],state:0},
{pos:[1,5,20],state:0},
{pos:[45,5,20],state:0},
{pos:[46,5,20],state:0},
{pos:[0,5,21],state:0},
{pos:[1,5,21],state:0},
{pos:[2,5,21],state:2},
{pos:[17,5,21],state:2},
{pos:[29,5,21],state:2},
{pos:[44,5,21],state:2},
{pos:[45,5,21],state:0},
{pos:[46,5,21],state:0},
{pos:[0,5,22],state:0},
{pos:[1,5,22],state:0},
{pos:[45,5,22],state:0},
{pos:[46,5,22],state:0},
{pos:[0,5,23],state:0},
{pos:[1,5,23],state:0},
{pos:[45,5,23],state:0},
{pos:[46,5,23],state:0},
{pos:[0,5,24],state:0},
{pos:[1,5,24],state:0},
{pos:[45,5,24],state:0},
{pos:[46,5,24],state:0},
{pos:[0,5,25],state:0},
{pos:[1,5,25],state:0},
{pos:[45,5,25],state:0},
{pos:[46,5,25],state:0},
{pos:[0,5,26],state:0},
{pos:[1,5,26],state:0},
{pos:[45,5,26],state:0},
{pos:[46,5,26],state:0},
{pos:[0,5,27],state:0},
{pos:[1,5,27],state:0},
{pos:[45,5,27],state:0},
{pos:[46,5,27],state:0},
{pos:[0,5,28],state:0},
{pos:[1,5,28],state:0},
{pos:[17,5,28],state:2},
{pos:[29,5,28],state:2},
{pos:[45,5,28],state:0},
{pos:[46,5,28],state:0},
{pos:[0,5,29],state:0},
{pos:[1,5,29],state:0},
{pos:[2,5,29],state:2},
{pos:[44,5,29],state:2},
{pos:[45,5,29],state:0},
{pos:[46,5,29],state:0},
{pos:[0,5,30],state:0},
{pos:[1,5,30],state:0},
{pos:[45,5,30],state:0},
{pos:[46,5,30],state:0},
{pos:[0,5,31],state:0},
{pos:[1,5,31],state:0},
{pos:[4,5,31],state:2},
{pos:[11,5,31],state:2},
{pos:[18,5,31],state:2},
{pos:[25,5,31],state:2},
{pos:[32,5,31],state:2},
{pos:[39,5,31],state:2},
{pos:[45,5,31],state:0},
{pos:[46,5,31],state:0},
{pos:[0,5,32],state:0},
{pos:[1,5,32],state:0},
{pos:[2,5,32],state:0},
{pos:[3,5,32],state:0},
{pos:[4,5,32],state:0},
{pos:[5,5,32],state:0},
{pos:[6,5,32],state:0},
{pos:[7,5,32],state:0},
{pos:[8,5,32],state:0},
{pos:[9,5,32],state:0},
{pos:[10,5,32],state:0},
{pos:[11,5,32],state:0},
{pos:[12,5,32],state:0},
{pos:[18,5,32],state:0},
{pos:[19,5,32],state:0},
{pos:[20,5,32],state:0},
{pos:[21,5,32],state:0},
{pos:[22,5,32],state:0},
{pos:[23,5,32],state:0},
{pos:[24,5,32],state:0},
{pos:[25,5,32],state:0},
{pos:[26,5,32],state:0},
{pos:[27,5,32],state:0},
{pos:[28,5,32],state:0},
{pos:[29,5,32],state:0},
{pos:[30,5,32],state:0},
{pos:[31,5,32],state:0},
{pos:[32,5,32],state:0},
{pos:[33,5,32],state:0},
{pos:[34,5,32],state:0},
{pos:[35,5,32],state:0},
{pos:[36,5,32],state:0},
{pos:[37,5,32],state:0},
{pos:[38,5,32],state:0},
{pos:[39,5,32],state:0},
{pos:[40,5,32],state:0},
{pos:[41,5,32],state:0},
{pos:[42,5,32],state:0},
{pos:[43,5,32],state:0},
{pos:[44,5,32],state:0},
{pos:[45,5,32],state:0},
{pos:[46,5,32],state:0},
{pos:[0,5,33],state:0},
{pos:[1,5,33],state:0},
{pos:[2,5,33],state:0},
{pos:[3,5,33],state:0},
{pos:[4,5,33],state:0},
{pos:[5,5,33],state:0},
{pos:[6,5,33],state:0},
{pos:[7,5,33],state:0},
{pos:[8,5,33],state:0},
{pos:[9,5,33],state:0},
{pos:[10,5,33],state:0},
{pos:[11,5,33],state:0},
{pos:[12,5,33],state:0},
{pos:[18,5,33],state:0},
{pos:[19,5,33],state:0},
{pos:[20,5,33],state:0},
{pos:[21,5,33],state:0},
{pos:[22,5,33],state:0},
{pos:[23,5,33],state:0},
{pos:[24,5,33],state:0},
{pos:[25,5,33],state:0},
{pos:[26,5,33],state:0},
{pos:[27,5,33],state:0},
{pos:[28,5,33],state:0},
{pos:[29,5,33],state:0},
{pos:[30,5,33],state:0},
{pos:[31,5,33],state:0},
{pos:[32,5,33],state:0},
{pos:[33,5,33],state:0},
{pos:[34,5,33],state:0},
{pos:[35,5,33],state:0},
{pos:[36,5,33],state:0},
{pos:[37,5,33],state:0},
{pos:[38,5,33],state:0},
{pos:[39,5,33],state:0},
{pos:[40,5,33],state:0},
{pos:[41,5,33],state:0},
{pos:[42,5,33],state:0},
{pos:[43,5,33],state:0},
{pos:[44,5,33],state:0},
{pos:[45,5,33],state:0},
{pos:[46,5,33],state:0},
{pos:[0,6,0],state:0},
{pos:[1,6,0],state:0},
{pos:[2,6,0],state:0},
{pos:[3,6,0],state:0},
{pos:[4,6,0],state:0},
{pos:[5,6,0],state:0},
{pos:[6,6,0],state:0},
{pos:[7,6,0],state:0},
{pos:[8,6,0],state:0},
{pos:[9,6,0],state:0},
{pos:[10,6,0],state:0},
{pos:[11,6,0],state:0},
{pos:[12,6,0],state:0},
{pos:[13,6,0],state:0},
{pos:[14,6,0],state:0},
{pos:[15,6,0],state:0},
{pos:[16,6,0],state:0},
{pos:[17,6,0],state:0},
{pos:[18,6,0],state:0},
{pos:[19,6,0],state:0},
{pos:[20,6,0],state:0},
{pos:[21,6,0],state:0},
{pos:[22,6,0],state:0},
{pos:[23,6,0],state:0},
{pos:[24,6,0],state:0},
{pos:[25,6,0],state:0},
{pos:[26,6,0],state:0},
{pos:[27,6,0],state:0},
{pos:[28,6,0],state:0},
{pos:[29,6,0],state:0},
{pos:[30,6,0],state:0},
{pos:[31,6,0],state:0},
{pos:[32,6,0],state:0},
{pos:[33,6,0],state:0},
{pos:[34,6,0],state:0},
{pos:[35,6,0],state:0},
{pos:[36,6,0],state:0},
{pos:[37,6,0],state:0},
{pos:[38,6,0],state:0},
{pos:[39,6,0],state:0},
{pos:[40,6,0],state:0},
{pos:[41,6,0],state:0},
{pos:[42,6,0],state:0},
{pos:[43,6,0],state:0},
{pos:[44,6,0],state:0},
{pos:[45,6,0],state:0},
{pos:[46,6,0],state:0},
{pos:[0,6,1],state:0},
{pos:[1,6,1],state:0},
{pos:[2,6,1],state:0},
{pos:[3,6,1],state:0},
{pos:[4,6,1],state:0},
{pos:[5,6,1],state:0},
{pos:[6,6,1],state:0},
{pos:[7,6,1],state:0},
{pos:[8,6,1],state:0},
{pos:[9,6,1],state:0},
{pos:[10,6,1],state:0},
{pos:[11,6,1],state:0},
{pos:[12,6,1],state:0},
{pos:[13,6,1],state:0},
{pos:[14,6,1],state:0},
{pos:[15,6,1],state:0},
{pos:[16,6,1],state:0},
{pos:[17,6,1],state:0},
{pos:[18,6,1],state:0},
{pos:[19,6,1],state:0},
{pos:[20,6,1],state:0},
{pos:[21,6,1],state:0},
{pos:[22,6,1],state:0},
{pos:[23,6,1],state:0},
{pos:[24,6,1],state:0},
{pos:[25,6,1],state:0},
{pos:[26,6,1],state:0},
{pos:[27,6,1],state:0},
{pos:[28,6,1],state:0},
{pos:[29,6,1],state:0},
{pos:[30,6,1],state:0},
{pos:[31,6,1],state:0},
{pos:[32,6,1],state:0},
{pos:[33,6,1],state:0},
{pos:[34,6,1],state:0},
{pos:[35,6,1],state:0},
{pos:[36,6,1],state:0},
{pos:[37,6,1],state:0},
{pos:[38,6,1],state:0},
{pos:[39,6,1],state:0},
{pos:[40,6,1],state:0},
{pos:[41,6,1],state:0},
{pos:[42,6,1],state:0},
{pos:[43,6,1],state:0},
{pos:[44,6,1],state:0},
{pos:[45,6,1],state:0},
{pos:[46,6,1],state:0},
{pos:[0,6,2],state:0},
{pos:[1,6,2],state:0},
{pos:[45,6,2],state:0},
{pos:[46,6,2],state:0},
{pos:[0,6,3],state:0},
{pos:[1,6,3],state:0},
{pos:[3,6,3],state:3},
{pos:[43,6,3],state:3},
{pos:[45,6,3],state:0},
{pos:[46,6,3],state:0},
{pos:[0,6,4],state:0},
{pos:[1,6,4],state:0},
{pos:[45,6,4],state:0},
{pos:[46,6,4],state:0},
{pos:[0,6,5],state:0},
{pos:[1,6,5],state:0},
{pos:[45,6,5],state:0},
{pos:[46,6,5],state:0},
{pos:[0,6,6],state:0},
{pos:[1,6,6],state:0},
{pos:[45,6,6],state:0},
{pos:[46,6,6],state:0},
{pos:[0,6,7],state:0},
{pos:[1,6,7],state:0},
{pos:[17,6,7],state:2},
{pos:[29,6,7],state:2},
{pos:[45,6,7],state:0},
{pos:[46,6,7],state:0},
{pos:[0,6,8],state:0},
{pos:[1,6,8],state:0},
{pos:[45,6,8],state:0},
{pos:[46,6,8],state:0},
{pos:[0,6,9],state:0},
{pos:[1,6,9],state:0},
{pos:[45,6,9],state:0},
{pos:[46,6,9],state:0},
{pos:[0,6,10],state:0},
{pos:[1,6,10],state:0},
{pos:[45,6,10],state:0},
{pos:[46,6,10],state:0},
{pos:[0,6,11],state:0},
{pos:[1,6,11],state:0},
{pos:[45,6,11],state:0},
{pos:[46,6,11],state:0},
{pos:[0,6,12],state:0},
{pos:[1,6,12],state:0},
{pos:[45,6,12],state:0},
{pos:[46,6,12],state:0},
{pos:[0,6,13],state:0},
{pos:[1,6,13],state:0},
{pos:[45,6,13],state:0},
{pos:[46,6,13],state:0},
{pos:[0,6,14],state:0},
{pos:[1,6,14],state:0},
{pos:[17,6,14],state:2},
{pos:[29,6,14],state:2},
{pos:[45,6,14],state:0},
{pos:[46,6,14],state:0},
{pos:[0,6,15],state:0},
{pos:[1,6,15],state:0},
{pos:[45,6,15],state:0},
{pos:[46,6,15],state:0},
{pos:[0,6,16],state:0},
{pos:[1,6,16],state:0},
{pos:[45,6,16],state:0},
{pos:[46,6,16],state:0},
{pos:[0,6,17],state:0},
{pos:[1,6,17],state:0},
{pos:[45,6,17],state:0},
{pos:[46,6,17],state:0},
{pos:[0,6,18],state:0},
{pos:[1,6,18],state:0},
{pos:[45,6,18],state:0},
{pos:[46,6,18],state:0},
{pos:[0,6,19],state:0},
{pos:[1,6,19],state:0},
{pos:[45,6,19],state:0},
{pos:[46,6,19],state:0},
{pos:[0,6,20],state:0},
{pos:[1,6,20],state:0},
{pos:[45,6,20],state:0},
{pos:[46,6,20],state:0},
{pos:[0,6,21],state:0},
{pos:[1,6,21],state:0},
{pos:[17,6,21],state:2},
{pos:[29,6,21],state:2},
{pos:[45,6,21],state:0},
{pos:[46,6,21],state:0},
{pos:[0,6,22],state:0},
{pos:[1,6,22],state:0},
{pos:[45,6,22],state:0},
{pos:[46,6,22],state:0},
{pos:[0,6,23],state:0},
{pos:[1,6,23],state:0},
{pos:[45,6,23],state:0},
{pos:[46,6,23],state:0},
{pos:[0,6,24],state:0},
{pos:[1,6,24],state:0},
{pos:[45,6,24],state:0},
{pos:[46,6,24],state:0},
{pos:[0,6,25],state:0},
{pos:[1,6,25],state:0},
{pos:[45,6,25],state:0},
{pos:[46,6,25],state:0},
{pos:[0,6,26],state:0},
{pos:[1,6,26],state:0},
{pos:[45,6,26],state:0},
{pos:[46,6,26],state:0},
{pos:[0,6,27],state:0},
{pos:[1,6,27],state:0},
{pos:[45,6,27],state:0},
{pos:[46,6,27],state:0},
{pos:[0,6,28],state:0},
{pos:[1,6,28],state:0},
{pos:[17,6,28],state:2},
{pos:[29,6,28],state:2},
{pos:[45,6,28],state:0},
{pos:[46,6,28],state:0},
{pos:[0,6,29],state:0},
{pos:[1,6,29],state:0},
{pos:[45,6,29],state:0},
{pos:[46,6,29],state:0},
{pos:[0,6,30],state:0},
{pos:[1,6,30],state:0},
{pos:[3,6,30],state:3},
{pos:[43,6,30],state:3},
{pos:[45,6,30],state:0},
{pos:[46,6,30],state:0},
{pos:[0,6,31],state:0},
{pos:[1,6,31],state:0},
{pos:[45,6,31],state:0},
{pos:[46,6,31],state:0},
{pos:[0,6,32],state:0},
{pos:[1,6,32],state:0},
{pos:[2,6,32],state:0},
{pos:[3,6,32],state:0},
{pos:[4,6,32],state:0},
{pos:[5,6,32],state:0},
{pos:[6,6,32],state:0},
{pos:[7,6,32],state:0},
{pos:[8,6,32],state:0},
{pos:[9,6,32],state:0},
{pos:[10,6,32],state:0},
{pos:[11,6,32],state:0},
{pos:[12,6,32],state:0},
{pos:[13,6,32],state:0},
{pos:[14,6,32],state:0},
{pos:[15,6,32],state:0},
{pos:[16,6,32],state:0},
{pos:[17,6,32],state:0},
{pos:[18,6,32],state:0},
{pos:[19,6,32],state:0},
{pos:[20,6,32],state:0},
{pos:[21,6,32],state:0},
{pos:[22,6,32],state:0},
{pos:[23,6,32],state:0},
{pos:[24,6,32],state:0},
{pos:[25,6,32],state:0},
{pos:[26,6,32],state:0},
{pos:[27,6,32],state:0},
{pos:[28,6,32],state:0},
{pos:[29,6,32],state:0},
{pos:[30,6,32],state:0},
{pos:[31,6,32],state:0},
{pos:[32,6,32],state:0},
{pos:[33,6,32],state:0},
{pos:[34,6,32],state:0},
{pos:[35,6,32],state:0},
{pos:[36,6,32],state:0},
{pos:[37,6,32],state:0},
{pos:[38,6,32],state:0},
{pos:[39,6,32],state:0},
{pos:[40,6,32],state:0},
{pos:[41,6,32],state:0},
{pos:[42,6,32],state:0},
{pos:[43,6,32],state:0},
{pos:[44,6,32],state:0},
{pos:[45,6,32],state:0},
{pos:[46,6,32],state:0},
{pos:[0,6,33],state:0},
{pos:[1,6,33],state:0},
{pos:[2,6,33],state:0},
{pos:[3,6,33],state:0},
{pos:[4,6,33],state:0},
{pos:[5,6,33],state:0},
{pos:[6,6,33],state:0},
{pos:[7,6,33],state:0},
{pos:[8,6,33],state:0},
{pos:[9,6,33],state:0},
{pos:[10,6,33],state:0},
{pos:[11,6,33],state:0},
{pos:[12,6,33],state:0},
{pos:[13,6,33],state:0},
{pos:[14,6,33],state:0},
{pos:[15,6,33],state:0},
{pos:[16,6,33],state:0},
{pos:[17,6,33],state:0},
{pos:[18,6,33],state:0},
{pos:[19,6,33],state:0},
{pos:[20,6,33],state:0},
{pos:[21,6,33],state:0},
{pos:[22,6,33],state:0},
{pos:[23,6,33],state:0},
{pos:[24,6,33],state:0},
{pos:[25,6,33],state:0},
{pos:[26,6,33],state:0},
{pos:[27,6,33],state:0},
{pos:[28,6,33],state:0},
{pos:[29,6,33],state:0},
{pos:[30,6,33],state:0},
{pos:[31,6,33],state:0},
{pos:[32,6,33],state:0},
{pos:[33,6,33],state:0},
{pos:[34,6,33],state:0},
{pos:[35,6,33],state:0},
{pos:[36,6,33],state:0},
{pos:[37,6,33],state:0},
{pos:[38,6,33],state:0},
{pos:[39,6,33],state:0},
{pos:[40,6,33],state:0},
{pos:[41,6,33],state:0},
{pos:[42,6,33],state:0},
{pos:[43,6,33],state:0},
{pos:[44,6,33],state:0},
{pos:[45,6,33],state:0},
{pos:[46,6,33],state:0},
{pos:[0,7,0],state:0},
{pos:[1,7,0],state:0},
{pos:[2,7,0],state:0},
{pos:[3,7,0],state:0},
{pos:[4,7,0],state:0},
{pos:[5,7,0],state:0},
{pos:[6,7,0],state:0},
{pos:[7,7,0],state:0},
{pos:[8,7,0],state:0},
{pos:[9,7,0],state:0},
{pos:[10,7,0],state:0},
{pos:[11,7,0],state:0},
{pos:[12,7,0],state:0},
{pos:[13,7,0],state:0},
{pos:[14,7,0],state:0},
{pos:[15,7,0],state:0},
{pos:[16,7,0],state:0},
{pos:[17,7,0],state:0},
{pos:[18,7,0],state:0},
{pos:[19,7,0],state:0},
{pos:[20,7,0],state:0},
{pos:[21,7,0],state:0},
{pos:[22,7,0],state:0},
{pos:[23,7,0],state:0},
{pos:[24,7,0],state:0},
{pos:[25,7,0],state:0},
{pos:[26,7,0],state:0},
{pos:[27,7,0],state:0},
{pos:[28,7,0],state:0},
{pos:[29,7,0],state:0},
{pos:[30,7,0],state:0},
{pos:[31,7,0],state:0},
{pos:[32,7,0],state:0},
{pos:[33,7,0],state:0},
{pos:[34,7,0],state:0},
{pos:[35,7,0],state:0},
{pos:[36,7,0],state:0},
{pos:[37,7,0],state:0},
{pos:[38,7,0],state:0},
{pos:[39,7,0],state:0},
{pos:[40,7,0],state:0},
{pos:[41,7,0],state:0},
{pos:[42,7,0],state:0},
{pos:[43,7,0],state:0},
{pos:[44,7,0],state:0},
{pos:[45,7,0],state:0},
{pos:[46,7,0],state:0},
{pos:[0,7,1],state:0},
{pos:[1,7,1],state:0},
{pos:[2,7,1],state:0},
{pos:[3,7,1],state:0},
{pos:[4,7,1],state:0},
{pos:[5,7,1],state:0},
{pos:[6,7,1],state:0},
{pos:[7,7,1],state:0},
{pos:[8,7,1],state:0},
{pos:[9,7,1],state:0},
{pos:[10,7,1],state:0},
{pos:[11,7,1],state:0},
{pos:[12,7,1],state:0},
{pos:[13,7,1],state:0},
{pos:[14,7,1],state:0},
{pos:[15,7,1],state:0},
{pos:[16,7,1],state:0},
{pos:[17,7,1],state:0},
{pos:[18,7,1],state:0},
{pos:[19,7,1],state:0},
{pos:[20,7,1],state:0},
{pos:[21,7,1],state:0},
{pos:[22,7,1],state:0},
{pos:[23,7,1],state:0},
{pos:[24,7,1],state:0},
{pos:[25,7,1],state:0},
{pos:[26,7,1],state:0},
{pos:[27,7,1],state:0},
{pos:[28,7,1],state:0},
{pos:[29,7,1],state:0},
{pos:[30,7,1],state:0},
{pos:[31,7,1],state:0},
{pos:[32,7,1],state:0},
{pos:[33,7,1],state:0},
{pos:[34,7,1],state:0},
{pos:[35,7,1],state:0},
{pos:[36,7,1],state:0},
{pos:[37,7,1],state:0},
{pos:[38,7,1],state:0},
{pos:[39,7,1],state:0},
{pos:[40,7,1],state:0},
{pos:[41,7,1],state:0},
{pos:[42,7,1],state:0},
{pos:[43,7,1],state:0},
{pos:[44,7,1],state:0},
{pos:[45,7,1],state:0},
{pos:[46,7,1],state:0},
{pos:[0,7,2],state:0},
{pos:[1,7,2],state:0},
{pos:[45,7,2],state:0},
{pos:[46,7,2],state:0},
{pos:[0,7,3],state:0},
{pos:[1,7,3],state:0},
{pos:[45,7,3],state:0},
{pos:[46,7,3],state:0},
{pos:[0,7,4],state:0},
{pos:[1,7,4],state:0},
{pos:[45,7,4],state:0},
{pos:[46,7,4],state:0},
{pos:[0,7,5],state:0},
{pos:[1,7,5],state:0},
{pos:[45,7,5],state:0},
{pos:[46,7,5],state:0},
{pos:[0,7,6],state:0},
{pos:[1,7,6],state:0},
{pos:[45,7,6],state:0},
{pos:[46,7,6],state:0},
{pos:[0,7,7],state:0},
{pos:[1,7,7],state:0},
{pos:[17,7,7],state:2},
{pos:[29,7,7],state:2},
{pos:[45,7,7],state:0},
{pos:[46,7,7],state:0},
{pos:[0,7,8],state:0},
{pos:[1,7,8],state:0},
{pos:[45,7,8],state:0},
{pos:[46,7,8],state:0},
{pos:[0,7,9],state:0},
{pos:[1,7,9],state:0},
{pos:[45,7,9],state:0},
{pos:[46,7,9],state:0},
{pos:[0,7,10],state:0},
{pos:[1,7,10],state:0},
{pos:[45,7,10],state:0},
{pos:[46,7,10],state:0},
{pos:[0,7,11],state:0},
{pos:[1,7,11],state:0},
{pos:[45,7,11],state:0},
{pos:[46,7,11],state:0},
{pos:[0,7,12],state:0},
{pos:[1,7,12],state:0},
{pos:[45,7,12],state:0},
{pos:[46,7,12],state:0},
{pos:[0,7,13],state:0},
{pos:[1,7,13],state:0},
{pos:[45,7,13],state:0},
{pos:[46,7,13],state:0},
{pos:[0,7,14],state:0},
{pos:[1,7,14],state:0},
{pos:[17,7,14],state:2},
{pos:[29,7,14],state:2},
{pos:[45,7,14],state:0},
{pos:[46,7,14],state:0},
{pos:[0,7,15],state:0},
{pos:[1,7,15],state:0},
{pos:[45,7,15],state:0},
{pos:[46,7,15],state:0},
{pos:[0,7,16],state:0},
{pos:[1,7,16],state:0},
{pos:[45,7,16],state:0},
{pos:[46,7,16],state:0},
{pos:[0,7,17],state:0},
{pos:[1,7,17],state:0},
{pos:[45,7,17],state:0},
{pos:[46,7,17],state:0},
{pos:[0,7,18],state:0},
{pos:[1,7,18],state:0},
{pos:[45,7,18],state:0},
{pos:[46,7,18],state:0},
{pos:[0,7,19],state:0},
{pos:[1,7,19],state:0},
{pos:[45,7,19],state:0},
{pos:[46,7,19],state:0},
{pos:[0,7,20],state:0},
{pos:[1,7,20],state:0},
{pos:[45,7,20],state:0},
{pos:[46,7,20],state:0},
{pos:[0,7,21],state:0},
{pos:[1,7,21],state:0},
{pos:[17,7,21],state:2},
{pos:[29,7,21],state:2},
{pos:[45,7,21],state:0},
{pos:[46,7,21],state:0},
{pos:[0,7,22],state:0},
{pos:[1,7,22],state:0},
{pos:[45,7,22],state:0},
{pos:[46,7,22],state:0},
{pos:[0,7,23],state:0},
{pos:[1,7,23],state:0},
{pos:[45,7,23],state:0},
{pos:[46,7,23],state:0},
{pos:[0,7,24],state:0},
{pos:[1,7,24],state:0},
{pos:[45,7,24],state:0},
{pos:[46,7,24],state:0},
{pos:[0,7,25],state:0},
{pos:[1,7,25],state:0},
{pos:[45,7,25],state:0},
{pos:[46,7,25],state:0},
{pos:[0,7,26],state:0},
{pos:[1,7,26],state:0},
{pos:[45,7,26],state:0},
{pos:[46,7,26],state:0},
{pos:[0,7,27],state:0},
{pos:[1,7,27],state:0},
{pos:[45,7,27],state:0},
{pos:[46,7,27],state:0},
{pos:[0,7,28],state:0},
{pos:[1,7,28],state:0},
{pos:[17,7,28],state:2},
{pos:[29,7,28],state:2},
{pos:[45,7,28],state:0},
{pos:[46,7,28],state:0},
{pos:[0,7,29],state:0},
{pos:[1,7,29],state:0},
{pos:[45,7,29],state:0},
{pos:[46,7,29],state:0},
{pos:[0,7,30],state:0},
{pos:[1,7,30],state:0},
{pos:[45,7,30],state:0},
{pos:[46,7,30],state:0},
{pos:[0,7,31],state:0},
{pos:[1,7,31],state:0},
{pos:[45,7,31],state:0},
{pos:[46,7,31],state:0},
{pos:[0,7,32],state:0},
{pos:[1,7,32],state:0},
{pos:[2,7,32],state:0},
{pos:[3,7,32],state:0},
{pos:[4,7,32],state:0},
{pos:[5,7,32],state:0},
{pos:[6,7,32],state:0},
{pos:[7,7,32],state:0},
{pos:[8,7,32],state:0},
{pos:[9,7,32],state:0},
{pos:[10,7,32],state:0},
{pos:[11,7,32],state:0},
{pos:[12,7,32],state:0},
{pos:[13,7,32],state:0},
{pos:[14,7,32],state:0},
{pos:[15,7,32],state:0},
{pos:[16,7,32],state:0},
{pos:[17,7,32],state:0},
{pos:[18,7,32],state:0},
{pos:[19,7,32],state:0},
{pos:[20,7,32],state:0},
{pos:[21,7,32],state:0},
{pos:[22,7,32],state:0},
{pos:[23,7,32],state:0},
{pos:[24,7,32],state:0},
{pos:[25,7,32],state:0},
{pos:[26,7,32],state:0},
{pos:[27,7,32],state:0},
{pos:[28,7,32],state:0},
{pos:[29,7,32],state:0},
{pos:[30,7,32],state:0},
{pos:[31,7,32],state:0},
{pos:[32,7,32],state:0},
{pos:[33,7,32],state:0},
{pos:[34,7,32],state:0},
{pos:[35,7,32],state:0},
{pos:[36,7,32],state:0},
{pos:[37,7,32],state:0},
{pos:[38,7,32],state:0},
{pos:[39,7,32],state:0},
{pos:[40,7,32],state:0},
{pos:[41,7,32],state:0},
{pos:[42,7,32],state:0},
{pos:[43,7,32],state:0},
{pos:[44,7,32],state:0},
{pos:[45,7,32],state:0},
{pos:[46,7,32],state:0},
{pos:[0,7,33],state:0},
{pos:[1,7,33],state:0},
{pos:[2,7,33],state:0},
{pos:[3,7,33],state:0},
{pos:[4,7,33],state:0},
{pos:[5,7,33],state:0},
{pos:[6,7,33],state:0},
{pos:[7,7,33],state:0},
{pos:[8,7,33],state:0},
{pos:[9,7,33],state:0},
{pos:[10,7,33],state:0},
{pos:[11,7,33],state:0},
{pos:[12,7,33],state:0},
{pos:[13,7,33],state:0},
{pos:[14,7,33],state:0},
{pos:[15,7,33],state:0},
{pos:[16,7,33],state:0},
{pos:[17,7,33],state:0},
{pos:[18,7,33],state:0},
{pos:[19,7,33],state:0},
{pos:[20,7,33],state:0},
{pos:[21,7,33],state:0},
{pos:[22,7,33],state:0},
{pos:[23,7,33],state:0},
{pos:[24,7,33],state:0},
{pos:[25,7,33],state:0},
{pos:[26,7,33],state:0},
{pos:[27,7,33],state:0},
{pos:[28,7,33],state:0},
{pos:[29,7,33],state:0},
{pos:[30,7,33],state:0},
{pos:[31,7,33],state:0},
{pos:[32,7,33],state:0},
{pos:[33,7,33],state:0},
{pos:[34,7,33],state:0},
{pos:[35,7,33],state:0},
{pos:[36,7,33],state:0},
{pos:[37,7,33],state:0},
{pos:[38,7,33],state:0},
{pos:[39,7,33],state:0},
{pos:[40,7,33],state:0},
{pos:[41,7,33],state:0},
{pos:[42,7,33],state:0},
{pos:[43,7,33],state:0},
{pos:[44,7,33],state:0},
{pos:[45,7,33],state:0},
{pos:[46,7,33],state:0},
{pos:[0,8,0],state:0},
{pos:[1,8,0],state:0},
{pos:[2,8,0],state:0},
{pos:[3,8,0],state:0},
{pos:[4,8,0],state:0},
{pos:[5,8,0],state:0},
{pos:[6,8,0],state:0},
{pos:[7,8,0],state:0},
{pos:[8,8,0],state:0},
{pos:[9,8,0],state:0},
{pos:[10,8,0],state:0},
{pos:[11,8,0],state:0},
{pos:[12,8,0],state:0},
{pos:[13,8,0],state:0},
{pos:[14,8,0],state:0},
{pos:[15,8,0],state:0},
{pos:[16,8,0],state:0},
{pos:[17,8,0],state:0},
{pos:[18,8,0],state:0},
{pos:[19,8,0],state:0},
{pos:[20,8,0],state:0},
{pos:[21,8,0],state:0},
{pos:[22,8,0],state:0},
{pos:[23,8,0],state:0},
{pos:[24,8,0],state:0},
{pos:[25,8,0],state:0},
{pos:[26,8,0],state:0},
{pos:[27,8,0],state:0},
{pos:[28,8,0],state:0},
{pos:[29,8,0],state:0},
{pos:[30,8,0],state:0},
{pos:[31,8,0],state:0},
{pos:[32,8,0],state:0},
{pos:[33,8,0],state:0},
{pos:[34,8,0],state:0},
{pos:[35,8,0],state:0},
{pos:[36,8,0],state:0},
{pos:[37,8,0],state:0},
{pos:[38,8,0],state:0},
{pos:[39,8,0],state:0},
{pos:[40,8,0],state:0},
{pos:[41,8,0],state:0},
{pos:[42,8,0],state:0},
{pos:[43,8,0],state:0},
{pos:[44,8,0],state:0},
{pos:[45,8,0],state:0},
{pos:[46,8,0],state:0},
{pos:[0,8,1],state:0},
{pos:[1,8,1],state:0},
{pos:[2,8,1],state:0},
{pos:[3,8,1],state:0},
{pos:[4,8,1],state:0},
{pos:[5,8,1],state:0},
{pos:[6,8,1],state:0},
{pos:[7,8,1],state:0},
{pos:[8,8,1],state:0},
{pos:[9,8,1],state:0},
{pos:[10,8,1],state:0},
{pos:[11,8,1],state:0},
{pos:[12,8,1],state:0},
{pos:[13,8,1],state:0},
{pos:[14,8,1],state:0},
{pos:[15,8,1],state:0},
{pos:[16,8,1],state:0},
{pos:[17,8,1],state:0},
{pos:[18,8,1],state:0},
{pos:[19,8,1],state:0},
{pos:[20,8,1],state:0},
{pos:[21,8,1],state:0},
{pos:[22,8,1],state:0},
{pos:[23,8,1],state:0},
{pos:[24,8,1],state:0},
{pos:[25,8,1],state:0},
{pos:[26,8,1],state:0},
{pos:[27,8,1],state:0},
{pos:[28,8,1],state:0},
{pos:[29,8,1],state:0},
{pos:[30,8,1],state:0},
{pos:[31,8,1],state:0},
{pos:[32,8,1],state:0},
{pos:[33,8,1],state:0},
{pos:[34,8,1],state:0},
{pos:[35,8,1],state:0},
{pos:[36,8,1],state:0},
{pos:[37,8,1],state:0},
{pos:[38,8,1],state:0},
{pos:[39,8,1],state:0},
{pos:[40,8,1],state:0},
{pos:[41,8,1],state:0},
{pos:[42,8,1],state:0},
{pos:[43,8,1],state:0},
{pos:[44,8,1],state:0},
{pos:[45,8,1],state:0},
{pos:[46,8,1],state:0},
{pos:[0,8,2],state:0},
{pos:[1,8,2],state:0},
{pos:[45,8,2],state:0},
{pos:[46,8,2],state:0},
{pos:[0,8,3],state:0},
{pos:[1,8,3],state:0},
{pos:[45,8,3],state:0},
{pos:[46,8,3],state:0},
{pos:[0,8,4],state:0},
{pos:[1,8,4],state:0},
{pos:[45,8,4],state:0},
{pos:[46,8,4],state:0},
{pos:[0,8,5],state:0},
{pos:[1,8,5],state:0},
{pos:[45,8,5],state:0},
{pos:[46,8,5],state:0},
{pos:[0,8,6],state:0},
{pos:[1,8,6],state:0},
{pos:[45,8,6],state:0},
{pos:[46,8,6],state:0},
{pos:[0,8,7],state:0},
{pos:[1,8,7],state:0},
{pos:[45,8,7],state:0},
{pos:[46,8,7],state:0},
{pos:[0,8,8],state:0},
{pos:[1,8,8],state:0},
{pos:[45,8,8],state:0},
{pos:[46,8,8],state:0},
{pos:[0,8,9],state:0},
{pos:[1,8,9],state:0},
{pos:[45,8,9],state:0},
{pos:[46,8,9],state:0},
{pos:[0,8,10],state:0},
{pos:[1,8,10],state:0},
{pos:[45,8,10],state:0},
{pos:[46,8,10],state:0},
{pos:[0,8,11],state:0},
{pos:[1,8,11],state:0},
{pos:[45,8,11],state:0},
{pos:[46,8,11],state:0},
{pos:[0,8,12],state:0},
{pos:[1,8,12],state:0},
{pos:[45,8,12],state:0},
{pos:[46,8,12],state:0},
{pos:[0,8,13],state:0},
{pos:[1,8,13],state:0},
{pos:[45,8,13],state:0},
{pos:[46,8,13],state:0},
{pos:[0,8,14],state:0},
{pos:[1,8,14],state:0},
{pos:[45,8,14],state:0},
{pos:[46,8,14],state:0},
{pos:[0,8,15],state:0},
{pos:[1,8,15],state:0},
{pos:[45,8,15],state:0},
{pos:[46,8,15],state:0},
{pos:[0,8,16],state:0},
{pos:[1,8,16],state:0},
{pos:[45,8,16],state:0},
{pos:[46,8,16],state:0},
{pos:[0,8,17],state:0},
{pos:[1,8,17],state:0},
{pos:[45,8,17],state:0},
{pos:[46,8,17],state:0},
{pos:[0,8,18],state:0},
{pos:[1,8,18],state:0},
{pos:[45,8,18],state:0},
{pos:[46,8,18],state:0},
{pos:[0,8,19],state:0},
{pos:[1,8,19],state:0},
{pos:[45,8,19],state:0},
{pos:[46,8,19],state:0},
{pos:[0,8,20],state:0},
{pos:[1,8,20],state:0},
{pos:[45,8,20],state:0},
{pos:[46,8,20],state:0},
{pos:[0,8,21],state:0},
{pos:[1,8,21],state:0},
{pos:[45,8,21],state:0},
{pos:[46,8,21],state:0},
{pos:[0,8,22],state:0},
{pos:[1,8,22],state:0},
{pos:[45,8,22],state:0},
{pos:[46,8,22],state:0},
{pos:[0,8,23],state:0},
{pos:[1,8,23],state:0},
{pos:[45,8,23],state:0},
{pos:[46,8,23],state:0},
{pos:[0,8,24],state:0},
{pos:[1,8,24],state:0},
{pos:[45,8,24],state:0},
{pos:[46,8,24],state:0},
{pos:[0,8,25],state:0},
{pos:[1,8,25],state:0},
{pos:[45,8,25],state:0},
{pos:[46,8,25],state:0},
{pos:[0,8,26],state:0},
{pos:[1,8,26],state:0},
{pos:[45,8,26],state:0},
{pos:[46,8,26],state:0},
{pos:[0,8,27],state:0},
{pos:[1,8,27],state:0},
{pos:[45,8,27],state:0},
{pos:[46,8,27],state:0},
{pos:[0,8,28],state:0},
{pos:[1,8,28],state:0},
{pos:[45,8,28],state:0},
{pos:[46,8,28],state:0},
{pos:[0,8,29],state:0},
{pos:[1,8,29],state:0},
{pos:[45,8,29],state:0},
{pos:[46,8,29],state:0},
{pos:[0,8,30],state:0},
{pos:[1,8,30],state:0},
{pos:[45,8,30],state:0},
{pos:[46,8,30],state:0},
{pos:[0,8,31],state:0},
{pos:[1,8,31],state:0},
{pos:[45,8,31],state:0},
{pos:[46,8,31],state:0},
{pos:[0,8,32],state:0},
{pos:[1,8,32],state:0},
{pos:[2,8,32],state:0},
{pos:[3,8,32],state:0},
{pos:[4,8,32],state:0},
{pos:[5,8,32],state:0},
{pos:[6,8,32],state:0},
{pos:[7,8,32],state:0},
{pos:[8,8,32],state:0},
{pos:[9,8,32],state:0},
{pos:[10,8,32],state:0},
{pos:[11,8,32],state:0},
{pos:[12,8,32],state:0},
{pos:[13,8,32],state:0},
{pos:[14,8,32],state:0},
{pos:[15,8,32],state:0},
{pos:[16,8,32],state:0},
{pos:[17,8,32],state:0},
{pos:[18,8,32],state:0},
{pos:[19,8,32],state:0},
{pos:[20,8,32],state:0},
{pos:[21,8,32],state:0},
{pos:[22,8,32],state:0},
{pos:[23,8,32],state:0},
{pos:[24,8,32],state:0},
{pos:[25,8,32],state:0},
{pos:[26,8,32],state:0},
{pos:[27,8,32],state:0},
{pos:[28,8,32],state:0},
{pos:[29,8,32],state:0},
{pos:[30,8,32],state:0},
{pos:[31,8,32],state:0},
{pos:[32,8,32],state:0},
{pos:[33,8,32],state:0},
{pos:[34,8,32],state:0},
{pos:[35,8,32],state:0},
{pos:[36,8,32],state:0},
{pos:[37,8,32],state:0},
{pos:[38,8,32],state:0},
{pos:[39,8,32],state:0},
{pos:[40,8,32],state:0},
{pos:[41,8,32],state:0},
{pos:[42,8,32],state:0},
{pos:[43,8,32],state:0},
{pos:[44,8,32],state:0},
{pos:[45,8,32],state:0},
{pos:[46,8,32],state:0},
{pos:[0,8,33],state:0},
{pos:[1,8,33],state:0},
{pos:[2,8,33],state:0},
{pos:[3,8,33],state:0},
{pos:[4,8,33],state:0},
{pos:[5,8,33],state:0},
{pos:[6,8,33],state:0},
{pos:[7,8,33],state:0},
{pos:[8,8,33],state:0},
{pos:[9,8,33],state:0},
{pos:[10,8,33],state:0},
{pos:[11,8,33],state:0},
{pos:[12,8,33],state:0},
{pos:[13,8,33],state:0},
{pos:[14,8,33],state:0},
{pos:[15,8,33],state:0},
{pos:[16,8,33],state:0},
{pos:[17,8,33],state:0},
{pos:[18,8,33],state:0},
{pos:[19,8,33],state:0},
{pos:[20,8,33],state:0},
{pos:[21,8,33],state:0},
{pos:[22,8,33],state:0},
{pos:[23,8,33],state:0},
{pos:[24,8,33],state:0},
{pos:[25,8,33],state:0},
{pos:[26,8,33],state:0},
{pos:[27,8,33],state:0},
{pos:[28,8,33],state:0},
{pos:[29,8,33],state:0},
{pos:[30,8,33],state:0},
{pos:[31,8,33],state:0},
{pos:[32,8,33],state:0},
{pos:[33,8,33],state:0},
{pos:[34,8,33],state:0},
{pos:[35,8,33],state:0},
{pos:[36,8,33],state:0},
{pos:[37,8,33],state:0},
{pos:[38,8,33],state:0},
{pos:[39,8,33],state:0},
{pos:[40,8,33],state:0},
{pos:[41,8,33],state:0},
{pos:[42,8,33],state:0},
{pos:[43,8,33],state:0},
{pos:[44,8,33],state:0},
{pos:[45,8,33],state:0},
{pos:[46,8,33],state:0},
{pos:[0,9,0],state:0},
{pos:[1,9,0],state:0},
{pos:[2,9,0],state:0},
{pos:[3,9,0],state:0},
{pos:[4,9,0],state:0},
{pos:[5,9,0],state:0},
{pos:[6,9,0],state:0},
{pos:[7,9,0],state:0},
{pos:[8,9,0],state:0},
{pos:[9,9,0],state:0},
{pos:[10,9,0],state:0},
{pos:[11,9,0],state:0},
{pos:[12,9,0],state:0},
{pos:[13,9,0],state:0},
{pos:[14,9,0],state:0},
{pos:[15,9,0],state:0},
{pos:[16,9,0],state:0},
{pos:[17,9,0],state:0},
{pos:[18,9,0],state:0},
{pos:[19,9,0],state:0},
{pos:[20,9,0],state:0},
{pos:[21,9,0],state:0},
{pos:[22,9,0],state:0},
{pos:[23,9,0],state:0},
{pos:[24,9,0],state:0},
{pos:[25,9,0],state:0},
{pos:[26,9,0],state:0},
{pos:[27,9,0],state:0},
{pos:[28,9,0],state:0},
{pos:[29,9,0],state:0},
{pos:[30,9,0],state:0},
{pos:[31,9,0],state:0},
{pos:[32,9,0],state:0},
{pos:[33,9,0],state:0},
{pos:[34,9,0],state:0},
{pos:[35,9,0],state:0},
{pos:[36,9,0],state:0},
{pos:[37,9,0],state:0},
{pos:[38,9,0],state:0},
{pos:[39,9,0],state:0},
{pos:[40,9,0],state:0},
{pos:[41,9,0],state:0},
{pos:[42,9,0],state:0},
{pos:[43,9,0],state:0},
{pos:[44,9,0],state:0},
{pos:[45,9,0],state:0},
{pos:[46,9,0],state:0},
{pos:[0,9,1],state:0},
{pos:[1,9,1],state:0},
{pos:[2,9,1],state:0},
{pos:[3,9,1],state:0},
{pos:[4,9,1],state:0},
{pos:[5,9,1],state:0},
{pos:[6,9,1],state:0},
{pos:[7,9,1],state:0},
{pos:[8,9,1],state:0},
{pos:[9,9,1],state:0},
{pos:[10,9,1],state:0},
{pos:[11,9,1],state:0},
{pos:[12,9,1],state:0},
{pos:[13,9,1],state:0},
{pos:[14,9,1],state:0},
{pos:[15,9,1],state:0},
{pos:[16,9,1],state:0},
{pos:[17,9,1],state:0},
{pos:[18,9,1],state:0},
{pos:[19,9,1],state:0},
{pos:[20,9,1],state:0},
{pos:[21,9,1],state:0},
{pos:[22,9,1],state:0},
{pos:[23,9,1],state:0},
{pos:[24,9,1],state:0},
{pos:[25,9,1],state:0},
{pos:[26,9,1],state:0},
{pos:[27,9,1],state:0},
{pos:[28,9,1],state:0},
{pos:[29,9,1],state:0},
{pos:[30,9,1],state:0},
{pos:[31,9,1],state:0},
{pos:[32,9,1],state:0},
{pos:[33,9,1],state:0},
{pos:[34,9,1],state:0},
{pos:[35,9,1],state:0},
{pos:[36,9,1],state:0},
{pos:[37,9,1],state:0},
{pos:[38,9,1],state:0},
{pos:[39,9,1],state:0},
{pos:[40,9,1],state:0},
{pos:[41,9,1],state:0},
{pos:[42,9,1],state:0},
{pos:[43,9,1],state:0},
{pos:[44,9,1],state:0},
{pos:[45,9,1],state:0},
{pos:[46,9,1],state:0},
{pos:[0,9,2],state:0},
{pos:[1,9,2],state:0},
{pos:[45,9,2],state:0},
{pos:[46,9,2],state:0},
{pos:[0,9,3],state:0},
{pos:[1,9,3],state:0},
{pos:[45,9,3],state:0},
{pos:[46,9,3],state:0},
{pos:[0,9,4],state:0},
{pos:[1,9,4],state:0},
{pos:[45,9,4],state:0},
{pos:[46,9,4],state:0},
{pos:[0,9,5],state:0},
{pos:[1,9,5],state:0},
{pos:[45,9,5],state:0},
{pos:[46,9,5],state:0},
{pos:[0,9,6],state:0},
{pos:[1,9,6],state:0},
{pos:[45,9,6],state:0},
{pos:[46,9,6],state:0},
{pos:[0,9,7],state:0},
{pos:[1,9,7],state:0},
{pos:[45,9,7],state:0},
{pos:[46,9,7],state:0},
{pos:[0,9,8],state:0},
{pos:[1,9,8],state:0},
{pos:[45,9,8],state:0},
{pos:[46,9,8],state:0},
{pos:[0,9,9],state:0},
{pos:[1,9,9],state:0},
{pos:[45,9,9],state:0},
{pos:[46,9,9],state:0},
{pos:[0,9,10],state:0},
{pos:[1,9,10],state:0},
{pos:[45,9,10],state:0},
{pos:[46,9,10],state:0},
{pos:[0,9,11],state:0},
{pos:[1,9,11],state:0},
{pos:[45,9,11],state:0},
{pos:[46,9,11],state:0},
{pos:[0,9,12],state:0},
{pos:[1,9,12],state:0},
{pos:[45,9,12],state:0},
{pos:[46,9,12],state:0},
{pos:[0,9,13],state:0},
{pos:[1,9,13],state:0},
{pos:[45,9,13],state:0},
{pos:[46,9,13],state:0},
{pos:[0,9,14],state:0},
{pos:[1,9,14],state:0},
{pos:[45,9,14],state:0},
{pos:[46,9,14],state:0},
{pos:[0,9,15],state:0},
{pos:[1,9,15],state:0},
{pos:[45,9,15],state:0},
{pos:[46,9,15],state:0},
{pos:[0,9,16],state:0},
{pos:[1,9,16],state:0},
{pos:[45,9,16],state:0},
{pos:[46,9,16],state:0},
{pos:[0,9,17],state:0},
{pos:[1,9,17],state:0},
{pos:[45,9,17],state:0},
{pos:[46,9,17],state:0},
{pos:[0,9,18],state:0},
{pos:[1,9,18],state:0},
{pos:[45,9,18],state:0},
{pos:[46,9,18],state:0},
{pos:[0,9,19],state:0},
{pos:[1,9,19],state:0},
{pos:[45,9,19],state:0},
{pos:[46,9,19],state:0},
{pos:[0,9,20],state:0},
{pos:[1,9,20],state:0},
{pos:[45,9,20],state:0},
{pos:[46,9,20],state:0},
{pos:[0,9,21],state:0},
{pos:[1,9,21],state:0},
{pos:[45,9,21],state:0},
{pos:[46,9,21],state:0},
{pos:[0,9,22],state:0},
{pos:[1,9,22],state:0},
{pos:[45,9,22],state:0},
{pos:[46,9,22],state:0},
{pos:[0,9,23],state:0},
{pos:[1,9,23],state:0},
{pos:[45,9,23],state:0},
{pos:[46,9,23],state:0},
{pos:[0,9,24],state:0},
{pos:[1,9,24],state:0},
{pos:[45,9,24],state:0},
{pos:[46,9,24],state:0},
{pos:[0,9,25],state:0},
{pos:[1,9,25],state:0},
{pos:[45,9,25],state:0},
{pos:[46,9,25],state:0},
{pos:[0,9,26],state:0},
{pos:[1,9,26],state:0},
{pos:[45,9,26],state:0},
{pos:[46,9,26],state:0},
{pos:[0,9,27],state:0},
{pos:[1,9,27],state:0},
{pos:[45,9,27],state:0},
{pos:[46,9,27],state:0},
{pos:[0,9,28],state:0},
{pos:[1,9,28],state:0},
{pos:[45,9,28],state:0},
{pos:[46,9,28],state:0},
{pos:[0,9,29],state:0},
{pos:[1,9,29],state:0},
{pos:[45,9,29],state:0},
{pos:[46,9,29],state:0},
{pos:[0,9,30],state:0},
{pos:[1,9,30],state:0},
{pos:[45,9,30],state:0},
{pos:[46,9,30],state:0},
{pos:[0,9,31],state:0},
{pos:[1,9,31],state:0},
{pos:[45,9,31],state:0},
{pos:[46,9,31],state:0},
{pos:[0,9,32],state:0},
{pos:[1,9,32],state:0},
{pos:[2,9,32],state:0},
{pos:[3,9,32],state:0},
{pos:[4,9,32],state:0},
{pos:[5,9,32],state:0},
{pos:[6,9,32],state:0},
{pos:[7,9,32],state:0},
{pos:[8,9,32],state:0},
{pos:[9,9,32],state:0},
{pos:[10,9,32],state:0},
{pos:[11,9,32],state:0},
{pos:[12,9,32],state:0},
{pos:[13,9,32],state:0},
{pos:[14,9,32],state:0},
{pos:[15,9,32],state:0},
{pos:[16,9,32],state:0},
{pos:[17,9,32],state:0},
{pos:[18,9,32],state:0},
{pos:[19,9,32],state:0},
{pos:[20,9,32],state:0},
{pos:[21,9,32],state:0},
{pos:[22,9,32],state:0},
{pos:[23,9,32],state:0},
{pos:[24,9,32],state:0},
{pos:[25,9,32],state:0},
{pos:[26,9,32],state:0},
{pos:[27,9,32],state:0},
{pos:[28,9,32],state:0},
{pos:[29,9,32],state:0},
{pos:[30,9,32],state:0},
{pos:[31,9,32],state:0},
{pos:[32,9,32],state:0},
{pos:[33,9,32],state:0},
{pos:[34,9,32],state:0},
{pos:[35,9,32],state:0},
{pos:[36,9,32],state:0},
{pos:[37,9,32],state:0},
{pos:[38,9,32],state:0},
{pos:[39,9,32],state:0},
{pos:[40,9,32],state:0},
{pos:[41,9,32],state:0},
{pos:[42,9,32],state:0},
{pos:[43,9,32],state:0},
{pos:[44,9,32],state:0},
{pos:[45,9,32],state:0},
{pos:[46,9,32],state:0},
{pos:[0,9,33],state:0},
{pos:[1,9,33],state:0},
{pos:[2,9,33],state:0},
{pos:[3,9,33],state:0},
{pos:[4,9,33],state:0},
{pos:[5,9,33],state:0},
{pos:[6,9,33],state:0},
{pos:[7,9,33],state:0},
{pos:[8,9,33],state:0},
{pos:[9,9,33],state:0},
{pos:[10,9,33],state:0},
{pos:[11,9,33],state:0},
{pos:[12,9,33],state:0},
{pos:[13,9,33],state:0},
{pos:[14,9,33],state:0},
{pos:[15,9,33],state:0},
{pos:[16,9,33],state:0},
{pos:[17,9,33],state:0},
{pos:[18,9,33],state:0},
{pos:[19,9,33],state:0},
{pos:[20,9,33],state:0},
{pos:[21,9,33],state:0},
{pos:[22,9,33],state:0},
{pos:[23,9,33],state:0},
{pos:[24,9,33],state:0},
{pos:[25,9,33],state:0},
{pos:[26,9,33],state:0},
{pos:[27,9,33],state:0},
{pos:[28,9,33],state:0},
{pos:[29,9,33],state:0},
{pos:[30,9,33],state:0},
{pos:[31,9,33],state:0},
{pos:[32,9,33],state:0},
{pos:[33,9,33],state:0},
{pos:[34,9,33],state:0},
{pos:[35,9,33],state:0},
{pos:[36,9,33],state:0},
{pos:[37,9,33],state:0},
{pos:[38,9,33],state:0},
{pos:[39,9,33],state:0},
{pos:[40,9,33],state:0},
{pos:[41,9,33],state:0},
{pos:[42,9,33],state:0},
{pos:[43,9,33],state:0},
{pos:[44,9,33],state:0},
{pos:[45,9,33],state:0},
{pos:[46,9,33],state:0},
{pos:[0,10,0],state:0},
{pos:[1,10,0],state:0},
{pos:[2,10,0],state:0},
{pos:[3,10,0],state:0},
{pos:[4,10,0],state:0},
{pos:[5,10,0],state:0},
{pos:[6,10,0],state:0},
{pos:[7,10,0],state:0},
{pos:[8,10,0],state:0},
{pos:[9,10,0],state:0},
{pos:[10,10,0],state:0},
{pos:[11,10,0],state:0},
{pos:[12,10,0],state:0},
{pos:[13,10,0],state:0},
{pos:[14,10,0],state:0},
{pos:[15,10,0],state:0},
{pos:[16,10,0],state:0},
{pos:[17,10,0],state:0},
{pos:[18,10,0],state:0},
{pos:[19,10,0],state:0},
{pos:[20,10,0],state:0},
{pos:[21,10,0],state:0},
{pos:[22,10,0],state:0},
{pos:[23,10,0],state:0},
{pos:[24,10,0],state:0},
{pos:[25,10,0],state:0},
{pos:[26,10,0],state:0},
{pos:[27,10,0],state:0},
{pos:[28,10,0],state:0},
{pos:[29,10,0],state:0},
{pos:[30,10,0],state:0},
{pos:[31,10,0],state:0},
{pos:[32,10,0],state:0},
{pos:[33,10,0],state:0},
{pos:[34,10,0],state:0},
{pos:[35,10,0],state:0},
{pos:[36,10,0],state:0},
{pos:[37,10,0],state:0},
{pos:[38,10,0],state:0},
{pos:[39,10,0],state:0},
{pos:[40,10,0],state:0},
{pos:[41,10,0],state:0},
{pos:[42,10,0],state:0},
{pos:[43,10,0],state:0},
{pos:[44,10,0],state:0},
{pos:[45,10,0],state:0},
{pos:[46,10,0],state:0},
{pos:[0,10,1],state:0},
{pos:[1,10,1],state:0},
{pos:[2,10,1],state:0},
{pos:[3,10,1],state:0},
{pos:[4,10,1],state:0},
{pos:[5,10,1],state:0},
{pos:[6,10,1],state:0},
{pos:[7,10,1],state:0},
{pos:[8,10,1],state:0},
{pos:[9,10,1],state:0},
{pos:[10,10,1],state:0},
{pos:[11,10,1],state:0},
{pos:[12,10,1],state:0},
{pos:[13,10,1],state:0},
{pos:[14,10,1],state:0},
{pos:[15,10,1],state:0},
{pos:[16,10,1],state:0},
{pos:[17,10,1],state:0},
{pos:[18,10,1],state:0},
{pos:[19,10,1],state:0},
{pos:[20,10,1],state:0},
{pos:[21,10,1],state:0},
{pos:[22,10,1],state:0},
{pos:[23,10,1],state:0},
{pos:[24,10,1],state:0},
{pos:[25,10,1],state:0},
{pos:[26,10,1],state:0},
{pos:[27,10,1],state:0},
{pos:[28,10,1],state:0},
{pos:[29,10,1],state:0},
{pos:[30,10,1],state:0},
{pos:[31,10,1],state:0},
{pos:[32,10,1],state:0},
{pos:[33,10,1],state:0},
{pos:[34,10,1],state:0},
{pos:[35,10,1],state:0},
{pos:[36,10,1],state:0},
{pos:[37,10,1],state:0},
{pos:[38,10,1],state:0},
{pos:[39,10,1],state:0},
{pos:[40,10,1],state:0},
{pos:[41,10,1],state:0},
{pos:[42,10,1],state:0},
{pos:[43,10,1],state:0},
{pos:[44,10,1],state:0},
{pos:[45,10,1],state:0},
{pos:[46,10,1],state:0},
{pos:[0,10,2],state:0},
{pos:[1,10,2],state:0},
{pos:[45,10,2],state:0},
{pos:[46,10,2],state:0},
{pos:[0,10,3],state:0},
{pos:[1,10,3],state:0},
{pos:[45,10,3],state:0},
{pos:[46,10,3],state:0},
{pos:[0,10,4],state:0},
{pos:[1,10,4],state:0},
{pos:[45,10,4],state:0},
{pos:[46,10,4],state:0},
{pos:[0,10,5],state:0},
{pos:[1,10,5],state:0},
{pos:[45,10,5],state:0},
{pos:[46,10,5],state:0},
{pos:[0,10,6],state:0},
{pos:[1,10,6],state:0},
{pos:[45,10,6],state:0},
{pos:[46,10,6],state:0},
{pos:[0,10,7],state:0},
{pos:[1,10,7],state:0},
{pos:[45,10,7],state:0},
{pos:[46,10,7],state:0},
{pos:[0,10,8],state:0},
{pos:[1,10,8],state:0},
{pos:[45,10,8],state:0},
{pos:[46,10,8],state:0},
{pos:[0,10,9],state:0},
{pos:[1,10,9],state:0},
{pos:[45,10,9],state:0},
{pos:[46,10,9],state:0},
{pos:[0,10,10],state:0},
{pos:[1,10,10],state:0},
{pos:[45,10,10],state:0},
{pos:[46,10,10],state:0},
{pos:[0,10,11],state:0},
{pos:[1,10,11],state:0},
{pos:[45,10,11],state:0},
{pos:[46,10,11],state:0},
{pos:[0,10,12],state:0},
{pos:[1,10,12],state:0},
{pos:[45,10,12],state:0},
{pos:[46,10,12],state:0},
{pos:[0,10,13],state:0},
{pos:[1,10,13],state:0},
{pos:[45,10,13],state:0},
{pos:[46,10,13],state:0},
{pos:[0,10,14],state:0},
{pos:[1,10,14],state:0},
{pos:[45,10,14],state:0},
{pos:[46,10,14],state:0},
{pos:[0,10,15],state:0},
{pos:[1,10,15],state:0},
{pos:[45,10,15],state:0},
{pos:[46,10,15],state:0},
{pos:[0,10,16],state:0},
{pos:[1,10,16],state:0},
{pos:[45,10,16],state:0},
{pos:[46,10,16],state:0},
{pos:[0,10,17],state:0},
{pos:[1,10,17],state:0},
{pos:[45,10,17],state:0},
{pos:[46,10,17],state:0},
{pos:[0,10,18],state:0},
{pos:[1,10,18],state:0},
{pos:[45,10,18],state:0},
{pos:[46,10,18],state:0},
{pos:[0,10,19],state:0},
{pos:[1,10,19],state:0},
{pos:[45,10,19],state:0},
{pos:[46,10,19],state:0},
{pos:[0,10,20],state:0},
{pos:[1,10,20],state:0},
{pos:[45,10,20],state:0},
{pos:[46,10,20],state:0},
{pos:[0,10,21],state:0},
{pos:[1,10,21],state:0},
{pos:[45,10,21],state:0},
{pos:[46,10,21],state:0},
{pos:[0,10,22],state:0},
{pos:[1,10,22],state:0},
{pos:[45,10,22],state:0},
{pos:[46,10,22],state:0},
{pos:[0,10,23],state:0},
{pos:[1,10,23],state:0},
{pos:[45,10,23],state:0},
{pos:[46,10,23],state:0},
{pos:[0,10,24],state:0},
{pos:[1,10,24],state:0},
{pos:[45,10,24],state:0},
{pos:[46,10,24],state:0},
{pos:[0,10,25],state:0},
{pos:[1,10,25],state:0},
{pos:[45,10,25],state:0},
{pos:[46,10,25],state:0},
{pos:[0,10,26],state:0},
{pos:[1,10,26],state:0},
{pos:[45,10,26],state:0},
{pos:[46,10,26],state:0},
{pos:[0,10,27],state:0},
{pos:[1,10,27],state:0},
{pos:[45,10,27],state:0},
{pos:[46,10,27],state:0},
{pos:[0,10,28],state:0},
{pos:[1,10,28],state:0},
{pos:[45,10,28],state:0},
{pos:[46,10,28],state:0},
{pos:[0,10,29],state:0},
{pos:[1,10,29],state:0},
{pos:[45,10,29],state:0},
{pos:[46,10,29],state:0},
{pos:[0,10,30],state:0},
{pos:[1,10,30],state:0},
{pos:[45,10,30],state:0},
{pos:[46,10,30],state:0},
{pos:[0,10,31],state:0},
{pos:[1,10,31],state:0},
{pos:[45,10,31],state:0},
{pos:[46,10,31],state:0},
{pos:[0,10,32],state:0},
{pos:[1,10,32],state:0},
