{DataVersion:3465,size:[31,20,27],palette:[{Name:"minecraft:obsidian"},{Name:"minecraft:polished_blackstone_bricks"},{Name:"minecraft:polished_deepslate"},{Name:"minecraft:sea_lantern"},{Name:"minecraft:structure_block"}],entities:[],blocks:[
{pos:[0,0,0],state:2},
{pos:[1,0,0],state:2},
{pos:[2,0,0],state:2},
{pos:[3,0,0],state:2},
{pos:[4,0,0],state:2},
{pos:[5,0,0],state:2},
{pos:[6,0,0],state:2},
{pos:[7,0,0],state:2},
{pos:[8,0,0],state:2},
{pos:[9,0,0],state:2},
{pos:[10,0,0],state:2},
{pos:[11,0,0],state:2},
{pos:[12,0,0],state:2},
{pos:[13,0,0],state:2},
{pos:[14,0,0],state:2},
{pos:[15,0,0],state:2},
{pos:[16,0,0],state:2},
{pos:[17,0,0],state:2},
{pos:[18,0,0],state:2},
{pos:[19,0,0],state:2},
{pos:[20,0,0],state:2},
{pos:[21,0,0],state:2},
{pos:[22,0,0],state:2},
{pos:[23,0,0],state:2},
{pos:[24,0,0],state:2},
{pos:[25,0,0],state:2},
{pos:[26,0,0],state:2},
{pos:[27,0,0],state:2},
{pos:[28,0,0],state:2},
{pos:[29,0,0],state:2},
{pos:[30,0,0],state:2},
{pos:[0,0,1],state:2},
{pos:[1,0,1],state:2},
{pos:[2,0,1],state:2},
{pos:[3,0,1],state:2},
{pos:[4,0,1],state:2},
{pos:[5,0,1],state:2},
{pos:[6,0,1],state:2},
{pos:[7,0,1],state:2},
{pos:[8,0,1],state:2},
{pos:[9,0,1],state:2},
{pos:[10,0,1],state:2},
{pos:[11,0,1],state:2},
{pos:[12,0,1],state:2},
{pos:[13,0,1],state:2},
{pos:[14,0,1],state:2},
{pos:[15,0,1],state:2},
{pos:[16,0,1],state:2},
{pos:[17,0,1],state:2},
{pos:[18,0,1],state:2},
{pos:[19,0,1],state:2},
{pos:[20,0,1],state:2},
{pos:[21,0,1],state:2},
{pos:[22,0,1],state:2},
{pos:[23,0,1],state:2},
{pos:[24,0,1],state:2},
{pos:[25,0,1],state:2},
{pos:[26,0,1],state:2},
{pos:[27,0,1],state:2},
{pos:[28,0,1],state:2},
{pos:[29,0,1],state:2},
{pos:[30,0,1],state:2},
{pos:[0,0,2],state:2},
{pos:[1,0,2],state:2},
{pos:[2,0,2],state:2},
{pos:[3,0,2],state:2},
{pos:[4,0,2],state:2},
{pos:[5,0,2],state:2},
{pos:[6,0,2],state:2},
{pos:[7,0,2],state:2},
{pos:[8,0,2],state:2},
{pos:[9,0,2],state:2},
{pos:[10,0,2],state:2},
{pos:[11,0,2],state:2},
{pos:[12,0,2],state:2},
{pos:[13,0,2],state:2},
{pos:[14,0,2],state:2},
{pos:[15,0,2],state:2},
{pos:[16,0,2],state:2},
{pos:[17,0,2],state:2},
{pos:[18,0,2],state:2},
{pos:[19,0,2],state:2},
{pos:[20,0,2],state:2},
{pos:[21,0,2],state:2},
{pos:[22,0,2],state:2},
{pos:[23,0,2],state:2},
{pos:[24,0,2],state:2},
{pos:[25,0,2],state:2},
{pos:[26,0,2],state:2},
{pos:[27,0,2],state:2},
{pos:[28,0,2],state:2},
{pos:[29,0,2],state:2},
{pos:[30,0,2],state:2},
{pos:[0,0,3],state:2},
{pos:[1,0,3],state:2},
{pos:[2,0,3],state:2},
{pos:[3,0,3],state:2},
{pos:[4,0,3],state:2},
{pos:[5,0,3],state:2},
{pos:[6,0,3],state:2},
{pos:[7,0,3],state:2},
{pos:[8,0,3],state:2},
{pos:[9,0,3],state:2},
{pos:[10,0,3],state:2},
{pos:[11,0,3],state:2},
{pos:[12,0,3],state:2},
{pos:[13,0,3],state:2},
{pos:[14,0,3],state:2},
{pos:[15,0,3],state:2},
{pos:[16,0,3],state:2},
{pos:[17,0,3],state:2},
{pos:[18,0,3],state:2},
{pos:[19,0,3],state:2},
{pos:[20,0,3],state:2},
{pos:[21,0,3],state:2},
{pos:[22,0,3],state:2},
{pos:[23,0,3],state:2},
{pos:[24,0,3],state:2},
{pos:[25,0,3],state:2},
{pos:[26,0,3],state:2},
{pos:[27,0,3],state:2},
{pos:[28,0,3],state:2},
{pos:[29,0,3],state:2},
{pos:[30,0,3],state:2},
{pos:[0,0,4],state:2},
{pos:[1,0,4],state:2},
{pos:[2,0,4],state:2},
{pos:[3,0,4],state:2},
{pos:[4,0,4],state:2},
{pos:[5,0,4],state:2},
{pos:[6,0,4],state:2},
{pos:[7,0,4],state:2},
{pos:[8,0,4],state:2},
{pos:[9,0,4],state:2},
{pos:[10,0,4],state:2},
{pos:[11,0,4],state:2},
{pos:[12,0,4],state:2},
{pos:[13,0,4],state:2},
{pos:[14,0,4],state:2},
{pos:[15,0,4],state:2},
{pos:[16,0,4],state:2},
{pos:[17,0,4],state:2},
{pos:[18,0,4],state:2},
{pos:[19,0,4],state:2},
{pos:[20,0,4],state:2},
{pos:[21,0,4],state:2},
{pos:[22,0,4],state:2},
{pos:[23,0,4],state:2},
{pos:[24,0,4],state:2},
{pos:[25,0,4],state:2},
{pos:[26,0,4],state:2},
{pos:[27,0,4],state:2},
{pos:[28,0,4],state:2},
{pos:[29,0,4],state:2},
{pos:[30,0,4],state:2},
{pos:[0,0,5],state:2},
{pos:[1,0,5],state:2},
{pos:[2,0,5],state:2},
{pos:[3,0,5],state:2},
{pos:[4,0,5],state:2},
{pos:[5,0,5],state:2},
{pos:[6,0,5],state:2},
{pos:[7,0,5],state:2},
{pos:[8,0,5],state:2},
{pos:[9,0,5],state:2},
{pos:[10,0,5],state:2},
{pos:[11,0,5],state:2},
{pos:[12,0,5],state:2},
{pos:[13,0,5],state:2},
{pos:[14,0,5],state:2},
{pos:[15,0,5],state:2},
{pos:[16,0,5],state:2},
{pos:[17,0,5],state:2},
{pos:[18,0,5],state:2},
{pos:[19,0,5],state:2},
{pos:[20,0,5],state:2},
{pos:[21,0,5],state:2},
{pos:[22,0,5],state:2},
{pos:[23,0,5],state:2},
{pos:[24,0,5],state:2},
{pos:[25,0,5],state:2},
{pos:[26,0,5],state:2},
{pos:[27,0,5],state:2},
{pos:[28,0,5],state:2},
{pos:[29,0,5],state:2},
{pos:[30,0,5],state:2},
{pos:[0,0,6],state:2},
{pos:[1,0,6],state:2},
{pos:[2,0,6],state:2},
{pos:[3,0,6],state:2},
{pos:[4,0,6],state:2},
{pos:[5,0,6],state:2},
{pos:[6,0,6],state:2},
{pos:[7,0,6],state:2},
{pos:[8,0,6],state:2},
{pos:[9,0,6],state:2},
{pos:[10,0,6],state:2},
{pos:[11,0,6],state:2},
{pos:[12,0,6],state:2},
{pos:[13,0,6],state:2},
{pos:[14,0,6],state:2},
{pos:[15,0,6],state:2},
{pos:[16,0,6],state:2},
{pos:[17,0,6],state:2},
{pos:[18,0,6],state:2},
{pos:[19,0,6],state:2},
{pos:[20,0,6],state:2},
{pos:[21,0,6],state:2},
{pos:[22,0,6],state:2},
{pos:[23,0,6],state:2},
{pos:[24,0,6],state:2},
{pos:[25,0,6],state:2},
{pos:[26,0,6],state:2},
{pos:[27,0,6],state:2},
{pos:[28,0,6],state:2},
{pos:[29,0,6],state:2},
{pos:[30,0,6],state:2},
{pos:[0,0,7],state:2},
{pos:[1,0,7],state:2},
{pos:[2,0,7],state:2},
{pos:[3,0,7],state:2},
{pos:[4,0,7],state:2},
{pos:[5,0,7],state:2},
{pos:[6,0,7],state:2},
{pos:[7,0,7],state:2},
{pos:[8,0,7],state:2},
{pos:[9,0,7],state:2},
{pos:[10,0,7],state:2},
{pos:[11,0,7],state:2},
{pos:[12,0,7],state:2},
{pos:[13,0,7],state:2},
{pos:[14,0,7],state:2},
{pos:[15,0,7],state:2},
{pos:[16,0,7],state:2},
{pos:[17,0,7],state:2},
{pos:[18,0,7],state:2},
{pos:[19,0,7],state:2},
{pos:[20,0,7],state:2},
{pos:[21,0,7],state:2},
{pos:[22,0,7],state:2},
{pos:[23,0,7],state:2},
{pos:[24,0,7],state:2},
{pos:[25,0,7],state:2},
{pos:[26,0,7],state:2},
{pos:[27,0,7],state:2},
{pos:[28,0,7],state:2},
{pos:[29,0,7],state:2},
{pos:[30,0,7],state:2},
{pos:[0,0,8],state:2},
{pos:[1,0,8],state:2},
{pos:[2,0,8],state:2},
{pos:[3,0,8],state:2},
{pos:[4,0,8],state:2},
{pos:[5,0,8],state:2},
{pos:[6,0,8],state:2},
{pos:[7,0,8],state:2},
{pos:[8,0,8],state:2},
{pos:[9,0,8],state:2},
{pos:[10,0,8],state:2},
{pos:[11,0,8],state:2},
{pos:[12,0,8],state:2},
{pos:[13,0,8],state:2},
{pos:[14,0,8],state:2},
{pos:[15,0,8],state:2},
{pos:[16,0,8],state:2},
{pos:[17,0,8],state:2},
{pos:[18,0,8],state:2},
{pos:[19,0,8],state:2},
{pos:[20,0,8],state:2},
{pos:[21,0,8],state:2},
{pos:[22,0,8],state:2},
{pos:[23,0,8],state:2},
{pos:[24,0,8],state:2},
{pos:[25,0,8],state:2},
{pos:[26,0,8],state:2},
{pos:[27,0,8],state:2},
{pos:[28,0,8],state:2},
{pos:[29,0,8],state:2},
{pos:[30,0,8],state:2},
{pos:[0,0,9],state:2},
{pos:[1,0,9],state:2},
{pos:[2,0,9],state:2},
{pos:[3,0,9],state:2},
{pos:[4,0,9],state:2},
{pos:[5,0,9],state:2},
{pos:[6,0,9],state:2},
{pos:[7,0,9],state:2},
{pos:[8,0,9],state:2},
{pos:[9,0,9],state:2},
{pos:[10,0,9],state:2},
{pos:[11,0,9],state:2},
{pos:[12,0,9],state:2},
{pos:[13,0,9],state:2},
{pos:[14,0,9],state:2},
{pos:[15,0,9],state:2},
{pos:[16,0,9],state:2},
{pos:[17,0,9],state:2},
{pos:[18,0,9],state:2},
{pos:[19,0,9],state:2},
{pos:[20,0,9],state:2},
{pos:[21,0,9],state:2},
{pos:[22,0,9],state:2},
{pos:[23,0,9],state:2},
{pos:[24,0,9],state:2},
{pos:[25,0,9],state:2},
{pos:[26,0,9],state:2},
{pos:[27,0,9],state:2},
{pos:[28,0,9],state:2},
{pos:[29,0,9],state:2},
{pos:[30,0,9],state:2},
{pos:[0,0,10],state:2},
{pos:[1,0,10],state:2},
{pos:[2,0,10],state:2},
{pos:[3,0,10],state:2},
{pos:[4,0,10],state:2},
{pos:[5,0,10],state:2},
{pos:[6,0,10],state:2},
{pos:[7,0,10],state:2},
{pos:[8,0,10],state:2},
{pos:[9,0,10],state:2},
{pos:[10,0,10],state:2},
{pos:[11,0,10],state:2},
{pos:[12,0,10],state:2},
{pos:[13,0,10],state:2},
{pos:[14,0,10],state:2},
{pos:[15,0,10],state:2},
{pos:[16,0,10],state:2},
{pos:[17,0,10],state:2},
{pos:[18,0,10],state:2},
{pos:[19,0,10],state:2},
{pos:[20,0,10],state:2},
{pos:[21,0,10],state:2},
{pos:[22,0,10],state:2},
{pos:[23,0,10],state:2},
{pos:[24,0,10],state:2},
{pos:[25,0,10],state:2},
{pos:[26,0,10],state:2},
{pos:[27,0,10],state:2},
{pos:[28,0,10],state:2},
{pos:[29,0,10],state:2},
{pos:[30,0,10],state:2},
{pos:[0,0,11],state:2},
{pos:[1,0,11],state:2},
{pos:[2,0,11],state:2},
{pos:[3,0,11],state:2},
{pos:[4,0,11],state:2},
{pos:[5,0,11],state:2},
{pos:[6,0,11],state:2},
{pos:[7,0,11],state:2},
{pos:[8,0,11],state:2},
{pos:[9,0,11],state:2},
{pos:[10,0,11],state:2},
{pos:[11,0,11],state:2},
{pos:[12,0,11],state:2},
{pos:[13,0,11],state:2},
{pos:[14,0,11],state:2},
{pos:[15,0,11],state:2},
{pos:[16,0,11],state:2},
{pos:[17,0,11],state:2},
{pos:[18,0,11],state:2},
{pos:[19,0,11],state:2},
{pos:[20,0,11],state:2},
{pos:[21,0,11],state:2},
{pos:[22,0,11],state:2},
{pos:[23,0,11],state:2},
{pos:[24,0,11],state:2},
{pos:[25,0,11],state:2},
{pos:[26,0,11],state:2},
{pos:[27,0,11],state:2},
{pos:[28,0,11],state:2},
{pos:[29,0,11],state:2},
{pos:[30,0,11],state:2},
{pos:[0,0,12],state:2},
{pos:[1,0,12],state:2},
{pos:[2,0,12],state:2},
{pos:[3,0,12],state:2},
{pos:[4,0,12],state:2},
{pos:[5,0,12],state:2},
{pos:[6,0,12],state:2},
{pos:[7,0,12],state:2},
{pos:[8,0,12],state:2},
{pos:[9,0,12],state:2},
{pos:[10,0,12],state:2},
{pos:[11,0,12],state:2},
{pos:[12,0,12],state:2},
{pos:[13,0,12],state:2},
{pos:[14,0,12],state:2},
{pos:[15,0,12],state:2},
{pos:[16,0,12],state:2},
{pos:[17,0,12],state:2},
{pos:[18,0,12],state:2},
{pos:[19,0,12],state:2},
{pos:[20,0,12],state:2},
{pos:[21,0,12],state:2},
{pos:[22,0,12],state:2},
{pos:[23,0,12],state:2},
{pos:[24,0,12],state:2},
{pos:[25,0,12],state:2},
{pos:[26,0,12],state:2},
{pos:[27,0,12],state:2},
{pos:[28,0,12],state:2},
{pos:[29,0,12],state:2},
{pos:[30,0,12],state:2},
{pos:[0,0,13],state:2},
{pos:[1,0,13],state:2},
{pos:[2,0,13],state:2},
{pos:[3,0,13],state:2},
{pos:[4,0,13],state:2},
{pos:[5,0,13],state:2},
{pos:[6,0,13],state:2},
{pos:[7,0,13],state:2},
{pos:[8,0,13],state:2},
{pos:[9,0,13],state:2},
{pos:[10,0,13],state:2},
{pos:[11,0,13],state:2},
{pos:[12,0,13],state:2},
{pos:[13,0,13],state:2},
{pos:[14,0,13],state:2},
{pos:[15,0,13],state:2},
{pos:[16,0,13],state:2},
{pos:[17,0,13],state:2},
{pos:[18,0,13],state:2},
{pos:[19,0,13],state:2},
{pos:[20,0,13],state:2},
{pos:[21,0,13],state:2},
{pos:[22,0,13],state:2},
{pos:[23,0,13],state:2},
{pos:[24,0,13],state:2},
{pos:[25,0,13],state:2},
{pos:[26,0,13],state:2},
{pos:[27,0,13],state:2},
{pos:[28,0,13],state:2},
{pos:[29,0,13],state:2},
{pos:[30,0,13],state:2},
{pos:[0,0,14],state:2},
{pos:[1,0,14],state:2},
{pos:[2,0,14],state:2},
{pos:[3,0,14],state:2},
{pos:[4,0,14],state:2},
{pos:[5,0,14],state:2},
{pos:[6,0,14],state:2},
{pos:[7,0,14],state:2},
{pos:[8,0,14],state:2},
{pos:[9,0,14],state:2},
{pos:[10,0,14],state:2},
{pos:[11,0,14],state:2},
{pos:[12,0,14],state:2},
{pos:[13,0,14],state:2},
{pos:[14,0,14],state:2},
{pos:[15,0,14],state:2},
{pos:[16,0,14],state:2},
{pos:[17,0,14],state:2},
{pos:[18,0,14],state:2},
{pos:[19,0,14],state:2},
{pos:[20,0,14],state:2},
{pos:[21,0,14],state:2},
{pos:[22,0,14],state:2},
{pos:[23,0,14],state:2},
{pos:[24,0,14],state:2},
{pos:[25,0,14],state:2},
{pos:[26,0,14],state:2},
{pos:[27,0,14],state:2},
{pos:[28,0,14],state:2},
{pos:[29,0,14],state:2},
{pos:[30,0,14],state:2},
{pos:[0,0,15],state:2},
{pos:[1,0,15],state:2},
{pos:[2,0,15],state:2},
{pos:[3,0,15],state:2},
{pos:[4,0,15],state:2},
{pos:[5,0,15],state:2},
{pos:[6,0,15],state:2},
{pos:[7,0,15],state:2},
{pos:[8,0,15],state:2},
{pos:[9,0,15],state:2},
{pos:[10,0,15],state:2},
{pos:[11,0,15],state:2},
{pos:[12,0,15],state:2},
{pos:[13,0,15],state:2},
{pos:[14,0,15],state:2},
{pos:[15,0,15],state:2},
{pos:[16,0,15],state:2},
{pos:[17,0,15],state:2},
{pos:[18,0,15],state:2},
{pos:[19,0,15],state:2},
{pos:[20,0,15],state:2},
{pos:[21,0,15],state:2},
{pos:[22,0,15],state:2},
{pos:[23,0,15],state:2},
{pos:[24,0,15],state:2},
{pos:[25,0,15],state:2},
{pos:[26,0,15],state:2},
{pos:[27,0,15],state:2},
{pos:[28,0,15],state:2},
{pos:[29,0,15],state:2},
{pos:[30,0,15],state:2},
{pos:[0,0,16],state:2},
{pos:[1,0,16],state:2},
{pos:[2,0,16],state:2},
{pos:[3,0,16],state:2},
{pos:[4,0,16],state:2},
{pos:[5,0,16],state:2},
{pos:[6,0,16],state:2},
{pos:[7,0,16],state:2},
{pos:[8,0,16],state:2},
{pos:[9,0,16],state:2},
{pos:[10,0,16],state:2},
{pos:[11,0,16],state:2},
{pos:[12,0,16],state:2},
{pos:[13,0,16],state:2},
{pos:[14,0,16],state:2},
{pos:[15,0,16],state:2},
{pos:[16,0,16],state:2},
{pos:[17,0,16],state:2},
{pos:[18,0,16],state:2},
{pos:[19,0,16],state:2},
{pos:[20,0,16],state:2},
{pos:[21,0,16],state:2},
{pos:[22,0,16],state:2},
{pos:[23,0,16],state:2},
{pos:[24,0,16],state:2},
{pos:[25,0,16],state:2},
{pos:[26,0,16],state:2},
{pos:[27,0,16],state:2},
{pos:[28,0,16],state:2},
{pos:[29,0,16],state:2},
{pos:[30,0,16],state:2},
{pos:[0,0,17],state:2},
{pos:[1,0,17],state:2},
{pos:[2,0,17],state:2},
{pos:[3,0,17],state:2},
{pos:[4,0,17],state:2},
{pos:[5,0,17],state:2},
{pos:[6,0,17],state:2},
{pos:[7,0,17],state:2},
{pos:[8,0,17],state:2},
{pos:[9,0,17],state:2},
{pos:[10,0,17],state:2},
{pos:[11,0,17],state:2},
{pos:[12,0,17],state:2},
{pos:[13,0,17],state:2},
{pos:[14,0,17],state:2},
{pos:[15,0,17],state:2},
{pos:[16,0,17],state:2},
{pos:[17,0,17],state:2},
{pos:[18,0,17],state:2},
{pos:[19,0,17],state:2},
{pos:[20,0,17],state:2},
{pos:[21,0,17],state:2},
{pos:[22,0,17],state:2},
{pos:[23,0,17],state:2},
{pos:[24,0,17],state:2},
{pos:[25,0,17],state:2},
{pos:[26,0,17],state:2},
{pos:[27,0,17],state:2},
{pos:[28,0,17],state:2},
{pos:[29,0,17],state:2},
{pos:[30,0,17],state:2},
{pos:[0,0,18],state:2},
{pos:[1,0,18],state:2},
{pos:[2,0,18],state:2},
{pos:[3,0,18],state:2},
{pos:[4,0,18],state:2},
{pos:[5,0,18],state:2},
{pos:[6,0,18],state:2},
{pos:[7,0,18],state:2},
{pos:[8,0,18],state:2},
{pos:[9,0,18],state:2},
{pos:[10,0,18],state:2},
{pos:[11,0,18],state:2},
{pos:[12,0,18],state:2},
{pos:[13,0,18],state:2},
{pos:[14,0,18],state:2},
{pos:[15,0,18],state:2},
{pos:[16,0,18],state:2},
{pos:[17,0,18],state:2},
{pos:[18,0,18],state:2},
{pos:[19,0,18],state:2},
{pos:[20,0,18],state:2},
{pos:[21,0,18],state:2},
{pos:[22,0,18],state:2},
{pos:[23,0,18],state:2},
{pos:[24,0,18],state:2},
{pos:[25,0,18],state:2},
{pos:[26,0,18],state:2},
{pos:[27,0,18],state:2},
{pos:[28,0,18],state:2},
{pos:[29,0,18],state:2},
{pos:[30,0,18],state:2},
{pos:[0,0,19],state:2},
{pos:[1,0,19],state:2},
{pos:[2,0,19],state:2},
{pos:[3,0,19],state:2},
{pos:[4,0,19],state:2},
{pos:[5,0,19],state:2},
{pos:[6,0,19],state:2},
{pos:[7,0,19],state:2},
{pos:[8,0,19],state:2},
{pos:[9,0,19],state:2},
{pos:[10,0,19],state:2},
{pos:[11,0,19],state:2},
{pos:[12,0,19],state:2},
{pos:[13,0,19],state:2},
{pos:[14,0,19],state:2},
{pos:[15,0,19],state:2},
{pos:[16,0,19],state:2},
{pos:[17,0,19],state:2},
{pos:[18,0,19],state:2},
{pos:[19,0,19],state:2},
{pos:[20,0,19],state:2},
{pos:[21,0,19],state:2},
{pos:[22,0,19],state:2},
{pos:[23,0,19],state:2},
{pos:[24,0,19],state:2},
{pos:[25,0,19],state:2},
{pos:[26,0,19],state:2},
{pos:[27,0,19],state:2},
{pos:[28,0,19],state:2},
{pos:[29,0,19],state:2},
{pos:[30,0,19],state:2},
{pos:[0,0,20],state:2},
{pos:[1,0,20],state:2},
{pos:[2,0,20],state:2},
{pos:[3,0,20],state:2},
{pos:[4,0,20],state:2},
{pos:[5,0,20],state:2},
{pos:[6,0,20],state:2},
{pos:[7,0,20],state:2},
{pos:[8,0,20],state:2},
{pos:[9,0,20],state:2},
{pos:[10,0,20],state:2},
{pos:[11,0,20],state:2},
{pos:[12,0,20],state:2},
{pos:[13,0,20],state:2},
{pos:[14,0,20],state:2},
{pos:[15,0,20],state:2},
{pos:[16,0,20],state:2},
{pos:[17,0,20],state:2},
{pos:[18,0,20],state:2},
{pos:[19,0,20],state:2},
{pos:[20,0,20],state:2},
{pos:[21,0,20],state:2},
{pos:[22,0,20],state:2},
{pos:[23,0,20],state:2},
{pos:[24,0,20],state:2},
{pos:[25,0,20],state:2},
{pos:[26,0,20],state:2},
{pos:[27,0,20],state:2},
{pos:[28,0,20],state:2},
{pos:[29,0,20],state:2},
{pos:[30,0,20],state:2},
{pos:[0,0,21],state:2},
{pos:[1,0,21],state:2},
{pos:[2,0,21],state:2},
{pos:[3,0,21],state:2},
{pos:[4,0,21],state:2},
{pos:[5,0,21],state:2},
{pos:[6,0,21],state:2},
{pos:[7,0,21],state:2},
{pos:[8,0,21],state:2},
{pos:[9,0,21],state:2},
{pos:[10,0,21],state:2},
{pos:[11,0,21],state:2},
{pos:[12,0,21],state:2},
{pos:[13,0,21],state:2},
{pos:[14,0,21],state:2},
{pos:[15,0,21],state:2},
{pos:[16,0,21],state:2},
{pos:[17,0,21],state:2},
{pos:[18,0,21],state:2},
{pos:[19,0,21],state:2},
{pos:[20,0,21],state:2},
{pos:[21,0,21],state:2},
{pos:[22,0,21],state:2},
{pos:[23,0,21],state:2},
{pos:[24,0,21],state:2},
{pos:[25,0,21],state:2},
{pos:[26,0,21],state:2},
{pos:[27,0,21],state:2},
{pos:[28,0,21],state:2},
{pos:[29,0,21],state:2},
{pos:[30,0,21],state:2},
{pos:[0,0,22],state:2},
{pos:[1,0,22],state:2},
{pos:[2,0,22],state:2},
{pos:[3,0,22],state:2},
{pos:[4,0,22],state:2},
{pos:[5,0,22],state:2},
{pos:[6,0,22],state:2},
{pos:[7,0,22],state:2},
{pos:[8,0,22],state:2},
{pos:[9,0,22],state:2},
{pos:[10,0,22],state:2},
{pos:[11,0,22],state:2},
{pos:[12,0,22],state:2},
{pos:[13,0,22],state:2},
{pos:[14,0,22],state:2},
{pos:[15,0,22],state:2},
{pos:[16,0,22],state:2},
{pos:[17,0,22],state:2},
{pos:[18,0,22],state:2},
{pos:[19,0,22],state:2},
{pos:[20,0,22],state:2},
{pos:[21,0,22],state:2},
{pos:[22,0,22],state:2},
{pos:[23,0,22],state:2},
{pos:[24,0,22],state:2},
{pos:[25,0,22],state:2},
{pos:[26,0,22],state:2},
{pos:[27,0,22],state:2},
{pos:[28,0,22],state:2},
{pos:[29,0,22],state:2},
{pos:[30,0,22],state:2},
{pos:[0,0,23],state:2},
{pos:[1,0,23],state:2},
{pos:[2,0,23],state:2},
{pos:[3,0,23],state:2},
{pos:[4,0,23],state:2},
{pos:[5,0,23],state:2},
{pos:[6,0,23],state:2},
{pos:[7,0,23],state:2},
{pos:[8,0,23],state:2},
{pos:[9,0,23],state:2},
{pos:[10,0,23],state:2},
{pos:[11,0,23],state:2},
{pos:[12,0,23],state:2},
{pos:[13,0,23],state:2},
{pos:[14,0,23],state:2},
{pos:[15,0,23],state:2},
{pos:[16,0,23],state:2},
{pos:[17,0,23],state:2},
{pos:[18,0,23],state:2},
{pos:[19,0,23],state:2},
{pos:[20,0,23],state:2},
{pos:[21,0,23],state:2},
{pos:[22,0,23],state:2},
{pos:[23,0,23],state:2},
{pos:[24,0,23],state:2},
{pos:[25,0,23],state:2},
{pos:[26,0,23],state:2},
{pos:[27,0,23],state:2},
{pos:[28,0,23],state:2},
{pos:[29,0,23],state:2},
{pos:[30,0,23],state:2},
{pos:[0,0,24],state:2},
{pos:[1,0,24],state:2},
{pos:[2,0,24],state:2},
{pos:[3,0,24],state:2},
{pos:[4,0,24],state:2},
{pos:[5,0,24],state:2},
{pos:[6,0,24],state:2},
{pos:[7,0,24],state:2},
{pos:[8,0,24],state:2},
{pos:[9,0,24],state:2},
{pos:[10,0,24],state:2},
{pos:[11,0,24],state:2},
{pos:[12,0,24],state:2},
{pos:[13,0,24],state:2},
{pos:[14,0,24],state:2},
{pos:[15,0,24],state:2},
{pos:[16,0,24],state:2},
{pos:[17,0,24],state:2},
{pos:[18,0,24],state:2},
{pos:[19,0,24],state:2},
{pos:[20,0,24],state:2},
{pos:[21,0,24],state:2},
{pos:[22,0,24],state:2},
{pos:[23,0,24],state:2},
{pos:[24,0,24],state:2},
{pos:[25,0,24],state:2},
{pos:[26,0,24],state:2},
{pos:[27,0,24],state:2},
{pos:[28,0,24],state:2},
{pos:[29,0,24],state:2},
{pos:[30,0,24],state:2},
{pos:[0,0,25],state:2},
{pos:[1,0,25],state:2},
{pos:[2,0,25],state:2},
{pos:[3,0,25],state:2},
{pos:[4,0,25],state:2},
{pos:[5,0,25],state:2},
{pos:[6,0,25],state:2},
{pos:[7,0,25],state:2},
{pos:[8,0,25],state:2},
{pos:[9,0,25],state:2},
{pos:[10,0,25],state:2},
{pos:[11,0,25],state:2},
{pos:[12,0,25],state:2},
{pos:[13,0,25],state:2},
{pos:[14,0,25],state:2},
{pos:[15,0,25],state:2},
{pos:[16,0,25],state:2},
{pos:[17,0,25],state:2},
{pos:[18,0,25],state:2},
{pos:[19,0,25],state:2},
{pos:[20,0,25],state:2},
{pos:[21,0,25],state:2},
{pos:[22,0,25],state:2},
{pos:[23,0,25],state:2},
{pos:[24,0,25],state:2},
{pos:[25,0,25],state:2},
{pos:[26,0,25],state:2},
{pos:[27,0,25],state:2},
{pos:[28,0,25],state:2},
{pos:[29,0,25],state:2},
{pos:[30,0,25],state:2},
{pos:[0,0,26],state:2},
{pos:[1,0,26],state:2},
{pos:[2,0,26],state:2},
{pos:[3,0,26],state:2},
{pos:[4,0,26],state:2},
{pos:[5,0,26],state:2},
{pos:[6,0,26],state:2},
{pos:[7,0,26],state:2},
{pos:[8,0,26],state:2},
{pos:[9,0,26],state:2},
{pos:[10,0,26],state:2},
{pos:[11,0,26],state:2},
{pos:[12,0,26],state:2},
{pos:[13,0,26],state:2},
{pos:[14,0,26],state:2},
{pos:[15,0,26],state:2},
{pos:[16,0,26],state:2},
{pos:[17,0,26],state:2},
{pos:[18,0,26],state:2},
{pos:[19,0,26],state:2},
{pos:[20,0,26],state:2},
{pos:[21,0,26],state:2},
{pos:[22,0,26],state:2},
{pos:[23,0,26],state:2},
{pos:[24,0,26],state:2},
{pos:[25,0,26],state:2},
{pos:[26,0,26],state:2},
{pos:[27,0,26],state:2},
{pos:[28,0,26],state:2},
{pos:[29,0,26],state:2},
{pos:[30,0,26],state:2},
{pos:[0,1,0],state:1},
{pos:[1,1,0],state:1},
{pos:[2,1,0],state:1},
{pos:[3,1,0],state:1},
{pos:[4,1,0],state:1},
{pos:[5,1,0],state:1},
{pos:[6,1,0],state:1},
{pos:[7,1,0],state:1},
{pos:[8,1,0],state:1},
{pos:[9,1,0],state:1},
{pos:[10,1,0],state:1},
{pos:[11,1,0],state:1},
{pos:[12,1,0],state:1},
{pos:[18,1,0],state:1},
{pos:[19,1,0],state:1},
{pos:[20,1,0],state:1},
{pos:[21,1,0],state:1},
{pos:[22,1,0],state:1},
{pos:[23,1,0],state:1},
{pos:[24,1,0],state:1},
{pos:[25,1,0],state:1},
{pos:[26,1,0],state:1},
{pos:[27,1,0],state:1},
{pos:[28,1,0],state:1},
{pos:[29,1,0],state:1},
{pos:[30,1,0],state:1},
{pos:[0,1,1],state:1},
{pos:[1,1,1],state:1},
{pos:[2,1,1],state:1},
{pos:[3,1,1],state:1},
{pos:[4,1,1],state:1},
{pos:[5,1,1],state:1},
{pos:[6,1,1],state:1},
{pos:[7,1,1],state:1},
{pos:[8,1,1],state:1},
{pos:[9,1,1],state:1},
{pos:[10,1,1],state:1},
{pos:[11,1,1],state:1},
{pos:[12,1,1],state:1},
{pos:[18,1,1],state:1},
{pos:[19,1,1],state:1},
{pos:[20,1,1],state:1},
{pos:[21,1,1],state:1},
{pos:[22,1,1],state:1},
{pos:[23,1,1],state:1},
{pos:[24,1,1],state:1},
{pos:[25,1,1],state:1},
{pos:[26,1,1],state:1},
{pos:[27,1,1],state:1},
{pos:[28,1,1],state:1},
{pos:[29,1,1],state:1},
{pos:[30,1,1],state:1},
{pos:[0,1,2],state:1},
{pos:[1,1,2],state:1},
{pos:[4,1,2],state:0},
{pos:[11,1,2],state:0},
{pos:[18,1,2],state:0},
{pos:[25,1,2],state:0},
{pos:[29,1,2],state:1},
{pos:[30,1,2],state:1},
{pos:[0,1,3],state:1},
{pos:[1,1,3],state:1},
{pos:[29,1,3],state:1},
{pos:[30,1,3],state:1},
{pos:[0,1,4],state:1},
{pos:[1,1,4],state:1},
{pos:[4,1,4],state:0},
{pos:[26,1,4],state:0},
{pos:[29,1,4],state:1},
{pos:[30,1,4],state:1},
{pos:[0,1,5],state:1},
{pos:[1,1,5],state:1},
{pos:[2,1,5],state:0},
{pos:[28,1,5],state:0},
{pos:[29,1,5],state:1},
{pos:[30,1,5],state:1},
{pos:[0,1,6],state:1},
{pos:[1,1,6],state:1},
{pos:[29,1,6],state:1},
{pos:[30,1,6],state:1},
{pos:[0,1,7],state:1},
{pos:[1,1,7],state:1},
{pos:[29,1,7],state:1},
{pos:[30,1,7],state:1},
{pos:[0,1,8],state:1},
{pos:[1,1,8],state:1},
{pos:[29,1,8],state:1},
{pos:[30,1,8],state:1},
{pos:[0,1,9],state:1},
{pos:[1,1,9],state:1},
{pos:[4,1,9],state:0},
{pos:[26,1,9],state:0},
{pos:[29,1,9],state:1},
{pos:[30,1,9],state:1},
{pos:[0,1,10],state:1},
{pos:[1,1,10],state:1},
{pos:[29,1,10],state:1},
{pos:[30,1,10],state:1},
{pos:[0,1,11],state:1},
{pos:[1,1,11],state:1},
{pos:[29,1,11],state:1},
{pos:[30,1,11],state:1},
{pos:[0,1,12],state:1},
{pos:[1,1,12],state:1},
{pos:[29,1,12],state:1},
{pos:[30,1,12],state:1},
{pos:[0,1,13],state:1},
{pos:[1,1,13],state:1},
{pos:[2,1,13],state:0},
{pos:[15,1,13],state:4,nbt:{mode:"DATA",metadata:"enemy:elite:1"}},
{pos:[28,1,13],state:0},
{pos:[29,1,13],state:1},
{pos:[30,1,13],state:1},
{pos:[0,1,14],state:1},
{pos:[1,1,14],state:1},
{pos:[4,1,14],state:0},
{pos:[26,1,14],state:0},
{pos:[29,1,14],state:1},
{pos:[30,1,14],state:1},
{pos:[0,1,15],state:1},
{pos:[1,1,15],state:1},
{pos:[29,1,15],state:1},
{pos:[30,1,15],state:1},
{pos:[0,1,16],state:1},
{pos:[1,1,16],state:1},
{pos:[29,1,16],state:1},
{pos:[30,1,16],state:1},
{pos:[0,1,17],state:1},
{pos:[1,1,17],state:1},
{pos:[29,1,17],state:1},
{pos:[30,1,17],state:1},
{pos:[0,1,18],state:1},
{pos:[1,1,18],state:1},
{pos:[29,1,18],state:1},
{pos:[30,1,18],state:1},
{pos:[0,1,19],state:1},
{pos:[1,1,19],state:1},
{pos:[4,1,19],state:0},
{pos:[26,1,19],state:0},
{pos:[29,1,19],state:1},
{pos:[30,1,19],state:1},
{pos:[0,1,20],state:1},
{pos:[1,1,20],state:1},
{pos:[29,1,20],state:1},
{pos:[30,1,20],state:1},
{pos:[0,1,21],state:1},
{pos:[1,1,21],state:1},
{pos:[2,1,21],state:0},
{pos:[28,1,21],state:0},
{pos:[29,1,21],state:1},
{pos:[30,1,21],state:1},
{pos:[0,1,22],state:1},
{pos:[1,1,22],state:1},
{pos:[29,1,22],state:1},
{pos:[30,1,22],state:1},
{pos:[0,1,23],state:1},
{pos:[1,1,23],state:1},
{pos:[15,1,23],state:4,nbt:{mode:"DATA",metadata:"checkpoint:boss"}},
{pos:[29,1,23],state:1},
{pos:[30,1,23],state:1},
{pos:[0,1,24],state:1},
{pos:[1,1,24],state:1},
{pos:[4,1,24],state:0},
{pos:[11,1,24],state:0},
{pos:[15,1,24],state:4,nbt:{mode:"DATA",metadata:"door:6"}},
{pos:[18,1,24],state:0},
{pos:[25,1,24],state:0},
{pos:[29,1,24],state:1},
{pos:[30,1,24],state:1},
{pos:[0,1,25],state:1},
{pos:[1,1,25],state:1},
{pos:[2,1,25],state:1},
{pos:[3,1,25],state:1},
{pos:[4,1,25],state:1},
{pos:[5,1,25],state:1},
{pos:[6,1,25],state:1},
{pos:[7,1,25],state:1},
{pos:[8,1,25],state:1},
{pos:[9,1,25],state:1},
{pos:[10,1,25],state:1},
{pos:[11,1,25],state:1},
{pos:[12,1,25],state:1},
{pos:[18,1,25],state:1},
{pos:[19,1,25],state:1},
{pos:[20,1,25],state:1},
{pos:[21,1,25],state:1},
{pos:[22,1,25],state:1},
{pos:[23,1,25],state:1},
{pos:[24,1,25],state:1},
{pos:[25,1,25],state:1},
{pos:[26,1,25],state:1},
{pos:[27,1,25],state:1},
{pos:[28,1,25],state:1},
{pos:[29,1,25],state:1},
{pos:[30,1,25],state:1},
{pos:[0,1,26],state:1},
{pos:[1,1,26],state:1},
{pos:[2,1,26],state:1},
{pos:[3,1,26],state:1},
{pos:[4,1,26],state:1},
{pos:[5,1,26],state:1},
{pos:[6,1,26],state:1},
{pos:[7,1,26],state:1},
{pos:[8,1,26],state:1},
{pos:[9,1,26],state:1},
{pos:[10,1,26],state:1},
{pos:[11,1,26],state:1},
{pos:[12,1,26],state:1},
{pos:[18,1,26],state:1},
{pos:[19,1,26],state:1},
{pos:[20,1,26],state:1},
{pos:[21,1,26],state:1},
{pos:[22,1,26],state:1},
{pos:[23,1,26],state:1},
{pos:[24,1,26],state:1},
{pos:[25,1,26],state:1},
{pos:[26,1,26],state:1},
{pos:[27,1,26],state:1},
{pos:[28,1,26],state:1},
{pos:[29,1,26],state:1},
{pos:[30,1,26],state:1},
{pos:[0,2,0],state:1},
{pos:[1,2,0],state:1},
{pos:[2,2,0],state:1},
{pos:[3,2,0],state:1},
{pos:[4,2,0],state:1},
{pos:[5,2,0],state:1},
{pos:[6,2,0],state:1},
{pos:[7,2,0],state:1},
{pos:[8,2,0],state:1},
{pos:[9,2,0],state:1},
{pos:[10,2,0],state:1},
{pos:[11,2,0],state:1},
{pos:[12,2,0],state:1},
{pos:[18,2,0],state:1},
{pos:[19,2,0],state:1},
{pos:[20,2,0],state:1},
{pos:[21,2,0],state:1},
{pos:[22,2,0],state:1},
{pos:[23,2,0],state:1},
{pos:[24,2,0],state:1},
{pos:[25,2,0],state:1},
{pos:[26,2,0],state:1},
{pos:[27,2,0],state:1},
{pos:[28,2,0],state:1},
{pos:[29,2,0],state:1},
{pos:[30,2,0],state:1},
{pos:[0,2,1],state:1},
{pos:[1,2,1],state:1},
{pos:[2,2,1],state:1},
{pos:[3,2,1],state:1},
{pos:[4,2,1],state:1},
{pos:[5,2,1],state:1},
{pos:[6,2,1],state:1},
{pos:[7,2,1],state:1},
{pos:[8,2,1],state:1},
{pos:[9,2,1],state:1},
{pos:[10,2,1],state:1},
{pos:[11,2,1],state:1},
{pos:[12,2,1],state:1},
{pos:[18,2,1],state:1},
{pos:[19,2,1],state:1},
{pos:[20,2,1],state:1},
{pos:[21,2,1],state:1},
{pos:[22,2,1],state:1},
{pos:[23,2,1],state:1},
{pos:[24,2,1],state:1},
{pos:[25,2,1],state:1},
{pos:[26,2,1],state:1},
{pos:[27,2,1],state:1},
{pos:[28,2,1],state:1},
{pos:[29,2,1],state:1},
{pos:[30,2,1],state:1},
{pos:[0,2,2],state:1},
{pos:[1,2,2],state:1},
{pos:[4,2,2],state:0},
{pos:[11,2,2],state:0},
{pos:[18,2,2],state:0},
{pos:[25,2,2],state:0},
{pos:[29,2,2],state:1},
{pos:[30,2,2],state:1},
{pos:[0,2,3],state:1},
{pos:[1,2,3],state:1},
{pos:[29,2,3],state:1},
{pos:[30,2,3],state:1},
{pos:[0,2,4],state:1},
{pos:[1,2,4],state:1},
{pos:[4,2,4],state:0},
{pos:[26,2,4],state:0},
{pos:[29,2,4],state:1},
{pos:[30,2,4],state:1},
{pos:[0,2,5],state:1},
{pos:[1,2,5],state:1},
{pos:[2,2,5],state:0},
{pos:[28,2,5],state:0},
{pos:[29,2,5],state:1},
{pos:[30,2,5],state:1},
{pos:[0,2,6],state:1},
{pos:[1,2,6],state:1},
{pos:[29,2,6],state:1},
{pos:[30,2,6],state:1},
{pos:[0,2,7],state:1},
{pos:[1,2,7],state:1},
{pos:[29,2,7],state:1},
{pos:[30,2,7],state:1},
{pos:[0,2,8],state:1},
{pos:[1,2,8],state:1},
{pos:[29,2,8],state:1},
{pos:[30,2,8],state:1},
{pos:[0,2,9],state:1},
{pos:[1,2,9],state:1},
{pos:[4,2,9],state:0},
{pos:[26,2,9],state:0},
{pos:[29,2,9],state:1},
{pos:[30,2,9],state:1},
{pos:[0,2,10],state:1},
{pos:[1,2,10],state:1},
{pos:[29,2,10],state:1},
{pos:[30,2,10],state:1},
{pos:[0,2,11],state:1},
{pos:[1,2,11],state:1},
{pos:[29,2,11],state:1},
{pos:[30,2,11],state:1},
{pos:[0,2,12],state:1},
{pos:[1,2,12],state:1},
{pos:[29,2,12],state:1},
{pos:[30,2,12],state:1},
{pos:[0,2,13],state:1},
{pos:[1,2,13],state:1},
{pos:[2,2,13],state:0},
{pos:[28,2,13],state:0},
{pos:[29,2,13],state:1},
{pos:[30,2,13],state:1},
{pos:[0,2,14],state:1},
{pos:[1,2,14],state:1},
{pos:[4,2,14],state:0},
{pos:[26,2,14],state:0},
{pos:[29,2,14],state:1},
{pos:[30,2,14],state:1},
{pos:[0,2,15],state:1},
{pos:[1,2,15],state:1},
{pos:[29,2,15],state:1},
{pos:[30,2,15],state:1},
{pos:[0,2,16],state:1},
{pos:[1,2,16],state:1},
{pos:[29,2,16],state:1},
{pos:[30,2,16],state:1},
{pos:[0,2,17],state:1},
{pos:[1,2,17],state:1},
{pos:[29,2,17],state:1},
{pos:[30,2,17],state:1},
{pos:[0,2,18],state:1},
{pos:[1,2,18],state:1},
{pos:[29,2,18],state:1},
{pos:[30,2,18],state:1},
{pos:[0,2,19],state:1},
{pos:[1,2,19],state:1},
{pos:[4,2,19],state:0},
{pos:[26,2,19],state:0},
{pos:[29,2,19],state:1},
{pos:[30,2,19],state:1},
{pos:[0,2,20],state:1},
{pos:[1,2,20],state:1},
{pos:[29,2,20],state:1},
{pos:[30,2,20],state:1},
{pos:[0,2,21],state:1},
{pos:[1,2,21],state:1},
{pos:[2,2,21],state:0},
{pos:[28,2,21],state:0},
{pos:[29,2,21],state:1},
{pos:[30,2,21],state:1},
{pos:[0,2,22],state:1},
{pos:[1,2,22],state:1},
{pos:[29,2,22],state:1},
{pos:[30,2,22],state:1},
{pos:[0,2,23],state:1},
{pos:[1,2,23],state:1},
{pos:[29,2,23],state:1},
{pos:[30,2,23],state:1},
{pos:[0,2,24],state:1},
{pos:[1,2,24],state:1},
{pos:[4,2,24],state:0},
{pos:[11,2,24],state:0},
{pos:[18,2,24],state:0},
{pos:[25,2,24],state:0},
{pos:[29,2,24],state:1},
{pos:[30,2,24],state:1},
{pos:[0,2,25],state:1},
{pos:[1,2,25],state:1},
{pos:[2,2,25],state:1},
{pos:[3,2,25],state:1},
{pos:[4,2,25],state:1},
{pos:[5,2,25],state:1},
{pos:[6,2,25],state:1},
{pos:[7,2,25],state:1},
{pos:[8,2,25],state:1},
{pos:[9,2,25],state:1},
{pos:[10,2,25],state:1},
{pos:[11,2,25],state:1},
{pos:[12,2,25],state:1},
{pos:[18,2,25],state:1},
{pos:[19,2,25],state:1},
{pos:[20,2,25],state:1},
{pos:[21,2,25],state:1},
{pos:[22,2,25],state:1},
{pos:[23,2,25],state:1},
{pos:[24,2,25],state:1},
{pos:[25,2,25],state:1},
{pos:[26,2,25],state:1},
{pos:[27,2,25],state:1},
{pos:[28,2,25],state:1},
{pos:[29,2,25],state:1},
{pos:[30,2,25],state:1},
{pos:[0,2,26],state:1},
{pos:[1,2,26],state:1},
{pos:[2,2,26],state:1},
{pos:[3,2,26],state:1},
{pos:[4,2,26],state:1},
{pos:[5,2,26],state:1},
{pos:[6,2,26],state:1},
{pos:[7,2,26],state:1},
{pos:[8,2,26],state:1},
{pos:[9,2,26],state:1},
{pos:[10,2,26],state:1},
{pos:[11,2,26],state:1},
{pos:[12,2,26],state:1},
{pos:[18,2,26],state:1},
{pos:[19,2,26],state:1},
{pos:[20,2,26],state:1},
{pos:[21,2,26],state:1},
{pos:[22,2,26],state:1},
{pos:[23,2,26],state:1},
{pos:[24,2,26],state:1},
{pos:[25,2,26],state:1},
{pos:[26,2,26],state:1},
{pos:[27,2,26],state:1},
{pos:[28,2,26],state:1},
{pos:[29,2,26],state:1},
{pos:[30,2,26],state:1},
{pos:[0,3,0],state:1},
{pos:[1,3,0],state:1},
{pos:[2,3,0],state:1},
{pos:[3,3,0],state:1},
{pos:[4,3,0],state:1},
{pos:[5,3,0],state:1},
{pos:[6,3,0],state:1},
{pos:[7,3,0],state:1},
{pos:[8,3,0],state:1},
{pos:[9,3,0],state:1},
{pos:[10,3,0],state:1},
{pos:[11,3,0],state:1},
{pos:[12,3,0],state:1},
{pos:[18,3,0],state:1},
{pos:[19,3,0],state:1},
{pos:[20,3,0],state:1},
{pos:[21,3,0],state:1},
{pos:[22,3,0],state:1},
{pos:[23,3,0],state:1},
{pos:[24,3,0],state:1},
{pos:[25,3,0],state:1},
{pos:[26,3,0],state:1},
{pos:[27,3,0],state:1},
{pos:[28,3,0],state:1},
{pos:[29,3,0],state:1},
{pos:[30,3,0],state:1},
{pos:[0,3,1],state:1},
{pos:[1,3,1],state:1},
{pos:[2,3,1],state:1},
{pos:[3,3,1],state:1},
{pos:[4,3,1],state:1},
{pos:[5,3,1],state:1},
{pos:[6,3,1],state:1},
{pos:[7,3,1],state:1},
{pos:[8,3,1],state:1},
{pos:[9,3,1],state:1},
{pos:[10,3,1],state:1},
{pos:[11,3,1],state:1},
{pos:[12,3,1],state:1},
{pos:[18,3,1],state:1},
{pos:[19,3,1],state:1},
{pos:[20,3,1],state:1},
{pos:[21,3,1],state:1},
{pos:[22,3,1],state:1},
{pos:[23,3,1],state:1},
{pos:[24,3,1],state:1},
{pos:[25,3,1],state:1},
{pos:[26,3,1],state:1},
{pos:[27,3,1],state:1},
{pos:[28,3,1],state:1},
{pos:[29,3,1],state:1},
{pos:[30,3,1],state:1},
{pos:[0,3,2],state:1},
{pos:[1,3,2],state:1},
{pos:[4,3,2],state:0},
{pos:[11,3,2],state:0},
{pos:[18,3,2],state:0},
{pos:[25,3,2],state:0},
{pos:[29,3,2],state:1},
{pos:[30,3,2],state:1},
{pos:[0,3,3],state:1},
{pos:[1,3,3],state:1},
{pos:[29,3,3],state:1},
{pos:[30,3,3],state:1},
{pos:[0,3,4],state:1},
{pos:[1,3,4],state:1},
{pos:[4,3,4],state:0},
{pos:[26,3,4],state:0},
{pos:[29,3,4],state:1},
{pos:[30,3,4],state:1},
{pos:[0,3,5],state:1},
{pos:[1,3,5],state:1},
{pos:[2,3,5],state:0},
{pos:[28,3,5],state:0},
{pos:[29,3,5],state:1},
{pos:[30,3,5],state:1},
{pos:[0,3,6],state:1},
{pos:[1,3,6],state:1},
{pos:[29,3,6],state:1},
{pos:[30,3,6],state:1},
{pos:[0,3,7],state:1},
{pos:[1,3,7],state:1},
{pos:[29,3,7],state:1},
{pos:[30,3,7],state:1},
{pos:[0,3,8],state:1},
{pos:[1,3,8],state:1},
{pos:[29,3,8],state:1},
{pos:[30,3,8],state:1},
{pos:[0,3,9],state:1},
{pos:[1,3,9],state:1},
{pos:[4,3,9],state:0},
{pos:[26,3,9],state:0},
{pos:[29,3,9],state:1},
{pos:[30,3,9],state:1},
{pos:[0,3,10],state:1},
{pos:[1,3,10],state:1},
{pos:[29,3,10],state:1},
{pos:[30,3,10],state:1},
{pos:[0,3,11],state:1},
{pos:[1,3,11],state:1},
{pos:[29,3,11],state:1},
{pos:[30,3,11],state:1},
{pos:[0,3,12],state:1},
{pos:[1,3,12],state:1},
{pos:[29,3,12],state:1},
{pos:[30,3,12],state:1},
{pos:[0,3,13],state:1},
{pos:[1,3,13],state:1},
{pos:[2,3,13],state:0},
{pos:[28,3,13],state:0},
{pos:[29,3,13],state:1},
{pos:[30,3,13],state:1},
{pos:[0,3,14],state:1},
{pos:[1,3,14],state:1},
{pos:[4,3,14],state:0},
{pos:[26,3,14],state:0},
{pos:[29,3,14],state:1},
{pos:[30,3,14],state:1},
{pos:[0,3,15],state:1},
{pos:[1,3,15],state:1},
{pos:[29,3,15],state:1},
{pos:[30,3,15],state:1},
{pos:[0,3,16],state:1},
{pos:[1,3,16],state:1},
{pos:[29,3,16],state:1},
{pos:[30,3,16],state:1},
{pos:[0,3,17],state:1},
{pos:[1,3,17],state:1},
{pos:[29,3,17],state:1},
{pos:[30,3,17],state:1},
{pos:[0,3,18],state:1},
{pos:[1,3,18],state:1},
{pos:[29,3,18],state:1},
{pos:[30,3,18],state:1},
{pos:[0,3,19],state:1},
{pos:[1,3,19],state:1},
{pos:[4,3,19],state:0},
{pos:[26,3,19],state:0},
{pos:[29,3,19],state:1},
{pos:[30,3,19],state:1},
{pos:[0,3,20],state:1},
{pos:[1,3,20],state:1},
{pos:[29,3,20],state:1},
{pos:[30,3,20],state:1},
{pos:[0,3,21],state:1},
{pos:[1,3,21],state:1},
{pos:[2,3,21],state:0},
{pos:[28,3,21],state:0},
{pos:[29,3,21],state:1},
{pos:[30,3,21],state:1},
{pos:[0,3,22],state:1},
{pos:[1,3,22],state:1},
{pos:[29,3,22],state:1},
{pos:[30,3,22],state:1},
{pos:[0,3,23],state:1},
{pos:[1,3,23],state:1},
{pos:[29,3,23],state:1},
{pos:[30,3,23],state:1},
{pos:[0,3,24],state:1},
{pos:[1,3,24],state:1},
{pos:[4,3,24],state:0},
{pos:[11,3,24],state:0},
{pos:[18,3,24],state:0},
{pos:[25,3,24],state:0},
{pos:[29,3,24],state:1},
{pos:[30,3,24],state:1},
{pos:[0,3,25],state:1},
{pos:[1,3,25],state:1},
{pos:[2,3,25],state:1},
{pos:[3,3,25],state:1},
{pos:[4,3,25],state:1},
{pos:[5,3,25],state:1},
{pos:[6,3,25],state:1},
{pos:[7,3,25],state:1},
{pos:[8,3,25],state:1},
{pos:[9,3,25],state:1},
{pos:[10,3,25],state:1},
{pos:[11,3,25],state:1},
{pos:[12,3,25],state:1},
{pos:[18,3,25],state:1},
{pos:[19,3,25],state:1},
{pos:[20,3,25],state:1},
{pos:[21,3,25],state:1},
{pos:[22,3,25],state:1},
{pos:[23,3,25],state:1},
{pos:[24,3,25],state:1},
{pos:[25,3,25],state:1},
{pos:[26,3,25],state:1},
{pos:[27,3,25],state:1},
{pos:[28,3,25],state:1},
{pos:[29,3,25],state:1},
{pos:[30,3,25],state:1},
{pos:[0,3,26],state:1},
{pos:[1,3,26],state:1},
{pos:[2,3,26],state:1},
{pos:[3,3,26],state:1},
{pos:[4,3,26],state:1},
{pos:[5,3,26],state:1},
{pos:[6,3,26],state:1},
{pos:[7,3,26],state:1},
{pos:[8,3,26],state:1},
{pos:[9,3,26],state:1},
{pos:[10,3,26],state:1},
{pos:[11,3,26],state:1},
{pos:[12,3,26],state:1},
{pos:[18,3,26],state:1},
{pos:[19,3,26],state:1},
{pos:[20,3,26],state:1},
{pos:[21,3,26],state:1},
{pos:[22,3,26],state:1},
{pos:[23,3,26],state:1},
{pos:[24,3,26],state:1},
{pos:[25,3,26],state:1},
{pos:[26,3,26],state:1},
{pos:[27,3,26],state:1},
{pos:[28,3,26],state:1},
{pos:[29,3,26],state:1},
{pos:[30,3,26],state:1},
{pos:[0,4,0],state:1},
{pos:[1,4,0],state:1},
{pos:[2,4,0],state:1},
{pos:[3,4,0],state:1},
{pos:[4,4,0],state:1},
{pos:[5,4,0],state:1},
{pos:[6,4,0],state:1},
{pos:[7,4,0],state:1},
{pos:[8,4,0],state:1},
{pos:[9,4,0],state:1},
{pos:[10,4,0],state:1},
{pos:[11,4,0],state:1},
{pos:[12,4,0],state:1},
{pos:[18,4,0],state:1},
{pos:[19,4,0],state:1},
{pos:[20,4,0],state:1},
{pos:[21,4,0],state:1},
{pos:[22,4,0],state:1},
{pos:[23,4,0],state:1},
{pos:[24,4,0],state:1},
{pos:[25,4,0],state:1},
{pos:[26,4,0],state:1},
{pos:[27,4,0],state:1},
{pos:[28,4,0],state:1},
{pos:[29,4,0],state:1},
{pos:[30,4,0],state:1},
{pos:[0,4,1],state:1},
{pos:[1,4,1],state:1},
{pos:[2,4,1],state:1},
{pos:[3,4,1],state:1},
{pos:[4,4,1],state:1},
{pos:[5,4,1],state:1},
{pos:[6,4,1],state:1},
{pos:[7,4,1],state:1},
{pos:[8,4,1],state:1},
{pos:[9,4,1],state:1},
{pos:[10,4,1],state:1},
{pos:[11,4,1],state:1},
{pos:[12,4,1],state:1},
{pos:[18,4,1],state:1},
{pos:[19,4,1],state:1},
{pos:[20,4,1],state:1},
{pos:[21,4,1],state:1},
{pos:[22,4,1],state:1},
{pos:[23,4,1],state:1},
{pos:[24,4,1],state:1},
{pos:[25,4,1],state:1},
{pos:[26,4,1],state:1},
{pos:[27,4,1],state:1},
{pos:[28,4,1],state:1},
{pos:[29,4,1],state:1},
{pos:[30,4,1],state:1},
{pos:[0,4,2],state:1},
{pos:[1,4,2],state:1},
{pos:[4,4,2],state:0},
{pos:[11,4,2],state:0},
{pos:[18,4,2],state:0},
{pos:[25,4,2],state:0},
{pos:[29,4,2],state:1},
{pos:[30,4,2],state:1},
{pos:[0,4,3],state:1},
{pos:[1,4,3],state:1},
{pos:[29,4,3],state:1},
{pos:[30,4,3],state:1},
{pos:[0,4,4],state:1},
{pos:[1,4,4],state:1},
{pos:[4,4,4],state:0},
{pos:[26,4,4],state:0},
{pos:[29,4,4],state:1},
{pos:[30,4,4],state:1},
{pos:[0,4,5],state:1},
{pos:[1,4,5],state:1},
{pos:[2,4,5],state:0},
{pos:[28,4,5],state:0},
{pos:[29,4,5],state:1},
{pos:[30,4,5],state:1},
{pos:[0,4,6],state:1},
{pos:[1,4,6],state:1},
{pos:[29,4,6],state:1},
{pos:[30,4,6],state:1},
{pos:[0,4,7],state:1},
{pos:[1,4,7],state:1},
{pos:[29,4,7],state:1},
{pos:[30,4,7],state:1},
{pos:[0,4,8],state:1},
{pos:[1,4,8],state:1},
{pos:[29,4,8],state:1},
{pos:[30,4,8],state:1},
{pos:[0,4,9],state:1},
{pos:[1,4,9],state:1},
{pos:[4,4,9],state:0},
{pos:[26,4,9],state:0},
{pos:[29,4,9],state:1},
{pos:[30,4,9],state:1},
{pos:[0,4,10],state:1},
{pos:[1,4,10],state:1},
{pos:[29,4,10],state:1},
{pos:[30,4,10],state:1},
{pos:[0,4,11],state:1},
{pos:[1,4,11],state:1},
{pos:[29,4,11],state:1},
{pos:[30,4,11],state:1},
{pos:[0,4,12],state:1},
{pos:[1,4,12],state:1},
{pos:[29,4,12],state:1},
{pos:[30,4,12],state:1},
{pos:[0,4,13],state:1},
{pos:[1,4,13],state:1},
{pos:[2,4,13],state:0},
{pos:[28,4,13],state:0},
{pos:[29,4,13],state:1},
{pos:[30,4,13],state:1},
{pos:[0,4,14],state:1},
{pos:[1,4,14],state:1},
{pos:[4,4,14],state:0},
{pos:[26,4,14],state:0},
{pos:[29,4,14],state:1},
{pos:[30,4,14],state:1},
{pos:[0,4,15],state:1},
{pos:[1,4,15],state:1},
{pos:[29,4,15],state:1},
{pos:[30,4,15],state:1},
{pos:[0,4,16],state:1},
{pos:[1,4,16],state:1},
{pos:[29,4,16],state:1},
{pos:[30,4,16],state:1},
{pos:[0,4,17],state:1},
{pos:[1,4,17],state:1},
{pos:[29,4,17],state:1},
{pos:[30,4,17],state:1},
{pos:[0,4,18],state:1},
{pos:[1,4,18],state:1},
{pos:[29,4,18],state:1},
{pos:[30,4,18],state:1},
{pos:[0,4,19],state:1},
{pos:[1,4,19],state:1},
{pos:[4,4,19],state:0},
{pos:[26,4,19],state:0},
{pos:[29,4,19],state:1},
{pos:[30,4,19],state:1},
{pos:[0,4,20],state:1},
{pos:[1,4,20],state:1},
{pos:[29,4,20],state:1},
{pos:[30,4,20],state:1},
{pos:[0,4,21],state:1},
{pos:[1,4,21],state:1},
{pos:[2,4,21],state:0},
{pos:[28,4,21],state:0},
{pos:[29,4,21],state:1},
{pos:[30,4,21],state:1},
{pos:[0,4,22],state:1},
{pos:[1,4,22],state:1},
{pos:[29,4,22],state:1},
{pos:[30,4,22],state:1},
{pos:[0,4,23],state:1},
{pos:[1,4,23],state:1},
{pos:[29,4,23],state:1},
{pos:[30,4,23],state:1},
{pos:[0,4,24],state:1},
{pos:[1,4,24],state:1},
{pos:[4,4,24],state:0},
{pos:[11,4,24],state:0},
{pos:[18,4,24],state:0},
{pos:[25,4,24],state:0},
{pos:[29,4,24],state:1},
{pos:[30,4,24],state:1},
{pos:[0,4,25],state:1},
{pos:[1,4,25],state:1},
{pos:[2,4,25],state:1},
{pos:[3,4,25],state:1},
{pos:[4,4,25],state:1},
{pos:[5,4,25],state:1},
{pos:[6,4,25],state:1},
{pos:[7,4,25],state:1},
{pos:[8,4,25],state:1},
{pos:[9,4,25],state:1},
{pos:[10,4,25],state:1},
{pos:[11,4,25],state:1},
{pos:[12,4,25],state:1},
{pos:[18,4,25],state:1},
{pos:[19,4,25],state:1},
{pos:[20,4,25],state:1},
{pos:[21,4,25],state:1},
{pos:[22,4,25],state:1},
{pos:[23,4,25],state:1},
{pos:[24,4,25],state:1},
{pos:[25,4,25],state:1},
{pos:[26,4,25],state:1},
{pos:[27,4,25],state:1},
{pos:[28,4,25],state:1},
{pos:[29,4,25],state:1},
{pos:[30,4,25],state:1},
{pos:[0,4,26],state:1},
{pos:[1,4,26],state:1},
{pos:[2,4,26],state:1},
{pos:[3,4,26],state:1},
{pos:[4,4,26],state:1},
{pos:[5,4,26],state:1},
{pos:[6,4,26],state:1},
{pos:[7,4,26],state:1},
{pos:[8,4,26],state:1},
{pos:[9,4,26],state:1},
{pos:[10,4,26],state:1},
{pos:[11,4,26],state:1},
{pos:[12,4,26],state:1},
{pos:[18,4,26],state:1},
{pos:[19,4,26],state:1},
{pos:[20,4,26],state:1},
{pos:[21,4,26],state:1},
{pos:[22,4,26],state:1},
{pos:[23,4,26],state:1},
{pos:[24,4,26],state:1},
{pos:[25,4,26],state:1},
{pos:[26,4,26],state:1},
{pos:[27,4,26],state:1},
{pos:[28,4,26],state:1},
{pos:[29,4,26],state:1},
{pos:[30,4,26],state:1},
{pos:[0,5,0],state:1},
{pos:[1,5,0],state:1},
{pos:[2,5,0],state:1},
{pos:[3,5,0],state:1},
{pos:[4,5,0],state:1},
{pos:[5,5,0],state:1},
{pos:[6,5,0],state:1},
{pos:[7,5,0],state:1},
{pos:[8,5,0],state:1},
{pos:[9,5,0],state:1},
{pos:[10,5,0],state:1},
{pos:[11,5,0],state:1},
{pos:[12,5,0],state:1},
{pos:[18,5,0],state:1},
{pos:[19,5,0],state:1},
{pos:[20,5,0],state:1},
{pos:[21,5,0],state:1},
{pos:[22,5,0],state:1},
{pos:[23,5,0],state:1},
{pos:[24,5,0],state:1},
{pos:[25,5,0],state:1},
{pos:[26,5,0],state:1},
{pos:[27,5,0],state:1},
{pos:[28,5,0],state:1},
{pos:[29,5,0],state:1},
{pos:[30,5,0],state:1},
{pos:[0,5,1],state:1},
{pos:[1,5,1],state:1},
{pos:[2,5,1],state:1},
{pos:[3,5,1],state:1},
{pos:[4,5,1],state:1},
{pos:[5,5,1],state:1},
{pos:[6,5,1],state:1},
{pos:[7,5,1],state:1},
{pos:[8,5,1],state:1},
{pos:[9,5,1],state:1},
{pos:[10,5,1],state:1},
{pos:[11,5,1],state:1},
{pos:[12,5,1],state:1},
{pos:[18,5,1],state:1},
{pos:[19,5,1],state:1},
{pos:[20,5,1],state:1},
{pos:[21,5,1],state:1},
{pos:[22,5,1],state:1},
{pos:[23,5,1],state:1},
{pos:[24,5,1],state:1},
{pos:[25,5,1],state:1},
{pos:[26,5,1],state:1},
{pos:[27,5,1],state:1},
{pos:[28,5,1],state:1},
{pos:[29,5,1],state:1},
{pos:[30,5,1],state:1},
{pos:[0,5,2],state:1},
{pos:[1,5,2],state:1},
{pos:[4,5,2],state:0},
{pos:[11,5,2],state:0},
{pos:[18,5,2],state:0},
{pos:[25,5,2],state:0},
{pos:[29,5,2],state:1},
{pos:[30,5,2],state:1},
{pos:[0,5,3],state:1},
{pos:[1,5,3],state:1},
{pos:[29,5,3],state:1},
{pos:[30,5,3],state:1},
{pos:[0,5,4],state:1},
{pos:[1,5,4],state:1},
{pos:[4,5,4],state:0},
{pos:[26,5,4],state:0},
{pos:[29,5,4],state:1},
{pos:[30,5,4],state:1},
{pos:[0,5,5],state:1},
{pos:[1,5,5],state:1},
{pos:[2,5,5],state:0},
{pos:[28,5,5],state:0},
{pos:[29,5,5],state:1},
{pos:[30,5,5],state:1},
{pos:[0,5,6],state:1},
{pos:[1,5,6],state:1},
{pos:[29,5,6],state:1},
{pos:[30,5,6],state:1},
{pos:[0,5,7],state:1},
{pos:[1,5,7],state:1},
{pos:[29,5,7],state:1},
{pos:[30,5,7],state:1},
{pos:[0,5,8],state:1},
{pos:[1,5,8],state:1},
{pos:[29,5,8],state:1},
{pos:[30,5,8],state:1},
{pos:[0,5,9],state:1},
{pos:[1,5,9],state:1},
{pos:[4,5,9],state:0},
{pos:[26,5,9],state:0},
{pos:[29,5,9],state:1},
{pos:[30,5,9],state:1},
{pos:[0,5,10],state:1},
{pos:[1,5,10],state:1},
{pos:[29,5,10],state:1},
{pos:[30,5,10],state:1},
{pos:[0,5,11],state:1},
{pos:[1,5,11],state:1},
{pos:[29,5,11],state:1},
{pos:[30,5,11],state:1},
{pos:[0,5,12],state:1},
{pos:[1,5,12],state:1},
{pos:[29,5,12],state:1},
{pos:[30,5,12],state:1},
{pos:[0,5,13],state:1},
{pos:[1,5,13],state:1},
{pos:[2,5,13],state:0},
{pos:[28,5,13],state:0},
{pos:[29,5,13],state:1},
{pos:[30,5,13],state:1},
{pos:[0,5,14],state:1},
{pos:[1,5,14],state:1},
{pos:[4,5,14],state:0},
{pos:[26,5,14],state:0},
{pos:[29,5,14],state:1},
{pos:[30,5,14],state:1},
{pos:[0,5,15],state:1},
{pos:[1,5,15],state:1},
{pos:[29,5,15],state:1},
{pos:[30,5,15],state:1},
{pos:[0,5,16],state:1},
{pos:[1,5,16],state:1},
{pos:[29,5,16],state:1},
{pos:[30,5,16],state:1},
{pos:[0,5,17],state:1},
{pos:[1,5,17],state:1},
{pos:[29,5,17],state:1},
{pos:[30,5,17],state:1},
{pos:[0,5,18],state:1},
{pos:[1,5,18],state:1},
{pos:[29,5,18],state:1},
{pos:[30,5,18],state:1},
{pos:[0,5,19],state:1},
{pos:[1,5,19],state:1},
{pos:[4,5,19],state:0},
{pos:[26,5,19],state:0},
{pos:[29,5,19],state:1},
{pos:[30,5,19],state:1},
{pos:[0,5,20],state:1},
{pos:[1,5,20],state:1},
{pos:[29,5,20],state:1},
{pos:[30,5,20],state:1},
{pos:[0,5,21],state:1},
{pos:[1,5,21],state:1},
{pos:[2,5,21],state:0},
{pos:[28,5,21],state:0},
{pos:[29,5,21],state:1},
{pos:[30,5,21],state:1},
{pos:[0,5,22],state:1},
{pos:[1,5,22],state:1},
{pos:[29,5,22],state:1},
{pos:[30,5,22],state:1},
{pos:[0,5,23],state:1},
{pos:[1,5,23],state:1},
{pos:[29,5,23],state:1},
{pos:[30,5,23],state:1},
{pos:[0,5,24],state:1},
{pos:[1,5,24],state:1},
{pos:[4,5,24],state:0},
{pos:[11,5,24],state:0},
{pos:[18,5,24],state:0},
{pos:[25,5,24],state:0},
{pos:[29,5,24],state:1},
{pos:[30,5,24],state:1},
{pos:[0,5,25],state:1},
{pos:[1,5,25],state:1},
{pos:[2,5,25],state:1},
{pos:[3,5,25],state:1},
{pos:[4,5,25],state:1},
{pos:[5,5,25],state:1},
{pos:[6,5,25],state:1},
{pos:[7,5,25],state:1},
{pos:[8,5,25],state:1},
{pos:[9,5,25],state:1},
{pos:[10,5,25],state:1},
{pos:[11,5,25],state:1},
{pos:[12,5,25],state:1},
{pos:[18,5,25],state:1},
{pos:[19,5,25],state:1},
{pos:[20,5,25],state:1},
{pos:[21,5,25],state:1},
{pos:[22,5,25],state:1},
{pos:[23,5,25],state:1},
{pos:[24,5,25],state:1},
{pos:[25,5,25],state:1},
{pos:[26,5,25],state:1},
{pos:[27,5,25],state:1},
{pos:[28,5,25],state:1},
{pos:[29,5,25],state:1},
{pos:[30,5,25],state:1},
{pos:[0,5,26],state:1},
{pos:[1,5,26],state:1},
{pos:[2,5,26],state:1},
{pos:[3,5,26],state:1},
{pos:[4,5,26],state:1},
{pos:[5,5,26],state:1},
{pos:[6,5,26],state:1},
{pos:[7,5,26],state:1},
{pos:[8,5,26],state:1},
{pos:[9,5,26],state:1},
{pos:[10,5,26],state:1},
{pos:[11,5,26],state:1},
{pos:[12,5,26],state:1},
{pos:[18,5,26],state:1},
{pos:[19,5,26],state:1},
{pos:[20,5,26],state:1},
{pos:[21,5,26],state:1},
{pos:[22,5,26],state:1},
{pos:[23,5,26],state:1},
{pos:[24,5,26],state:1},
{pos:[25,5,26],state:1},
{pos:[26,5,26],state:1},
{pos:[27,5,26],state:1},
{pos:[28,5,26],state:1},
{pos:[29,5,26],state:1},
{pos:[30,5,26],state:1},
{pos:[0,6,0],state:1},
{pos:[1,6,0],state:1},
{pos:[2,6,0],state:1},
{pos:[3,6,0],state:1},
{pos:[4,6,0],state:1},
{pos:[5,6,0],state:1},
{pos:[6,6,0],state:1},
{pos:[7,6,0],state:1},
{pos:[8,6,0],state:1},
{pos:[9,6,0],state:1},
{pos:[10,6,0],state:1},
{pos:[11,6,0],state:1},
{pos:[12,6,0],state:1},
{pos:[13,6,0],state:1},
{pos:[14,6,0],state:1},
{pos:[15,6,0],state:1},
{pos:[16,6,0],state:1},
{pos:[17,6,0],state:1},
{pos:[18,6,0],state:1},
{pos:[19,6,0],state:1},
{pos:[20,6,0],state:1},
{pos:[21,6,0],state:1},
{pos:[22,6,0],state:1},
{pos:[23,6,0],state:1},
{pos:[24,6,0],state:1},
{pos:[25,6,0],state:1},
{pos:[26,6,0],state:1},
{pos:[27,6,0],state:1},
{pos:[28,6,0],state:1},
{pos:[29,6,0],state:1},
{pos:[30,6,0],state:1},
{pos:[0,6,1],state:1},
{pos:[1,6,1],state:1},
{pos:[2,6,1],state:1},
{pos:[3,6,1],state:1},
{pos:[4,6,1],state:1},
{pos:[5,6,1],state:1},
{pos:[6,6,1],state:1},
{pos:[7,6,1],state:1},
{pos:[8,6,1],state:1},
{pos:[9,6,1],state:1},
{pos:[10,6,1],state:1},
{pos:[11,6,1],state:1},
{pos:[12,6,1],state:1},
{pos:[13,6,1],state:1},
{pos:[14,6,1],state:1},
{pos:[15,6,1],state:1},
{pos:[16,6,1],state:1},
{pos:[17,6,1],state:1},
{pos:[18,6,1],state:1},
{pos:[19,6,1],state:1},
{pos:[20,6,1],state:1},
{pos:[21,6,1],state:1},
{pos:[22,6,1],state:1},
{pos:[23,6,1],state:1},
{pos:[24,6,1],state:1},
{pos:[25,6,1],state:1},
{pos:[26,6,1],state:1},
{pos:[27,6,1],state:1},
{pos:[28,6,1],state:1},
{pos:[29,6,1],state:1},
{pos:[30,6,1],state:1},
{pos:[0,6,2],state:1},
{pos:[1,6,2],state:1},
{pos:[29,6,2],state:1},
{pos:[30,6,2],state:1},
{pos:[0,6,3],state:1},
{pos:[1,6,3],state:1},
{pos:[3,6,3],state:3},
{pos:[27,6,3],state:3},
{pos:[29,6,3],state:1},
{pos:[30,6,3],state:1},
{pos:[0,6,4],state:1},
{pos:[1,6,4],state:1},
{pos:[4,6,4],state:0},
{pos:[26,6,4],state:0},
{pos:[29,6,4],state:1},
{pos:[30,6,4],state:1},
{pos:[0,6,5],state:1},
{pos:[1,6,5],state:1},
{pos:[29,6,5],state:1},
{pos:[30,6,5],state:1},
{pos:[0,6,6],state:1},
{pos:[1,6,6],state:1},
{pos:[29,6,6],state:1},
{pos:[30,6,6],state:1},
{pos:[0,6,7],state:1},
{pos:[1,6,7],state:1},
{pos:[29,6,7],state:1},
{pos:[30,6,7],state:1},
{pos:[0,6,8],state:1},
{pos:[1,6,8],state:1},
{pos:[29,6,8],state:1},
{pos:[30,6,8],state:1},
{pos:[0,6,9],state:1},
{pos:[1,6,9],state:1},
{pos:[4,6,9],state:0},
{pos:[26,6,9],state:0},
{pos:[29,6,9],state:1},
{pos:[30,6,9],state:1},
{pos:[0,6,10],state:1},
{pos:[1,6,10],state:1},
{pos:[29,6,10],state:1},
{pos:[30,6,10],state:1},
{pos:[0,6,11],state:1},
{pos:[1,6,11],state:1},
{pos:[29,6,11],state:1},
{pos:[30,6,11],state:1},
{pos:[0,6,12],state:1},
{pos:[1,6,12],state:1},
{pos:[29,6,12],state:1},
{pos:[30,6,12],state:1},
{pos:[0,6,13],state:1},
{pos:[1,6,13],state:1},
{pos:[29,6,13],state:1},
{pos:[30,6,13],state:1},
{pos:[0,6,14],state:1},
{pos:[1,6,14],state:1},
{pos:[4,6,14],state:0},
{pos:[26,6,14],state:0},
{pos:[29,6,14],state:1},
{pos:[30,6,14],state:1},
{pos:[0,6,15],state:1},
{pos:[1,6,15],state:1},
{pos:[29,6,15],state:1},
{pos:[30,6,15],state:1},
{pos:[0,6,16],state:1},
{pos:[1,6,16],state:1},
{pos:[29,6,16],state:1},
{pos:[30,6,16],state:1},
{pos:[0,6,17],state:1},
{pos:[1,6,17],state:1},
{pos:[29,6,17],state:1},
{pos:[30,6,17],state:1},
{pos:[0,6,18],state:1},
{pos:[1,6,18],state:1},
{pos:[29,6,18],state:1},
{pos:[30,6,18],state:1},
{pos:[0,6,19],state:1},
{pos:[1,6,19],state:1},
{pos:[4,6,19],state:0},
{pos:[26,6,19],state:0},
{pos:[29,6,19],state:1},
{pos:[30,6,19],state:1},
{pos:[0,6,20],state:1},
{pos:[1,6,20],state:1},
{pos:[29,6,20],state:1},
{pos:[30,6,20],state:1},
{pos:[0,6,21],state:1},
{pos:[1,6,21],state:1},
{pos:[29,6,21],state:1},
{pos:[30,6,21],state:1},
{pos:[0,6,22],state:1},
{pos:[1,6,22],state:1},
{pos:[29,6,22],state:1},
{pos:[30,6,22],state:1},
{pos:[0,6,23],state:1},
{pos:[1,6,23],state:1},
{pos:[3,6,23],state:3},
{pos:[27,6,23],state:3},
{pos:[29,6,23],state:1},
{pos:[30,6,23],state:1},
{pos:[0,6,24],state:1},
{pos:[1,6,24],state:1},
{pos:[29,6,24],state:1},
{pos:[30,6,24],state:1},
{pos:[0,6,25],state:1},
{pos:[1,6,25],state:1},
{pos:[2,6,25],state:1},
{pos:[3,6,25],state:1},
{pos:[4,6,25],state:1},
{pos:[5,6,25],state:1},
{pos:[6,6,25],state:1},
{pos:[7,6,25],state:1},
{pos:[8,6,25],state:1},
{pos:[9,6,25],state:1},
{pos:[10,6,25],state:1},
{pos:[11,6,25],state:1},
{pos:[12,6,25],state:1},
{pos:[13,6,25],state:1},
{pos:[14,6,25],state:1},
{pos:[15,6,25],state:1},
{pos:[16,6,25],state:1},
{pos:[17,6,25],state:1},
{pos:[18,6,25],state:1},
{pos:[19,6,25],state:1},
{pos:[20,6,25],state:1},
{pos:[21,6,25],state:1},
{pos:[22,6,25],state:1},
{pos:[23,6,25],state:1},
{pos:[24,6,25],state:1},
{pos:[25,6,25],state:1},
{pos:[26,6,25],state:1},
{pos:[27,6,25],state:1},
{pos:[28,6,25],state:1},
{pos:[29,6,25],state:1},
{pos:[30,6,25],state:1},
{pos:[0,6,26],state:1},
{pos:[1,6,26],state:1},
{pos:[2,6,26],state:1},
{pos:[3,6,26],state:1},
{pos:[4,6,26],state:1},
{pos:[5,6,26],state:1},
{pos:[6,6,26],state:1},
{pos:[7,6,26],state:1},
{pos:[8,6,26],state:1},
{pos:[9,6,26],state:1},
{pos:[10,6,26],state:1},
{pos:[11,6,26],state:1},
{pos:[12,6,26],state:1},
{pos:[13,6,26],state:1},
{pos:[14,6,26],state:1},
{pos:[15,6,26],state:1},
{pos:[16,6,26],state:1},
{pos:[17,6,26],state:1},
{pos:[18,6,26],state:1},
{pos:[19,6,26],state:1},
{pos:[20,6,26],state:1},
{pos:[21,6,26],state:1},
{pos:[22,6,26],state:1},
{pos:[23,6,26],state:1},
{pos:[24,6,26],state:1},
{pos:[25,6,26],state:1},
{pos:[26,6,26],state:1},
{pos:[27,6,26],state:1},
{pos:[28,6,26],state:1},
{pos:[29,6,26],state:1},
{pos:[30,6,26],state:1},
{pos:[0,7,0],state:1},
{pos:[1,7,0],state:1},
{pos:[2,7,0],state:1},
{pos:[3,7,0],state:1},
{pos:[4,7,0],state:1},
{pos:[5,7,0],state:1},
{pos:[6,7,0],state:1},
{pos:[7,7,0],state:1},
{pos:[8,7,0],state:1},
{pos:[9,7,0],state:1},
{pos:[10,7,0],state:1},
{pos:[11,7,0],state:1},
{pos:[12,7,0],state:1},
{pos:[13,7,0],state:1},
{pos:[14,7,0],state:1},
{pos:[15,7,0],state:1},
{pos:[16,7,0],state:1},
{pos:[17,7,0],state:1},
{pos:[18,7,0],state:1},
{pos:[19,7,0],state:1},
{pos:[20,7,0],state:1},
{pos:[21,7,0],state:1},
{pos:[22,7,0],state:1},
{pos:[23,7,0],state:1},
{pos:[24,7,0],state:1},
{pos:[25,7,0],state:1},
{pos:[26,7,0],state:1},
{pos:[27,7,0],state:1},
{pos:[28,7,0],state:1},
{pos:[29,7,0],state:1},
{pos:[30,7,0],state:1},
{pos:[0,7,1],state:1},
{pos:[1,7,1],state:1},
{pos:[2,7,1],state:1},
{pos:[3,7,1],state:1},
{pos:[4,7,1],state:1},
{pos:[5,7,1],state:1},
{pos:[6,7,1],state:1},
{pos:[7,7,1],state:1},
{pos:[8,7,1],state:1},
{pos:[9,7,1],state:1},
{pos:[10,7,1],state:1},
{pos:[11,7,1],state:1},
{pos:[12,7,1],state:1},
{pos:[13,7,1],state:1},
{pos:[14,7,1],state:1},
{pos:[15,7,1],state:1},
{pos:[16,7,1],state:1},
{pos:[17,7,1],state:1},
{pos:[18,7,1],state:1},
{pos:[19,7,1],state:1},
{pos:[20,7,1],state:1},
{pos:[21,7,1],state:1},
{pos:[22,7,1],state:1},
{pos:[23,7,1],state:1},
{pos:[24,7,1],state:1},
{pos:[25,7,1],state:1},
{pos:[26,7,1],state:1},
{pos:[27,7,1],state:1},
{pos:[28,7,1],state:1},
{pos:[29,7,1],state:1},
{pos:[30,7,1],state:1},
{pos:[0,7,2],state:1},
{pos:[1,7,2],state:1},
{pos:[29,7,2],state:1},
{pos:[30,7,2],state:1},
{pos:[0,7,3],state:1},
{pos:[1,7,3],state:1},
{pos:[29,7,3],state:1},
{pos:[30,7,3],state:1},
{pos:[0,7,4],state:1},
{pos:[1,7,4],state:1},
{pos:[4,7,4],state:0},
{pos:[26,7,4],state:0},
{pos:[29,7,4],state:1},
{pos:[30,7,4],state:1},
{pos:[0,7,5],state:1},
{pos:[1,7,5],state:1},
{pos:[29,7,5],state:1},
{pos:[30,7,5],state:1},
{pos:[0,7,6],state:1},
{pos:[1,7,6],state:1},
{pos:[29,7,6],state:1},
{pos:[30,7,6],state:1},
{pos:[0,7,7],state:1},
{pos:[1,7,7],state:1},
{pos:[29,7,7],state:1},
{pos:[30,7,7],state:1},
{pos:[0,7,8],state:1},
{pos:[1,7,8],state:1},
{pos:[29,7,8],state:1},
{pos:[30,7,8],state:1},
{pos:[0,7,9],state:1},
{pos:[1,7,9],state:1},
{pos:[4,7,9],state:0},
{pos:[26,7,9],state:0},
{pos:[29,7,9],state:1},
{pos:[30,7,9],state:1},
{pos:[0,7,10],state:1},
{pos:[1,7,10],state:1},
{pos:[29,7,10],state:1},
{pos:[30,7,10],state:1},
{pos:[0,7,11],state:1},
{pos:[1,7,11],state:1},
{pos:[29,7,11],state:1},
{pos:[30,7,11],state:1},
{pos:[0,7,12],state:1},
{pos:[1,7,12],state:1},
{pos:[29,7,12],state:1},
{pos:[30,7,12],state:1},
{pos:[0,7,13],state:1},
{pos:[1,7,13],state:1},
{pos:[29,7,13],state:1},
{pos:[30,7,13],state:1},
{pos:[0,7,14],state:1},
{pos:[1,7,14],state:1},
{pos:[4,7,14],state:0},
{pos:[26,7,14],state:0},
{pos:[29,7,14],state:1},
{pos:[30,7,14],state:1},
{pos:[0,7,15],state:1},
{pos:[1,7,15],state:1},
{pos:[29,7,15],state:1},
{pos:[30,7,15],state:1},
{pos:[0,7,16],state:1},
{pos:[1,7,16],state:1},
{pos:[29,7,16],state:1},
{pos:[30,7,16],state:1},
{pos:[0,7,17],state:1},
{pos:[1,7,17],state:1},
{pos:[29,7,17],state:1},
{pos:[30,7,17],state:1},
{pos:[0,7,18],state:1},
{pos:[1,7,18],state:1},
{pos:[29,7,18],state:1},
{pos:[30,7,18],state:1},
{pos:[0,7,19],state:1},
{pos:[1,7,19],state:1},
{pos:[4,7,19],state:0},
{pos:[26,7,19],state:0},
{pos:[29,7,19],state:1},
{pos:[30,7,19],state:1},
{pos:[0,7,20],state:1},
{pos:[1,7,20],state:1},
{pos:[29,7,20],state:1},
{pos:[30,7,20],state:1},
{pos:[0,7,21],state:1},
{pos:[1,7,21],state:1},
{pos:[29,7,21],state:1},
{pos:[30,7,21],state:1},
{pos:[0,7,22],state:1},
{pos:[1,7,22],state:1},
{pos:[29,7,22],state:1},
{pos:[30,7,22],state:1},
{pos:[0,7,23],state:1},
{pos:[1,7,23],state:1},
{pos:[29,7,23],state:1},
{pos:[30,7,23],state:1},
{pos:[0,7,24],state:1},
{pos:[1,7,24],state:1},
{pos:[29,7,24],state:1},
{pos:[30,7,24],state:1},
{pos:[0,7,25],state:1},
{pos:[1,7,25],state:1},
{pos:[2,7,25],state:1},
{pos:[3,7,25],state:1},
{pos:[4,7,25],state:1},
{pos:[5,7,25],state:1},
{pos:[6,7,25],state:1},
{pos:[7,7,25],state:1},
{pos:[8,7,25],state:1},
{pos:[9,7,25],state:1},
{pos:[10,7,25],state:1},
{pos:[11,7,25],state:1},
{pos:[12,7,25],state:1},
{pos:[13,7,25],state:1},
{pos:[14,7,25],state:1},
{pos:[15,7,25],state:1},
{pos:[16,7,25],state:1},
{pos:[17,7,25],state:1},
{pos:[18,7,25],state:1},
{pos:[19,7,25],state:1},
{pos:[20,7,25],state:1},
{pos:[21,7,25],state:1},
{pos:[22,7,25],state:1},
{pos:[23,7,25],state:1},
{pos:[24,7,25],state:1},
{pos:[25,7,25],state:1},
{pos:[26,7,25],state:1},
{pos:[27,7,25],state:1},
{pos:[28,7,25],state:1},
{pos:[29,7,25],state:1},
{pos:[30,7,25],state:1},
{pos:[0,7,26],state:1},
{pos:[1,7,26],state:1},
{pos:[2,7,26],state:1},
{pos:[3,7,26],state:1},
{pos:[4,7,26],state:1},
{pos:[5,7,26],state:1},
{pos:[6,7,26],state:1},
{pos:[7,7,26],state:1},
{pos:[8,7,26],state:1},
{pos:[9,7,26],state:1},
{pos:[10,7,26],state:1},
{pos:[11,7,26],state:1},
{pos:[12,7,26],state:1},
{pos:[13,7,26],state:1},
{pos:[14,7,26],state:1},
{pos:[15,7,26],state:1},
{pos:[16,7,26],state:1},
{pos:[17,7,26],state:1},
{pos:[18,7,26],state:1},
{pos:[19,7,26],state:1},
{pos:[20,7,26],state:1},
{pos:[21,7,26],state:1},
{pos:[22,7,26],state:1},
{pos:[23,7,26],state:1},
{pos:[24,7,26],state:1},
{pos:[25,7,26],state:1},
{pos:[26,7,26],state:1},
{pos:[27,7,26],state:1},
{pos:[28,7,26],state:1},
{pos:[29,7,26],state:1},
{pos:[30,7,26],state:1},
{pos:[0,8,0],state:1},
{pos:[1,8,0],state:1},
{pos:[2,8,0],state:1},
{pos:[3,8,0],state:1},
{pos:[4,8,0],state:1},
{pos:[5,8,0],state:1},
{pos:[6,8,0],state:1},
{pos:[7,8,0],state:1},
{pos:[8,8,0],state:1},
{pos:[9,8,0],state:1},
{pos:[10,8,0],state:1},
{pos:[11,8,0],state:1},
{pos:[12,8,0],state:1},
{pos:[13,8,0],state:1},
{pos:[14,8,0],state:1},
{pos:[15,8,0],state:1},
{pos:[16,8,0],state:1},
{pos:[17,8,0],state:1},
{pos:[18,8,0],state:1},
{pos:[19,8,0],state:1},
{pos:[20,8,0],state:1},
{pos:[21,8,0],state:1},
{pos:[22,8,0],state:1},
{pos:[23,8,0],state:1},
{pos:[24,8,0],state:1},
{pos:[25,8,0],state:1},
{pos:[26,8,0],state:1},
{pos:[27,8,0],state:1},
{pos:[28,8,0],state:1},
{pos:[29,8,0],state:1},
{pos:[30,8,0],state:1},
{pos:[0,8,1],state:1},
{pos:[1,8,1],state:1},
{pos:[2,8,1],state:1},
{pos:[3,8,1],state:1},
{pos:[4,8,1],state:1},
{pos:[5,8,1],state:1},
{pos:[6,8,1],state:1},
{pos:[7,8,1],state:1},
{pos:[8,8,1],state:1},
{pos:[9,8,1],state:1},
{pos:[10,8,1],state:1},
{pos:[11,8,1],state:1},
{pos:[12,8,1],state:1},
{pos:[13,8,1],state:1},
{pos:[14,8,1],state:1},
{pos:[15,8,1],state:1},
{pos:[16,8,1],state:1},
{pos:[17,8,1],state:1},
{pos:[18,8,1],state:1},
{pos:[19,8,1],state:1},
{pos:[20,8,1],state:1},
{pos:[21,8,1],state:1},
{pos:[22,8,1],state:1},
{pos:[23,8,1],state:1},
{pos:[24,8,1],state:1},
{pos:[25,8,1],state:1},
{pos:[26,8,1],state:1},
{pos:[27,8,1],state:1},
{pos:[28,8,1],state:1},
{pos:[29,8,1],state:1},
{pos:[30,8,1],state:1},
{pos:[0,8,2],state:1},
{pos:[1,8,2],state:1},
{pos:[29,8,2],state:1},
{pos:[30,8,2],state:1},
{pos:[0,8,3],state:1},
{pos:[1,8,3],state:1},
{pos:[29,8,3],state:1},
{pos:[30,8,3],state:1},
{pos:[0,8,4],state:1},
{pos:[1,8,4],state:1},
{pos:[4,8,4],state:0},
{pos:[26,8,4],state:0},
{pos:[29,8,4],state:1},
{pos:[30,8,4],state:1},
{pos:[0,8,5],state:1},
{pos:[1,8,5],state:1},
{pos:[29,8,5],state:1},
{pos:[30,8,5],state:1},
{pos:[0,8,6],state:1},
{pos:[1,8,6],state:1},
{pos:[29,8,6],state:1},
{pos:[30,8,6],state:1},
{pos:[0,8,7],state:1},
{pos:[1,8,7],state:1},
{pos:[29,8,7],state:1},
{pos:[30,8,7],state:1},
{pos:[0,8,8],state:1},
{pos:[1,8,8],state:1},
{pos:[29,8,8],state:1},
{pos:[30,8,8],state:1},
{pos:[0,8,9],state:1},
{pos:[1,8,9],state:1},
{pos:[4,8,9],state:0},
{pos:[26,8,9],state:0},
{pos:[29,8,9],state:1},
{pos:[30,8,9],state:1},
{pos:[0,8,10],state:1},
{pos:[1,8,10],state:1},
{pos:[29,8,10],state:1},
{pos:[30,8,10],state:1},
{pos:[0,8,11],state:1},
{pos:[1,8,11],state:1},
{pos:[29,8,11],state:1},
{pos:[30,8,11],state:1},
{pos:[0,8,12],state:1},
{pos:[1,8,12],state:1},
{pos:[29,8,12],state:1},
{pos:[30,8,12],state:1},
{pos:[0,8,13],state:1},
{pos:[1,8,13],state:1},
{pos:[29,8,13],state:1},
{pos:[30,8,13],state:1},
{pos:[0,8,14],state:1},
{pos:[1,8,14],state:1},
{pos:[4,8,14],state:0},
{pos:[26,8,14],state:0},
{pos:[29,8,14],state:1},
{pos:[30,8,14],state:1},
{pos:[0,8,15],state:1},
{pos:[1,8,15],state:1},
{pos:[29,8,15],state:1},
{pos:[30,8,15],state:1},
{pos:[0,8,16],state:1},
{pos:[1,8,16],state:1},
{pos:[29,8,16],state:1},
{pos:[30,8,16],state:1},
{pos:[0,8,17],state:1},
{pos:[1,8,17],state:1},
{pos:[29,8,17],state:1},
{pos:[30,8,17],state:1},
{pos:[0,8,18],state:1},
{pos:[1,8,18],state:1},
{pos:[29,8,18],state:1},
{pos:[30,8,18],state:1},
{pos:[0,8,19],state:1},
{pos:[1,8,19],state:1},
{pos:[4,8,19],state:0},
{pos:[26,8,19],state:0},
{pos:[29,8,19],state:1},
{pos:[30,8,19],state:1},
{pos:[0,8,20],state:1},
{pos:[1,8,20],state:1},
{pos:[29,8,20],state:1},
{pos:[30,8,20],state:1},
{pos:[0,8,21],state:1},
{pos:[1,8,21],state:1},
{pos:[29,8,21],state:1},
{pos:[30,8,21],state:1},
{pos:[0,8,22],state:1},
{pos:[1,8,22],state:1},
{pos:[29,8,22],state:1},
{pos:[30,8,22],state:1},
{pos:[0,8,23],state:1},
{pos:[1,8,23],state:1},
{pos:[29,8,23],state:1},
{pos:[30,8,23],state:1},
{pos:[0,8,24],state:1},
{pos:[1,8,24],state:1},
{pos:[29,8,24],state:1},
{pos:[30,8,24],state:1},
{pos:[0,8,25],state:1},
{pos:[1,8,25],state:1},
{pos:[2,8,25],state:1},
{pos:[3,8,25],state:1},
{pos:[4,8,25],state:1},
{pos:[5,8,25],state:1},
{pos:[6,8,25],state:1},
{pos:[7,8,25],state:1},
{pos:[8,8,25],state:1},
{pos:[9,8,25],state:1},
{pos:[10,8,25],state:1},
{pos:[11,8,25],state:1},
{pos:[12,8,25],state:1},
{pos:[13,8,25],state:1},
{pos:[14,8,25],state:1},
{pos:[15,8,25],state:1},
{pos:[16,8,25],state:1},
{pos:[17,8,25],state:1},
{pos:[18,8,25],state:1},
{pos:[19,8,25],state:1},
{pos:[20,8,25],state:1},
{pos:[21,8,25],state:1},
{pos:[22,8,25],state:1},
{pos:[23,8,25],state:1},
{pos:[24,8,25],state:1},
{pos:[25,8,25],state:1},
{pos:[26,8,25],state:1},
{pos:[27,8,25],state:1},
{pos:[28,8,25],state:1},
{pos:[29,8,25],state:1},
{pos:[30,8,25],state:1},
{pos:[0,8,26],state:1},
{pos:[1,8,26],state:1},
{pos:[2,8,26],state:1},
{pos:[3,8,26],state:1},
{pos:[4,8,26],state:1},
{pos:[5,8,26],state:1},
{pos:[6,8,26],state:1},
{pos:[7,8,26],state:1},
{pos:[8,8,26],state:1},
{pos:[9,8,26],state:1},
{pos:[10,8,26],state:1},
{pos:[11,8,26],state:1},
{pos:[12,8,26],state:1},
{pos:[13,8,26],state:1},
{pos:[14,8,26],state:1},
{pos:[15,8,26],state:1},
{pos:[16,8,26],state:1},
{pos:[17,8,26],state:1},
{pos:[18,8,26],state:1},
{pos:[19,8,26],state:1},
{pos:[20,8,26],state:1},
{pos:[21,8,26],state:1},
{pos:[22,8,26],state:1},
{pos:[23,8,26],state:1},
{pos:[24,8,26],state:1},
{pos:[25,8,26],state:1},
{pos:[26,8,26],state:1},
{pos:[27,8,26],state:1},
{pos:[28,8,26],state:1},
{pos:[29,8,26],state:1},
{pos:[30,8,26],state:1},
{pos:[0,9,0],state:1},
{pos:[1,9,0],state:1},
{pos:[2,9,0],state:1},
{pos:[3,9,0],state:1},
{pos:[4,9,0],state:1},
{pos:[5,9,0],state:1},
{pos:[6,9,0],state:1},
{pos:[7,9,0],state:1},
{pos:[8,9,0],state:1},
{pos:[9,9,0],state:1},
{pos:[10,9,0],state:1},
{pos:[11,9,0],state:1},
{pos:[12,9,0],state:1},
{pos:[13,9,0],state:1},
{pos:[14,9,0],state:1},
{pos:[15,9,0],state:1},
{pos:[16,9,0],state:1},
{pos:[17,9,0],state:1},
{pos:[18,9,0],state:1},
{pos:[19,9,0],state:1},
{pos:[20,9,0],state:1},
{pos:[21,9,0],state:1},
{pos:[22,9,0],state:1},
{pos:[23,9,0],state:1},
{pos:[24,9,0],state:1},
{pos:[25,9,0],state:1},
{pos:[26,9,0],state:1},
{pos:[27,9,0],state:1},
{pos:[28,9,0],state:1},
{pos:[29,9,0],state:1},
{pos:[30,9,0],state:1},
{pos:[0,9,1],state:1},
{pos:[1,9,1],state:1},
{pos:[2,9,1],state:1},
{pos:[3,9,1],state:1},
{pos:[4,9,1],state:1},
{pos:[5,9,1],state:1},
{pos:[6,9,1],state:1},
{pos:[7,9,1],state:1},
{pos:[8,9,1],state:1},
{pos:[9,9,1],state:1},
{pos:[10,9,1],state:1},
{pos:[11,9,1],state:1},
{pos:[12,9,1],state:1},
{pos:[13,9,1],state:1},
{pos:[14,9,1],state:1},
{pos:[15,9,1],state:1},
{pos:[16,9,1],state:1},
{pos:[17,9,1],state:1},
{pos:[18,9,1],state:1},
{pos:[19,9,1],state:1},
{pos:[20,9,1],state:1},
{pos:[21,9,1],state:1},
{pos:[22,9,1],state:1},
{pos:[23,9,1],state:1},
{pos:[24,9,1],state:1},
{pos:[25,9,1],state:1},
{pos:[26,9,1],state:1},
{pos:[27,9,1],state:1},
{pos:[28,9,1],state:1},
{pos:[29,9,1],state:1},
{pos:[30,9,1],state:1},
{pos:[0,9,2],state:1},
{pos:[1,9,2],state:1},
{pos:[29,9,2],state:1},
{pos:[30,9,2],state:1},
{pos:[0,9,3],state:1},
{pos:[1,9,3],state:1},
{pos:[29,9,3],state:1},
{pos:[30,9,3],state:1},
{pos:[0,9,4],state:1},
{pos:[1,9,4],state:1},
{pos:[4,9,4],state:0},
{pos:[26,9,4],state:0},
{pos:[29,9,4],state:1},
{pos:[30,9,4],state:1},
{pos:[0,9,5],state:1},
{pos:[1,9,5],state:1},
{pos:[29,9,5],state:1},
{pos:[30,9,5],state:1},
{pos:[0,9,6],state:1},
{pos:[1,9,6],state:1},
{pos:[29,9,6],state:1},
{pos:[30,9,6],state:1},
{pos:[0,9,7],state:1},
{pos:[1,9,7],state:1},
{pos:[29,9,7],state:1},
{pos:[30,9,7],state:1},
{pos:[0,9,8],state:1},
{pos:[1,9,8],state:1},
{pos:[29,9,8],state:1},
{pos:[30,9,8],state:1},
{pos:[0,9,9],state:1},
{pos:[1,9,9],state:1},
{pos:[4,9,9],state:0},
{pos:[26,9,9],state:0},
{pos:[29,9,9],state:1},
{pos:[30,9,9],state:1},
{pos:[0,9,10],state:1},
{pos:[1,9,10],state:1},
{pos:[29,9,10],state:1},
{pos:[30,9,10],state:1},
{pos:[0,9,11],state:1},
{pos:[1,9,11],state:1},
{pos:[29,9,11],state:1},
{pos:[30,9,11],state:1},
{pos:[0,9,12],state:1},
{pos:[1,9,12],state:1},
{pos:[29,9,12],state:1},
{pos:[30,9,12],state:1},
{pos:[0,9,13],state:1},
{pos:[1,9,13],state:1},
{pos:[29,9,13],state:1},
{pos:[30,9,13],state:1},
{pos:[0,9,14],state:1},
{pos:[1,9,14],state:1},
{pos:[4,9,14],state:0},
{pos:[26,9,14],state:0},
{pos:[29,9,14],state:1},
{pos:[30,9,14],state:1},
{pos:[0,9,15],state:1},
{pos:[1,9,15],state:1},
{pos:[29,9,15],state:1},
{pos:[30,9,15],state:1},
{pos:[0,9,16],state:1},
{pos:[1,9,16],state:1},
{pos:[29,9,16],state:1},
{pos:[30,9,16],state:1},
{pos:[0,9,17],state:1},
{pos:[1,9,17],state:1},
{pos:[29,9,17],state:1},
{pos:[30,9,17],state:1},
{pos:[0,9,18],state:1},
{pos:[1,9,18],state:1},
{pos:[29,9,18],state:1},
{pos:[30,9,18],state:1},
{pos:[0,9,19],state:1},
{pos:[1,9,19],state:1},
{pos:[4,9,19],state:0},
{pos:[26,9,19],state:0},
{pos:[29,9,19],state:1},
{pos:[30,9,19],state:1},
{pos:[0,9,20],state:1},
{pos:[1,9,20],state:1},
{pos:[29,9,20],state:1},
{pos:[30,9,20],state:1},
{pos:[0,9,21],state:1},
{pos:[1,9,21],state:1},
{pos:[29,9,21],state:1},
{pos:[30,9,21],state:1},
{pos:[0,9,22],state:1},
{pos:[1,9,22],state:1},
{pos:[29,9,22],state:1},
{pos:[30,9,22],state:1},
{pos:[0,9,23],state:1},
{pos:[1,9,23],state:1},
{pos:[29,9,23],state:1},
{pos:[30,9,23],state:1},
{pos:[0,9,24],state:1},
{pos:[1,9,24],state:1},
{pos:[29,9,24],state:1},
{pos:[30,9,24],state:1},
{pos:[0,9,25],state:1},
{pos:[1,9,25],state:1},
{pos:[2,9,25],state:1},
{pos:[3,9,25],state:1},
{pos:[4,9,25],state:1},
{pos:[5,9,25],state:1},
{pos:[6,9,25],state:1},
{pos:[7,9,25],state:1},
{pos:[8,9,25],state:1},
{pos:[9,9,25],state:1},
{pos:[10,9,25],state:1},
{pos:[11,9,25],state:1},
{pos:[12,9,25],state:1},
{pos:[13,9,25],state:1},
{pos:[14,9,25],state:1},
{pos:[15,9,25],state:1},
{pos:[16,9,25],state:1},
{pos:[17,9,25],state:1},
{pos:[18,9,25],state:1},
{pos:[19,9,25],state:1},
{pos:[20,9,25],state:1},
{pos:[21,9,25],state:1},
{pos:[22,9,25],state:1},
{pos:[23,9,25],state:1},
{pos:[24,9,25],state:1},
{pos:[25,9,25],state:1},
{pos:[26,9,25],state:1},
{pos:[27,9,25],state:1},
{pos:[28,9,25],state:1},
{pos:[29,9,25],state:1},
{pos:[30,9,25],state:1},
{pos:[0,9,26],state:1},
{pos:[1,9,26],state:1},
{pos:[2,9,26],state:1},
{pos:[3,9,26],state:1},
{pos:[4,9,26],state:1},
{pos:[5,9,26],state:1},
{pos:[6,9,26],state:1},
{pos:[7,9,26],state:1},
{pos:[8,9,26],state:1},
{pos:[9,9,26],state:1},
{pos:[10,9,26],state:1},
{pos:[11,9,26],state:1},
{pos:[12,9,26],state:1},
{pos:[13,9,26],state:1},
{pos:[14,9,26],state:1},
{pos:[15,9,26],state:1},
{pos:[16,9,26],state:1},
{pos:[17,9,26],state:1},
{pos:[18,9,26],state:1},
{pos:[19,9,26],state:1},
{pos:[20,9,26],state:1},
{pos:[21,9,26],state:1},
{pos:[22,9,26],state:1},
{pos:[23,9,26],state:1},
{pos:[24,9,26],state:1},
{pos:[25,9,26],state:1},
{pos:[26,9,26],state:1},
{pos:[27,9,26],state:1},
{pos:[28,9,26],state:1},
{pos:[29,9,26],state:1},
{pos:[30,9,26],state:1},
{pos:[0,10,0],state:1},
{pos:[1,10,0],state:1},
{pos:[2,10,0],state:1},
{pos:[3,10,0],state:1},
{pos:[4,10,0],state:1},
{pos:[5,10,0],state:1},
{pos:[6,10,0],state:1},
{pos:[7,10,0],state:1},
{pos:[8,10,0],state:1},
{pos:[9,10,0],state:1},
{pos:[10,10,0],state:1},
{pos:[11,10,0],state:1},
{pos:[12,10,0],state:1},
{pos:[13,10,0],state:1},
{pos:[14,10,0],state:1},
{pos:[15,10,0],state:1},
{pos:[16,10,0],state:1},
{pos:[17,10,0],state:1},
{pos:[18,10,0],state:1},
{pos:[19,10,0],state:1},
{pos:[20,10,0],state:1},
{pos:[21,10,0],state:1},
{pos:[22,10,0],state:1},
{pos:[23,10,0],state:1},
{pos:[24,10,0],state:1},
{pos:[25,10,0],state:1},
{pos:[26,10,0],state:1},
{pos:[27,10,0],state:1},
{pos:[28,10,0],state:1},
{pos:[29,10,0],state:1},
{pos:[30,10,0],state:1},
{pos:[0,10,1],state:1},
{pos:[1,10,1],state:1},
{pos:[2,10,1],state:1},
{pos:[3,10,1],state:1},
{pos:[4,10,1],state:1},
{pos:[5,10,1],state:1},
{pos:[6,10,1],state:1},
{pos:[7,10,1],state:1},
{pos:[8,10,1],state:1},
{pos:[9,10,1],state:1},
{pos:[10,10,1],state:1},
{pos:[11,10,1],state:1},
{pos:[12,10,1],state:1},
{pos:[13,10,1],state:1},
{pos:[14,10,1],state:1},
{pos:[15,10,1],state:1},
{pos:[16,10,1],state:1},
{pos:[17,10,1],state:1},
{pos:[18,10,1],state:1},
{pos:[19,10,1],state:1},
{pos:[20,10,1],state:1},
{pos:[21,10,1],state:1},
{pos:[22,10,1],state:1},
{pos:[23,10,1],state:1},
{pos:[24,10,1],state:1},
{pos:[25,10,1],state:1},
{pos:[26,10,1],state:1},
{pos:[27,10,1],state:1},
{pos:[28,10,1],state:1},
{pos:[29,10,1],state:1},
{pos:[30,10,1],state:1},
{pos:[0,10,2],state:1},
{pos:[1,10,2],state:1},
{pos:[29,10,2],state:1},
{pos:[30,10,2],state:1},
{pos:[0,10,3],state:1},
{pos:[1,10,3],state:1},
{pos:[29,10,3],state:1},
{pos:[30,10,3],state:1},
{pos:[0,10,4],state:1},
{pos:[1,10,4],state:1},
{pos:[4,10,4],state:0},
{pos:[26,10,4],state:0},
{pos:[29,10,4],state:1},
{pos:[30,10,4],state:1},
{pos:[0,10,5],state:1},
{pos:[1,10,5],state:1},
{pos:[29,10,5],state:1},
{pos:[30,10,5],state:1},
{pos:[0,10,6],state:1},
{pos:[1,10,6],state:1},
{pos:[29,10,6],state:1},
{pos:[30,10,6],state:1},
{pos:[0,10,7],state:1},
{pos:[1,10,7],state:1},
{pos:[29,10,7],state:1},
{pos:[30,10,7],state:1},
{pos:[0,10,8],state:1},
{pos:[1,10,8],state:1},
{pos:[29,10,8],state:1},
{pos:[30,10,8],state:1},
{pos:[0,10,9],state:1},
{pos:[1,10,9],state:1},
{pos:[4,10,9],state:0},
{pos:[26,10,9],state:0},
{pos:[29,10,9],state:1},
{pos:[30,10,9],state:1},
{pos:[0,10,10],state:1},
{pos:[1,10,10],state:1},
{pos:[29,10,10],state:1},
{pos:[30,10,10],state:1},
{pos:[0,10,11],state:1},
{pos:[1,10,11],state:1},
{pos:[29,10,11],state:1},
{pos:[30,10,11],state:1},
{pos:[0,10,12],state:1},
{pos:[1,10,12],state:1},
{pos:[29,10,12],state:1},
{pos:[30,10,12],state:1},
{pos:[0,10,13],state:1},
{pos:[1,10,13],state:1},
{pos:[29,10,13],state:1},
{pos:[30,10,13],state:1},
{pos:[0,10,14],state:1},
{pos:[1,10,14],state:1},
{pos:[4,10,14],state:0},
{pos:[26,10,14],state:0},
{pos:[29,10,14],state:1},
{pos:[30,10,14],state:1},
{pos:[0,10,15],state:1},
{pos:[1,10,15],state:1},
{pos:[29,10,15],state:1},
{pos:[30,10,15],state:1},
{pos:[0,10,16],state:1},
{pos:[1,10,16],state:1},
{pos:[29,10,16],state:1},
{pos:[30,10,16],state:1},
{pos:[0,10,17],state:1},
{pos:[1,10,17],state:1},
{pos:[29,10,17],state:1},
{pos:[30,10,17],state:1},
{pos:[0,10,18],state:1},
{pos:[1,10,18],state:1},
{pos:[29,10,18],state:1},
{pos:[30,10,18],state:1},
{pos:[0,10,19],state:1},
{pos:[1,10,19],state:1},
{pos:[4,10,19],state:0},
{pos:[26,10,19],state:0},
{pos:[29,10,19],state:1},
{pos:[30,10,19],state:1},
{pos:[0,10,20],state:1},
{pos:[1,10,20],state:1},
{pos:[29,10,20],state:1},
{pos:[30,10,20],state:1},
{pos:[0,10,21],state:1},
{pos:[1,10,21],state:1},
{pos:[29,10,21],state:1},
{pos:[30,10,21],state:1},
{pos:[0,10,22],state:1},
{pos:[1,10,22],state:1},
{pos:[29,10,22],state:1},
{pos:[30,10,22],state:1},
{pos:[0,10,23],state:1},
{pos:[1,10,23],state:1},
{pos:[29,10,23],state:1},
{pos:[30,10,23],state:1},
{pos:[0,10,24],state:1},
{pos:[1,10,24],state:1},
{pos:[29,10,24],state:1},
{pos:[30,10,24],state:1},
{pos:[0,10,25],state:1},
{pos:[1,10,25],state:1},
{pos:[2,10,25],state:1},
{pos:[3,10,25],state:1},
{pos:[4,10,25],state:1},
{pos:[5,10,25],state:1},
{pos:[6,10,25],state:1},
{pos:[7,10,25],state:1},
{pos:[8,10,25],state:1},
{pos:[9,10,25],state:1},
{pos:[10,10,25],state:1},
{pos:[11,10,25],state:1},
{pos:[12,10,25],state:1},
{pos:[13,10,25],state:1},
{pos:[14,10,25],state:1},
{pos:[15,10,25],state:1},
{pos:[16,10,25],state:1},
{pos:[17,10,25],state:1},
{pos:[18,10,25],state:1},
{pos:[19,10,25],state:1},
{pos:[20,10,25],state:1},
{pos:[21,10,25],state:1},
{pos:[22,10,25],state:1},
{pos:[23,10,25],state:1},
{pos:[24,10,25],state:1},
{pos:[25,10,25],state:1},
{pos:[26,10,25],state:1},
{pos:[27,10,25],state:1},
{pos:[28,10,25],state:1},
{pos:[29,10,25],state:1},
{pos:[30,10,25],state:1},
{pos:[0,10,26],state:1},
{pos:[1,10,26],state:1},
{pos:[2,10,26],state:1},
{pos:[3,10,26],state:1},
{pos:[4,10,26],state:1},
{pos:[5,10,26],state:1},
{pos:[6,10,26],state:1},
{pos:[7,10,26],state:1},
{pos:[8,10,26],state:1},
{pos:[9,10,26],state:1},
{pos:[10,10,26],state:1},
{pos:[11,10,26],state:1},
{pos:[12,10,26],state:1},
{pos:[13,10,26],state:1},
{pos:[14,10,26],state:1},
{pos:[15,10,26],state:1},
{pos:[16,10,26],state:1},
{pos:[17,10,26],state:1},
{pos:[18,10,26],state:1},
{pos:[19,10,26],state:1},
{pos:[20,10,26],state:1},
{pos:[21,10,26],state:1},
{pos:[22,10,26],state:1},
{pos:[23,10,26],state:1},
{pos:[24,10,26],state:1},
{pos:[25,10,26],state:1},
{pos:[26,10,26],state:1},
{pos:[27,10,26],state:1},
{pos:[28,10,26],state:1},
{pos:[29,10,26],state:1},
{pos:[30,10,26],state:1},
{pos:[0,11,0],state:1},
{pos:[1,11,0],state:1},
{pos:[2,11,0],state:1},
{pos:[3,11,0],state:1},
{pos:[4,11,0],state:1},
{pos:[5,11,0],state:1},
{pos:[6,11,0],state:1},
{pos:[7,11,0],state:1},
{pos:[8,11,0],state:1},
{pos:[9,11,0],state:1},
{pos:[10,11,0],state:1},
{pos:[11,11,0],state:1},
{pos:[12,11,0],state:1},
{pos:[13,11,0],state:1},
{pos:[14,11,0],state:1},
{pos:[15,11,0],state:1},
{pos:[16,11,0],state:1},
{pos:[17,11,0],state:1},
{pos:[18,11,0],state:1},
{pos:[19,11,0],state:1},
{pos:[20,11,0],state:1},
{pos:[21,11,0],state:1},
{pos:[22,11,0],state:1},
{pos:[23,11,0],state:1},
{pos:[24,11,0],state:1},
{pos:[25,11,0],state:1},
{pos:[26,11,0],state:1},
{pos:[27,11,0],state:1},
{pos:[28,11,0],state:1},
{pos:[29,11,0],state:1},
{pos:[30,11,0],state:1},
{pos:[0,11,1],state:1},
{pos:[1,11,1],state:1},
{pos:[2,11,1],state:1},
{pos:[3,11,1],state:1},
{pos:[4,11,1],state:1},
{pos:[5,11,1],state:1},
{pos:[6,11,1],state:1},
{pos:[7,11,1],state:1},
{pos:[8,11,1],state:1},
{pos:[9,11,1],state:1},
{pos:[10,11,1],state:1},
{pos:[11,11,1],state:1},
{pos:[12,11,1],state:1},
{pos:[13,11,1],state:1},
{pos:[14,11,1],state:1},
{pos:[15,11,1],state:1},
{pos:[16,11,1],state:1},
{pos:[17,11,1],state:1},
{pos:[18,11,1],state:1},
{pos:[19,11,1],state:1},
{pos:[20,11,1],state:1},
{pos:[21,11,1],state:1},
{pos:[22,11,1],state:1},
{pos:[23,11,1],state:1},
{pos:[24,11,1],state:1},
{pos:[25,11,1],state:1},
{pos:[26,11,1],state:1},
{pos:[27,11,1],state:1},
{pos:[28,11,1],state:1},
{pos:[29,11,1],state:1},
{pos:[30,11,1],state:1},
{pos:[0,11,2],state:1},
{pos:[1,11,2],state:1},
{pos:[29,11,2],state:1},
{pos:[30,11,2],state:1},
{pos:[0,11,3],state:1},
{pos:[1,11,3],state:1},
{pos:[29,11,3],state:1},
{pos:[30,11,3],state:1},
{pos:[0,11,4],state:1},
{pos:[1,11,4],state:1},
{pos:[29,11,4],state:1},
{pos:[30,11,4],state:1},
{pos:[0,11,5],state:1},
{pos:[1,11,5],state:1},
{pos:[29,11,5],state:1},
{pos:[30,11,5],state:1},
{pos:[0,11,6],state:1},
{pos:[1,11,6],state:1},
{pos:[29,11,6],state:1},
{pos:[30,11,6],state:1},
{pos:[0,11,7],state:1},
{pos:[1,11,7],state:1},
{pos:[29,11,7],state:1},
{pos:[30,11,7],state:1},
{pos:[0,11,8],state:1},
{pos:[1,11,8],state:1},
{pos:[29,11,8],state:1},
{pos:[30,11,8],state:1},
{pos:[0,11,9],state:1},
{pos:[1,11,9],state:1},
{pos:[29,11,9],state:1},
{pos:[30,11,9],state:1},
{pos:[0,11,10],state:1},
{pos:[1,11,10],state:1},
{pos:[29,11,10],state:1},
{pos:[30,11,10],state:1},
{pos:[0,11,11],state:1},
{pos:[1,11,11],state:1},
{pos:[29,11,11],state:1},
{pos:[30,11,11],state:1},
{pos:[0,11,12],state:1},
{pos:[1,11,12],state:1},
{pos:[29,11,12],state:1},
{pos:[30,11,12],state:1},
{pos:[0,11,13],state:1},
{pos:[1,11,13],state:1},
{pos:[29,11,13],state:1},
{pos:[30,11,13],state:1},
{pos:[0,11,14],state:1},
{pos:[1,11,14],state:1},
{pos:[29,11,14],state:1},
{pos:[30,11,14],state:1},
{pos:[0,11,15],state:1},
{pos:[1,11,15],state:1},
{pos:[29,11,15],state:1},
{pos:[30,11,15],state:1},
{pos:[0,11,16],state:1},
{pos:[1,11,16],state:1},
{pos:[29,11,16],state:1},
{pos:[30,11,16],state:1},
{pos:[0,11,17],state:1},
{pos:[1,11,17],state:1},
{pos:[29,11,17],state:1},
{pos:[30,11,17],state:1},
{pos:[0,11,18],state:1},
{pos:[1,11,18],state:1},
{pos:[29,11,18],state:1},
{pos:[30,11,18],state:1},
{pos:[0,11,19],state:1},
{pos:[1,11,19],state:1},
{pos:[29,11,19],state:1},
{pos:[30,11,19],state:1},
{pos:[0,11,20],state:1},
{pos:[1,11,20],state:1},
{pos:[29,11,20],state:1},
{pos:[30,11,20],state:1},
{pos:[0,11,21],state:1},
{pos:[1,11,21],state:1},
{pos:[29,11,21],state:1},
{pos:[30,11,21],state:1},
{pos:[0,11,22],state:1},
{pos:[1,11,22],state:1},
{pos:[29,11,22],state:1},
{pos:[30,11,22],state:1},
{pos:[0,11,23],state:1},
{pos:[1,11,23],state:1},
{pos:[29,11,23],state:1},
{pos:[30,11,23],state:1},
{pos:[0,11,24],state:1},
{pos:[1,11,24],state:1},
{pos:[29,11,24],state:1},
{pos:[30,11,24],state:1},
{pos:[0,11,25],state:1},
{pos:[1,11,25],state:1},
{pos:[2,11,25],state:1},
{pos:[3,11,25],state:1},
{pos:[4,11,25],state:1},
{pos:[5,11,25],state:1},
{pos:[6,11,25],state:1},
{pos:[7,11,25],state:1},
{pos:[8,11,25],state:1},
{pos:[9,11,25],state:1},
{pos:[10,11,25],state:1},
{pos:[11,11,25],state:1},
{pos:[12,11,25],state:1},
{pos:[13,11,25],state:1},
{pos:[14,11,25],state:1},
{pos:[15,11,25],state:1},
{pos:[16,11,25],state:1},
{pos:[17,11,25],state:1},
{pos:[18,11,25],state:1},
{pos:[19,11,25],state:1},
{pos:[20,11,25],state:1},
{pos:[21,11,25],state:1},
{pos:[22,11,25],state:1},
{pos:[23,11,25],state:1},
{pos:[24,11,25],state:1},
{pos:[25,11,25],state:1},
{pos:[26,11,25],state:1},
{pos:[27,11,25],state:1},
{pos:[28,11,25],state:1},
{pos:[29,11,25],state:1},
{pos:[30,11,25],state:1},
{pos:[0,11,26],state:1},
{pos:[1,11,26],state:1},
{pos:[2,11,26],state:1},
{pos:[3,11,26],state:1},
{pos:[4,11,26],state:1},
{pos:[5,11,26],state:1},
{pos:[6,11,26],state:1},
{pos:[7,11,26],state:1},
{pos:[8,11,26],state:1},
{pos:[9,11,26],state:1},
{pos:[10,11,26],state:1},
{pos:[11,11,26],state:1},
{pos:[12,11,26],state:1},
{pos:[13,11,26],state:1},
{pos:[14,11,26],state:1},
{pos:[15,11,26],state:1},
{pos:[16,11,26],state:1},
{pos:[17,11,26],state:1},
{pos:[18,11,26],state:1},
{pos:[19,11,26],state:1},
{pos:[20,11,26],state:1},
{pos:[21,11,26],state:1},
{pos:[22,11,26],state:1},
{pos:[23,11,26],state:1},
{pos:[24,11,26],state:1},
{pos:[25,11,26],state:1},
{pos:[26,11,26],state:1},
{pos:[27,11,26],state:1},
{pos:[28,11,26],state:1},
{pos:[29,11,26],state:1},
{pos:[30,11,26],state:1},
{pos:[0,12,0],state:1},
{pos:[1,12,0],state:1},
{pos:[2,12,0],state:1},
{pos:[3,12,0],state:1},
{pos:[4,12,0],state:1},
{pos:[5,12,0],state:1},
{pos:[6,12,0],state:1},
{pos:[7,12,0],state:1},
{pos:[8,12,0],state:1},
{pos:[9,12,0],state:1},
{pos:[10,12,0],state:1},
{pos:[11,12,0],state:1},
{pos:[12,12,0],state:1},
{pos:[13,12,0],state:1},
{pos:[14,12,0],state:1},
{pos:[15,12,0],state:1},
{pos:[16,12,0],state:1},
{pos:[17,12,0],state:1},
{pos:[18,12,0],state:1},
{pos:[19,12,0],state:1},
{pos:[20,12,0],state:1},
{pos:[21,12,0],state:1},
{pos:[22,12,0],state:1},
{pos:[23,12,0],state:1},
{pos:[24,12,0],state:1},
{pos:[25,12,0],state:1},
{pos:[26,12,0],state:1},
{pos:[27,12,0],state:1},
{pos:[28,12,0],state:1},
{pos:[29,12,0],state:1},
{pos:[30,12,0],state:1},
{pos:[0,12,1],state:1},
{pos:[1,12,1],state:1},
{pos:[2,12,1],state:1},
{pos:[3,12,1],state:1},
{pos:[4,12,1],state:1},
{pos:[5,12,1],state:1},
{pos:[6,12,1],state:1},
{pos:[7,12,1],state:1},
{pos:[8,12,1],state:1},
{pos:[9,12,1],state:1},
{pos:[10,12,1],state:1},
{pos:[11,12,1],state:1},
{pos:[12,12,1],state:1},
{pos:[13,12,1],state:1},
{pos:[14,12,1],state:1},
{pos:[15,12,1],state:1},
{pos:[16,12,1],state:1},
{pos:[17,12,1],state:1},
{pos:[18,12,1],state:1},
{pos:[19,12,1],state:1},
{pos:[20,12,1],state:1},
{pos:[21,12,1],state:1},
{pos:[22,12,1],state:1},
{pos:[23,12,1],state:1},
{pos:[24,12,1],state:1},
{pos:[25,12,1],state:1},
{pos:[26,12,1],state:1},
{pos:[27,12,1],state:1},
{pos:[28,12,1],state:1},
{pos:[29,12,1],state:1},
{pos:[30,12,1],state:1},
{pos:[0,12,2],state:1},
{pos:[1,12,2],state:1},
{pos:[29,12,2],state:1},
{pos:[30,12,2],state:1},
{pos:[0,12,3],state:1},
{pos:[1,12,3],state:1},
{pos:[29,12,3],state:1},
{pos:[30,12,3],state:1},
{pos:[0,12,4],state:1},
{pos:[1,12,4],state:1},
{pos:[29,12,4],state:1},
{pos:[30,12,4],state:1},
{pos:[0,12,5],state:1},
{pos:[1,12,5],state:1},
{pos:[29,12,5],state:1},
{pos:[30,12,5],state:1},
{pos:[0,12,6],state:1},
{pos:[1,12,6],state:1},
{pos:[29,12,6],state:1},
{pos:[30,12,6],state:1},
{pos:[0,12,7],state:1},
{pos:[1,12,7],state:1},
{pos:[29,12,7],state:1},
{pos:[30,12,7],state:1},
{pos:[0,12,8],state:1},
{pos:[1,12,8],state:1},
{pos:[29,12,8],state:1},
{pos:[30,12,8],state:1},
{pos:[0,12,9],state:1},
{pos:[1,12,9],state:1},
{pos:[29,12,9],state:1},
{pos:[30,12,9],state:1},
{pos:[0,12,10],state:1},
{pos:[1,12,10],state:1},
{pos:[29,12,10],state:1},
{pos:[30,12,10],state:1},
{pos:[0,12,11],state:1},
{pos:[1,12,11],state:1},
{pos:[29,12,11],state:1},
{pos:[30,12,11],state:1},
{pos:[0,12,12],state:1},
{pos:[1,12,12],state:1},
{pos:[29,12,12],state:1},
{pos:[30,12,12],state:1},
{pos:[0,12,13],state:1},
{pos:[1,12,13],state:1},
{pos:[29,12,13],state:1},
{pos:[30,12,13],state:1},
{pos:[0,12,14],state:1},
{pos:[1,12,14],state:1},
{pos:[29,12,14],state:1},
{pos:[30,12,14],state:1},
{pos:[0,12,15],state:1},
{pos:[1,12,15],state:1},
{pos:[29,12,15],state:1},
{pos:[30,12,15],state:1},
{pos:[0,12,16],state:1},
{pos:[1,12,16],state:1},
{pos:[29,12,16],state:1},
{pos:[30,12,16],state:1},
{pos:[0,12,17],state:1},
{pos:[1,12,17],state:1},
{pos:[29,12,17],state:1},
{pos:[30,12,17],state:1},
{pos:[0,12,18],state:1},
{pos:[1,12,18],state:1},
{pos:[29,12,18],state:1},
{pos:[30,12,18],state:1},
{pos:[0,12,19],state:1},
{pos:[1,12,19],state:1},
{pos:[29,12,19],state:1},
{pos:[30,12,19],state:1},
{pos:[0,12,20],state:1},
{pos:[1,12,20],state:1},
{pos:[29,12,20],state:1},
{pos:[30,12,20],state:1},
{pos:[0,12,21],state:1},
{pos:[1,12,21],state:1},
{pos:[29,12,21],state:1},
{pos:[30,12,21],state:1},
{pos:[0,12,22],state:1},
{pos:[1,12,22],state:1},
{pos:[29,12,22],state:1},
{pos:[30,12,22],state:1},
{pos:[0,12,23],state:1},
{pos:[1,12,23],state:1},
{pos:[29,12,23],state:1},
{pos:[30,12,23],state:1},
{pos:[0,12,24],state:1},
{pos:[1,12,24],state:1},
{pos:[29,12,24],state:1},
{pos:[30,12,24],state:1},
{pos:[0,12,25],state:1},
{pos:[1,12,25],state:1},
{pos:[2,12,25],state:1},
{pos:[3,12,25],state:1},
{pos:[4,12,25],state:1},
{pos:[5,12,25],state:1},
{pos:[6,12,25],state:1},
{pos:[7,12,25],state:1},
{pos:[8,12,25],state:1},
{pos:[9,12,25],state:1},
{pos:[10,12,25],state:1},
{pos:[11,12,25],state:1},
{pos:[12,12,25],state:1},
{pos:[13,12,25],state:1},
{pos:[14,12,25],state:1},
{pos:[15,12,25],state:1},
{pos:[16,12,25],state:1},
{pos:[17,12,25],state:1},
{pos:[18,12,25],state:1},
{pos:[19,12,25],state:1},
{pos:[20,12,25],state:1},
{pos:[21,12,25],state:1},
{pos:[22,12,25],state:1},
{pos:[23,12,25],state:1},
{pos:[24,12,25],state:1},
{pos:[25,12,25],state:1},
{pos:[26,12,25],state:1},
{pos:[27,12,25],state:1},
{pos:[28,12,25],state:1},
{pos:[29,12,25],state:1},
{pos:[30,12,25],state:1},
{pos:[0,12,26],state:1},
{pos:[1,12,26],state:1},
{pos:[2,12,26],state:1},
{pos:[3,12,26],state:1},
{pos:[4,12,26],state:1},
{pos:[5,12,26],state:1},
{pos:[6,12,26],state:1},
{pos:[7,12,26],state:1},
{pos:[8,12,26],state:1},
{pos:[9,12,26],state:1},
{pos:[10,12,26],state:1},
{pos:[11,12,26],state:1},
{pos:[12,12,26],state:1},
{pos:[13,12,26],state:1},
{pos:[14,12,26],state:1},
{pos:[15,12,26],state:1},
{pos:[16,12,26],state:1},
{pos:[17,12,26],state:1},
{pos:[18,12,26],state:1},
{pos:[19,12,26],state:1},
{pos:[20,12,26],state:1},
{pos:[21,12,26],state:1},
{pos:[22,12,26],state:1},
{pos:[23,12,26],state:1},
{pos:[24,12,26],state:1},
{pos:[25,12,26],state:1},
{pos:[26,12,26],state:1},
{pos:[27,12,26],state:1},
{pos:[28,12,26],state:1},
{pos:[29,12,26],state:1},
{pos:[30,12,26],state:1},
{pos:[0,13,0],state:1},
{pos:[1,13,0],state:1},
{pos:[2,13,0],state:1},
{pos:[3,13,0],state:1},
{pos:[4,13,0],state:1},
{pos:[5,13,0],state:1},
{pos:[6,13,0],state:1},
{pos:[7,13,0],state:1},
{pos:[8,13,0],state:1},
{pos:[9,13,0],state:1},
{pos:[10,13,0],state:1},
{pos:[11,13,0],state:1},
{pos:[12,13,0],state:1},
{pos:[13,13,0],state:1},
{pos:[14,13,0],state:1},
{pos:[15,13,0],state:1},
{pos:[16,13,0],state:1},
{pos:[17,13,0],state:1},
{pos:[18,13,0],state:1},
{pos:[19,13,0],state:1},
{pos:[20,13,0],state:1},
{pos:[21,13,0],state:1},
{pos:[22,13,0],state:1},
{pos:[23,13,0],state:1},
{pos:[24,13,0],state:1},
{pos:[25,13,0],state:1},
{pos:[26,13,0],state:1},
{pos:[27,13,0],state:1},
{pos:[28,13,0],state:1},
{pos:[29,13,0],state:1},
{pos:[30,13,0],state:1},
{pos:[0,13,1],state:1},
{pos:[1,13,1],state:1},
{pos:[2,13,1],state:1},
{pos:[3,13,1],state:1},
{pos:[4,13,1],state:1},
{pos:[5,13,1],state:1},
{pos:[6,13,1],state:1},
{pos:[7,13,1],state:1},
{pos:[8,13,1],state:1},
{pos:[9,13,1],state:1},
{pos:[10,13,1],state:1},
{pos:[11,13,1],state:1},
{pos:[12,13,1],state:1},
{pos:[13,13,1],state:1},
{pos:[14,13,1],state:1},
{pos:[15,13,1],state:1},
{pos:[16,13,1],state:1},
{pos:[17,13,1],state:1},
{pos:[18,13,1],state:1},
{pos:[19,13,1],state:1},
{pos:[20,13,1],state:1},
{pos:[21,13,1],state:1},
{pos:[22,13,1],state:1},
{pos:[23,13,1],state:1},
{pos:[24,13,1],state:1},
{pos:[25,13,1],state:1},
{pos:[26,13,1],state:1},
{pos:[27,13,1],state:1},
{pos:[28,13,1],state:1},
{pos:[29,13,1],state:1},
{pos:[30,13,1],state:1},
{pos:[0,13,2],state:1},
{pos:[1,13,2],state:1},
{pos:[29,13,2],state:1},
{pos:[30,13,2],state:1},
{pos:[0,13,3],state:1},
{pos:[1,13,3],state:1},
{pos:[29,13,3],state:1},
{pos:[30,13,3],state:1},
{pos:[0,13,4],state:1},
{pos:[1,13,4],state:1},
{pos:[29,13,4],state:1},
{pos:[30,13,4],state:1},
{pos:[0,13,5],state:1},
{pos:[1,13,5],state:1},
{pos:[29,13,5],state:1},
{pos:[30,13,5],state:1},
{pos:[0,13,6],state:1},
{pos:[1,13,6],state:1},
{pos:[29,13,6],state:1},
{pos:[30,13,6],state:1},
{pos:[0,13,7],state:1},
{pos:[1,13,7],state:1},
{pos:[29,13,7],state:1},
{pos:[30,13,7],state:1},
{pos:[0,13,8],state:1},
{pos:[1,13,8],state:1},
{pos:[29,13,8],state:1},
{pos:[30,13,8],state:1},
{pos:[0,13,9],state:1},
{pos:[1,13,9],state:1},
{pos:[29,13,9],state:1},
{pos:[30,13,9],state:1},
{pos:[0,13,10],state:1},
{pos:[1,13,10],state:1},
{pos:[29,13,10],state:1},
{pos:[30,13,10],state:1},
{pos:[0,13,11],state:1},
{pos:[1,13,11],state:1},
{pos:[29,13,11],state:1},
{pos:[30,13,11],state:1},
{pos:[0,13,12],state:1},
{pos:[1,13,12],state:1},
{pos:[29,13,12],state:1},
{pos:[30,13,12],state:1},
{pos:[0,13,13],state:1},
{pos:[1,13,13],state:1},
{pos:[29,13,13],state:1},
{pos:[30,13,13],state:1},
{pos:[0,13,14],state:1},
{pos:[1,13,14],state:1},
{pos:[29,13,14],state:1},
{pos:[30,13,14],state:1},
{pos:[0,13,15],state:1},
{pos:[1,13,15],state:1},
{pos:[29,13,15],state:1},
{pos:[30,13,15],state:1},
{pos:[0,13,16],state:1},
{pos:[1,13,16],state:1},
{pos:[29,13,16],state:1},
{pos:[30,13,16],state:1},
{pos:[0,13,17],state:1},
{pos:[1,13,17],state:1},
{pos:[29,13,17],state:1},
{pos:[30,13,17],state:1},
{pos:[0,13,18],state:1},
{pos:[1,13,18],state:1},
{pos:[29,13,18],state:1},
{pos:[30,13,18],state:1},
{pos:[0,13,19],state:1},
{pos:[1,13,19],state:1},
{pos:[29,13,19],state:1},
{pos:[30,13,19],state:1},
{pos:[0,13,20],state:1},
{pos:[1,13,20],state:1},
{pos:[29,13,20],state:1},
{pos:[30,13,20],state:1},
{pos:[0,13,21],state:1},
{pos:[1,13,21],state:1},
{pos:[29,13,21],state:1},
{pos:[30,13,21],state:1},
{pos:[0,13,22],state:1},
{pos:[1,13,22],state:1},
{pos:[29,13,22],state:1},
{pos:[30,13,22],state:1},
{pos:[0,13,23],state:1},
{pos:[1,13,23],state:1},
{pos:[29,13,23],state:1},
{pos:[30,13,23],state:1},
{pos:[0,13,24],state:1},
{pos:[1,13,24],state:1},
{pos:[29,13,24],state:1},
{pos:[30,13,24],state:1},
{pos:[0,13,25],state:1},
{pos:[1,13,25],state:1},
{pos:[2,13,25],state:1},
{pos:[3,13,25],state:1},
{pos:[4,13,25],state:1},
{pos:[5,13,25],state:1},
{pos:[6,13,25],state:1},
{pos:[7,13,25],state:1},
{pos:[8,13,25],state:1},
{pos:[9,13,25],state:1},
{pos:[10,13,25],state:1},
{pos:[11,13,25],state:1},
{pos:[12,13,25],state:1},
{pos:[13,13,25],state:1},
{pos:[14,13,25],state:1},
{pos:[15,13,25],state:1},
{pos:[16,13,25],state:1},
{pos:[17,13,25],state:1},
{pos:[18,13,25],state:1},
{pos:[19,13,25],state:1},
{pos:[20,13,25],state:1},
{pos:[21,13,25],state:1},
{pos:[22,13,25],state:1},
{pos:[23,13,25],state:1},
{pos:[24,13,25],state:1},
{pos:[25,13,25],state:1},
{pos:[26,13,25],state:1},
{pos:[27,13,25],state:1},
{pos:[28,13,25],state:1},
{pos:[29,13,25],state:1},
{pos:[30,13,25],state:1},
{pos:[0,13,26],state:1},
{pos:[1,13,26],state:1},
{pos:[2,13,26],state:1},
{pos:[3,13,26],state:1},
{pos:[4,13,26],state:1},
{pos:[5,13,26],state:1},
{pos:[6,13,26],state:1},
{pos:[7,13,26],state:1},
{pos:[8,13,26],state:1},
{pos:[9,13,26],state:1},
{pos:[10,13,26],state:1},
{pos:[11,13,26],state:1},
{pos:[12,13,26],state:1},
{pos:[13,13,26],state:1},
{pos:[14,13,26],state:1},
{pos:[15,13,26],state:1},
{pos:[16,13,26],state:1},
{pos:[17,13,26],state:1},
{pos:[18,13,26],state:1},
{pos:[19,13,26],state:1},
{pos:[20,13,26],state:1},
{pos:[21,13,26],state:1},
{pos:[22,13,26],state:1},
{pos:[23,13,26],state:1},
{pos:[24,13,26],state:1},
{pos:[25,13,26],state:1},
{pos:[26,13,26],state:1},
{pos:[27,13,26],state:1},
{pos:[28,13,26],state:1},
{pos:[29,13,26],state:1},
{pos:[30,13,26],state:1},
{pos:[0,14,0],state:1},
{pos:[1,14,0],state:1},
{pos:[2,14,0],state:1},
{pos:[3,14,0],state:1},
{pos:[4,14,0],state:1},
{pos:[5,14,0],state:1},
{pos:[6,14,0],state:1},
{pos:[7,14,0],state:1},
{pos:[8,14,0],state:1},
{pos:[9,14,0],state:1},
{pos:[10,14,0],state:1},
{pos:[11,14,0],state:1},
{pos:[12,14,0],state:1},
{pos:[13,14,0],state:1},
{pos:[14,14,0],state:1},
{pos:[15,14,0],state:1},
{pos:[16,14,0],state:1},
{pos:[17,14,0],state:1},
{pos:[18,14,0],state:1},
{pos:[19,14,0],state:1},
{pos:[20,14,0],state:1},
{pos:[21,14,0],state:1},
{pos:[22,14,0],state:1},
{pos:[23,14,0],state:1},
{pos:[24,14,0],state:1},
{pos:[25,14,0],state:1},
{pos:[26,14,0],state:1},
{pos:[27,14,0],state:1},
{pos:[28,14,0],state:1},
{pos:[29,14,0],state:1},
{pos:[30,14,0],state:1},
{pos:[0,14,1],state:1},
{pos:[1,14,1],state:1},
{pos:[2,14,1],state:1},
{pos:[3,14,1],state:1},
{pos:[4,14,1],state:1},
{pos:[5,14,1],state:1},
{pos:[6,14,1],state:1},
{pos:[7,14,1],state:1},
{pos:[8,14,1],state:1},
{pos:[9,14,1],state:1},
{pos:[10,14,1],state:1},
{pos:[11,14,1],state:1},
{pos:[12,14,1],state:1},
{pos:[13,14,1],state:1},
{pos:[14,14,1],state:1},
{pos:[15,14,1],state:1},
{pos:[16,14,1],state:1},
{pos:[17,14,1],state:1},
{pos:[18,14,1],state:1},
{pos:[19,14,1],state:1},
{pos:[20,14,1],state:1},
{pos:[21,14,1],state:1},
{pos:[22,14,1],state:1},
{pos:[23,14,1],state:1},
{pos:[24,14,1],state:1},
{pos:[25,14,1],state:1},
{pos:[26,14,1],state:1},
{pos:[27,14,1],state:1},
{pos:[28,14,1],state:1},
{pos:[29,14,1],state:1},
{pos:[30,14,1],state:1},
{pos:[0,14,2],state:1},
{pos:[1,14,2],state:1},
{pos:[29,14,2],state:1},
{pos:[30,14,2],state:1},
{pos:[0,14,3],state:1},
{pos:[1,14,3],state:1},
{pos:[29,14,3],state:1},
{pos:[30,14,3],state:1},
{pos:[0,14,4],state:1},
{pos:[1,14,4],state:1},
{pos:[29,14,4],state:1},
{pos:[30,14,4],state:1},
{pos:[0,14,5],state:1},
{pos:[1,14,5],state:1},
{pos:[29,14,5],state:1},
{pos:[30,14,5],state:1},
{pos:[0,14,6],state:1},
{pos:[1,14,6],state:1},
{pos:[29,14,6],state:1},
{pos:[30,14,6],state:1},
{pos:[0,14,7],state:1},
{pos:[1,14,7],state:1},
{pos:[29,14,7],state:1},
{pos:[30,14,7],state:1},
{pos:[0,14,8],state:1},
{pos:[1,14,8],state:1},
{pos:[29,14,8],state:1},
{pos:[30,14,8],state:1},
{pos:[0,14,9],state:1},
{pos:[1,14,9],state:1},
{pos:[29,14,9],state:1},
{pos:[30,14,9],state:1},
{pos:[0,14,10],state:1},
{pos:[1,14,10],state:1},
{pos:[29,14,10],state:1},
{pos:[30,14,10],state:1},
{pos:[0,14,11],state:1},
{pos:[1,14,11],state:1},
{pos:[29,14,11],state:1},
{pos:[30,14,11],state:1},
{pos:[0,14,12],state:1},
{pos:[1,14,12],state:1},
{pos:[29,14,12],state:1},
{pos:[30,14,12],state:1},
{pos:[0,14,13],state:1},
{pos:[1,14,13],state:1},
{pos:[29,14,13],state:1},
{pos:[30,14,13],state:1},
{pos:[0,14,14],state:1},
{pos:[1,14,14],state:1},
{pos:[29,14,14],state:1},
{pos:[30,14,14],state:1},
{pos:[0,14,15],state:1},
{pos:[1,14,15],state:1},
{pos:[29,14,15],state:1},
{pos:[30,14,15],state:1},
{pos:[0,14,16],state:1},
{pos:[1,14,16],state:1},
{pos:[29,14,16],state:1},
{pos:[30,14,16],state:1},
{pos:[0,14,17],state:1},
{pos:[1,14,17],state:1},
{pos:[29,14,17],state:1},
{pos:[30,14,17],state:1},
{pos:[0,14,18],state:1},
{pos:[1,14,18],state:1},
{pos:[29,14,18],state:1},
{pos:[30,14,18],state:1},
{pos:[0,14,19],state:1},
{pos:[1,14,19],state:1},
{pos:[29,14,19],state:1},
{pos:[30,14,19],state:1},
{pos:[0,14,20],state:1},
{pos:[1,14,20],state:1},
{pos:[29,14,20],state:1},
{pos:[30,14,20],state:1},
{pos:[0,14,21],state:1},
{pos:[1,14,21],state:1},
{pos:[29,14,21],state:1},
{pos:[30,14,21],state:1},
{pos:[0,14,22],state:1},
{pos:[1,14,22],state:1},
{pos:[29,14,22],state:1},
{pos:[30,14,22],state:1},
{pos:[0,14,23],state:1},
{pos:[1,14,23],state:1},
{pos:[29,14,23],state:1},
{pos:[30,14,23],state:1},
{pos:[0,14,24],state:1},
{pos:[1,14,24],state:1},
{pos:[29,14,24],state:1},
{pos:[30,14,24],state:1},
{pos:[0,14,25],state:1},
{pos:[1,14,25],state:1},
{pos:[2,14,25],state:1},
{pos:[3,14,25],state:1},
{pos:[4,14,25],state:1},
{pos:[5,14,25],state:1},
{pos:[6,14,25],state:1},
{pos:[7,14,25],state:1},
{pos:[8,14,25],state:1},
{pos:[9,14,25],state:1},
{pos:[10,14,25],state:1},
{pos:[11,14,25],state:1},
{pos:[12,14,25],state:1},
{pos:[13,14,25],state:1},
{pos:[14,14,25],state:1},
{pos:[15,14,25],state:1},
{pos:[16,14,25],state:1},
{pos:[17,14,25],state:1},
{pos:[18,14,25],state:1},
{pos:[19,14,25],state:1},
{pos:[20,14,25],state:1},
{pos:[21,14,25],state:1},
{pos:[22,14,25],state:1},
{pos:[23,14,25],state:1},
{pos:[24,14,25],state:1},
{pos:[25,14,25],state:1},
{pos:[26,14,25],state:1},
{pos:[27,14,25],state:1},
{pos:[28,14,25],state:1},
{pos:[29,14,25],state:1},
{pos:[30,14,25],state:1},
{pos:[0,14,26],state:1},
{pos:[1,14,26],state:1},
{pos:[2,14,26],state:1},
{pos:[3,14,26],state:1},
{pos:[4,14,26],state:1},
{pos:[5,14,26],state:1},
{pos:[6,14,26],state:1},
{pos:[7,14,26],state:1},
{pos:[8,14,26],state:1},
{pos:[9,14,26],state:1},
{pos:[10,14,26],state:1},
{pos:[11,14,26],state:1},
{pos:[12,14,26],state:1},
{pos:[13,14,26],state:1},
{pos:[14,14,26],state:1},
{pos:[15,14,26],state:1},
{pos:[16,14,26],state:1},
{pos:[17,14,26],state:1},
{pos:[18,14,26],state:1},
{pos:[19,14,26],state:1},
{pos:[20,14,26],state:1},
{pos:[21,14,26],state:1},
{pos:[22,14,26],state:1},
{pos:[23,14,26],state:1},
{pos:[24,14,26],state:1},
{pos:[25,14,26],state:1},
{pos:[26,14,26],state:1},
{pos:[27,14,26],state:1},
{pos:[28,14,26],state:1},
{pos:[29,14,26],state:1},
{pos:[30,14,26],state:1},
{pos:[0,15,0],state:1},
{pos:[1,15,0],state:1},
{pos:[2,15,0],state:1},
{pos:[3,15,0],state:1},
{pos:[4,15,0],state:1},
{pos:[5,15,0],state:1},
{pos:[6,15,0],state:1},
{pos:[7,15,0],state:1},
{pos:[8,15,0],state:1},
{pos:[9,15,0],state:1},
{pos:[10,15,0],state:1},
{pos:[11,15,0],state:1},
{pos:[12,15,0],state:1},
{pos:[13,15,0],state:1},
{pos:[14,15,0],state:1},
{pos:[15,15,0],state:1},
{pos:[16,15,0],state:1},
{pos:[17,15,0],state:1},
{pos:[18,15,0],state:1},
{pos:[19,15,0],state:1},
{pos:[20,15,0],state:1},
{pos:[21,15,0],state:1},
{pos:[22,15,0],state:1},
{pos:[23,15,0],state:1},
{pos:[24,15,0],state:1},
{pos:[25,15,0],state:1},
{pos:[26,15,0],state:1},
{pos:[27,15,0],state:1},
{pos:[28,15,0],state:1},
{pos:[29,15,0],state:1},
{pos:[30,15,0],state:1},
{pos:[0,15,1],state:1},
{pos:[1,15,1],state:1},
{pos:[2,15,1],state:1},
{pos:[3,15,1],state:1},
{pos:[4,15,1],state:1},
{pos:[5,15,1],state:1},
{pos:[6,15,1],state:1},
{pos:[7,15,1],state:1},
{pos:[8,15,1],state:1},
{pos:[9,15,1],state:1},
{pos:[10,15,1],state:1},
{pos:[11,15,1],state:1},
{pos:[12,15,1],state:1},
{pos:[13,15,1],state:1},
{pos:[14,15,1],state:1},
{pos:[15,15,1],state:1},
{pos:[16,15,1],state:1},
{pos:[17,15,1],state:1},
{pos:[18,15,1],state:1},
{pos:[19,15,1],state:1},
{pos:[20,15,1],state:1},
{pos:[21,15,1],state:1},
{pos:[22,15,1],state:1},
{pos:[23,15,1],state:1},
{pos:[24,15,1],state:1},
{pos:[25,15,1],state:1},
{pos:[26,15,1],state:1},
{pos:[27,15,1],state:1},
{pos:[28,15,1],state:1},
{pos:[29,15,1],state:1},
{pos:[30,15,1],state:1},
{pos:[0,15,2],state:1},
{pos:[1,15,2],state:1},
{pos:[29,15,2],state:1},
{pos:[30,15,2],state:1},
{pos:[0,15,3],state:1},
{pos:[1,15,3],state:1},
{pos:[29,15,3],state:1},
{pos:[30,15,3],state:1},
{pos:[0,15,4],state:1},
{pos:[1,15,4],state:1},
{pos:[29,15,4],state:1},
{pos:[30,15,4],state:1},
{pos:[0,15,5],state:1},
{pos:[1,15,5],state:1},
{pos:[29,15,5],state:1},
{pos:[30,15,5],state:1},
{pos:[0,15,6],state:1},
{pos:[1,15,6],state:1},
{pos:[29,15,6],state:1},
{pos:[30,15,6],state:1},
{pos:[0,15,7],state:1},
{pos:[1,15,7],state:1},
{pos:[29,15,7],state:1},
{pos:[30,15,7],state:1},
{pos:[0,15,8],state:1},
{pos:[1,15,8],state:1},
{pos:[29,15,8],state:1},
{pos:[30,15,8],state:1},
{pos:[0,15,9],state:1},
{pos:[1,15,9],state:1},
{pos:[29,15,9],state:1},
{pos:[30,15,9],state:1},
{pos:[0,15,10],state:1},
{pos:[1,15,10],state:1},
{pos:[29,15,10],state:1},
{pos:[30,15,10],state:1},
{pos:[0,15,11],state:1},
{pos:[1,15,11],state:1},
{pos:[29,15,11],state:1},
{pos:[30,15,11],state:1},
{pos:[0,15,12],state:1},
{pos:[1,15,12],state:1},
{pos:[29,15,12],state:1},
{pos:[30,15,12],state:1},
{pos:[0,15,13],state:1},
{pos:[1,15,13],state:1},
{pos:[29,15,13],state:1},
{pos:[30,15,13],state:1},
{pos:[0,15,14],state:1},
{pos:[1,15,14],state:1},
{pos:[29,15,14],state:1},
{pos:[30,15,14],state:1},
{pos:[0,15,15],state:1},
{pos:[1,15,15],state:1},
{pos:[29,15,15],state:1},
{pos:[30,15,15],state:1},
{pos:[0,15,16],state:1},
{pos:[1,15,16],state:1},
{pos:[29,15,16],state:1},
{pos:[30,15,16],state:1},
{pos:[0,15,17],state:1},
{pos:[1,15,17],state:1},
{pos:[29,15,17],state:1},
{pos:[30,15,17],state:1},
{pos:[0,15,18],state:1},
{pos:[1,15,18],state:1},
{pos:[29,15,18],state:1},
{pos:[30,15,18],state:1},
{pos:[0,15,19],state:1},
{pos:[1,15,19],state:1},
{pos:[29,15,19],state:1},
{pos:[30,15,19],state:1},
{pos:[0,15,20],state:1},
{pos:[1,15,20],state:1},
{pos:[29,15,20],state:1},
{pos:[30,15,20],state:1},
{pos:[0,15,21],state:1},
{pos:[1,15,21],state:1},
{pos:[29,15,21],state:1},
{pos:[30,15,21],state:1},
{pos:[0,15,22],state:1},
{pos:[1,15,22],state:1},
{pos:[29,15,22],state:1},
{pos:[30,15,22],state:1},
{pos:[0,15,23],state:1},
{pos:[1,15,23],state:1},
{pos:[29,15,23],state:1},
{pos:[30,15,23],state:1},
{pos:[0,15,24],state:1},
