{DataVersion:3465,size:[31,20,31],palette:[{Name:"minecraft:gold_block"},{Name:"minecraft:polished_blackstone_bricks"},{Name:"minecraft:sea_lantern"},{Name:"minecraft:smooth_quartz"},{Name:"minecraft:structure_block"}],entities:[],blocks:[
{pos:[0,0,0],state:3},
{pos:[1,0,0],state:3},
{pos:[2,0,0],state:3},
{pos:[3,0,0],state:3},
{pos:[4,0,0],state:3},
{pos:[5,0,0],state:3},
{pos:[6,0,0],state:3},
{pos:[7,0,0],state:3},
{pos:[8,0,0],state:3},
{pos:[9,0,0],state:3},
{pos:[10,0,0],state:3},
{pos:[11,0,0],state:3},
{pos:[12,0,0],state:3},
{pos:[13,0,0],state:3},
{pos:[14,0,0],state:3},
{pos:[15,0,0],state:3},
{pos:[16,0,0],state:3},
{pos:[17,0,0],state:3},
{pos:[18,0,0],state:3},
{pos:[19,0,0],state:3},
{pos:[20,0,0],state:3},
{pos:[21,0,0],state:3},
{pos:[22,0,0],state:3},
{pos:[23,0,0],state:3},
{pos:[24,0,0],state:3},
{pos:[25,0,0],state:3},
{pos:[26,0,0],state:3},
{pos:[27,0,0],state:3},
{pos:[28,0,0],state:3},
{pos:[29,0,0],state:3},
{pos:[30,0,0],state:3},
{pos:[0,0,1],state:3},
{pos:[1,0,1],state:3},
{pos:[2,0,1],state:3},
{pos:[3,0,1],state:3},
{pos:[4,0,1],state:3},
{pos:[5,0,1],state:3},
{pos:[6,0,1],state:3},
{pos:[7,0,1],state:3},
{pos:[8,0,1],state:3},
{pos:[9,0,1],state:3},
{pos:[10,0,1],state:3},
{pos:[11,0,1],state:3},
{pos:[12,0,1],state:3},
{pos:[13,0,1],state:3},
{pos:[14,0,1],state:3},
{pos:[15,0,1],state:3},
{pos:[16,0,1],state:3},
{pos:[17,0,1],state:3},
{pos:[18,0,1],state:3},
{pos:[19,0,1],state:3},
{pos:[20,0,1],state:3},
{pos:[21,0,1],state:3},
{pos:[22,0,1],state:3},
{pos:[23,0,1],state:3},
{pos:[24,0,1],state:3},
{pos:[25,0,1],state:3},
{pos:[26,0,1],state:3},
{pos:[27,0,1],state:3},
{pos:[28,0,1],state:3},
{pos:[29,0,1],state:3},
{pos:[30,0,1],state:3},
{pos:[0,0,2],state:3},
{pos:[1,0,2],state:3},
{pos:[2,0,2],state:3},
{pos:[3,0,2],state:3},
{pos:[4,0,2],state:3},
{pos:[5,0,2],state:3},
{pos:[6,0,2],state:3},
{pos:[7,0,2],state:3},
{pos:[8,0,2],state:3},
{pos:[9,0,2],state:3},
{pos:[10,0,2],state:3},
{pos:[11,0,2],state:3},
{pos:[12,0,2],state:3},
{pos:[13,0,2],state:3},
{pos:[14,0,2],state:3},
{pos:[15,0,2],state:3},
{pos:[16,0,2],state:3},
{pos:[17,0,2],state:3},
{pos:[18,0,2],state:3},
{pos:[19,0,2],state:3},
{pos:[20,0,2],state:3},
{pos:[21,0,2],state:3},
{pos:[22,0,2],state:3},
{pos:[23,0,2],state:3},
{pos:[24,0,2],state:3},
{pos:[25,0,2],state:3},
{pos:[26,0,2],state:3},
{pos:[27,0,2],state:3},
{pos:[28,0,2],state:3},
{pos:[29,0,2],state:3},
{pos:[30,0,2],state:3},
{pos:[0,0,3],state:3},
{pos:[1,0,3],state:3},
{pos:[2,0,3],state:3},
{pos:[3,0,3],state:3},
{pos:[4,0,3],state:3},
{pos:[5,0,3],state:3},
{pos:[6,0,3],state:3},
{pos:[7,0,3],state:3},
{pos:[8,0,3],state:3},
{pos:[9,0,3],state:3},
{pos:[10,0,3],state:3},
{pos:[11,0,3],state:3},
{pos:[12,0,3],state:3},
{pos:[13,0,3],state:3},
{pos:[14,0,3],state:3},
{pos:[15,0,3],state:3},
{pos:[16,0,3],state:3},
{pos:[17,0,3],state:3},
{pos:[18,0,3],state:3},
{pos:[19,0,3],state:3},
{pos:[20,0,3],state:3},
{pos:[21,0,3],state:3},
{pos:[22,0,3],state:3},
{pos:[23,0,3],state:3},
{pos:[24,0,3],state:3},
{pos:[25,0,3],state:3},
{pos:[26,0,3],state:3},
{pos:[27,0,3],state:3},
{pos:[28,0,3],state:3},
{pos:[29,0,3],state:3},
{pos:[30,0,3],state:3},
{pos:[0,0,4],state:3},
{pos:[1,0,4],state:3},
{pos:[2,0,4],state:3},
{pos:[3,0,4],state:3},
{pos:[4,0,4],state:3},
{pos:[5,0,4],state:3},
{pos:[6,0,4],state:3},
{pos:[7,0,4],state:3},
{pos:[8,0,4],state:3},
{pos:[9,0,4],state:3},
{pos:[10,0,4],state:3},
{pos:[11,0,4],state:3},
{pos:[12,0,4],state:3},
{pos:[13,0,4],state:3},
{pos:[14,0,4],state:3},
{pos:[15,0,4],state:3},
{pos:[16,0,4],state:3},
{pos:[17,0,4],state:3},
{pos:[18,0,4],state:3},
{pos:[19,0,4],state:3},
{pos:[20,0,4],state:3},
{pos:[21,0,4],state:3},
{pos:[22,0,4],state:3},
{pos:[23,0,4],state:3},
{pos:[24,0,4],state:3},
{pos:[25,0,4],state:3},
{pos:[26,0,4],state:3},
{pos:[27,0,4],state:3},
{pos:[28,0,4],state:3},
{pos:[29,0,4],state:3},
{pos:[30,0,4],state:3},
{pos:[0,0,5],state:3},
{pos:[1,0,5],state:3},
{pos:[2,0,5],state:3},
{pos:[3,0,5],state:3},
{pos:[4,0,5],state:3},
{pos:[5,0,5],state:3},
{pos:[6,0,5],state:3},
{pos:[7,0,5],state:3},
{pos:[8,0,5],state:3},
{pos:[9,0,5],state:3},
{pos:[10,0,5],state:3},
{pos:[11,0,5],state:3},
{pos:[12,0,5],state:3},
{pos:[13,0,5],state:3},
{pos:[14,0,5],state:3},
{pos:[15,0,5],state:3},
{pos:[16,0,5],state:3},
{pos:[17,0,5],state:3},
{pos:[18,0,5],state:3},
{pos:[19,0,5],state:3},
{pos:[20,0,5],state:3},
{pos:[21,0,5],state:3},
{pos:[22,0,5],state:3},
{pos:[23,0,5],state:3},
{pos:[24,0,5],state:3},
{pos:[25,0,5],state:3},
{pos:[26,0,5],state:3},
{pos:[27,0,5],state:3},
{pos:[28,0,5],state:3},
{pos:[29,0,5],state:3},
{pos:[30,0,5],state:3},
{pos:[0,0,6],state:3},
{pos:[1,0,6],state:3},
{pos:[2,0,6],state:3},
{pos:[3,0,6],state:3},
{pos:[4,0,6],state:3},
{pos:[5,0,6],state:3},
{pos:[6,0,6],state:3},
{pos:[7,0,6],state:3},
{pos:[8,0,6],state:3},
{pos:[9,0,6],state:3},
{pos:[10,0,6],state:3},
{pos:[11,0,6],state:3},
{pos:[12,0,6],state:3},
{pos:[13,0,6],state:3},
{pos:[14,0,6],state:3},
{pos:[15,0,6],state:3},
{pos:[16,0,6],state:3},
{pos:[17,0,6],state:3},
{pos:[18,0,6],state:3},
{pos:[19,0,6],state:3},
{pos:[20,0,6],state:3},
{pos:[21,0,6],state:3},
{pos:[22,0,6],state:3},
{pos:[23,0,6],state:3},
{pos:[24,0,6],state:3},
{pos:[25,0,6],state:3},
{pos:[26,0,6],state:3},
{pos:[27,0,6],state:3},
{pos:[28,0,6],state:3},
{pos:[29,0,6],state:3},
{pos:[30,0,6],state:3},
{pos:[0,0,7],state:3},
{pos:[1,0,7],state:3},
{pos:[2,0,7],state:3},
{pos:[3,0,7],state:3},
{pos:[4,0,7],state:3},
{pos:[5,0,7],state:3},
{pos:[6,0,7],state:3},
{pos:[7,0,7],state:3},
{pos:[8,0,7],state:3},
{pos:[9,0,7],state:3},
{pos:[10,0,7],state:3},
{pos:[11,0,7],state:3},
{pos:[12,0,7],state:3},
{pos:[13,0,7],state:3},
{pos:[14,0,7],state:3},
{pos:[15,0,7],state:3},
{pos:[16,0,7],state:3},
{pos:[17,0,7],state:3},
{pos:[18,0,7],state:3},
{pos:[19,0,7],state:3},
{pos:[20,0,7],state:3},
{pos:[21,0,7],state:3},
{pos:[22,0,7],state:3},
{pos:[23,0,7],state:3},
{pos:[24,0,7],state:3},
{pos:[25,0,7],state:3},
{pos:[26,0,7],state:3},
{pos:[27,0,7],state:3},
{pos:[28,0,7],state:3},
{pos:[29,0,7],state:3},
{pos:[30,0,7],state:3},
{pos:[0,0,8],state:3},
{pos:[1,0,8],state:3},
{pos:[2,0,8],state:3},
{pos:[3,0,8],state:3},
{pos:[4,0,8],state:3},
{pos:[5,0,8],state:3},
{pos:[6,0,8],state:3},
{pos:[7,0,8],state:3},
{pos:[8,0,8],state:3},
{pos:[9,0,8],state:3},
{pos:[10,0,8],state:3},
{pos:[11,0,8],state:3},
{pos:[12,0,8],state:3},
{pos:[13,0,8],state:3},
{pos:[14,0,8],state:3},
{pos:[15,0,8],state:3},
{pos:[16,0,8],state:3},
{pos:[17,0,8],state:3},
{pos:[18,0,8],state:3},
{pos:[19,0,8],state:3},
{pos:[20,0,8],state:3},
{pos:[21,0,8],state:3},
{pos:[22,0,8],state:3},
{pos:[23,0,8],state:3},
{pos:[24,0,8],state:3},
{pos:[25,0,8],state:3},
{pos:[26,0,8],state:3},
{pos:[27,0,8],state:3},
{pos:[28,0,8],state:3},
{pos:[29,0,8],state:3},
{pos:[30,0,8],state:3},
{pos:[0,0,9],state:3},
{pos:[1,0,9],state:3},
{pos:[2,0,9],state:3},
{pos:[3,0,9],state:3},
{pos:[4,0,9],state:3},
{pos:[5,0,9],state:3},
{pos:[6,0,9],state:3},
{pos:[7,0,9],state:3},
{pos:[8,0,9],state:3},
{pos:[9,0,9],state:3},
{pos:[10,0,9],state:3},
{pos:[11,0,9],state:3},
{pos:[12,0,9],state:3},
{pos:[13,0,9],state:3},
{pos:[14,0,9],state:3},
{pos:[15,0,9],state:3},
{pos:[16,0,9],state:3},
{pos:[17,0,9],state:3},
{pos:[18,0,9],state:3},
{pos:[19,0,9],state:3},
{pos:[20,0,9],state:3},
{pos:[21,0,9],state:3},
{pos:[22,0,9],state:3},
{pos:[23,0,9],state:3},
{pos:[24,0,9],state:3},
{pos:[25,0,9],state:3},
{pos:[26,0,9],state:3},
{pos:[27,0,9],state:3},
{pos:[28,0,9],state:3},
{pos:[29,0,9],state:3},
{pos:[30,0,9],state:3},
{pos:[0,0,10],state:3},
{pos:[1,0,10],state:3},
{pos:[2,0,10],state:3},
{pos:[3,0,10],state:3},
{pos:[4,0,10],state:3},
{pos:[5,0,10],state:3},
{pos:[6,0,10],state:3},
{pos:[7,0,10],state:3},
{pos:[8,0,10],state:3},
{pos:[9,0,10],state:3},
{pos:[10,0,10],state:3},
{pos:[11,0,10],state:3},
{pos:[12,0,10],state:3},
{pos:[13,0,10],state:3},
{pos:[14,0,10],state:3},
{pos:[15,0,10],state:3},
{pos:[16,0,10],state:3},
{pos:[17,0,10],state:3},
{pos:[18,0,10],state:3},
{pos:[19,0,10],state:3},
{pos:[20,0,10],state:3},
{pos:[21,0,10],state:3},
{pos:[22,0,10],state:3},
{pos:[23,0,10],state:3},
{pos:[24,0,10],state:3},
{pos:[25,0,10],state:3},
{pos:[26,0,10],state:3},
{pos:[27,0,10],state:3},
{pos:[28,0,10],state:3},
{pos:[29,0,10],state:3},
{pos:[30,0,10],state:3},
{pos:[0,0,11],state:3},
{pos:[1,0,11],state:3},
{pos:[2,0,11],state:3},
{pos:[3,0,11],state:3},
{pos:[4,0,11],state:3},
{pos:[5,0,11],state:3},
{pos:[6,0,11],state:3},
{pos:[7,0,11],state:3},
{pos:[8,0,11],state:3},
{pos:[9,0,11],state:3},
{pos:[10,0,11],state:3},
{pos:[11,0,11],state:3},
{pos:[12,0,11],state:3},
{pos:[13,0,11],state:3},
{pos:[14,0,11],state:3},
{pos:[15,0,11],state:3},
{pos:[16,0,11],state:3},
{pos:[17,0,11],state:3},
{pos:[18,0,11],state:3},
{pos:[19,0,11],state:3},
{pos:[20,0,11],state:3},
{pos:[21,0,11],state:3},
{pos:[22,0,11],state:3},
{pos:[23,0,11],state:3},
{pos:[24,0,11],state:3},
{pos:[25,0,11],state:3},
{pos:[26,0,11],state:3},
{pos:[27,0,11],state:3},
{pos:[28,0,11],state:3},
{pos:[29,0,11],state:3},
{pos:[30,0,11],state:3},
{pos:[0,0,12],state:3},
{pos:[1,0,12],state:3},
{pos:[2,0,12],state:3},
{pos:[3,0,12],state:3},
{pos:[4,0,12],state:3},
{pos:[5,0,12],state:3},
{pos:[6,0,12],state:3},
{pos:[7,0,12],state:3},
{pos:[8,0,12],state:3},
{pos:[9,0,12],state:3},
{pos:[10,0,12],state:3},
{pos:[11,0,12],state:3},
{pos:[12,0,12],state:3},
{pos:[13,0,12],state:3},
{pos:[14,0,12],state:3},
{pos:[15,0,12],state:3},
{pos:[16,0,12],state:3},
{pos:[17,0,12],state:3},
{pos:[18,0,12],state:3},
{pos:[19,0,12],state:3},
{pos:[20,0,12],state:3},
{pos:[21,0,12],state:3},
{pos:[22,0,12],state:3},
{pos:[23,0,12],state:3},
{pos:[24,0,12],state:3},
{pos:[25,0,12],state:3},
{pos:[26,0,12],state:3},
{pos:[27,0,12],state:3},
{pos:[28,0,12],state:3},
{pos:[29,0,12],state:3},
{pos:[30,0,12],state:3},
{pos:[0,0,13],state:3},
{pos:[1,0,13],state:3},
{pos:[2,0,13],state:3},
{pos:[3,0,13],state:3},
{pos:[4,0,13],state:3},
{pos:[5,0,13],state:3},
{pos:[6,0,13],state:3},
{pos:[7,0,13],state:3},
{pos:[8,0,13],state:3},
{pos:[9,0,13],state:3},
{pos:[10,0,13],state:3},
{pos:[11,0,13],state:3},
{pos:[12,0,13],state:3},
{pos:[13,0,13],state:3},
{pos:[14,0,13],state:3},
{pos:[15,0,13],state:3},
{pos:[16,0,13],state:3},
{pos:[17,0,13],state:3},
{pos:[18,0,13],state:3},
{pos:[19,0,13],state:3},
{pos:[20,0,13],state:3},
{pos:[21,0,13],state:3},
{pos:[22,0,13],state:3},
{pos:[23,0,13],state:3},
{pos:[24,0,13],state:3},
{pos:[25,0,13],state:3},
{pos:[26,0,13],state:3},
{pos:[27,0,13],state:3},
{pos:[28,0,13],state:3},
{pos:[29,0,13],state:3},
{pos:[30,0,13],state:3},
{pos:[0,0,14],state:3},
{pos:[1,0,14],state:3},
{pos:[2,0,14],state:3},
{pos:[3,0,14],state:3},
{pos:[4,0,14],state:3},
{pos:[5,0,14],state:3},
{pos:[6,0,14],state:3},
{pos:[7,0,14],state:3},
{pos:[8,0,14],state:3},
{pos:[9,0,14],state:3},
{pos:[10,0,14],state:3},
{pos:[11,0,14],state:3},
{pos:[12,0,14],state:3},
{pos:[13,0,14],state:3},
{pos:[14,0,14],state:3},
{pos:[15,0,14],state:3},
{pos:[16,0,14],state:3},
{pos:[17,0,14],state:3},
{pos:[18,0,14],state:3},
{pos:[19,0,14],state:3},
{pos:[20,0,14],state:3},
{pos:[21,0,14],state:3},
{pos:[22,0,14],state:3},
{pos:[23,0,14],state:3},
{pos:[24,0,14],state:3},
{pos:[25,0,14],state:3},
{pos:[26,0,14],state:3},
{pos:[27,0,14],state:3},
{pos:[28,0,14],state:3},
{pos:[29,0,14],state:3},
{pos:[30,0,14],state:3},
{pos:[0,0,15],state:3},
{pos:[1,0,15],state:3},
{pos:[2,0,15],state:3},
{pos:[3,0,15],state:3},
{pos:[4,0,15],state:3},
{pos:[5,0,15],state:3},
{pos:[6,0,15],state:3},
{pos:[7,0,15],state:3},
{pos:[8,0,15],state:3},
{pos:[9,0,15],state:3},
{pos:[10,0,15],state:3},
{pos:[11,0,15],state:3},
{pos:[12,0,15],state:3},
{pos:[13,0,15],state:3},
{pos:[14,0,15],state:3},
{pos:[15,0,15],state:3},
{pos:[16,0,15],state:3},
{pos:[17,0,15],state:3},
{pos:[18,0,15],state:3},
{pos:[19,0,15],state:3},
{pos:[20,0,15],state:3},
{pos:[21,0,15],state:3},
{pos:[22,0,15],state:3},
{pos:[23,0,15],state:3},
{pos:[24,0,15],state:3},
{pos:[25,0,15],state:3},
{pos:[26,0,15],state:3},
{pos:[27,0,15],state:3},
{pos:[28,0,15],state:3},
{pos:[29,0,15],state:3},
{pos:[30,0,15],state:3},
{pos:[0,0,16],state:3},
{pos:[1,0,16],state:3},
{pos:[2,0,16],state:3},
{pos:[3,0,16],state:3},
{pos:[4,0,16],state:3},
{pos:[5,0,16],state:3},
{pos:[6,0,16],state:3},
{pos:[7,0,16],state:3},
{pos:[8,0,16],state:3},
{pos:[9,0,16],state:3},
{pos:[10,0,16],state:3},
{pos:[11,0,16],state:3},
{pos:[12,0,16],state:3},
{pos:[13,0,16],state:3},
{pos:[14,0,16],state:3},
{pos:[15,0,16],state:3},
{pos:[16,0,16],state:3},
{pos:[17,0,16],state:3},
{pos:[18,0,16],state:3},
{pos:[19,0,16],state:3},
{pos:[20,0,16],state:3},
{pos:[21,0,16],state:3},
{pos:[22,0,16],state:3},
{pos:[23,0,16],state:3},
{pos:[24,0,16],state:3},
{pos:[25,0,16],state:3},
{pos:[26,0,16],state:3},
{pos:[27,0,16],state:3},
{pos:[28,0,16],state:3},
{pos:[29,0,16],state:3},
{pos:[30,0,16],state:3},
{pos:[0,0,17],state:3},
{pos:[1,0,17],state:3},
{pos:[2,0,17],state:3},
{pos:[3,0,17],state:3},
{pos:[4,0,17],state:3},
{pos:[5,0,17],state:3},
{pos:[6,0,17],state:3},
{pos:[7,0,17],state:3},
{pos:[8,0,17],state:3},
{pos:[9,0,17],state:3},
{pos:[10,0,17],state:3},
{pos:[11,0,17],state:3},
{pos:[12,0,17],state:3},
{pos:[13,0,17],state:3},
{pos:[14,0,17],state:3},
{pos:[15,0,17],state:3},
{pos:[16,0,17],state:3},
{pos:[17,0,17],state:3},
{pos:[18,0,17],state:3},
{pos:[19,0,17],state:3},
{pos:[20,0,17],state:3},
{pos:[21,0,17],state:3},
{pos:[22,0,17],state:3},
{pos:[23,0,17],state:3},
{pos:[24,0,17],state:3},
{pos:[25,0,17],state:3},
{pos:[26,0,17],state:3},
{pos:[27,0,17],state:3},
{pos:[28,0,17],state:3},
{pos:[29,0,17],state:3},
{pos:[30,0,17],state:3},
{pos:[0,0,18],state:3},
{pos:[1,0,18],state:3},
{pos:[2,0,18],state:3},
{pos:[3,0,18],state:3},
{pos:[4,0,18],state:3},
{pos:[5,0,18],state:3},
{pos:[6,0,18],state:3},
{pos:[7,0,18],state:3},
{pos:[8,0,18],state:3},
{pos:[9,0,18],state:3},
{pos:[10,0,18],state:3},
{pos:[11,0,18],state:3},
{pos:[12,0,18],state:3},
{pos:[13,0,18],state:3},
{pos:[14,0,18],state:3},
{pos:[15,0,18],state:3},
{pos:[16,0,18],state:3},
{pos:[17,0,18],state:3},
{pos:[18,0,18],state:3},
{pos:[19,0,18],state:3},
{pos:[20,0,18],state:3},
{pos:[21,0,18],state:3},
{pos:[22,0,18],state:3},
{pos:[23,0,18],state:3},
{pos:[24,0,18],state:3},
{pos:[25,0,18],state:3},
{pos:[26,0,18],state:3},
{pos:[27,0,18],state:3},
{pos:[28,0,18],state:3},
{pos:[29,0,18],state:3},
{pos:[30,0,18],state:3},
{pos:[0,0,19],state:3},
{pos:[1,0,19],state:3},
{pos:[2,0,19],state:3},
{pos:[3,0,19],state:3},
{pos:[4,0,19],state:3},
{pos:[5,0,19],state:3},
{pos:[6,0,19],state:3},
{pos:[7,0,19],state:3},
{pos:[8,0,19],state:3},
{pos:[9,0,19],state:3},
{pos:[10,0,19],state:3},
{pos:[11,0,19],state:3},
{pos:[12,0,19],state:3},
{pos:[13,0,19],state:3},
{pos:[14,0,19],state:3},
{pos:[15,0,19],state:3},
{pos:[16,0,19],state:3},
{pos:[17,0,19],state:3},
{pos:[18,0,19],state:3},
{pos:[19,0,19],state:3},
{pos:[20,0,19],state:3},
{pos:[21,0,19],state:3},
{pos:[22,0,19],state:3},
{pos:[23,0,19],state:3},
{pos:[24,0,19],state:3},
{pos:[25,0,19],state:3},
{pos:[26,0,19],state:3},
{pos:[27,0,19],state:3},
{pos:[28,0,19],state:3},
{pos:[29,0,19],state:3},
{pos:[30,0,19],state:3},
{pos:[0,0,20],state:3},
{pos:[1,0,20],state:3},
{pos:[2,0,20],state:3},
{pos:[3,0,20],state:3},
{pos:[4,0,20],state:3},
{pos:[5,0,20],state:3},
{pos:[6,0,20],state:3},
{pos:[7,0,20],state:3},
{pos:[8,0,20],state:3},
{pos:[9,0,20],state:3},
{pos:[10,0,20],state:3},
{pos:[11,0,20],state:3},
{pos:[12,0,20],state:3},
{pos:[13,0,20],state:3},
{pos:[14,0,20],state:3},
{pos:[15,0,20],state:3},
{pos:[16,0,20],state:3},
{pos:[17,0,20],state:3},
{pos:[18,0,20],state:3},
{pos:[19,0,20],state:3},
{pos:[20,0,20],state:3},
{pos:[21,0,20],state:3},
{pos:[22,0,20],state:3},
{pos:[23,0,20],state:3},
{pos:[24,0,20],state:3},
{pos:[25,0,20],state:3},
{pos:[26,0,20],state:3},
{pos:[27,0,20],state:3},
{pos:[28,0,20],state:3},
{pos:[29,0,20],state:3},
{pos:[30,0,20],state:3},
{pos:[0,0,21],state:3},
{pos:[1,0,21],state:3},
{pos:[2,0,21],state:3},
{pos:[3,0,21],state:3},
{pos:[4,0,21],state:3},
{pos:[5,0,21],state:3},
{pos:[6,0,21],state:3},
{pos:[7,0,21],state:3},
{pos:[8,0,21],state:3},
{pos:[9,0,21],state:3},
{pos:[10,0,21],state:3},
{pos:[11,0,21],state:3},
{pos:[12,0,21],state:3},
{pos:[13,0,21],state:3},
{pos:[14,0,21],state:3},
{pos:[15,0,21],state:3},
{pos:[16,0,21],state:3},
{pos:[17,0,21],state:3},
{pos:[18,0,21],state:3},
{pos:[19,0,21],state:3},
{pos:[20,0,21],state:3},
{pos:[21,0,21],state:3},
{pos:[22,0,21],state:3},
{pos:[23,0,21],state:3},
{pos:[24,0,21],state:3},
{pos:[25,0,21],state:3},
{pos:[26,0,21],state:3},
{pos:[27,0,21],state:3},
{pos:[28,0,21],state:3},
{pos:[29,0,21],state:3},
{pos:[30,0,21],state:3},
{pos:[0,0,22],state:3},
{pos:[1,0,22],state:3},
{pos:[2,0,22],state:3},
{pos:[3,0,22],state:3},
{pos:[4,0,22],state:3},
{pos:[5,0,22],state:3},
{pos:[6,0,22],state:3},
{pos:[7,0,22],state:3},
{pos:[8,0,22],state:3},
{pos:[9,0,22],state:3},
{pos:[10,0,22],state:3},
{pos:[11,0,22],state:3},
{pos:[12,0,22],state:3},
{pos:[13,0,22],state:3},
{pos:[14,0,22],state:3},
{pos:[15,0,22],state:3},
{pos:[16,0,22],state:3},
{pos:[17,0,22],state:3},
{pos:[18,0,22],state:3},
{pos:[19,0,22],state:3},
{pos:[20,0,22],state:3},
{pos:[21,0,22],state:3},
{pos:[22,0,22],state:3},
{pos:[23,0,22],state:3},
{pos:[24,0,22],state:3},
{pos:[25,0,22],state:3},
{pos:[26,0,22],state:3},
{pos:[27,0,22],state:3},
{pos:[28,0,22],state:3},
{pos:[29,0,22],state:3},
{pos:[30,0,22],state:3},
{pos:[0,0,23],state:3},
{pos:[1,0,23],state:3},
{pos:[2,0,23],state:3},
{pos:[3,0,23],state:3},
{pos:[4,0,23],state:3},
{pos:[5,0,23],state:3},
{pos:[6,0,23],state:3},
{pos:[7,0,23],state:3},
{pos:[8,0,23],state:3},
{pos:[9,0,23],state:3},
{pos:[10,0,23],state:3},
{pos:[11,0,23],state:3},
{pos:[12,0,23],state:3},
{pos:[13,0,23],state:3},
{pos:[14,0,23],state:3},
{pos:[15,0,23],state:3},
{pos:[16,0,23],state:3},
{pos:[17,0,23],state:3},
{pos:[18,0,23],state:3},
{pos:[19,0,23],state:3},
{pos:[20,0,23],state:3},
{pos:[21,0,23],state:3},
{pos:[22,0,23],state:3},
{pos:[23,0,23],state:3},
{pos:[24,0,23],state:3},
{pos:[25,0,23],state:3},
{pos:[26,0,23],state:3},
{pos:[27,0,23],state:3},
{pos:[28,0,23],state:3},
{pos:[29,0,23],state:3},
{pos:[30,0,23],state:3},
{pos:[0,0,24],state:3},
{pos:[1,0,24],state:3},
{pos:[2,0,24],state:3},
{pos:[3,0,24],state:3},
{pos:[4,0,24],state:3},
{pos:[5,0,24],state:3},
{pos:[6,0,24],state:3},
{pos:[7,0,24],state:3},
{pos:[8,0,24],state:3},
{pos:[9,0,24],state:3},
{pos:[10,0,24],state:3},
{pos:[11,0,24],state:3},
{pos:[12,0,24],state:3},
{pos:[13,0,24],state:3},
{pos:[14,0,24],state:3},
{pos:[15,0,24],state:3},
{pos:[16,0,24],state:3},
{pos:[17,0,24],state:3},
{pos:[18,0,24],state:3},
{pos:[19,0,24],state:3},
{pos:[20,0,24],state:3},
{pos:[21,0,24],state:3},
{pos:[22,0,24],state:3},
{pos:[23,0,24],state:3},
{pos:[24,0,24],state:3},
{pos:[25,0,24],state:3},
{pos:[26,0,24],state:3},
{pos:[27,0,24],state:3},
{pos:[28,0,24],state:3},
{pos:[29,0,24],state:3},
{pos:[30,0,24],state:3},
{pos:[0,0,25],state:3},
{pos:[1,0,25],state:3},
{pos:[2,0,25],state:3},
{pos:[3,0,25],state:3},
{pos:[4,0,25],state:3},
{pos:[5,0,25],state:3},
{pos:[6,0,25],state:3},
{pos:[7,0,25],state:3},
{pos:[8,0,25],state:3},
{pos:[9,0,25],state:3},
{pos:[10,0,25],state:3},
{pos:[11,0,25],state:3},
{pos:[12,0,25],state:3},
{pos:[13,0,25],state:3},
{pos:[14,0,25],state:3},
{pos:[15,0,25],state:3},
{pos:[16,0,25],state:3},
{pos:[17,0,25],state:3},
{pos:[18,0,25],state:3},
{pos:[19,0,25],state:3},
{pos:[20,0,25],state:3},
{pos:[21,0,25],state:3},
{pos:[22,0,25],state:3},
{pos:[23,0,25],state:3},
{pos:[24,0,25],state:3},
{pos:[25,0,25],state:3},
{pos:[26,0,25],state:3},
{pos:[27,0,25],state:3},
{pos:[28,0,25],state:3},
{pos:[29,0,25],state:3},
{pos:[30,0,25],state:3},
{pos:[0,0,26],state:3},
{pos:[1,0,26],state:3},
{pos:[2,0,26],state:3},
{pos:[3,0,26],state:3},
{pos:[4,0,26],state:3},
{pos:[5,0,26],state:3},
{pos:[6,0,26],state:3},
{pos:[7,0,26],state:3},
{pos:[8,0,26],state:3},
{pos:[9,0,26],state:3},
{pos:[10,0,26],state:3},
{pos:[11,0,26],state:3},
{pos:[12,0,26],state:3},
{pos:[13,0,26],state:3},
{pos:[14,0,26],state:3},
{pos:[15,0,26],state:3},
{pos:[16,0,26],state:3},
{pos:[17,0,26],state:3},
{pos:[18,0,26],state:3},
{pos:[19,0,26],state:3},
{pos:[20,0,26],state:3},
{pos:[21,0,26],state:3},
{pos:[22,0,26],state:3},
{pos:[23,0,26],state:3},
{pos:[24,0,26],state:3},
{pos:[25,0,26],state:3},
{pos:[26,0,26],state:3},
{pos:[27,0,26],state:3},
{pos:[28,0,26],state:3},
{pos:[29,0,26],state:3},
{pos:[30,0,26],state:3},
{pos:[0,0,27],state:3},
{pos:[1,0,27],state:3},
{pos:[2,0,27],state:3},
{pos:[3,0,27],state:3},
{pos:[4,0,27],state:3},
{pos:[5,0,27],state:3},
{pos:[6,0,27],state:3},
{pos:[7,0,27],state:3},
{pos:[8,0,27],state:3},
{pos:[9,0,27],state:3},
{pos:[10,0,27],state:3},
{pos:[11,0,27],state:3},
{pos:[12,0,27],state:3},
{pos:[13,0,27],state:3},
{pos:[14,0,27],state:3},
{pos:[15,0,27],state:3},
{pos:[16,0,27],state:3},
{pos:[17,0,27],state:3},
{pos:[18,0,27],state:3},
{pos:[19,0,27],state:3},
{pos:[20,0,27],state:3},
{pos:[21,0,27],state:3},
{pos:[22,0,27],state:3},
{pos:[23,0,27],state:3},
{pos:[24,0,27],state:3},
{pos:[25,0,27],state:3},
{pos:[26,0,27],state:3},
{pos:[27,0,27],state:3},
{pos:[28,0,27],state:3},
{pos:[29,0,27],state:3},
{pos:[30,0,27],state:3},
{pos:[0,0,28],state:3},
{pos:[1,0,28],state:3},
{pos:[2,0,28],state:3},
{pos:[3,0,28],state:3},
{pos:[4,0,28],state:3},
{pos:[5,0,28],state:3},
{pos:[6,0,28],state:3},
{pos:[7,0,28],state:3},
{pos:[8,0,28],state:3},
{pos:[9,0,28],state:3},
{pos:[10,0,28],state:3},
{pos:[11,0,28],state:3},
{pos:[12,0,28],state:3},
{pos:[13,0,28],state:3},
{pos:[14,0,28],state:3},
{pos:[15,0,28],state:3},
{pos:[16,0,28],state:3},
{pos:[17,0,28],state:3},
{pos:[18,0,28],state:3},
{pos:[19,0,28],state:3},
{pos:[20,0,28],state:3},
{pos:[21,0,28],state:3},
{pos:[22,0,28],state:3},
{pos:[23,0,28],state:3},
{pos:[24,0,28],state:3},
{pos:[25,0,28],state:3},
{pos:[26,0,28],state:3},
{pos:[27,0,28],state:3},
{pos:[28,0,28],state:3},
{pos:[29,0,28],state:3},
{pos:[30,0,28],state:3},
{pos:[0,0,29],state:3},
{pos:[1,0,29],state:3},
{pos:[2,0,29],state:3},
{pos:[3,0,29],state:3},
{pos:[4,0,29],state:3},
{pos:[5,0,29],state:3},
{pos:[6,0,29],state:3},
{pos:[7,0,29],state:3},
{pos:[8,0,29],state:3},
{pos:[9,0,29],state:3},
{pos:[10,0,29],state:3},
{pos:[11,0,29],state:3},
{pos:[12,0,29],state:3},
{pos:[13,0,29],state:3},
{pos:[14,0,29],state:3},
{pos:[15,0,29],state:3},
{pos:[16,0,29],state:3},
{pos:[17,0,29],state:3},
{pos:[18,0,29],state:3},
{pos:[19,0,29],state:3},
{pos:[20,0,29],state:3},
{pos:[21,0,29],state:3},
{pos:[22,0,29],state:3},
{pos:[23,0,29],state:3},
{pos:[24,0,29],state:3},
{pos:[25,0,29],state:3},
{pos:[26,0,29],state:3},
{pos:[27,0,29],state:3},
{pos:[28,0,29],state:3},
{pos:[29,0,29],state:3},
{pos:[30,0,29],state:3},
{pos:[0,0,30],state:3},
{pos:[1,0,30],state:3},
{pos:[2,0,30],state:3},
{pos:[3,0,30],state:3},
{pos:[4,0,30],state:3},
{pos:[5,0,30],state:3},
{pos:[6,0,30],state:3},
{pos:[7,0,30],state:3},
{pos:[8,0,30],state:3},
{pos:[9,0,30],state:3},
{pos:[10,0,30],state:3},
{pos:[11,0,30],state:3},
{pos:[12,0,30],state:3},
{pos:[13,0,30],state:3},
{pos:[14,0,30],state:3},
{pos:[15,0,30],state:3},
{pos:[16,0,30],state:3},
{pos:[17,0,30],state:3},
{pos:[18,0,30],state:3},
{pos:[19,0,30],state:3},
{pos:[20,0,30],state:3},
{pos:[21,0,30],state:3},
{pos:[22,0,30],state:3},
{pos:[23,0,30],state:3},
{pos:[24,0,30],state:3},
{pos:[25,0,30],state:3},
{pos:[26,0,30],state:3},
{pos:[27,0,30],state:3},
{pos:[28,0,30],state:3},
{pos:[29,0,30],state:3},
{pos:[30,0,30],state:3},
{pos:[0,1,0],state:1},
{pos:[1,1,0],state:1},
{pos:[2,1,0],state:1},
{pos:[3,1,0],state:1},
{pos:[4,1,0],state:1},
{pos:[5,1,0],state:1},
{pos:[6,1,0],state:1},
{pos:[7,1,0],state:1},
{pos:[8,1,0],state:1},
{pos:[9,1,0],state:1},
{pos:[10,1,0],state:1},
{pos:[11,1,0],state:1},
{pos:[12,1,0],state:1},
{pos:[13,1,0],state:1},
{pos:[14,1,0],state:1},
{pos:[15,1,0],state:1},
{pos:[16,1,0],state:1},
{pos:[17,1,0],state:1},
{pos:[18,1,0],state:1},
{pos:[19,1,0],state:1},
{pos:[20,1,0],state:1},
{pos:[21,1,0],state:1},
{pos:[22,1,0],state:1},
{pos:[23,1,0],state:1},
{pos:[24,1,0],state:1},
{pos:[25,1,0],state:1},
{pos:[26,1,0],state:1},
{pos:[27,1,0],state:1},
{pos:[28,1,0],state:1},
{pos:[29,1,0],state:1},
{pos:[30,1,0],state:1},
{pos:[0,1,1],state:1},
{pos:[1,1,1],state:1},
{pos:[2,1,1],state:1},
{pos:[3,1,1],state:1},
{pos:[4,1,1],state:1},
{pos:[5,1,1],state:1},
{pos:[6,1,1],state:1},
{pos:[7,1,1],state:1},
{pos:[8,1,1],state:1},
{pos:[9,1,1],state:1},
{pos:[10,1,1],state:1},
{pos:[11,1,1],state:1},
{pos:[12,1,1],state:1},
{pos:[13,1,1],state:1},
{pos:[14,1,1],state:1},
{pos:[15,1,1],state:1},
{pos:[16,1,1],state:1},
{pos:[17,1,1],state:1},
{pos:[18,1,1],state:1},
{pos:[19,1,1],state:1},
{pos:[20,1,1],state:1},
{pos:[21,1,1],state:1},
{pos:[22,1,1],state:1},
{pos:[23,1,1],state:1},
{pos:[24,1,1],state:1},
{pos:[25,1,1],state:1},
{pos:[26,1,1],state:1},
{pos:[27,1,1],state:1},
{pos:[28,1,1],state:1},
{pos:[29,1,1],state:1},
{pos:[30,1,1],state:1},
{pos:[0,1,2],state:1},
{pos:[1,1,2],state:1},
{pos:[4,1,2],state:0},
{pos:[11,1,2],state:0},
{pos:[18,1,2],state:0},
{pos:[25,1,2],state:0},
{pos:[29,1,2],state:1},
{pos:[30,1,2],state:1},
{pos:[0,1,3],state:1},
{pos:[1,1,3],state:1},
{pos:[29,1,3],state:1},
{pos:[30,1,3],state:1},
{pos:[0,1,4],state:1},
{pos:[1,1,4],state:1},
{pos:[29,1,4],state:1},
{pos:[30,1,4],state:1},
{pos:[0,1,5],state:1},
{pos:[1,1,5],state:1},
{pos:[2,1,5],state:0},
{pos:[28,1,5],state:0},
{pos:[29,1,5],state:1},
{pos:[30,1,5],state:1},
{pos:[0,1,6],state:1},
{pos:[1,1,6],state:1},
{pos:[29,1,6],state:1},
{pos:[30,1,6],state:1},
{pos:[0,1,7],state:1},
{pos:[1,1,7],state:1},
{pos:[29,1,7],state:1},
{pos:[30,1,7],state:1},
{pos:[0,1,8],state:1},
{pos:[1,1,8],state:1},
{pos:[29,1,8],state:1},
{pos:[30,1,8],state:1},
{pos:[0,1,9],state:1},
{pos:[1,1,9],state:1},
{pos:[29,1,9],state:1},
{pos:[30,1,9],state:1},
{pos:[0,1,10],state:1},
{pos:[1,1,10],state:1},
{pos:[29,1,10],state:1},
{pos:[30,1,10],state:1},
{pos:[0,1,11],state:1},
{pos:[1,1,11],state:1},
{pos:[29,1,11],state:1},
{pos:[30,1,11],state:1},
{pos:[11,1,12],state:0},
{pos:[12,1,12],state:0},
{pos:[13,1,12],state:0},
{pos:[14,1,12],state:0},
{pos:[15,1,12],state:0},
{pos:[16,1,12],state:0},
{pos:[17,1,12],state:0},
{pos:[18,1,12],state:0},
{pos:[19,1,12],state:0},
{pos:[29,1,12],state:1},
{pos:[30,1,12],state:1},
{pos:[2,1,13],state:0},
{pos:[11,1,13],state:0},
{pos:[12,1,13],state:0},
{pos:[13,1,13],state:0},
{pos:[14,1,13],state:0},
{pos:[15,1,13],state:0},
{pos:[16,1,13],state:0},
{pos:[17,1,13],state:0},
{pos:[18,1,13],state:0},
{pos:[19,1,13],state:0},
{pos:[28,1,13],state:0},
{pos:[29,1,13],state:1},
{pos:[30,1,13],state:1},
{pos:[11,1,14],state:0},
{pos:[12,1,14],state:0},
{pos:[13,1,14],state:0},
{pos:[14,1,14],state:0},
{pos:[15,1,14],state:0},
{pos:[16,1,14],state:0},
{pos:[17,1,14],state:0},
{pos:[18,1,14],state:0},
{pos:[19,1,14],state:0},
{pos:[24,1,14],state:4,nbt:{mode:"DATA",metadata:"exit"}},
{pos:[29,1,14],state:1},
{pos:[30,1,14],state:1},
{pos:[11,1,15],state:0},
{pos:[12,1,15],state:0},
{pos:[13,1,15],state:0},
{pos:[14,1,15],state:0},
{pos:[15,1,15],state:0},
{pos:[16,1,15],state:0},
{pos:[17,1,15],state:0},
{pos:[18,1,15],state:0},
{pos:[19,1,15],state:0},
{pos:[29,1,15],state:1},
{pos:[30,1,15],state:1},
{pos:[11,1,16],state:0},
{pos:[12,1,16],state:0},
{pos:[13,1,16],state:0},
{pos:[14,1,16],state:0},
{pos:[15,1,16],state:0},
{pos:[16,1,16],state:0},
{pos:[17,1,16],state:0},
{pos:[18,1,16],state:0},
{pos:[19,1,16],state:0},
{pos:[29,1,16],state:1},
{pos:[30,1,16],state:1},
{pos:[0,1,17],state:1},
{pos:[1,1,17],state:1},
{pos:[11,1,17],state:0},
{pos:[12,1,17],state:0},
{pos:[13,1,17],state:0},
{pos:[14,1,17],state:0},
{pos:[15,1,17],state:0},
{pos:[16,1,17],state:0},
{pos:[17,1,17],state:0},
{pos:[18,1,17],state:0},
{pos:[19,1,17],state:0},
{pos:[29,1,17],state:1},
{pos:[30,1,17],state:1},
{pos:[0,1,18],state:1},
{pos:[1,1,18],state:1},
{pos:[11,1,18],state:0},
{pos:[12,1,18],state:0},
{pos:[13,1,18],state:0},
{pos:[14,1,18],state:0},
{pos:[15,1,18],state:0},
{pos:[16,1,18],state:0},
{pos:[17,1,18],state:0},
{pos:[18,1,18],state:0},
{pos:[19,1,18],state:0},
{pos:[29,1,18],state:1},
{pos:[30,1,18],state:1},
{pos:[0,1,19],state:1},
{pos:[1,1,19],state:1},
{pos:[29,1,19],state:1},
{pos:[30,1,19],state:1},
{pos:[0,1,20],state:1},
{pos:[1,1,20],state:1},
{pos:[29,1,20],state:1},
{pos:[30,1,20],state:1},
{pos:[0,1,21],state:1},
{pos:[1,1,21],state:1},
{pos:[2,1,21],state:0},
{pos:[28,1,21],state:0},
{pos:[29,1,21],state:1},
{pos:[30,1,21],state:1},
{pos:[0,1,22],state:1},
{pos:[1,1,22],state:1},
{pos:[29,1,22],state:1},
{pos:[30,1,22],state:1},
{pos:[0,1,23],state:1},
{pos:[1,1,23],state:1},
{pos:[29,1,23],state:1},
{pos:[30,1,23],state:1},
{pos:[0,1,24],state:1},
{pos:[1,1,24],state:1},
{pos:[29,1,24],state:1},
{pos:[30,1,24],state:1},
{pos:[0,1,25],state:1},
{pos:[1,1,25],state:1},
{pos:[29,1,25],state:1},
{pos:[30,1,25],state:1},
{pos:[0,1,26],state:1},
{pos:[1,1,26],state:1},
{pos:[29,1,26],state:1},
{pos:[30,1,26],state:1},
{pos:[0,1,27],state:1},
{pos:[1,1,27],state:1},
{pos:[29,1,27],state:1},
{pos:[30,1,27],state:1},
{pos:[0,1,28],state:1},
{pos:[1,1,28],state:1},
{pos:[4,1,28],state:0},
{pos:[11,1,28],state:0},
{pos:[18,1,28],state:0},
{pos:[25,1,28],state:0},
{pos:[29,1,28],state:1},
{pos:[30,1,28],state:1},
{pos:[0,1,29],state:1},
{pos:[1,1,29],state:1},
{pos:[2,1,29],state:1},
{pos:[3,1,29],state:1},
{pos:[4,1,29],state:1},
{pos:[5,1,29],state:1},
{pos:[6,1,29],state:1},
{pos:[7,1,29],state:1},
{pos:[8,1,29],state:1},
{pos:[9,1,29],state:1},
{pos:[10,1,29],state:1},
{pos:[11,1,29],state:1},
{pos:[12,1,29],state:1},
{pos:[13,1,29],state:1},
{pos:[14,1,29],state:1},
{pos:[15,1,29],state:1},
{pos:[16,1,29],state:1},
{pos:[17,1,29],state:1},
{pos:[18,1,29],state:1},
{pos:[19,1,29],state:1},
{pos:[20,1,29],state:1},
{pos:[21,1,29],state:1},
{pos:[22,1,29],state:1},
{pos:[23,1,29],state:1},
{pos:[24,1,29],state:1},
{pos:[25,1,29],state:1},
{pos:[26,1,29],state:1},
{pos:[27,1,29],state:1},
{pos:[28,1,29],state:1},
{pos:[29,1,29],state:1},
{pos:[30,1,29],state:1},
{pos:[0,1,30],state:1},
{pos:[1,1,30],state:1},
{pos:[2,1,30],state:1},
{pos:[3,1,30],state:1},
{pos:[4,1,30],state:1},
{pos:[5,1,30],state:1},
{pos:[6,1,30],state:1},
{pos:[7,1,30],state:1},
{pos:[8,1,30],state:1},
{pos:[9,1,30],state:1},
{pos:[10,1,30],state:1},
{pos:[11,1,30],state:1},
{pos:[12,1,30],state:1},
{pos:[13,1,30],state:1},
{pos:[14,1,30],state:1},
{pos:[15,1,30],state:1},
{pos:[16,1,30],state:1},
{pos:[17,1,30],state:1},
{pos:[18,1,30],state:1},
{pos:[19,1,30],state:1},
{pos:[20,1,30],state:1},
{pos:[21,1,30],state:1},
{pos:[22,1,30],state:1},
{pos:[23,1,30],state:1},
{pos:[24,1,30],state:1},
{pos:[25,1,30],state:1},
{pos:[26,1,30],state:1},
{pos:[27,1,30],state:1},
{pos:[28,1,30],state:1},
{pos:[29,1,30],state:1},
{pos:[30,1,30],state:1},
{pos:[0,2,0],state:1},
{pos:[1,2,0],state:1},
{pos:[2,2,0],state:1},
{pos:[3,2,0],state:1},
{pos:[4,2,0],state:1},
{pos:[5,2,0],state:1},
{pos:[6,2,0],state:1},
{pos:[7,2,0],state:1},
{pos:[8,2,0],state:1},
{pos:[9,2,0],state:1},
{pos:[10,2,0],state:1},
{pos:[11,2,0],state:1},
{pos:[12,2,0],state:1},
{pos:[13,2,0],state:1},
{pos:[14,2,0],state:1},
{pos:[15,2,0],state:1},
{pos:[16,2,0],state:1},
{pos:[17,2,0],state:1},
{pos:[18,2,0],state:1},
{pos:[19,2,0],state:1},
{pos:[20,2,0],state:1},
{pos:[21,2,0],state:1},
{pos:[22,2,0],state:1},
{pos:[23,2,0],state:1},
{pos:[24,2,0],state:1},
{pos:[25,2,0],state:1},
{pos:[26,2,0],state:1},
{pos:[27,2,0],state:1},
{pos:[28,2,0],state:1},
{pos:[29,2,0],state:1},
{pos:[30,2,0],state:1},
{pos:[0,2,1],state:1},
{pos:[1,2,1],state:1},
{pos:[2,2,1],state:1},
{pos:[3,2,1],state:1},
{pos:[4,2,1],state:1},
{pos:[5,2,1],state:1},
{pos:[6,2,1],state:1},
{pos:[7,2,1],state:1},
{pos:[8,2,1],state:1},
{pos:[9,2,1],state:1},
{pos:[10,2,1],state:1},
{pos:[11,2,1],state:1},
{pos:[12,2,1],state:1},
{pos:[13,2,1],state:1},
{pos:[14,2,1],state:1},
{pos:[15,2,1],state:1},
{pos:[16,2,1],state:1},
{pos:[17,2,1],state:1},
{pos:[18,2,1],state:1},
{pos:[19,2,1],state:1},
{pos:[20,2,1],state:1},
{pos:[21,2,1],state:1},
{pos:[22,2,1],state:1},
{pos:[23,2,1],state:1},
{pos:[24,2,1],state:1},
{pos:[25,2,1],state:1},
{pos:[26,2,1],state:1},
{pos:[27,2,1],state:1},
{pos:[28,2,1],state:1},
{pos:[29,2,1],state:1},
{pos:[30,2,1],state:1},
{pos:[0,2,2],state:1},
{pos:[1,2,2],state:1},
{pos:[4,2,2],state:0},
{pos:[11,2,2],state:0},
{pos:[18,2,2],state:0},
{pos:[25,2,2],state:0},
{pos:[29,2,2],state:1},
{pos:[30,2,2],state:1},
{pos:[0,2,3],state:1},
{pos:[1,2,3],state:1},
{pos:[29,2,3],state:1},
{pos:[30,2,3],state:1},
{pos:[0,2,4],state:1},
{pos:[1,2,4],state:1},
{pos:[29,2,4],state:1},
{pos:[30,2,4],state:1},
{pos:[0,2,5],state:1},
{pos:[1,2,5],state:1},
{pos:[2,2,5],state:0},
{pos:[28,2,5],state:0},
{pos:[29,2,5],state:1},
{pos:[30,2,5],state:1},
{pos:[0,2,6],state:1},
{pos:[1,2,6],state:1},
{pos:[29,2,6],state:1},
{pos:[30,2,6],state:1},
{pos:[0,2,7],state:1},
{pos:[1,2,7],state:1},
{pos:[29,2,7],state:1},
{pos:[30,2,7],state:1},
{pos:[0,2,8],state:1},
{pos:[1,2,8],state:1},
{pos:[29,2,8],state:1},
{pos:[30,2,8],state:1},
{pos:[0,2,9],state:1},
{pos:[1,2,9],state:1},
{pos:[29,2,9],state:1},
{pos:[30,2,9],state:1},
{pos:[0,2,10],state:1},
{pos:[1,2,10],state:1},
{pos:[29,2,10],state:1},
{pos:[30,2,10],state:1},
{pos:[0,2,11],state:1},
{pos:[1,2,11],state:1},
{pos:[29,2,11],state:1},
{pos:[30,2,11],state:1},
{pos:[11,2,12],state:0},
{pos:[12,2,12],state:0},
{pos:[13,2,12],state:0},
{pos:[14,2,12],state:0},
{pos:[15,2,12],state:0},
{pos:[16,2,12],state:0},
{pos:[17,2,12],state:0},
{pos:[18,2,12],state:0},
{pos:[19,2,12],state:0},
{pos:[29,2,12],state:1},
{pos:[30,2,12],state:1},
{pos:[2,2,13],state:0},
{pos:[11,2,13],state:0},
{pos:[12,2,13],state:0},
{pos:[13,2,13],state:0},
{pos:[14,2,13],state:0},
{pos:[15,2,13],state:0},
{pos:[16,2,13],state:0},
{pos:[17,2,13],state:0},
{pos:[18,2,13],state:0},
{pos:[19,2,13],state:0},
{pos:[28,2,13],state:0},
{pos:[29,2,13],state:1},
{pos:[30,2,13],state:1},
{pos:[11,2,14],state:0},
{pos:[12,2,14],state:0},
{pos:[13,2,14],state:0},
{pos:[14,2,14],state:0},
{pos:[15,2,14],state:0},
{pos:[16,2,14],state:0},
{pos:[17,2,14],state:0},
{pos:[18,2,14],state:0},
{pos:[19,2,14],state:0},
{pos:[29,2,14],state:1},
{pos:[30,2,14],state:1},
{pos:[11,2,15],state:0},
{pos:[12,2,15],state:0},
{pos:[13,2,15],state:0},
{pos:[14,2,15],state:0},
{pos:[15,2,15],state:0},
{pos:[16,2,15],state:0},
{pos:[17,2,15],state:0},
{pos:[18,2,15],state:0},
{pos:[19,2,15],state:0},
{pos:[29,2,15],state:1},
{pos:[30,2,15],state:1},
{pos:[11,2,16],state:0},
{pos:[12,2,16],state:0},
{pos:[13,2,16],state:0},
{pos:[14,2,16],state:0},
{pos:[15,2,16],state:0},
{pos:[16,2,16],state:0},
{pos:[17,2,16],state:0},
{pos:[18,2,16],state:0},
{pos:[19,2,16],state:0},
{pos:[29,2,16],state:1},
{pos:[30,2,16],state:1},
{pos:[0,2,17],state:1},
{pos:[1,2,17],state:1},
{pos:[11,2,17],state:0},
{pos:[12,2,17],state:0},
{pos:[13,2,17],state:0},
{pos:[14,2,17],state:0},
{pos:[15,2,17],state:0},
{pos:[16,2,17],state:0},
{pos:[17,2,17],state:0},
{pos:[18,2,17],state:0},
{pos:[19,2,17],state:0},
{pos:[29,2,17],state:1},
{pos:[30,2,17],state:1},
{pos:[0,2,18],state:1},
{pos:[1,2,18],state:1},
{pos:[11,2,18],state:0},
{pos:[12,2,18],state:0},
{pos:[13,2,18],state:0},
{pos:[14,2,18],state:0},
{pos:[15,2,18],state:0},
{pos:[16,2,18],state:0},
{pos:[17,2,18],state:0},
{pos:[18,2,18],state:0},
{pos:[19,2,18],state:0},
{pos:[29,2,18],state:1},
{pos:[30,2,18],state:1},
{pos:[0,2,19],state:1},
{pos:[1,2,19],state:1},
{pos:[29,2,19],state:1},
{pos:[30,2,19],state:1},
{pos:[0,2,20],state:1},
{pos:[1,2,20],state:1},
{pos:[29,2,20],state:1},
{pos:[30,2,20],state:1},
{pos:[0,2,21],state:1},
{pos:[1,2,21],state:1},
{pos:[2,2,21],state:0},
{pos:[28,2,21],state:0},
{pos:[29,2,21],state:1},
{pos:[30,2,21],state:1},
{pos:[0,2,22],state:1},
{pos:[1,2,22],state:1},
{pos:[29,2,22],state:1},
{pos:[30,2,22],state:1},
{pos:[0,2,23],state:1},
{pos:[1,2,23],state:1},
{pos:[29,2,23],state:1},
{pos:[30,2,23],state:1},
{pos:[0,2,24],state:1},
{pos:[1,2,24],state:1},
{pos:[29,2,24],state:1},
{pos:[30,2,24],state:1},
{pos:[0,2,25],state:1},
{pos:[1,2,25],state:1},
{pos:[29,2,25],state:1},
{pos:[30,2,25],state:1},
{pos:[0,2,26],state:1},
{pos:[1,2,26],state:1},
{pos:[29,2,26],state:1},
{pos:[30,2,26],state:1},
{pos:[0,2,27],state:1},
{pos:[1,2,27],state:1},
{pos:[29,2,27],state:1},
{pos:[30,2,27],state:1},
{pos:[0,2,28],state:1},
{pos:[1,2,28],state:1},
{pos:[4,2,28],state:0},
{pos:[11,2,28],state:0},
{pos:[18,2,28],state:0},
{pos:[25,2,28],state:0},
{pos:[29,2,28],state:1},
{pos:[30,2,28],state:1},
{pos:[0,2,29],state:1},
{pos:[1,2,29],state:1},
{pos:[2,2,29],state:1},
{pos:[3,2,29],state:1},
{pos:[4,2,29],state:1},
{pos:[5,2,29],state:1},
{pos:[6,2,29],state:1},
{pos:[7,2,29],state:1},
{pos:[8,2,29],state:1},
{pos:[9,2,29],state:1},
{pos:[10,2,29],state:1},
{pos:[11,2,29],state:1},
{pos:[12,2,29],state:1},
{pos:[13,2,29],state:1},
{pos:[14,2,29],state:1},
{pos:[15,2,29],state:1},
{pos:[16,2,29],state:1},
{pos:[17,2,29],state:1},
{pos:[18,2,29],state:1},
{pos:[19,2,29],state:1},
{pos:[20,2,29],state:1},
{pos:[21,2,29],state:1},
{pos:[22,2,29],state:1},
{pos:[23,2,29],state:1},
{pos:[24,2,29],state:1},
{pos:[25,2,29],state:1},
{pos:[26,2,29],state:1},
{pos:[27,2,29],state:1},
{pos:[28,2,29],state:1},
{pos:[29,2,29],state:1},
{pos:[30,2,29],state:1},
{pos:[0,2,30],state:1},
{pos:[1,2,30],state:1},
{pos:[2,2,30],state:1},
{pos:[3,2,30],state:1},
{pos:[4,2,30],state:1},
{pos:[5,2,30],state:1},
{pos:[6,2,30],state:1},
{pos:[7,2,30],state:1},
{pos:[8,2,30],state:1},
{pos:[9,2,30],state:1},
{pos:[10,2,30],state:1},
{pos:[11,2,30],state:1},
{pos:[12,2,30],state:1},
{pos:[13,2,30],state:1},
{pos:[14,2,30],state:1},
{pos:[15,2,30],state:1},
{pos:[16,2,30],state:1},
{pos:[17,2,30],state:1},
{pos:[18,2,30],state:1},
{pos:[19,2,30],state:1},
{pos:[20,2,30],state:1},
{pos:[21,2,30],state:1},
{pos:[22,2,30],state:1},
{pos:[23,2,30],state:1},
{pos:[24,2,30],state:1},
{pos:[25,2,30],state:1},
{pos:[26,2,30],state:1},
{pos:[27,2,30],state:1},
{pos:[28,2,30],state:1},
{pos:[29,2,30],state:1},
{pos:[30,2,30],state:1},
{pos:[0,3,0],state:1},
{pos:[1,3,0],state:1},
{pos:[2,3,0],state:1},
{pos:[3,3,0],state:1},
{pos:[4,3,0],state:1},
{pos:[5,3,0],state:1},
{pos:[6,3,0],state:1},
{pos:[7,3,0],state:1},
{pos:[8,3,0],state:1},
{pos:[9,3,0],state:1},
{pos:[10,3,0],state:1},
{pos:[11,3,0],state:1},
{pos:[12,3,0],state:1},
{pos:[13,3,0],state:1},
{pos:[14,3,0],state:1},
{pos:[15,3,0],state:1},
{pos:[16,3,0],state:1},
{pos:[17,3,0],state:1},
{pos:[18,3,0],state:1},
{pos:[19,3,0],state:1},
{pos:[20,3,0],state:1},
{pos:[21,3,0],state:1},
{pos:[22,3,0],state:1},
{pos:[23,3,0],state:1},
{pos:[24,3,0],state:1},
{pos:[25,3,0],state:1},
{pos:[26,3,0],state:1},
{pos:[27,3,0],state:1},
{pos:[28,3,0],state:1},
{pos:[29,3,0],state:1},
{pos:[30,3,0],state:1},
{pos:[0,3,1],state:1},
{pos:[1,3,1],state:1},
{pos:[2,3,1],state:1},
{pos:[3,3,1],state:1},
{pos:[4,3,1],state:1},
{pos:[5,3,1],state:1},
{pos:[6,3,1],state:1},
{pos:[7,3,1],state:1},
{pos:[8,3,1],state:1},
{pos:[9,3,1],state:1},
{pos:[10,3,1],state:1},
{pos:[11,3,1],state:1},
{pos:[12,3,1],state:1},
{pos:[13,3,1],state:1},
{pos:[14,3,1],state:1},
{pos:[15,3,1],state:1},
{pos:[16,3,1],state:1},
{pos:[17,3,1],state:1},
{pos:[18,3,1],state:1},
{pos:[19,3,1],state:1},
{pos:[20,3,1],state:1},
{pos:[21,3,1],state:1},
{pos:[22,3,1],state:1},
{pos:[23,3,1],state:1},
{pos:[24,3,1],state:1},
{pos:[25,3,1],state:1},
{pos:[26,3,1],state:1},
{pos:[27,3,1],state:1},
{pos:[28,3,1],state:1},
{pos:[29,3,1],state:1},
{pos:[30,3,1],state:1},
{pos:[0,3,2],state:1},
{pos:[1,3,2],state:1},
{pos:[4,3,2],state:0},
{pos:[11,3,2],state:0},
{pos:[18,3,2],state:0},
{pos:[25,3,2],state:0},
{pos:[29,3,2],state:1},
{pos:[30,3,2],state:1},
{pos:[0,3,3],state:1},
{pos:[1,3,3],state:1},
{pos:[29,3,3],state:1},
{pos:[30,3,3],state:1},
{pos:[0,3,4],state:1},
{pos:[1,3,4],state:1},
{pos:[29,3,4],state:1},
{pos:[30,3,4],state:1},
{pos:[0,3,5],state:1},
{pos:[1,3,5],state:1},
{pos:[2,3,5],state:0},
{pos:[28,3,5],state:0},
{pos:[29,3,5],state:1},
{pos:[30,3,5],state:1},
{pos:[0,3,6],state:1},
{pos:[1,3,6],state:1},
{pos:[29,3,6],state:1},
{pos:[30,3,6],state:1},
{pos:[0,3,7],state:1},
{pos:[1,3,7],state:1},
{pos:[29,3,7],state:1},
{pos:[30,3,7],state:1},
{pos:[0,3,8],state:1},
{pos:[1,3,8],state:1},
{pos:[29,3,8],state:1},
{pos:[30,3,8],state:1},
{pos:[0,3,9],state:1},
{pos:[1,3,9],state:1},
{pos:[29,3,9],state:1},
{pos:[30,3,9],state:1},
{pos:[0,3,10],state:1},
{pos:[1,3,10],state:1},
{pos:[29,3,10],state:1},
{pos:[30,3,10],state:1},
{pos:[0,3,11],state:1},
{pos:[1,3,11],state:1},
{pos:[29,3,11],state:1},
{pos:[30,3,11],state:1},
{pos:[11,3,12],state:0},
{pos:[12,3,12],state:0},
{pos:[13,3,12],state:0},
{pos:[14,3,12],state:0},
{pos:[15,3,12],state:0},
{pos:[16,3,12],state:0},
{pos:[17,3,12],state:0},
{pos:[18,3,12],state:0},
{pos:[19,3,12],state:0},
{pos:[29,3,12],state:1},
{pos:[30,3,12],state:1},
{pos:[2,3,13],state:0},
{pos:[11,3,13],state:0},
{pos:[12,3,13],state:0},
{pos:[13,3,13],state:0},
{pos:[14,3,13],state:0},
{pos:[15,3,13],state:0},
{pos:[16,3,13],state:0},
{pos:[17,3,13],state:0},
{pos:[18,3,13],state:0},
{pos:[19,3,13],state:0},
{pos:[28,3,13],state:0},
{pos:[29,3,13],state:1},
{pos:[30,3,13],state:1},
{pos:[11,3,14],state:0},
{pos:[12,3,14],state:0},
{pos:[13,3,14],state:0},
{pos:[14,3,14],state:0},
{pos:[15,3,14],state:0},
{pos:[16,3,14],state:0},
{pos:[17,3,14],state:0},
{pos:[18,3,14],state:0},
{pos:[19,3,14],state:0},
{pos:[29,3,14],state:1},
{pos:[30,3,14],state:1},
{pos:[11,3,15],state:0},
{pos:[12,3,15],state:0},
{pos:[13,3,15],state:0},
{pos:[14,3,15],state:0},
{pos:[15,3,15],state:0},
{pos:[16,3,15],state:0},
{pos:[17,3,15],state:0},
{pos:[18,3,15],state:0},
{pos:[19,3,15],state:0},
{pos:[29,3,15],state:1},
{pos:[30,3,15],state:1},
{pos:[11,3,16],state:0},
{pos:[12,3,16],state:0},
{pos:[13,3,16],state:0},
{pos:[14,3,16],state:0},
{pos:[15,3,16],state:0},
{pos:[16,3,16],state:0},
{pos:[17,3,16],state:0},
{pos:[18,3,16],state:0},
{pos:[19,3,16],state:0},
{pos:[29,3,16],state:1},
{pos:[30,3,16],state:1},
{pos:[0,3,17],state:1},
{pos:[1,3,17],state:1},
{pos:[11,3,17],state:0},
{pos:[12,3,17],state:0},
{pos:[13,3,17],state:0},
{pos:[14,3,17],state:0},
{pos:[15,3,17],state:0},
{pos:[16,3,17],state:0},
{pos:[17,3,17],state:0},
{pos:[18,3,17],state:0},
{pos:[19,3,17],state:0},
{pos:[29,3,17],state:1},
{pos:[30,3,17],state:1},
{pos:[0,3,18],state:1},
{pos:[1,3,18],state:1},
{pos:[11,3,18],state:0},
{pos:[12,3,18],state:0},
{pos:[13,3,18],state:0},
{pos:[14,3,18],state:0},
{pos:[15,3,18],state:0},
{pos:[16,3,18],state:0},
{pos:[17,3,18],state:0},
{pos:[18,3,18],state:0},
{pos:[19,3,18],state:0},
{pos:[29,3,18],state:1},
{pos:[30,3,18],state:1},
{pos:[0,3,19],state:1},
{pos:[1,3,19],state:1},
{pos:[29,3,19],state:1},
{pos:[30,3,19],state:1},
{pos:[0,3,20],state:1},
{pos:[1,3,20],state:1},
{pos:[29,3,20],state:1},
{pos:[30,3,20],state:1},
{pos:[0,3,21],state:1},
{pos:[1,3,21],state:1},
{pos:[2,3,21],state:0},
{pos:[28,3,21],state:0},
{pos:[29,3,21],state:1},
{pos:[30,3,21],state:1},
{pos:[0,3,22],state:1},
{pos:[1,3,22],state:1},
{pos:[29,3,22],state:1},
{pos:[30,3,22],state:1},
{pos:[0,3,23],state:1},
{pos:[1,3,23],state:1},
{pos:[29,3,23],state:1},
{pos:[30,3,23],state:1},
{pos:[0,3,24],state:1},
{pos:[1,3,24],state:1},
{pos:[29,3,24],state:1},
{pos:[30,3,24],state:1},
{pos:[0,3,25],state:1},
{pos:[1,3,25],state:1},
{pos:[29,3,25],state:1},
{pos:[30,3,25],state:1},
{pos:[0,3,26],state:1},
{pos:[1,3,26],state:1},
{pos:[29,3,26],state:1},
{pos:[30,3,26],state:1},
{pos:[0,3,27],state:1},
{pos:[1,3,27],state:1},
{pos:[29,3,27],state:1},
{pos:[30,3,27],state:1},
{pos:[0,3,28],state:1},
{pos:[1,3,28],state:1},
{pos:[4,3,28],state:0},
{pos:[11,3,28],state:0},
{pos:[18,3,28],state:0},
{pos:[25,3,28],state:0},
{pos:[29,3,28],state:1},
{pos:[30,3,28],state:1},
{pos:[0,3,29],state:1},
{pos:[1,3,29],state:1},
{pos:[2,3,29],state:1},
{pos:[3,3,29],state:1},
{pos:[4,3,29],state:1},
{pos:[5,3,29],state:1},
{pos:[6,3,29],state:1},
{pos:[7,3,29],state:1},
{pos:[8,3,29],state:1},
{pos:[9,3,29],state:1},
{pos:[10,3,29],state:1},
{pos:[11,3,29],state:1},
{pos:[12,3,29],state:1},
{pos:[13,3,29],state:1},
{pos:[14,3,29],state:1},
{pos:[15,3,29],state:1},
{pos:[16,3,29],state:1},
{pos:[17,3,29],state:1},
{pos:[18,3,29],state:1},
{pos:[19,3,29],state:1},
{pos:[20,3,29],state:1},
{pos:[21,3,29],state:1},
{pos:[22,3,29],state:1},
{pos:[23,3,29],state:1},
{pos:[24,3,29],state:1},
{pos:[25,3,29],state:1},
{pos:[26,3,29],state:1},
{pos:[27,3,29],state:1},
{pos:[28,3,29],state:1},
{pos:[29,3,29],state:1},
{pos:[30,3,29],state:1},
{pos:[0,3,30],state:1},
{pos:[1,3,30],state:1},
{pos:[2,3,30],state:1},
{pos:[3,3,30],state:1},
{pos:[4,3,30],state:1},
{pos:[5,3,30],state:1},
{pos:[6,3,30],state:1},
{pos:[7,3,30],state:1},
{pos:[8,3,30],state:1},
{pos:[9,3,30],state:1},
{pos:[10,3,30],state:1},
{pos:[11,3,30],state:1},
{pos:[12,3,30],state:1},
{pos:[13,3,30],state:1},
{pos:[14,3,30],state:1},
{pos:[15,3,30],state:1},
{pos:[16,3,30],state:1},
{pos:[17,3,30],state:1},
{pos:[18,3,30],state:1},
{pos:[19,3,30],state:1},
{pos:[20,3,30],state:1},
{pos:[21,3,30],state:1},
{pos:[22,3,30],state:1},
{pos:[23,3,30],state:1},
{pos:[24,3,30],state:1},
{pos:[25,3,30],state:1},
{pos:[26,3,30],state:1},
{pos:[27,3,30],state:1},
{pos:[28,3,30],state:1},
{pos:[29,3,30],state:1},
{pos:[30,3,30],state:1},
{pos:[0,4,0],state:1},
{pos:[1,4,0],state:1},
{pos:[2,4,0],state:1},
{pos:[3,4,0],state:1},
{pos:[4,4,0],state:1},
{pos:[5,4,0],state:1},
{pos:[6,4,0],state:1},
{pos:[7,4,0],state:1},
{pos:[8,4,0],state:1},
{pos:[9,4,0],state:1},
{pos:[10,4,0],state:1},
{pos:[11,4,0],state:1},
{pos:[12,4,0],state:1},
{pos:[13,4,0],state:1},
{pos:[14,4,0],state:1},
{pos:[15,4,0],state:1},
{pos:[16,4,0],state:1},
{pos:[17,4,0],state:1},
{pos:[18,4,0],state:1},
{pos:[19,4,0],state:1},
{pos:[20,4,0],state:1},
{pos:[21,4,0],state:1},
{pos:[22,4,0],state:1},
{pos:[23,4,0],state:1},
{pos:[24,4,0],state:1},
{pos:[25,4,0],state:1},
{pos:[26,4,0],state:1},
{pos:[27,4,0],state:1},
{pos:[28,4,0],state:1},
{pos:[29,4,0],state:1},
{pos:[30,4,0],state:1},
{pos:[0,4,1],state:1},
{pos:[1,4,1],state:1},
{pos:[2,4,1],state:1},
{pos:[3,4,1],state:1},
{pos:[4,4,1],state:1},
{pos:[5,4,1],state:1},
{pos:[6,4,1],state:1},
{pos:[7,4,1],state:1},
{pos:[8,4,1],state:1},
{pos:[9,4,1],state:1},
{pos:[10,4,1],state:1},
{pos:[11,4,1],state:1},
{pos:[12,4,1],state:1},
{pos:[13,4,1],state:1},
{pos:[14,4,1],state:1},
{pos:[15,4,1],state:1},
{pos:[16,4,1],state:1},
{pos:[17,4,1],state:1},
{pos:[18,4,1],state:1},
{pos:[19,4,1],state:1},
{pos:[20,4,1],state:1},
{pos:[21,4,1],state:1},
{pos:[22,4,1],state:1},
{pos:[23,4,1],state:1},
{pos:[24,4,1],state:1},
{pos:[25,4,1],state:1},
{pos:[26,4,1],state:1},
{pos:[27,4,1],state:1},
{pos:[28,4,1],state:1},
{pos:[29,4,1],state:1},
{pos:[30,4,1],state:1},
{pos:[0,4,2],state:1},
{pos:[1,4,2],state:1},
{pos:[4,4,2],state:0},
{pos:[11,4,2],state:0},
{pos:[18,4,2],state:0},
{pos:[25,4,2],state:0},
{pos:[29,4,2],state:1},
{pos:[30,4,2],state:1},
{pos:[0,4,3],state:1},
{pos:[1,4,3],state:1},
{pos:[29,4,3],state:1},
{pos:[30,4,3],state:1},
{pos:[0,4,4],state:1},
{pos:[1,4,4],state:1},
{pos:[29,4,4],state:1},
{pos:[30,4,4],state:1},
{pos:[0,4,5],state:1},
{pos:[1,4,5],state:1},
{pos:[2,4,5],state:0},
{pos:[28,4,5],state:0},
{pos:[29,4,5],state:1},
{pos:[30,4,5],state:1},
{pos:[0,4,6],state:1},
{pos:[1,4,6],state:1},
{pos:[29,4,6],state:1},
{pos:[30,4,6],state:1},
{pos:[0,4,7],state:1},
{pos:[1,4,7],state:1},
{pos:[29,4,7],state:1},
{pos:[30,4,7],state:1},
{pos:[0,4,8],state:1},
{pos:[1,4,8],state:1},
{pos:[29,4,8],state:1},
{pos:[30,4,8],state:1},
{pos:[0,4,9],state:1},
{pos:[1,4,9],state:1},
{pos:[29,4,9],state:1},
{pos:[30,4,9],state:1},
{pos:[0,4,10],state:1},
{pos:[1,4,10],state:1},
{pos:[29,4,10],state:1},
{pos:[30,4,10],state:1},
{pos:[0,4,11],state:1},
{pos:[1,4,11],state:1},
{pos:[29,4,11],state:1},
{pos:[30,4,11],state:1},
{pos:[29,4,12],state:1},
{pos:[30,4,12],state:1},
{pos:[2,4,13],state:0},
{pos:[28,4,13],state:0},
{pos:[29,4,13],state:1},
{pos:[30,4,13],state:1},
{pos:[15,4,14],state:4,nbt:{mode:"DATA",metadata:"reward"}},
{pos:[29,4,14],state:1},
{pos:[30,4,14],state:1},
{pos:[29,4,15],state:1},
{pos:[30,4,15],state:1},
{pos:[29,4,16],state:1},
{pos:[30,4,16],state:1},
{pos:[0,4,17],state:1},
{pos:[1,4,17],state:1},
{pos:[29,4,17],state:1},
{pos:[30,4,17],state:1},
{pos:[0,4,18],state:1},
{pos:[1,4,18],state:1},
{pos:[29,4,18],state:1},
{pos:[30,4,18],state:1},
{pos:[0,4,19],state:1},
{pos:[1,4,19],state:1},
{pos:[29,4,19],state:1},
{pos:[30,4,19],state:1},
{pos:[0,4,20],state:1},
{pos:[1,4,20],state:1},
{pos:[29,4,20],state:1},
{pos:[30,4,20],state:1},
{pos:[0,4,21],state:1},
{pos:[1,4,21],state:1},
{pos:[2,4,21],state:0},
{pos:[28,4,21],state:0},
{pos:[29,4,21],state:1},
{pos:[30,4,21],state:1},
{pos:[0,4,22],state:1},
{pos:[1,4,22],state:1},
{pos:[29,4,22],state:1},
{pos:[30,4,22],state:1},
{pos:[0,4,23],state:1},
{pos:[1,4,23],state:1},
{pos:[29,4,23],state:1},
{pos:[30,4,23],state:1},
{pos:[0,4,24],state:1},
{pos:[1,4,24],state:1},
{pos:[29,4,24],state:1},
{pos:[30,4,24],state:1},
{pos:[0,4,25],state:1},
{pos:[1,4,25],state:1},
{pos:[29,4,25],state:1},
{pos:[30,4,25],state:1},
{pos:[0,4,26],state:1},
{pos:[1,4,26],state:1},
{pos:[29,4,26],state:1},
{pos:[30,4,26],state:1},
{pos:[0,4,27],state:1},
{pos:[1,4,27],state:1},
{pos:[29,4,27],state:1},
{pos:[30,4,27],state:1},
{pos:[0,4,28],state:1},
{pos:[1,4,28],state:1},
{pos:[4,4,28],state:0},
{pos:[11,4,28],state:0},
{pos:[18,4,28],state:0},
{pos:[25,4,28],state:0},
{pos:[29,4,28],state:1},
{pos:[30,4,28],state:1},
{pos:[0,4,29],state:1},
{pos:[1,4,29],state:1},
{pos:[2,4,29],state:1},
{pos:[3,4,29],state:1},
{pos:[4,4,29],state:1},
{pos:[5,4,29],state:1},
{pos:[6,4,29],state:1},
{pos:[7,4,29],state:1},
{pos:[8,4,29],state:1},
{pos:[9,4,29],state:1},
{pos:[10,4,29],state:1},
{pos:[11,4,29],state:1},
{pos:[12,4,29],state:1},
{pos:[13,4,29],state:1},
{pos:[14,4,29],state:1},
{pos:[15,4,29],state:1},
{pos:[16,4,29],state:1},
{pos:[17,4,29],state:1},
{pos:[18,4,29],state:1},
{pos:[19,4,29],state:1},
{pos:[20,4,29],state:1},
{pos:[21,4,29],state:1},
{pos:[22,4,29],state:1},
{pos:[23,4,29],state:1},
{pos:[24,4,29],state:1},
{pos:[25,4,29],state:1},
{pos:[26,4,29],state:1},
{pos:[27,4,29],state:1},
{pos:[28,4,29],state:1},
{pos:[29,4,29],state:1},
{pos:[30,4,29],state:1},
{pos:[0,4,30],state:1},
{pos:[1,4,30],state:1},
{pos:[2,4,30],state:1},
{pos:[3,4,30],state:1},
{pos:[4,4,30],state:1},
{pos:[5,4,30],state:1},
{pos:[6,4,30],state:1},
{pos:[7,4,30],state:1},
{pos:[8,4,30],state:1},
{pos:[9,4,30],state:1},
{pos:[10,4,30],state:1},
{pos:[11,4,30],state:1},
{pos:[12,4,30],state:1},
{pos:[13,4,30],state:1},
{pos:[14,4,30],state:1},
{pos:[15,4,30],state:1},
{pos:[16,4,30],state:1},
{pos:[17,4,30],state:1},
{pos:[18,4,30],state:1},
{pos:[19,4,30],state:1},
{pos:[20,4,30],state:1},
{pos:[21,4,30],state:1},
{pos:[22,4,30],state:1},
{pos:[23,4,30],state:1},
{pos:[24,4,30],state:1},
{pos:[25,4,30],state:1},
{pos:[26,4,30],state:1},
{pos:[27,4,30],state:1},
{pos:[28,4,30],state:1},
{pos:[29,4,30],state:1},
{pos:[30,4,30],state:1},
{pos:[0,5,0],state:1},
{pos:[1,5,0],state:1},
{pos:[2,5,0],state:1},
{pos:[3,5,0],state:1},
{pos:[4,5,0],state:1},
{pos:[5,5,0],state:1},
{pos:[6,5,0],state:1},
{pos:[7,5,0],state:1},
{pos:[8,5,0],state:1},
{pos:[9,5,0],state:1},
{pos:[10,5,0],state:1},
{pos:[11,5,0],state:1},
{pos:[12,5,0],state:1},
{pos:[13,5,0],state:1},
{pos:[14,5,0],state:1},
{pos:[15,5,0],state:1},
{pos:[16,5,0],state:1},
{pos:[17,5,0],state:1},
{pos:[18,5,0],state:1},
{pos:[19,5,0],state:1},
{pos:[20,5,0],state:1},
{pos:[21,5,0],state:1},
{pos:[22,5,0],state:1},
{pos:[23,5,0],state:1},
{pos:[24,5,0],state:1},
{pos:[25,5,0],state:1},
{pos:[26,5,0],state:1},
{pos:[27,5,0],state:1},
{pos:[28,5,0],state:1},
{pos:[29,5,0],state:1},
{pos:[30,5,0],state:1},
{pos:[0,5,1],state:1},
{pos:[1,5,1],state:1},
{pos:[2,5,1],state:1},
{pos:[3,5,1],state:1},
{pos:[4,5,1],state:1},
{pos:[5,5,1],state:1},
{pos:[6,5,1],state:1},
{pos:[7,5,1],state:1},
{pos:[8,5,1],state:1},
{pos:[9,5,1],state:1},
{pos:[10,5,1],state:1},
{pos:[11,5,1],state:1},
{pos:[12,5,1],state:1},
{pos:[13,5,1],state:1},
{pos:[14,5,1],state:1},
{pos:[15,5,1],state:1},
{pos:[16,5,1],state:1},
{pos:[17,5,1],state:1},
{pos:[18,5,1],state:1},
{pos:[19,5,1],state:1},
{pos:[20,5,1],state:1},
{pos:[21,5,1],state:1},
{pos:[22,5,1],state:1},
{pos:[23,5,1],state:1},
{pos:[24,5,1],state:1},
{pos:[25,5,1],state:1},
{pos:[26,5,1],state:1},
{pos:[27,5,1],state:1},
{pos:[28,5,1],state:1},
{pos:[29,5,1],state:1},
{pos:[30,5,1],state:1},
{pos:[0,5,2],state:1},
{pos:[1,5,2],state:1},
{pos:[4,5,2],state:0},
{pos:[11,5,2],state:0},
{pos:[18,5,2],state:0},
{pos:[25,5,2],state:0},
{pos:[29,5,2],state:1},
{pos:[30,5,2],state:1},
{pos:[0,5,3],state:1},
{pos:[1,5,3],state:1},
{pos:[29,5,3],state:1},
{pos:[30,5,3],state:1},
{pos:[0,5,4],state:1},
{pos:[1,5,4],state:1},
{pos:[29,5,4],state:1},
{pos:[30,5,4],state:1},
{pos:[0,5,5],state:1},
{pos:[1,5,5],state:1},
{pos:[2,5,5],state:0},
{pos:[28,5,5],state:0},
{pos:[29,5,5],state:1},
{pos:[30,5,5],state:1},
{pos:[0,5,6],state:1},
{pos:[1,5,6],state:1},
{pos:[29,5,6],state:1},
{pos:[30,5,6],state:1},
{pos:[0,5,7],state:1},
{pos:[1,5,7],state:1},
{pos:[29,5,7],state:1},
{pos:[30,5,7],state:1},
{pos:[0,5,8],state:1},
{pos:[1,5,8],state:1},
{pos:[29,5,8],state:1},
{pos:[30,5,8],state:1},
{pos:[0,5,9],state:1},
{pos:[1,5,9],state:1},
{pos:[29,5,9],state:1},
{pos:[30,5,9],state:1},
{pos:[0,5,10],state:1},
{pos:[1,5,10],state:1},
{pos:[29,5,10],state:1},
{pos:[30,5,10],state:1},
{pos:[0,5,11],state:1},
{pos:[1,5,11],state:1},
{pos:[29,5,11],state:1},
{pos:[30,5,11],state:1},
{pos:[29,5,12],state:1},
{pos:[30,5,12],state:1},
{pos:[2,5,13],state:0},
{pos:[28,5,13],state:0},
{pos:[29,5,13],state:1},
{pos:[30,5,13],state:1},
{pos:[29,5,14],state:1},
{pos:[30,5,14],state:1},
{pos:[29,5,15],state:1},
{pos:[30,5,15],state:1},
{pos:[29,5,16],state:1},
{pos:[30,5,16],state:1},
{pos:[0,5,17],state:1},
{pos:[1,5,17],state:1},
{pos:[29,5,17],state:1},
{pos:[30,5,17],state:1},
{pos:[0,5,18],state:1},
{pos:[1,5,18],state:1},
{pos:[29,5,18],state:1},
{pos:[30,5,18],state:1},
{pos:[0,5,19],state:1},
{pos:[1,5,19],state:1},
{pos:[29,5,19],state:1},
{pos:[30,5,19],state:1},
{pos:[0,5,20],state:1},
{pos:[1,5,20],state:1},
{pos:[29,5,20],state:1},
{pos:[30,5,20],state:1},
{pos:[0,5,21],state:1},
{pos:[1,5,21],state:1},
{pos:[2,5,21],state:0},
{pos:[28,5,21],state:0},
{pos:[29,5,21],state:1},
{pos:[30,5,21],state:1},
{pos:[0,5,22],state:1},
{pos:[1,5,22],state:1},
{pos:[29,5,22],state:1},
{pos:[30,5,22],state:1},
{pos:[0,5,23],state:1},
{pos:[1,5,23],state:1},
{pos:[29,5,23],state:1},
{pos:[30,5,23],state:1},
{pos:[0,5,24],state:1},
{pos:[1,5,24],state:1},
{pos:[29,5,24],state:1},
{pos:[30,5,24],state:1},
{pos:[0,5,25],state:1},
{pos:[1,5,25],state:1},
{pos:[29,5,25],state:1},
{pos:[30,5,25],state:1},
{pos:[0,5,26],state:1},
{pos:[1,5,26],state:1},
{pos:[29,5,26],state:1},
{pos:[30,5,26],state:1},
{pos:[0,5,27],state:1},
{pos:[1,5,27],state:1},
{pos:[29,5,27],state:1},
{pos:[30,5,27],state:1},
{pos:[0,5,28],state:1},
{pos:[1,5,28],state:1},
{pos:[4,5,28],state:0},
{pos:[11,5,28],state:0},
{pos:[18,5,28],state:0},
{pos:[25,5,28],state:0},
{pos:[29,5,28],state:1},
{pos:[30,5,28],state:1},
{pos:[0,5,29],state:1},
{pos:[1,5,29],state:1},
{pos:[2,5,29],state:1},
{pos:[3,5,29],state:1},
{pos:[4,5,29],state:1},
{pos:[5,5,29],state:1},
{pos:[6,5,29],state:1},
{pos:[7,5,29],state:1},
{pos:[8,5,29],state:1},
{pos:[9,5,29],state:1},
{pos:[10,5,29],state:1},
{pos:[11,5,29],state:1},
{pos:[12,5,29],state:1},
{pos:[13,5,29],state:1},
{pos:[14,5,29],state:1},
{pos:[15,5,29],state:1},
{pos:[16,5,29],state:1},
{pos:[17,5,29],state:1},
{pos:[18,5,29],state:1},
{pos:[19,5,29],state:1},
{pos:[20,5,29],state:1},
{pos:[21,5,29],state:1},
{pos:[22,5,29],state:1},
{pos:[23,5,29],state:1},
{pos:[24,5,29],state:1},
{pos:[25,5,29],state:1},
{pos:[26,5,29],state:1},
{pos:[27,5,29],state:1},
{pos:[28,5,29],state:1},
{pos:[29,5,29],state:1},
{pos:[30,5,29],state:1},
{pos:[0,5,30],state:1},
{pos:[1,5,30],state:1},
{pos:[2,5,30],state:1},
{pos:[3,5,30],state:1},
{pos:[4,5,30],state:1},
{pos:[5,5,30],state:1},
{pos:[6,5,30],state:1},
{pos:[7,5,30],state:1},
{pos:[8,5,30],state:1},
{pos:[9,5,30],state:1},
{pos:[10,5,30],state:1},
{pos:[11,5,30],state:1},
{pos:[12,5,30],state:1},
{pos:[13,5,30],state:1},
{pos:[14,5,30],state:1},
{pos:[15,5,30],state:1},
{pos:[16,5,30],state:1},
{pos:[17,5,30],state:1},
{pos:[18,5,30],state:1},
{pos:[19,5,30],state:1},
{pos:[20,5,30],state:1},
{pos:[21,5,30],state:1},
{pos:[22,5,30],state:1},
{pos:[23,5,30],state:1},
{pos:[24,5,30],state:1},
{pos:[25,5,30],state:1},
{pos:[26,5,30],state:1},
{pos:[27,5,30],state:1},
{pos:[28,5,30],state:1},
{pos:[29,5,30],state:1},
{pos:[30,5,30],state:1},
{pos:[0,6,0],state:1},
{pos:[1,6,0],state:1},
{pos:[2,6,0],state:1},
{pos:[3,6,0],state:1},
{pos:[4,6,0],state:1},
{pos:[5,6,0],state:1},
{pos:[6,6,0],state:1},
{pos:[7,6,0],state:1},
{pos:[8,6,0],state:1},
{pos:[9,6,0],state:1},
{pos:[10,6,0],state:1},
{pos:[11,6,0],state:1},
{pos:[12,6,0],state:1},
{pos:[13,6,0],state:1},
{pos:[14,6,0],state:1},
{pos:[15,6,0],state:1},
{pos:[16,6,0],state:1},
{pos:[17,6,0],state:1},
{pos:[18,6,0],state:1},
{pos:[19,6,0],state:1},
{pos:[20,6,0],state:1},
{pos:[21,6,0],state:1},
{pos:[22,6,0],state:1},
{pos:[23,6,0],state:1},
{pos:[24,6,0],state:1},
{pos:[25,6,0],state:1},
{pos:[26,6,0],state:1},
{pos:[27,6,0],state:1},
{pos:[28,6,0],state:1},
{pos:[29,6,0],state:1},
{pos:[30,6,0],state:1},
{pos:[0,6,1],state:1},
{pos:[1,6,1],state:1},
{pos:[2,6,1],state:1},
{pos:[3,6,1],state:1},
{pos:[4,6,1],state:1},
{pos:[5,6,1],state:1},
{pos:[6,6,1],state:1},
{pos:[7,6,1],state:1},
{pos:[8,6,1],state:1},
{pos:[9,6,1],state:1},
{pos:[10,6,1],state:1},
{pos:[11,6,1],state:1},
{pos:[12,6,1],state:1},
{pos:[13,6,1],state:1},
{pos:[14,6,1],state:1},
{pos:[15,6,1],state:1},
{pos:[16,6,1],state:1},
{pos:[17,6,1],state:1},
{pos:[18,6,1],state:1},
{pos:[19,6,1],state:1},
{pos:[20,6,1],state:1},
{pos:[21,6,1],state:1},
{pos:[22,6,1],state:1},
{pos:[23,6,1],state:1},
{pos:[24,6,1],state:1},
{pos:[25,6,1],state:1},
{pos:[26,6,1],state:1},
{pos:[27,6,1],state:1},
{pos:[28,6,1],state:1},
{pos:[29,6,1],state:1},
{pos:[30,6,1],state:1},
{pos:[0,6,2],state:1},
{pos:[1,6,2],state:1},
{pos:[29,6,2],state:1},
{pos:[30,6,2],state:1},
{pos:[0,6,3],state:1},
{pos:[1,6,3],state:1},
{pos:[3,6,3],state:2},
{pos:[27,6,3],state:2},
{pos:[29,6,3],state:1},
{pos:[30,6,3],state:1},
{pos:[0,6,4],state:1},
{pos:[1,6,4],state:1},
{pos:[29,6,4],state:1},
{pos:[30,6,4],state:1},
{pos:[0,6,5],state:1},
{pos:[1,6,5],state:1},
{pos:[29,6,5],state:1},
{pos:[30,6,5],state:1},
{pos:[0,6,6],state:1},
{pos:[1,6,6],state:1},
{pos:[29,6,6],state:1},
{pos:[30,6,6],state:1},
{pos:[0,6,7],state:1},
{pos:[1,6,7],state:1},
{pos:[29,6,7],state:1},
{pos:[30,6,7],state:1},
{pos:[0,6,8],state:1},
{pos:[1,6,8],state:1},
{pos:[29,6,8],state:1},
{pos:[30,6,8],state:1},
{pos:[0,6,9],state:1},
{pos:[1,6,9],state:1},
{pos:[29,6,9],state:1},
{pos:[30,6,9],state:1},
{pos:[0,6,10],state:1},
{pos:[1,6,10],state:1},
{pos:[29,6,10],state:1},
{pos:[30,6,10],state:1},
{pos:[0,6,11],state:1},
{pos:[1,6,11],state:1},
{pos:[29,6,11],state:1},
{pos:[30,6,11],state:1},
{pos:[0,6,12],state:1},
{pos:[1,6,12],state:1},
{pos:[29,6,12],state:1},
{pos:[30,6,12],state:1},
{pos:[0,6,13],state:1},
{pos:[1,6,13],state:1},
{pos:[29,6,13],state:1},
{pos:[30,6,13],state:1},
{pos:[0,6,14],state:1},
{pos:[1,6,14],state:1},
{pos:[15,6,14],state:4,nbt:{mode:"DATA",metadata:"audio:reward"}},
{pos:[29,6,14],state:1},
{pos:[30,6,14],state:1},
{pos:[0,6,15],state:1},
{pos:[1,6,15],state:1},
{pos:[29,6,15],state:1},
{pos:[30,6,15],state:1},
{pos:[0,6,16],state:1},
{pos:[1,6,16],state:1},
{pos:[29,6,16],state:1},
{pos:[30,6,16],state:1},
{pos:[0,6,17],state:1},
{pos:[1,6,17],state:1},
{pos:[29,6,17],state:1},
{pos:[30,6,17],state:1},
{pos:[0,6,18],state:1},
{pos:[1,6,18],state:1},
{pos:[29,6,18],state:1},
{pos:[30,6,18],state:1},
{pos:[0,6,19],state:1},
{pos:[1,6,19],state:1},
{pos:[29,6,19],state:1},
{pos:[30,6,19],state:1},
{pos:[0,6,20],state:1},
{pos:[1,6,20],state:1},
{pos:[29,6,20],state:1},
{pos:[30,6,20],state:1},
{pos:[0,6,21],state:1},
{pos:[1,6,21],state:1},
{pos:[29,6,21],state:1},
{pos:[30,6,21],state:1},
{pos:[0,6,22],state:1},
{pos:[1,6,22],state:1},
{pos:[29,6,22],state:1},
{pos:[30,6,22],state:1},
{pos:[0,6,23],state:1},
{pos:[1,6,23],state:1},
{pos:[29,6,23],state:1},
{pos:[30,6,23],state:1},
{pos:[0,6,24],state:1},
{pos:[1,6,24],state:1},
{pos:[29,6,24],state:1},
{pos:[30,6,24],state:1},
{pos:[0,6,25],state:1},
{pos:[1,6,25],state:1},
{pos:[29,6,25],state:1},
{pos:[30,6,25],state:1},
{pos:[0,6,26],state:1},
{pos:[1,6,26],state:1},
{pos:[29,6,26],state:1},
{pos:[30,6,26],state:1},
{pos:[0,6,27],state:1},
{pos:[1,6,27],state:1},
{pos:[3,6,27],state:2},
{pos:[27,6,27],state:2},
{pos:[29,6,27],state:1},
{pos:[30,6,27],state:1},
{pos:[0,6,28],state:1},
{pos:[1,6,28],state:1},
{pos:[29,6,28],state:1},
{pos:[30,6,28],state:1},
{pos:[0,6,29],state:1},
{pos:[1,6,29],state:1},
{pos:[2,6,29],state:1},
{pos:[3,6,29],state:1},
{pos:[4,6,29],state:1},
{pos:[5,6,29],state:1},
{pos:[6,6,29],state:1},
{pos:[7,6,29],state:1},
{pos:[8,6,29],state:1},
{pos:[9,6,29],state:1},
{pos:[10,6,29],state:1},
{pos:[11,6,29],state:1},
{pos:[12,6,29],state:1},
{pos:[13,6,29],state:1},
{pos:[14,6,29],state:1},
{pos:[15,6,29],state:1},
{pos:[16,6,29],state:1},
{pos:[17,6,29],state:1},
{pos:[18,6,29],state:1},
{pos:[19,6,29],state:1},
{pos:[20,6,29],state:1},
{pos:[21,6,29],state:1},
{pos:[22,6,29],state:1},
{pos:[23,6,29],state:1},
{pos:[24,6,29],state:1},
{pos:[25,6,29],state:1},
{pos:[26,6,29],state:1},
{pos:[27,6,29],state:1},
{pos:[28,6,29],state:1},
{pos:[29,6,29],state:1},
{pos:[30,6,29],state:1},
{pos:[0,6,30],state:1},
{pos:[1,6,30],state:1},
{pos:[2,6,30],state:1},
{pos:[3,6,30],state:1},
{pos:[4,6,30],state:1},
{pos:[5,6,30],state:1},
{pos:[6,6,30],state:1},
{pos:[7,6,30],state:1},
{pos:[8,6,30],state:1},
{pos:[9,6,30],state:1},
{pos:[10,6,30],state:1},
{pos:[11,6,30],state:1},
{pos:[12,6,30],state:1},
{pos:[13,6,30],state:1},
{pos:[14,6,30],state:1},
{pos:[15,6,30],state:1},
{pos:[16,6,30],state:1},
{pos:[17,6,30],state:1},
{pos:[18,6,30],state:1},
{pos:[19,6,30],state:1},
{pos:[20,6,30],state:1},
{pos:[21,6,30],state:1},
{pos:[22,6,30],state:1},
{pos:[23,6,30],state:1},
{pos:[24,6,30],state:1},
{pos:[25,6,30],state:1},
{pos:[26,6,30],state:1},
{pos:[27,6,30],state:1},
{pos:[28,6,30],state:1},
{pos:[29,6,30],state:1},
{pos:[30,6,30],state:1},
{pos:[0,7,0],state:1},
{pos:[1,7,0],state:1},
{pos:[2,7,0],state:1},
{pos:[3,7,0],state:1},
{pos:[4,7,0],state:1},
{pos:[5,7,0],state:1},
{pos:[6,7,0],state:1},
{pos:[7,7,0],state:1},
{pos:[8,7,0],state:1},
{pos:[9,7,0],state:1},
{pos:[10,7,0],state:1},
{pos:[11,7,0],state:1},
{pos:[12,7,0],state:1},
{pos:[13,7,0],state:1},
{pos:[14,7,0],state:1},
{pos:[15,7,0],state:1},
{pos:[16,7,0],state:1},
{pos:[17,7,0],state:1},
{pos:[18,7,0],state:1},
{pos:[19,7,0],state:1},
{pos:[20,7,0],state:1},
{pos:[21,7,0],state:1},
{pos:[22,7,0],state:1},
{pos:[23,7,0],state:1},
{pos:[24,7,0],state:1},
{pos:[25,7,0],state:1},
{pos:[26,7,0],state:1},
{pos:[27,7,0],state:1},
{pos:[28,7,0],state:1},
{pos:[29,7,0],state:1},
{pos:[30,7,0],state:1},
{pos:[0,7,1],state:1},
{pos:[1,7,1],state:1},
{pos:[2,7,1],state:1},
{pos:[3,7,1],state:1},
{pos:[4,7,1],state:1},
{pos:[5,7,1],state:1},
{pos:[6,7,1],state:1},
{pos:[7,7,1],state:1},
{pos:[8,7,1],state:1},
{pos:[9,7,1],state:1},
{pos:[10,7,1],state:1},
{pos:[11,7,1],state:1},
{pos:[12,7,1],state:1},
{pos:[13,7,1],state:1},
{pos:[14,7,1],state:1},
{pos:[15,7,1],state:1},
{pos:[16,7,1],state:1},
{pos:[17,7,1],state:1},
{pos:[18,7,1],state:1},
{pos:[19,7,1],state:1},
{pos:[20,7,1],state:1},
{pos:[21,7,1],state:1},
{pos:[22,7,1],state:1},
{pos:[23,7,1],state:1},
{pos:[24,7,1],state:1},
{pos:[25,7,1],state:1},
{pos:[26,7,1],state:1},
{pos:[27,7,1],state:1},
{pos:[28,7,1],state:1},
{pos:[29,7,1],state:1},
{pos:[30,7,1],state:1},
{pos:[0,7,2],state:1},
{pos:[1,7,2],state:1},
{pos:[29,7,2],state:1},
{pos:[30,7,2],state:1},
{pos:[0,7,3],state:1},
{pos:[1,7,3],state:1},
{pos:[29,7,3],state:1},
{pos:[30,7,3],state:1},
{pos:[0,7,4],state:1},
{pos:[1,7,4],state:1},
{pos:[29,7,4],state:1},
{pos:[30,7,4],state:1},
{pos:[0,7,5],state:1},
{pos:[1,7,5],state:1},
{pos:[29,7,5],state:1},
{pos:[30,7,5],state:1},
{pos:[0,7,6],state:1},
{pos:[1,7,6],state:1},
{pos:[29,7,6],state:1},
{pos:[30,7,6],state:1},
{pos:[0,7,7],state:1},
{pos:[1,7,7],state:1},
{pos:[29,7,7],state:1},
{pos:[30,7,7],state:1},
{pos:[0,7,8],state:1},
{pos:[1,7,8],state:1},
{pos:[29,7,8],state:1},
{pos:[30,7,8],state:1},
{pos:[0,7,9],state:1},
{pos:[1,7,9],state:1},
{pos:[29,7,9],state:1},
{pos:[30,7,9],state:1},
{pos:[0,7,10],state:1},
{pos:[1,7,10],state:1},
{pos:[29,7,10],state:1},
{pos:[30,7,10],state:1},
{pos:[0,7,11],state:1},
{pos:[1,7,11],state:1},
{pos:[29,7,11],state:1},
{pos:[30,7,11],state:1},
{pos:[0,7,12],state:1},
{pos:[1,7,12],state:1},
{pos:[29,7,12],state:1},
{pos:[30,7,12],state:1},
{pos:[0,7,13],state:1},
{pos:[1,7,13],state:1},
{pos:[29,7,13],state:1},
{pos:[30,7,13],state:1},
{pos:[0,7,14],state:1},
{pos:[1,7,14],state:1},
{pos:[29,7,14],state:1},
{pos:[30,7,14],state:1},
{pos:[0,7,15],state:1},
{pos:[1,7,15],state:1},
{pos:[29,7,15],state:1},
{pos:[30,7,15],state:1},
{pos:[0,7,16],state:1},
{pos:[1,7,16],state:1},
{pos:[29,7,16],state:1},
{pos:[30,7,16],state:1},
{pos:[0,7,17],state:1},
{pos:[1,7,17],state:1},
{pos:[29,7,17],state:1},
{pos:[30,7,17],state:1},
{pos:[0,7,18],state:1},
{pos:[1,7,18],state:1},
{pos:[29,7,18],state:1},
{pos:[30,7,18],state:1},
{pos:[0,7,19],state:1},
{pos:[1,7,19],state:1},
{pos:[29,7,19],state:1},
{pos:[30,7,19],state:1},
{pos:[0,7,20],state:1},
{pos:[1,7,20],state:1},
{pos:[29,7,20],state:1},
{pos:[30,7,20],state:1},
{pos:[0,7,21],state:1},
{pos:[1,7,21],state:1},
{pos:[29,7,21],state:1},
{pos:[30,7,21],state:1},
{pos:[0,7,22],state:1},
{pos:[1,7,22],state:1},
{pos:[29,7,22],state:1},
{pos:[30,7,22],state:1},
{pos:[0,7,23],state:1},
{pos:[1,7,23],state:1},
{pos:[29,7,23],state:1},
{pos:[30,7,23],state:1},
{pos:[0,7,24],state:1},
{pos:[1,7,24],state:1},
{pos:[29,7,24],state:1},
{pos:[30,7,24],state:1},
{pos:[0,7,25],state:1},
{pos:[1,7,25],state:1},
{pos:[29,7,25],state:1},
{pos:[30,7,25],state:1},
{pos:[0,7,26],state:1},
{pos:[1,7,26],state:1},
{pos:[29,7,26],state:1},
{pos:[30,7,26],state:1},
{pos:[0,7,27],state:1},
{pos:[1,7,27],state:1},
{pos:[29,7,27],state:1},
{pos:[30,7,27],state:1},
{pos:[0,7,28],state:1},
{pos:[1,7,28],state:1},
{pos:[29,7,28],state:1},
{pos:[30,7,28],state:1},
{pos:[0,7,29],state:1},
{pos:[1,7,29],state:1},
{pos:[2,7,29],state:1},
{pos:[3,7,29],state:1},
{pos:[4,7,29],state:1},
{pos:[5,7,29],state:1},
{pos:[6,7,29],state:1},
{pos:[7,7,29],state:1},
{pos:[8,7,29],state:1},
{pos:[9,7,29],state:1},
{pos:[10,7,29],state:1},
{pos:[11,7,29],state:1},
{pos:[12,7,29],state:1},
{pos:[13,7,29],state:1},
{pos:[14,7,29],state:1},
{pos:[15,7,29],state:1},
{pos:[16,7,29],state:1},
{pos:[17,7,29],state:1},
{pos:[18,7,29],state:1},
{pos:[19,7,29],state:1},
{pos:[20,7,29],state:1},
{pos:[21,7,29],state:1},
{pos:[22,7,29],state:1},
{pos:[23,7,29],state:1},
{pos:[24,7,29],state:1},
{pos:[25,7,29],state:1},
{pos:[26,7,29],state:1},
{pos:[27,7,29],state:1},
{pos:[28,7,29],state:1},
{pos:[29,7,29],state:1},
{pos:[30,7,29],state:1},
{pos:[0,7,30],state:1},
{pos:[1,7,30],state:1},
{pos:[2,7,30],state:1},
{pos:[3,7,30],state:1},
{pos:[4,7,30],state:1},
{pos:[5,7,30],state:1},
{pos:[6,7,30],state:1},
{pos:[7,7,30],state:1},
{pos:[8,7,30],state:1},
{pos:[9,7,30],state:1},
{pos:[10,7,30],state:1},
{pos:[11,7,30],state:1},
{pos:[12,7,30],state:1},
{pos:[13,7,30],state:1},
{pos:[14,7,30],state:1},
{pos:[15,7,30],state:1},
{pos:[16,7,30],state:1},
{pos:[17,7,30],state:1},
{pos:[18,7,30],state:1},
{pos:[19,7,30],state:1},
{pos:[20,7,30],state:1},
{pos:[21,7,30],state:1},
{pos:[22,7,30],state:1},
{pos:[23,7,30],state:1},
{pos:[24,7,30],state:1},
{pos:[25,7,30],state:1},
{pos:[26,7,30],state:1},
{pos:[27,7,30],state:1},
{pos:[28,7,30],state:1},
{pos:[29,7,30],state:1},
{pos:[30,7,30],state:1},
{pos:[0,8,0],state:1},
{pos:[1,8,0],state:1},
{pos:[2,8,0],state:1},
{pos:[3,8,0],state:1},
{pos:[4,8,0],state:1},
{pos:[5,8,0],state:1},
{pos:[6,8,0],state:1},
{pos:[7,8,0],state:1},
{pos:[8,8,0],state:1},
{pos:[9,8,0],state:1},
{pos:[10,8,0],state:1},
{pos:[11,8,0],state:1},
{pos:[12,8,0],state:1},
{pos:[13,8,0],state:1},
{pos:[14,8,0],state:1},
{pos:[15,8,0],state:1},
{pos:[16,8,0],state:1},
{pos:[17,8,0],state:1},
{pos:[18,8,0],state:1},
{pos:[19,8,0],state:1},
{pos:[20,8,0],state:1},
{pos:[21,8,0],state:1},
{pos:[22,8,0],state:1},
{pos:[23,8,0],state:1},
{pos:[24,8,0],state:1},
{pos:[25,8,0],state:1},
{pos:[26,8,0],state:1},
{pos:[27,8,0],state:1},
{pos:[28,8,0],state:1},
{pos:[29,8,0],state:1},
{pos:[30,8,0],state:1},
{pos:[0,8,1],state:1},
{pos:[1,8,1],state:1},
{pos:[2,8,1],state:1},
{pos:[3,8,1],state:1},
{pos:[4,8,1],state:1},
{pos:[5,8,1],state:1},
{pos:[6,8,1],state:1},
{pos:[7,8,1],state:1},
{pos:[8,8,1],state:1},
{pos:[9,8,1],state:1},
{pos:[10,8,1],state:1},
{pos:[11,8,1],state:1},
{pos:[12,8,1],state:1},
{pos:[13,8,1],state:1},
{pos:[14,8,1],state:1},
{pos:[15,8,1],state:1},
{pos:[16,8,1],state:1},
{pos:[17,8,1],state:1},
{pos:[18,8,1],state:1},
{pos:[19,8,1],state:1},
{pos:[20,8,1],state:1},
{pos:[21,8,1],state:1},
{pos:[22,8,1],state:1},
{pos:[23,8,1],state:1},
{pos:[24,8,1],state:1},
{pos:[25,8,1],state:1},
{pos:[26,8,1],state:1},
{pos:[27,8,1],state:1},
{pos:[28,8,1],state:1},
{pos:[29,8,1],state:1},
{pos:[30,8,1],state:1},
{pos:[0,8,2],state:1},
{pos:[1,8,2],state:1},
{pos:[29,8,2],state:1},
{pos:[30,8,2],state:1},
{pos:[0,8,3],state:1},
{pos:[1,8,3],state:1},
{pos:[29,8,3],state:1},
{pos:[30,8,3],state:1},
{pos:[0,8,4],state:1},
{pos:[1,8,4],state:1},
{pos:[29,8,4],state:1},
{pos:[30,8,4],state:1},
{pos:[0,8,5],state:1},
{pos:[1,8,5],state:1},
{pos:[29,8,5],state:1},
{pos:[30,8,5],state:1},
{pos:[0,8,6],state:1},
{pos:[1,8,6],state:1},
{pos:[29,8,6],state:1},
{pos:[30,8,6],state:1},
{pos:[0,8,7],state:1},
{pos:[1,8,7],state:1},
{pos:[29,8,7],state:1},
{pos:[30,8,7],state:1},
{pos:[0,8,8],state:1},
{pos:[1,8,8],state:1},
{pos:[29,8,8],state:1},
{pos:[30,8,8],state:1},
{pos:[0,8,9],state:1},
{pos:[1,8,9],state:1},
{pos:[29,8,9],state:1},
{pos:[30,8,9],state:1},
{pos:[0,8,10],state:1},
{pos:[1,8,10],state:1},
{pos:[29,8,10],state:1},
{pos:[30,8,10],state:1},
{pos:[0,8,11],state:1},
{pos:[1,8,11],state:1},
{pos:[29,8,11],state:1},
{pos:[30,8,11],state:1},
{pos:[0,8,12],state:1},
{pos:[1,8,12],state:1},
{pos:[29,8,12],state:1},
{pos:[30,8,12],state:1},
{pos:[0,8,13],state:1},
{pos:[1,8,13],state:1},
{pos:[29,8,13],state:1},
{pos:[30,8,13],state:1},
{pos:[0,8,14],state:1},
{pos:[1,8,14],state:1},
{pos:[29,8,14],state:1},
{pos:[30,8,14],state:1},
{pos:[0,8,15],state:1},
{pos:[1,8,15],state:1},
{pos:[29,8,15],state:1},
{pos:[30,8,15],state:1},
{pos:[0,8,16],state:1},
{pos:[1,8,16],state:1},
{pos:[29,8,16],state:1},
{pos:[30,8,16],state:1},
{pos:[0,8,17],state:1},
{pos:[1,8,17],state:1},
{pos:[29,8,17],state:1},
{pos:[30,8,17],state:1},
{pos:[0,8,18],state:1},
{pos:[1,8,18],state:1},
{pos:[29,8,18],state:1},
{pos:[30,8,18],state:1},
{pos:[0,8,19],state:1},
{pos:[1,8,19],state:1},
{pos:[29,8,19],state:1},
{pos:[30,8,19],state:1},
{pos:[0,8,20],state:1},
{pos:[1,8,20],state:1},
{pos:[29,8,20],state:1},
{pos:[30,8,20],state:1},
{pos:[0,8,21],state:1},
{pos:[1,8,21],state:1},
{pos:[29,8,21],state:1},
{pos:[30,8,21],state:1},
{pos:[0,8,22],state:1},
{pos:[1,8,22],state:1},
{pos:[29,8,22],state:1},
{pos:[30,8,22],state:1},
{pos:[0,8,23],state:1},
{pos:[1,8,23],state:1},
{pos:[29,8,23],state:1},
{pos:[30,8,23],state:1},
{pos:[0,8,24],state:1},
{pos:[1,8,24],state:1},
{pos:[29,8,24],state:1},
{pos:[30,8,24],state:1},
{pos:[0,8,25],state:1},
{pos:[1,8,25],state:1},
{pos:[29,8,25],state:1},
{pos:[30,8,25],state:1},
{pos:[0,8,26],state:1},
{pos:[1,8,26],state:1},
{pos:[29,8,26],state:1},
{pos:[30,8,26],state:1},
{pos:[0,8,27],state:1},
{pos:[1,8,27],state:1},
{pos:[29,8,27],state:1},
{pos:[30,8,27],state:1},
{pos:[0,8,28],state:1},
{pos:[1,8,28],state:1},
{pos:[29,8,28],state:1},
{pos:[30,8,28],state:1},
{pos:[0,8,29],state:1},
{pos:[1,8,29],state:1},
{pos:[2,8,29],state:1},
{pos:[3,8,29],state:1},
{pos:[4,8,29],state:1},
{pos:[5,8,29],state:1},
{pos:[6,8,29],state:1},
{pos:[7,8,29],state:1},
{pos:[8,8,29],state:1},
{pos:[9,8,29],state:1},
{pos:[10,8,29],state:1},
{pos:[11,8,29],state:1},
{pos:[12,8,29],state:1},
{pos:[13,8,29],state:1},
{pos:[14,8,29],state:1},
{pos:[15,8,29],state:1},
{pos:[16,8,29],state:1},
{pos:[17,8,29],state:1},
{pos:[18,8,29],state:1},
{pos:[19,8,29],state:1},
{pos:[20,8,29],state:1},
{pos:[21,8,29],state:1},
{pos:[22,8,29],state:1},
{pos:[23,8,29],state:1},
{pos:[24,8,29],state:1},
{pos:[25,8,29],state:1},
{pos:[26,8,29],state:1},
{pos:[27,8,29],state:1},
{pos:[28,8,29],state:1},
{pos:[29,8,29],state:1},
{pos:[30,8,29],state:1},
{pos:[0,8,30],state:1},
{pos:[1,8,30],state:1},
{pos:[2,8,30],state:1},
{pos:[3,8,30],state:1},
{pos:[4,8,30],state:1},
{pos:[5,8,30],state:1},
{pos:[6,8,30],state:1},
{pos:[7,8,30],state:1},
{pos:[8,8,30],state:1},
{pos:[9,8,30],state:1},
{pos:[10,8,30],state:1},
{pos:[11,8,30],state:1},
{pos:[12,8,30],state:1},
{pos:[13,8,30],state:1},
{pos:[14,8,30],state:1},
{pos:[15,8,30],state:1},
{pos:[16,8,30],state:1},
{pos:[17,8,30],state:1},
{pos:[18,8,30],state:1},
{pos:[19,8,30],state:1},
{pos:[20,8,30],state:1},
{pos:[21,8,30],state:1},
{pos:[22,8,30],state:1},
{pos:[23,8,30],state:1},
{pos:[24,8,30],state:1},
{pos:[25,8,30],state:1},
{pos:[26,8,30],state:1},
{pos:[27,8,30],state:1},
{pos:[28,8,30],state:1},
{pos:[29,8,30],state:1},
{pos:[30,8,30],state:1},
{pos:[0,9,0],state:1},
{pos:[1,9,0],state:1},
{pos:[2,9,0],state:1},
{pos:[3,9,0],state:1},
{pos:[4,9,0],state:1},
{pos:[5,9,0],state:1},
{pos:[6,9,0],state:1},
{pos:[7,9,0],state:1},
{pos:[8,9,0],state:1},
{pos:[9,9,0],state:1},
{pos:[10,9,0],state:1},
{pos:[11,9,0],state:1},
{pos:[12,9,0],state:1},
{pos:[13,9,0],state:1},
{pos:[14,9,0],state:1},
{pos:[15,9,0],state:1},
{pos:[16,9,0],state:1},
{pos:[17,9,0],state:1},
{pos:[18,9,0],state:1},
{pos:[19,9,0],state:1},
{pos:[20,9,0],state:1},
{pos:[21,9,0],state:1},
{pos:[22,9,0],state:1},
{pos:[23,9,0],state:1},
{pos:[24,9,0],state:1},
{pos:[25,9,0],state:1},
{pos:[26,9,0],state:1},
{pos:[27,9,0],state:1},
{pos:[28,9,0],state:1},
{pos:[29,9,0],state:1},
{pos:[30,9,0],state:1},
{pos:[0,9,1],state:1},
{pos:[1,9,1],state:1},
{pos:[2,9,1],state:1},
{pos:[3,9,1],state:1},
{pos:[4,9,1],state:1},
{pos:[5,9,1],state:1},
{pos:[6,9,1],state:1},
{pos:[7,9,1],state:1},
{pos:[8,9,1],state:1},
{pos:[9,9,1],state:1},
{pos:[10,9,1],state:1},
{pos:[11,9,1],state:1},
{pos:[12,9,1],state:1},
{pos:[13,9,1],state:1},
{pos:[14,9,1],state:1},
{pos:[15,9,1],state:1},
{pos:[16,9,1],state:1},
{pos:[17,9,1],state:1},
{pos:[18,9,1],state:1},
{pos:[19,9,1],state:1},
{pos:[20,9,1],state:1},
{pos:[21,9,1],state:1},
{pos:[22,9,1],state:1},
{pos:[23,9,1],state:1},
{pos:[24,9,1],state:1},
{pos:[25,9,1],state:1},
{pos:[26,9,1],state:1},
{pos:[27,9,1],state:1},
{pos:[28,9,1],state:1},
{pos:[29,9,1],state:1},
{pos:[30,9,1],state:1},
{pos:[0,9,2],state:1},
{pos:[1,9,2],state:1},
{pos:[29,9,2],state:1},
{pos:[30,9,2],state:1},
{pos:[0,9,3],state:1},
{pos:[1,9,3],state:1},
{pos:[29,9,3],state:1},
{pos:[30,9,3],state:1},
{pos:[0,9,4],state:1},
{pos:[1,9,4],state:1},
{pos:[29,9,4],state:1},
{pos:[30,9,4],state:1},
{pos:[0,9,5],state:1},
{pos:[1,9,5],state:1},
{pos:[29,9,5],state:1},
{pos:[30,9,5],state:1},
{pos:[0,9,6],state:1},
{pos:[1,9,6],state:1},
{pos:[29,9,6],state:1},
{pos:[30,9,6],state:1},
{pos:[0,9,7],state:1},
{pos:[1,9,7],state:1},
{pos:[29,9,7],state:1},
{pos:[30,9,7],state:1},
{pos:[0,9,8],state:1},
{pos:[1,9,8],state:1},
{pos:[29,9,8],state:1},
{pos:[30,9,8],state:1},
{pos:[0,9,9],state:1},
{pos:[1,9,9],state:1},
{pos:[29,9,9],state:1},
{pos:[30,9,9],state:1},
{pos:[0,9,10],state:1},
{pos:[1,9,10],state:1},
{pos:[29,9,10],state:1},
{pos:[30,9,10],state:1},
{pos:[0,9,11],state:1},
{pos:[1,9,11],state:1},
{pos:[29,9,11],state:1},
{pos:[30,9,11],state:1},
{pos:[0,9,12],state:1},
{pos:[1,9,12],state:1},
{pos:[29,9,12],state:1},
{pos:[30,9,12],state:1},
{pos:[0,9,13],state:1},
{pos:[1,9,13],state:1},
{pos:[29,9,13],state:1},
{pos:[30,9,13],state:1},
{pos:[0,9,14],state:1},
{pos:[1,9,14],state:1},
{pos:[29,9,14],state:1},
{pos:[30,9,14],state:1},
{pos:[0,9,15],state:1},
{pos:[1,9,15],state:1},
{pos:[29,9,15],state:1},
{pos:[30,9,15],state:1},
{pos:[0,9,16],state:1},
{pos:[1,9,16],state:1},
{pos:[29,9,16],state:1},
{pos:[30,9,16],state:1},
{pos:[0,9,17],state:1},
{pos:[1,9,17],state:1},
{pos:[29,9,17],state:1},
{pos:[30,9,17],state:1},
{pos:[0,9,18],state:1},
{pos:[1,9,18],state:1},
{pos:[29,9,18],state:1},
{pos:[30,9,18],state:1},
{pos:[0,9,19],state:1},
{pos:[1,9,19],state:1},
{pos:[29,9,19],state:1},
{pos:[30,9,19],state:1},
{pos:[0,9,20],state:1},
{pos:[1,9,20],state:1},
{pos:[29,9,20],state:1},
{pos:[30,9,20],state:1},
{pos:[0,9,21],state:1},
{pos:[1,9,21],state:1},
{pos:[29,9,21],state:1},
{pos:[30,9,21],state:1},
{pos:[0,9,22],state:1},
{pos:[1,9,22],state:1},
{pos:[29,9,22],state:1},
{pos:[30,9,22],state:1},
{pos:[0,9,23],state:1},
{pos:[1,9,23],state:1},
{pos:[29,9,23],state:1},
{pos:[30,9,23],state:1},
{pos:[0,9,24],state:1},
{pos:[1,9,24],state:1},
{pos:[29,9,24],state:1},
{pos:[30,9,24],state:1},
{pos:[0,9,25],state:1},
{pos:[1,9,25],state:1},
{pos:[29,9,25],state:1},
{pos:[30,9,25],state:1},
{pos:[0,9,26],state:1},
{pos:[1,9,26],state:1},
{pos:[29,9,26],state:1},
{pos:[30,9,26],state:1},
{pos:[0,9,27],state:1},
{pos:[1,9,27],state:1},
{pos:[29,9,27],state:1},
{pos:[30,9,27],state:1},
{pos:[0,9,28],state:1},
{pos:[1,9,28],state:1},
{pos:[29,9,28],state:1},
{pos:[30,9,28],state:1},
{pos:[0,9,29],state:1},
{pos:[1,9,29],state:1},
{pos:[2,9,29],state:1},
{pos:[3,9,29],state:1},
{pos:[4,9,29],state:1},
{pos:[5,9,29],state:1},
{pos:[6,9,29],state:1},
{pos:[7,9,29],state:1},
{pos:[8,9,29],state:1},
{pos:[9,9,29],state:1},
{pos:[10,9,29],state:1},
{pos:[11,9,29],state:1},
{pos:[12,9,29],state:1},
{pos:[13,9,29],state:1},
{pos:[14,9,29],state:1},
{pos:[15,9,29],state:1},
{pos:[16,9,29],state:1},
{pos:[17,9,29],state:1},
{pos:[18,9,29],state:1},
{pos:[19,9,29],state:1},
{pos:[20,9,29],state:1},
{pos:[21,9,29],state:1},
{pos:[22,9,29],state:1},
{pos:[23,9,29],state:1},
{pos:[24,9,29],state:1},
{pos:[25,9,29],state:1},
{pos:[26,9,29],state:1},
{pos:[27,9,29],state:1},
{pos:[28,9,29],state:1},
{pos:[29,9,29],state:1},
{pos:[30,9,29],state:1},
{pos:[0,9,30],state:1},
{pos:[1,9,30],state:1},
{pos:[2,9,30],state:1},
{pos:[3,9,30],state:1},
{pos:[4,9,30],state:1},
{pos:[5,9,30],state:1},
{pos:[6,9,30],state:1},
{pos:[7,9,30],state:1},
{pos:[8,9,30],state:1},
{pos:[9,9,30],state:1},
{pos:[10,9,30],state:1},
{pos:[11,9,30],state:1},
{pos:[12,9,30],state:1},
{pos:[13,9,30],state:1},
{pos:[14,9,30],state:1},
{pos:[15,9,30],state:1},
{pos:[16,9,30],state:1},
{pos:[17,9,30],state:1},
{pos:[18,9,30],state:1},
{pos:[19,9,30],state:1},
{pos:[20,9,30],state:1},
{pos:[21,9,30],state:1},
{pos:[22,9,30],state:1},
{pos:[23,9,30],state:1},
{pos:[24,9,30],state:1},
{pos:[25,9,30],state:1},
{pos:[26,9,30],state:1},
{pos:[27,9,30],state:1},
{pos:[28,9,30],state:1},
{pos:[29,9,30],state:1},
{pos:[30,9,30],state:1},
{pos:[0,10,0],state:1},
{pos:[1,10,0],state:1},
{pos:[2,10,0],state:1},
{pos:[3,10,0],state:1},
{pos:[4,10,0],state:1},
{pos:[5,10,0],state:1},
{pos:[6,10,0],state:1},
{pos:[7,10,0],state:1},
{pos:[8,10,0],state:1},
{pos:[9,10,0],state:1},
{pos:[10,10,0],state:1},
{pos:[11,10,0],state:1},
{pos:[12,10,0],state:1},
{pos:[13,10,0],state:1},
{pos:[14,10,0],state:1},
{pos:[15,10,0],state:1},
{pos:[16,10,0],state:1},
{pos:[17,10,0],state:1},
{pos:[18,10,0],state:1},
{pos:[19,10,0],state:1},
{pos:[20,10,0],state:1},
{pos:[21,10,0],state:1},
{pos:[22,10,0],state:1},
{pos:[23,10,0],state:1},
{pos:[24,10,0],state:1},
{pos:[25,10,0],state:1},
{pos:[26,10,0],state:1},
{pos:[27,10,0],state:1},
{pos:[28,10,0],state:1},
{pos:[29,10,0],state:1},
{pos:[30,10,0],state:1},
{pos:[0,10,1],state:1},
{pos:[1,10,1],state:1},
{pos:[2,10,1],state:1},
{pos:[3,10,1],state:1},
{pos:[4,10,1],state:1},
{pos:[5,10,1],state:1},
{pos:[6,10,1],state:1},
{pos:[7,10,1],state:1},
{pos:[8,10,1],state:1},
{pos:[9,10,1],state:1},
{pos:[10,10,1],state:1},
{pos:[11,10,1],state:1},
{pos:[12,10,1],state:1},
{pos:[13,10,1],state:1},
{pos:[14,10,1],state:1},
{pos:[15,10,1],state:1},
{pos:[16,10,1],state:1},
{pos:[17,10,1],state:1},
{pos:[18,10,1],state:1},
{pos:[19,10,1],state:1},
{pos:[20,10,1],state:1},
{pos:[21,10,1],state:1},
{pos:[22,10,1],state:1},
{pos:[23,10,1],state:1},
{pos:[24,10,1],state:1},
{pos:[25,10,1],state:1},
{pos:[26,10,1],state:1},
{pos:[27,10,1],state:1},
{pos:[28,10,1],state:1},
{pos:[29,10,1],state:1},
{pos:[30,10,1],state:1},
{pos:[0,10,2],state:1},
{pos:[1,10,2],state:1},
{pos:[29,10,2],state:1},
{pos:[30,10,2],state:1},
{pos:[0,10,3],state:1},
{pos:[1,10,3],state:1},
{pos:[29,10,3],state:1},
{pos:[30,10,3],state:1},
{pos:[0,10,4],state:1},
{pos:[1,10,4],state:1},
{pos:[29,10,4],state:1},
{pos:[30,10,4],state:1},
{pos:[0,10,5],state:1},
{pos:[1,10,5],state:1},
{pos:[29,10,5],state:1},
{pos:[30,10,5],state:1},
{pos:[0,10,6],state:1},
{pos:[1,10,6],state:1},
{pos:[29,10,6],state:1},
{pos:[30,10,6],state:1},
{pos:[0,10,7],state:1},
{pos:[1,10,7],state:1},
{pos:[29,10,7],state:1},
{pos:[30,10,7],state:1},
{pos:[0,10,8],state:1},
{pos:[1,10,8],state:1},
{pos:[29,10,8],state:1},
{pos:[30,10,8],state:1},
{pos:[0,10,9],state:1},
{pos:[1,10,9],state:1},
{pos:[29,10,9],state:1},
{pos:[30,10,9],state:1},
{pos:[0,10,10],state:1},
{pos:[1,10,10],state:1},
{pos:[29,10,10],state:1},
{pos:[30,10,10],state:1},
{pos:[0,10,11],state:1},
{pos:[1,10,11],state:1},
{pos:[29,10,11],state:1},
{pos:[30,10,11],state:1},
{pos:[0,10,12],state:1},
{pos:[1,10,12],state:1},
{pos:[29,10,12],state:1},
{pos:[30,10,12],state:1},
{pos:[0,10,13],state:1},
{pos:[1,10,13],state:1},
{pos:[29,10,13],state:1},
{pos:[30,10,13],state:1},
{pos:[0,10,14],state:1},
{pos:[1,10,14],state:1},
{pos:[29,10,14],state:1},
{pos:[30,10,14],state:1},
{pos:[0,10,15],state:1},
{pos:[1,10,15],state:1},
{pos:[29,10,15],state:1},
{pos:[30,10,15],state:1},
{pos:[0,10,16],state:1},
{pos:[1,10,16],state:1},
{pos:[29,10,16],state:1},
{pos:[30,10,16],state:1},
{pos:[0,10,17],state:1},
{pos:[1,10,17],state:1},
{pos:[29,10,17],state:1},
{pos:[30,10,17],state:1},
{pos:[0,10,18],state:1},
{pos:[1,10,18],state:1},
{pos:[29,10,18],state:1},
{pos:[30,10,18],state:1},
{pos:[0,10,19],state:1},
{pos:[1,10,19],state:1},
{pos:[29,10,19],state:1},
{pos:[30,10,19],state:1},
{pos:[0,10,20],state:1},
{pos:[1,10,20],state:1},
{pos:[29,10,20],state:1},
{pos:[30,10,20],state:1},
{pos:[0,10,21],state:1},
{pos:[1,10,21],state:1},
{pos:[29,10,21],state:1},
{pos:[30,10,21],state:1},
{pos:[0,10,22],state:1},
{pos:[1,10,22],state:1},
{pos:[29,10,22],state:1},
{pos:[30,10,22],state:1},
{pos:[0,10,23],state:1},
{pos:[1,10,23],state:1},
{pos:[29,10,23],state:1},
{pos:[30,10,23],state:1},
{pos:[0,10,24],state:1},
{pos:[1,10,24],state:1},
{pos:[29,10,24],state:1},
{pos:[30,10,24],state:1},
{pos:[0,10,25],state:1},
{pos:[1,10,25],state:1},
{pos:[29,10,25],state:1},
{pos:[30,10,25],state:1},
{pos:[0,10,26],state:1},
{pos:[1,10,26],state:1},
{pos:[29,10,26],state:1},
{pos:[30,10,26],state:1},
{pos:[0,10,27],state:1},
{pos:[1,10,27],state:1},
{pos:[29,10,27],state:1},
{pos:[30,10,27],state:1},
{pos:[0,10,28],state:1},
{pos:[1,10,28],state:1},
{pos:[29,10,28],state:1},
{pos:[30,10,28],state:1},
{pos:[0,10,29],state:1},
{pos:[1,10,29],state:1},
{pos:[2,10,29],state:1},
{pos:[3,10,29],state:1},
{pos:[4,10,29],state:1},
{pos:[5,10,29],state:1},
{pos:[6,10,29],state:1},
{pos:[7,10,29],state:1},
{pos:[8,10,29],state:1},
{pos:[9,10,29],state:1},
{pos:[10,10,29],state:1},
{pos:[11,10,29],state:1},
{pos:[12,10,29],state:1},
{pos:[13,10,29],state:1},
{pos:[14,10,29],state:1},
{pos:[15,10,29],state:1},
{pos:[16,10,29],state:1},
{pos:[17,10,29],state:1},
{pos:[18,10,29],state:1},
{pos:[19,10,29],state:1},
{pos:[20,10,29],state:1},
{pos:[21,10,29],state:1},
{pos:[22,10,29],state:1},
{pos:[23,10,29],state:1},
{pos:[24,10,29],state:1},
{pos:[25,10,29],state:1},
{pos:[26,10,29],state:1},
{pos:[27,10,29],state:1},
{pos:[28,10,29],state:1},
{pos:[29,10,29],state:1},
{pos:[30,10,29],state:1},
{pos:[0,10,30],state:1},
{pos:[1,10,30],state:1},
{pos:[2,10,30],state:1},
{pos:[3,10,30],state:1},
{pos:[4,10,30],state:1},
{pos:[5,10,30],state:1},
{pos:[6,10,30],state:1},
{pos:[7,10,30],state:1},
{pos:[8,10,30],state:1},
{pos:[9,10,30],state:1},
{pos:[10,10,30],state:1},
{pos:[11,10,30],state:1},
{pos:[12,10,30],state:1},
{pos:[13,10,30],state:1},
{pos:[14,10,30],state:1},
{pos:[15,10,30],state:1},
{pos:[16,10,30],state:1},
{pos:[17,10,30],state:1},
{pos:[18,10,30],state:1},
{pos:[19,10,30],state:1},
{pos:[20,10,30],state:1},
{pos:[21,10,30],state:1},
{pos:[22,10,30],state:1},
{pos:[23,10,30],state:1},
{pos:[24,10,30],state:1},
{pos:[25,10,30],state:1},
{pos:[26,10,30],state:1},
{pos:[27,10,30],state:1},
{pos:[28,10,30],state:1},
{pos:[29,10,30],state:1},
{pos:[30,10,30],state:1},
{pos:[0,11,0],state:1},
{pos:[1,11,0],state:1},
{pos:[2,11,0],state:1},
{pos:[3,11,0],state:1},
{pos:[4,11,0],state:1},
{pos:[5,11,0],state:1},
{pos:[6,11,0],state:1},
{pos:[7,11,0],state:1},
{pos:[8,11,0],state:1},
{pos:[9,11,0],state:1},
{pos:[10,11,0],state:1},
{pos:[11,11,0],state:1},
{pos:[12,11,0],state:1},
{pos:[13,11,0],state:1},
{pos:[14,11,0],state:1},
{pos:[15,11,0],state:1},
{pos:[16,11,0],state:1},
{pos:[17,11,0],state:1},
{pos:[18,11,0],state:1},
{pos:[19,11,0],state:1},
{pos:[20,11,0],state:1},
{pos:[21,11,0],state:1},
{pos:[22,11,0],state:1},
{pos:[23,11,0],state:1},
{pos:[24,11,0],state:1},
{pos:[25,11,0],state:1},
{pos:[26,11,0],state:1},
{pos:[27,11,0],state:1},
{pos:[28,11,0],state:1},
{pos:[29,11,0],state:1},
{pos:[30,11,0],state:1},
{pos:[0,11,1],state:1},
{pos:[1,11,1],state:1},
{pos:[2,11,1],state:1},
{pos:[3,11,1],state:1},
{pos:[4,11,1],state:1},
{pos:[5,11,1],state:1},
{pos:[6,11,1],state:1},
{pos:[7,11,1],state:1},
{pos:[8,11,1],state:1},
{pos:[9,11,1],state:1},
{pos:[10,11,1],state:1},
{pos:[11,11,1],state:1},
{pos:[12,11,1],state:1},
{pos:[13,11,1],state:1},
{pos:[14,11,1],state:1},
{pos:[15,11,1],state:1},
{pos:[16,11,1],state:1},
{pos:[17,11,1],state:1},
{pos:[18,11,1],state:1},
{pos:[19,11,1],state:1},
{pos:[20,11,1],state:1},
{pos:[21,11,1],state:1},
{pos:[22,11,1],state:1},
{pos:[23,11,1],state:1},
{pos:[24,11,1],state:1},
{pos:[25,11,1],state:1},
{pos:[26,11,1],state:1},
{pos:[27,11,1],state:1},
{pos:[28,11,1],state:1},
{pos:[29,11,1],state:1},
{pos:[30,11,1],state:1},
{pos:[0,11,2],state:1},
{pos:[1,11,2],state:1},
{pos:[29,11,2],state:1},
{pos:[30,11,2],state:1},
{pos:[0,11,3],state:1},
{pos:[1,11,3],state:1},
{pos:[29,11,3],state:1},
{pos:[30,11,3],state:1},
{pos:[0,11,4],state:1},
{pos:[1,11,4],state:1},
{pos:[29,11,4],state:1},
{pos:[30,11,4],state:1},
{pos:[0,11,5],state:1},
{pos:[1,11,5],state:1},
{pos:[29,11,5],state:1},
{pos:[30,11,5],state:1},
{pos:[0,11,6],state:1},
{pos:[1,11,6],state:1},
{pos:[29,11,6],state:1},
{pos:[30,11,6],state:1},
{pos:[0,11,7],state:1},
{pos:[1,11,7],state:1},
{pos:[29,11,7],state:1},
{pos:[30,11,7],state:1},
{pos:[0,11,8],state:1},
{pos:[1,11,8],state:1},
{pos:[29,11,8],state:1},
{pos:[30,11,8],state:1},
{pos:[0,11,9],state:1},
{pos:[1,11,9],state:1},
{pos:[29,11,9],state:1},
{pos:[30,11,9],state:1},
{pos:[0,11,10],state:1},
{pos:[1,11,10],state:1},
{pos:[29,11,10],state:1},
{pos:[30,11,10],state:1},
{pos:[0,11,11],state:1},
{pos:[1,11,11],state:1},
{pos:[29,11,11],state:1},
{pos:[30,11,11],state:1},
{pos:[0,11,12],state:1},
{pos:[1,11,12],state:1},
{pos:[29,11,12],state:1},
{pos:[30,11,12],state:1},
{pos:[0,11,13],state:1},
{pos:[1,11,13],state:1},
{pos:[29,11,13],state:1},
{pos:[30,11,13],state:1},
{pos:[0,11,14],state:1},
{pos:[1,11,14],state:1},
{pos:[29,11,14],state:1},
{pos:[30,11,14],state:1},
{pos:[0,11,15],state:1},
{pos:[1,11,15],state:1},
{pos:[29,11,15],state:1},
{pos:[30,11,15],state:1},
{pos:[0,11,16],state:1},
{pos:[1,11,16],state:1},
{pos:[29,11,16],state:1},
{pos:[30,11,16],state:1},
{pos:[0,11,17],state:1},
{pos:[1,11,17],state:1},
{pos:[29,11,17],state:1},
{pos:[30,11,17],state:1},
{pos:[0,11,18],state:1},
{pos:[1,11,18],state:1},
{pos:[29,11,18],state:1},
{pos:[30,11,18],state:1},
{pos:[0,11,19],state:1},
{pos:[1,11,19],state:1},
{pos:[29,11,19],state:1},
{pos:[30,11,19],state:1},
{pos:[0,11,20],state:1},
{pos:[1,11,20],state:1},
{pos:[29,11,20],state:1},
{pos:[30,11,20],state:1},
{pos:[0,11,21],state:1},
{pos:[1,11,21],state:1},
{pos:[29,11,21],state:1},
{pos:[30,11,21],state:1},
{pos:[0,11,22],state:1},
{pos:[1,11,22],state:1},
{pos:[29,11,22],state:1},
{pos:[30,11,22],state:1},
{pos:[0,11,23],state:1},
{pos:[1,11,23],state:1},
{pos:[29,11,23],state:1},
{pos:[30,11,23],state:1},
{pos:[0,11,24],state:1},
{pos:[1,11,24],state:1},
{pos:[29,11,24],state:1},
{pos:[30,11,24],state:1},
{pos:[0,11,25],state:1},
{pos:[1,11,25],state:1},
{pos:[29,11,25],state:1},
{pos:[30,11,25],state:1},
{pos:[0,11,26],state:1},
{pos:[1,11,26],state:1},
{pos:[29,11,26],state:1},
{pos:[30,11,26],state:1},
{pos:[0,11,27],state:1},
{pos:[1,11,27],state:1},
{pos:[29,11,27],state:1},
{pos:[30,11,27],state:1},
{pos:[0,11,28],state:1},
{pos:[1,11,28],state:1},
{pos:[29,11,28],state:1},
{pos:[30,11,28],state:1},
{pos:[0,11,29],state:1},
{pos:[1,11,29],state:1},
{pos:[2,11,29],state:1},
{pos:[3,11,29],state:1},
{pos:[4,11,29],state:1},
{pos:[5,11,29],state:1},
{pos:[6,11,29],state:1},
{pos:[7,11,29],state:1},
{pos:[8,11,29],state:1},
{pos:[9,11,29],state:1},
{pos:[10,11,29],state:1},
{pos:[11,11,29],state:1},
{pos:[12,11,29],state:1},
{pos:[13,11,29],state:1},
{pos:[14,11,29],state:1},
{pos:[15,11,29],state:1},
{pos:[16,11,29],state:1},
{pos:[17,11,29],state:1},
{pos:[18,11,29],state:1},
{pos:[19,11,29],state:1},
{pos:[20,11,29],state:1},
{pos:[21,11,29],state:1},
{pos:[22,11,29],state:1},
{pos:[23,11,29],state:1},
{pos:[24,11,29],state:1},
{pos:[25,11,29],state:1},
{pos:[26,11,29],state:1},
{pos:[27,11,29],state:1},
{pos:[28,11,29],state:1},
{pos:[29,11,29],state:1},
{pos:[30,11,29],state:1},
{pos:[0,11,30],state:1},
{pos:[1,11,30],state:1},
{pos:[2,11,30],state:1},
{pos:[3,11,30],state:1},
{pos:[4,11,30],state:1},
{pos:[5,11,30],state:1},
{pos:[6,11,30],state:1},
{pos:[7,11,30],state:1},
{pos:[8,11,30],state:1},
{pos:[9,11,30],state:1},
{pos:[10,11,30],state:1},
{pos:[11,11,30],state:1},
{pos:[12,11,30],state:1},
{pos:[13,11,30],state:1},
{pos:[14,11,30],state:1},
{pos:[15,11,30],state:1},
{pos:[16,11,30],state:1},
{pos:[17,11,30],state:1},
{pos:[18,11,30],state:1},
{pos:[19,11,30],state:1},
{pos:[20,11,30],state:1},
{pos:[21,11,30],state:1},
{pos:[22,11,30],state:1},
{pos:[23,11,30],state:1},
{pos:[24,11,30],state:1},
{pos:[25,11,30],state:1},
{pos:[26,11,30],state:1},
{pos:[27,11,30],state:1},
{pos:[28,11,30],state:1},
{pos:[29,11,30],state:1},
{pos:[30,11,30],state:1},
{pos:[0,12,0],state:1},
{pos:[1,12,0],state:1},
{pos:[2,12,0],state:1},
{pos:[3,12,0],state:1},
{pos:[4,12,0],state:1},
{pos:[5,12,0],state:1},
{pos:[6,12,0],state:1},
{pos:[7,12,0],state:1},
{pos:[8,12,0],state:1},
{pos:[9,12,0],state:1},
{pos:[10,12,0],state:1},
{pos:[11,12,0],state:1},
{pos:[12,12,0],state:1},
{pos:[13,12,0],state:1},
{pos:[14,12,0],state:1},
{pos:[15,12,0],state:1},
{pos:[16,12,0],state:1},
{pos:[17,12,0],state:1},
{pos:[18,12,0],state:1},
{pos:[19,12,0],state:1},
{pos:[20,12,0],state:1},
{pos:[21,12,0],state:1},
{pos:[22,12,0],state:1},
{pos:[23,12,0],state:1},
{pos:[24,12,0],state:1},
{pos:[25,12,0],state:1},
{pos:[26,12,0],state:1},
{pos:[27,12,0],state:1},
{pos:[28,12,0],state:1},
{pos:[29,12,0],state:1},
{pos:[30,12,0],state:1},
{pos:[0,12,1],state:1},
{pos:[1,12,1],state:1},
{pos:[2,12,1],state:1},
{pos:[3,12,1],state:1},
{pos:[4,12,1],state:1},
{pos:[5,12,1],state:1},
{pos:[6,12,1],state:1},
{pos:[7,12,1],state:1},
{pos:[8,12,1],state:1},
{pos:[9,12,1],state:1},
{pos:[10,12,1],state:1},
{pos:[11,12,1],state:1},
{pos:[12,12,1],state:1},
{pos:[13,12,1],state:1},
{pos:[14,12,1],state:1},
{pos:[15,12,1],state:1},
{pos:[16,12,1],state:1},
{pos:[17,12,1],state:1},
{pos:[18,12,1],state:1},
{pos:[19,12,1],state:1},
{pos:[20,12,1],state:1},
{pos:[21,12,1],state:1},
{pos:[22,12,1],state:1},
{pos:[23,12,1],state:1},
{pos:[24,12,1],state:1},
{pos:[25,12,1],state:1},
{pos:[26,12,1],state:1},
{pos:[27,12,1],state:1},
{pos:[28,12,1],state:1},
{pos:[29,12,1],state:1},
{pos:[30,12,1],state:1},
{pos:[0,12,2],state:1},
{pos:[1,12,2],state:1},
{pos:[29,12,2],state:1},
{pos:[30,12,2],state:1},
{pos:[0,12,3],state:1},
{pos:[1,12,3],state:1},
{pos:[29,12,3],state:1},
{pos:[30,12,3],state:1},
{pos:[0,12,4],state:1},
{pos:[1,12,4],state:1},
{pos:[29,12,4],state:1},
{pos:[30,12,4],state:1},
{pos:[0,12,5],state:1},
{pos:[1,12,5],state:1},
{pos:[29,12,5],state:1},
{pos:[30,12,5],state:1},
{pos:[0,12,6],state:1},
{pos:[1,12,6],state:1},
{pos:[29,12,6],state:1},
{pos:[30,12,6],state:1},
{pos:[0,12,7],state:1},
{pos:[1,12,7],state:1},
{pos:[29,12,7],state:1},
{pos:[30,12,7],state:1},
{pos:[0,12,8],state:1},
{pos:[1,12,8],state:1},
{pos:[29,12,8],state:1},
{pos:[30,12,8],state:1},
{pos:[0,12,9],state:1},
{pos:[1,12,9],state:1},
{pos:[29,12,9],state:1},
{pos:[30,12,9],state:1},
{pos:[0,12,10],state:1},
{pos:[1,12,10],state:1},
{pos:[29,12,10],state:1},
{pos:[30,12,10],state:1},
{pos:[0,12,11],state:1},
{pos:[1,12,11],state:1},
{pos:[29,12,11],state:1},
{pos:[30,12,11],state:1},
{pos:[0,12,12],state:1},
{pos:[1,12,12],state:1},
{pos:[29,12,12],state:1},
{pos:[30,12,12],state:1},
{pos:[0,12,13],state:1},
{pos:[1,12,13],state:1},
{pos:[29,12,13],state:1},
{pos:[30,12,13],state:1},
{pos:[0,12,14],state:1},
{pos:[1,12,14],state:1},
{pos:[29,12,14],state:1},
{pos:[30,12,14],state:1},
{pos:[0,12,15],state:1},
{pos:[1,12,15],state:1},
{pos:[29,12,15],state:1},
{pos:[30,12,15],state:1},
{pos:[0,12,16],state:1},
{pos:[1,12,16],state:1},
{pos:[29,12,16],state:1},
{pos:[30,12,16],state:1},
{pos:[0,12,17],state:1},
{pos:[1,12,17],state:1},
{pos:[29,12,17],state:1},
{pos:[30,12,17],state:1},
{pos:[0,12,18],state:1},
{pos:[1,12,18],state:1},
{pos:[29,12,18],state:1},
{pos:[30,12,18],state:1},
{pos:[0,12,19],state:1},
{pos:[1,12,19],state:1},
{pos:[29,12,19],state:1},
{pos:[30,12,19],state:1},
{pos:[0,12,20],state:1},
{pos:[1,12,20],state:1},
{pos:[29,12,20],state:1},
{pos:[30,12,20],state:1},
{pos:[0,12,21],state:1},
{pos:[1,12,21],state:1},
{pos:[29,12,21],state:1},
{pos:[30,12,21],state:1},
{pos:[0,12,22],state:1},
{pos:[1,12,22],state:1},
{pos:[29,12,22],state:1},
{pos:[30,12,22],state:1},
{pos:[0,12,23],state:1},
{pos:[1,12,23],state:1},
{pos:[29,12,23],state:1},
{pos:[30,12,23],state:1},
{pos:[0,12,24],state:1},
{pos:[1,12,24],state:1},
{pos:[29,12,24],state:1},
{pos:[30,12,24],state:1},
{pos:[0,12,25],state:1},
{pos:[1,12,25],state:1},
{pos:[29,12,25],state:1},
{pos:[30,12,25],state:1},
{pos:[0,12,26],state:1},
{pos:[1,12,26],state:1},
{pos:[29,12,26],state:1},
{pos:[30,12,26],state:1},
{pos:[0,12,27],state:1},
{pos:[1,12,27],state:1},
{pos:[29,12,27],state:1},
{pos:[30,12,27],state:1},
{pos:[0,12,28],state:1},
{pos:[1,12,28],state:1},
{pos:[29,12,28],state:1},
{pos:[30,12,28],state:1},
{pos:[0,12,29],state:1},
{pos:[1,12,29],state:1},
{pos:[2,12,29],state:1},
{pos:[3,12,29],state:1},
{pos:[4,12,29],state:1},
{pos:[5,12,29],state:1},
{pos:[6,12,29],state:1},
{pos:[7,12,29],state:1},
{pos:[8,12,29],state:1},
{pos:[9,12,29],state:1},
{pos:[10,12,29],state:1},
{pos:[11,12,29],state:1},
{pos:[12,12,29],state:1},
{pos:[13,12,29],state:1},
{pos:[14,12,29],state:1},
{pos:[15,12,29],state:1},
{pos:[16,12,29],state:1},
{pos:[17,12,29],state:1},
{pos:[18,12,29],state:1},
{pos:[19,12,29],state:1},
{pos:[20,12,29],state:1},
{pos:[21,12,29],state:1},
{pos:[22,12,29],state:1},
{pos:[23,12,29],state:1},
{pos:[24,12,29],state:1},
{pos:[25,12,29],state:1},
{pos:[26,12,29],state:1},
{pos:[27,12,29],state:1},
{pos:[28,12,29],state:1},
{pos:[29,12,29],state:1},
{pos:[30,12,29],state:1},
{pos:[0,12,30],state:1},
{pos:[1,12,30],state:1},
{pos:[2,12,30],state:1},
{pos:[3,12,30],state:1},
{pos:[4,12,30],state:1},
{pos:[5,12,30],state:1},
{pos:[6,12,30],state:1},
{pos:[7,12,30],state:1},
{pos:[8,12,30],state:1},
{pos:[9,12,30],state:1},
{pos:[10,12,30],state:1},
{pos:[11,12,30],state:1},
{pos:[12,12,30],state:1},
{pos:[13,12,30],state:1},
{pos:[14,12,30],state:1},
{pos:[15,12,30],state:1},
{pos:[16,12,30],state:1},
{pos:[17,12,30],state:1},
{pos:[18,12,30],state:1},
{pos:[19,12,30],state:1},
{pos:[20,12,30],state:1},
{pos:[21,12,30],state:1},
{pos:[22,12,30],state:1},
{pos:[23,12,30],state:1},
{pos:[24,12,30],state:1},
{pos:[25,12,30],state:1},
{pos:[26,12,30],state:1},
{pos:[27,12,30],state:1},
{pos:[28,12,30],state:1},
{pos:[29,12,30],state:1},
{pos:[30,12,30],state:1},
{pos:[0,13,0],state:1},
{pos:[1,13,0],state:1},
{pos:[2,13,0],state:1},
{pos:[3,13,0],state:1},
{pos:[4,13,0],state:1},
{pos:[5,13,0],state:1},
{pos:[6,13,0],state:1},
{pos:[7,13,0],state:1},
{pos:[8,13,0],state:1},
{pos:[9,13,0],state:1},
{pos:[10,13,0],state:1},
{pos:[11,13,0],state:1},
{pos:[12,13,0],state:1},
{pos:[13,13,0],state:1},
{pos:[14,13,0],state:1},
{pos:[15,13,0],state:1},
{pos:[16,13,0],state:1},
{pos:[17,13,0],state:1},
{pos:[18,13,0],state:1},
{pos:[19,13,0],state:1},
{pos:[20,13,0],state:1},
{pos:[21,13,0],state:1},
{pos:[22,13,0],state:1},
{pos:[23,13,0],state:1},
{pos:[24,13,0],state:1},
{pos:[25,13,0],state:1},
{pos:[26,13,0],state:1},
{pos:[27,13,0],state:1},
{pos:[28,13,0],state:1},
{pos:[29,13,0],state:1},
{pos:[30,13,0],state:1},
{pos:[0,13,1],state:1},
{pos:[1,13,1],state:1},
{pos:[2,13,1],state:1},
{pos:[3,13,1],state:1},
{pos:[4,13,1],state:1},
{pos:[5,13,1],state:1},
{pos:[6,13,1],state:1},
{pos:[7,13,1],state:1},
{pos:[8,13,1],state:1},
{pos:[9,13,1],state:1},
{pos:[10,13,1],state:1},
{pos:[11,13,1],state:1},
{pos:[12,13,1],state:1},
{pos:[13,13,1],state:1},
{pos:[14,13,1],state:1},
{pos:[15,13,1],state:1},
{pos:[16,13,1],state:1},
{pos:[17,13,1],state:1},
{pos:[18,13,1],state:1},
{pos:[19,13,1],state:1},
{pos:[20,13,1],state:1},
{pos:[21,13,1],state:1},
{pos:[22,13,1],state:1},
{pos:[23,13,1],state:1},
{pos:[24,13,1],state:1},
{pos:[25,13,1],state:1},
{pos:[26,13,1],state:1},
{pos:[27,13,1],state:1},
{pos:[28,13,1],state:1},
{pos:[29,13,1],state:1},
{pos:[30,13,1],state:1},
{pos:[0,13,2],state:1},
{pos:[1,13,2],state:1},
{pos:[29,13,2],state:1},
{pos:[30,13,2],state:1},
{pos:[0,13,3],state:1},
{pos:[1,13,3],state:1},
{pos:[29,13,3],state:1},
{pos:[30,13,3],state:1},
{pos:[0,13,4],state:1},
{pos:[1,13,4],state:1},
{pos:[29,13,4],state:1},
{pos:[30,13,4],state:1},
{pos:[0,13,5],state:1},
{pos:[1,13,5],state:1},
{pos:[29,13,5],state:1},
{pos:[30,13,5],state:1},
{pos:[0,13,6],state:1},
{pos:[1,13,6],state:1},
{pos:[29,13,6],state:1},
{pos:[30,13,6],state:1},
{pos:[0,13,7],state:1},
{pos:[1,13,7],state:1},
{pos:[29,13,7],state:1},
{pos:[30,13,7],state:1},
{pos:[0,13,8],state:1},
{pos:[1,13,8],state:1},
{pos:[29,13,8],state:1},
{pos:[30,13,8],state:1},
{pos:[0,13,9],state:1},
{pos:[1,13,9],state:1},
{pos:[29,13,9],state:1},
{pos:[30,13,9],state:1},
{pos:[0,13,10],state:1},
{pos:[1,13,10],state:1},
{pos:[29,13,10],state:1},
{pos:[30,13,10],state:1},
{pos:[0,13,11],state:1},
{pos:[1,13,11],state:1},
{pos:[29,13,11],state:1},
{pos:[30,13,11],state:1},
{pos:[0,13,12],state:1},
{pos:[1,13,12],state:1},
{pos:[29,13,12],state:1},
{pos:[30,13,12],state:1},
{pos:[0,13,13],state:1},
{pos:[1,13,13],state:1},
{pos:[29,13,13],state:1},
{pos:[30,13,13],state:1},
{pos:[0,13,14],state:1},
{pos:[1,13,14],state:1},
{pos:[29,13,14],state:1},
